Workbook
Name _15A: [3]가격조사서!$D$4:$D$11
Name _B22: [4]일위대가!$1400:$1413=[4]일위대가!$A$1400
Name _B22: [5]일위대가!$1400:$1413=[5]일위대가!$A$1400
Name _DAN2: [6]단가조사서!$M$1:$N$65536
Name _DAN2: [7]단가조사서!$M$1:$N$65536
Name _JIP1: [6]집계표!$A$1:$K$65536
Name _JIP1: [7]집계표!$A$1:$K$65536
Name _K02: [4]일위대가!$732:$745=[4]일위대가!$A$732
Name _K02: [5]일위대가!$732:$745=[5]일위대가!$A$732
Name _O03: [4]일위대가!$1516:$1529=[4]일위대가!$A$1516
Name _O03: [5]일위대가!$1516:$1529=[5]일위대가!$A$1516
Name _QTY1: [10]SHEET2!$F$3:$F$101
Name _RAN5: [11]토목품셈!$D$1:$AI$146
Name _RAN5: [12]토목품셈!$D$1:$AI$146
Name _RAN6: [11]토목품셈!$BO$1:$BZ$25
Name _RAN6: [12]토목품셈!$BO$1:$BZ$25
Name _RAN7: [11]토목품셈!$CB$1:$CJ$24
Name _RAN7: [12]토목품셈!$CB$1:$CJ$24
Name ABCD: [13]CABdata!$E$22:$F$46
Name ABCD: [14]CABdata!$E$22:$F$46
Name A노임단가: '[15]노무비(DB)'!$A$1:$D$208
Name A노임단가: '[16]노무비(DB)'!$A$1:$D$208
Name bdfgdgr: [17]!Macro8
Name bdfgdgr: [17]!Macro8
Name BLDG: [18]LEGEND!$D$8
Name CABDIA: [13]MOTOR!$A$86:$B$408
Name CABDIA: [14]MOTOR!$A$86:$B$408
Name CABLEA: [13]MOTOR!$B$66:$C$82
Name CABLEA: [14]MOTOR!$B$66:$C$82
Name CABLEB: [13]MOTOR!$D$66:$E$82
Name CABLEB: [14]MOTOR!$D$66:$E$82
Name CABLED: [13]MOTOR!$F$66:$G$82
Name CABLED: [14]MOTOR!$F$66:$G$82
Name CABLEE: [13]MOTOR!$H$66:$I$82
Name CABLEE: [14]MOTOR!$H$66:$I$82
Name CAB허용: [13]MOTOR!$J$66:$N$81
Name CAB허용: [14]MOTOR!$J$66:$N$81
Name cds: 장비견적서!cds
Name cds: [0]!cds
Name cds가로등: 장비견적서!cds가로등
Name cds가로등: [0]!cds가로등
Name CIRCUIT: [19]Sheet1!$C$4:$D$10
Name CLIENT: [18]LEGEND!$D$6
Name CTC: [20]DATA!$H$30:$I$57
Name CTC: [21]DATA!$H$30:$I$57
Name DANGA_: '[22]Y-WORK'!$D$19:$D$19,'[22]Y-WORK'!$F$19:$BD$19
Name DAT: [23]MCC제원!$A$5:$AG$80
Name DAT: [24]MCC제원!$A$5:$AG$80
Name ddd가로등: 장비견적서!ddd가로등
Name ddd가로등: [0]!ddd가로등
Name dfffffs: 장비견적서!dfffffs
Name dfffffs: [0]!dfffffs
Name dffffs가로등: 장비견적서!dffffs가로등
Name dffffs가로등: [0]!dffffs가로등
Name dfs가로등: 장비견적서!dfs가로등
Name dfs가로등: [0]!dfs가로등
Name df가로등: 장비견적서!df가로등
Name df가로등: [0]!df가로등
Name DGS: [25]data!$S$4:$T$32
Name DGS: [26]data!$S$4:$T$32

Sheet 내역서
A1: 공사비 내역서 제출 양식
A3: 연번 | B3: 공종명 | C3: 규격 | D3: 수량 | E3: 단위 | F3: 내역금액 | N3: 비고 | O3: 신기술 보호범위
F4: 재료비 | H4: 노무비 | J4: 경비 | L4: 합계
F5: 단가 | G5: 금액 | H5: 단가 | I5: 금액 | J5: 단가 | K5: 금액 | L5: 단가 | M5: 금액
B6: 부단수 차단(강관제) | C6: 1200 | G6: =INT(SUM(G7:G18)) -> 62922300 | I6: =INT(SUM(I7:I18)) -> 14105559 | K6: =INT(SUM(K7:K18)) -> 18607133 | M6: =G6+I6+K6 -> 95634992
A7: 1 | B7: 바탕처리(강관제) | C7: 1200 | D7: 1 | E7: nr | F7: =일위대가호표!I7 -> 656 | G7: =F7*D7 -> 656 | H7: =일위대가호표!K7 -> 163517 | I7: =H7*D7 -> 163517 | J7: =일위대가호표!M7 -> 915 | K7: =J7*D7 -> 915 | L7: =F7+H7+J7 -> 165088 | M7: =L7*D7 -> 165088 | O7: 연계)기술내용
A8: 2 | B8: 부단수 할정자관 부설 및 접합(강관제) | C8: 1200 | D8: 1 | E8: nr | F8: =일위대가호표!I24 -> 31146687 | G8: =F8*D8 -> 31146687 | H8: =일위대가호표!K24 -> 3875021 | I8: =H8*D8 -> 3875021 | J8: =일위대가호표!M24 -> 855278 | K8: =J8*D8 -> 855278 | L8: =F8+H8+J8 -> 35876986 | M8: =L8*D8 -> 35876986 | O8: 연계)기술내용
A9: 3 | B9: 샌드위치 밸브 부설 및 접합 | C9: 850 | D9: 1 | E9: nr | F9: =일위대가호표!I52 -> 550910 | G9: =F9*D9 -> 550910 | H9: =일위대가호표!K52 -> 498114 | I9: =H9*D9 -> 498114 | J9: =일위대가호표!M52 -> 1169510 | K9: =J9*D9 -> 1169510 | L9: =F9+H9+J9 -> 2218534 | M9: =L9*D9 -> 2218534 | O9: 연계)기술내용
A10: 4 | B10: 부단수천공 분기점 분기/철거 | C10: 850 | D10: 1 | E10: nr | F10: =일위대가호표!I73 -> 16802955 | G10: =F10*D10 -> 16802955 | H10: =일위대가호표!K73 -> 2344095 | I10: =H10*D10 -> 2344095 | J10: =일위대가호표!M73 -> 5764530 | K10: =J10*D10 -> 5764530 | L10: =F10+H10+J10 -> 24911580 | M10: =L10*D10 -> 24911580 | O10: 연계)기술내용
A11: 5 | B11: 등압관 설치/철거 | C11: 100 | D11: 1 | E11: nr | F11: =일위대가호표!I127 -> 480686 | G11: =F11*D11 -> 480686 | H11: =일위대가호표!K127 -> 235729 | I11: =H11*D11 -> 235729 | J11: =일위대가호표!M127 -> 84487 | K11: =J11*D11 -> 84487 | L11: =F11+H11+J11 -> 800902 | M11: =L11*D11 -> 800902 | O11: 연계)기술내용
A12: 6 | B12: 부단수차단/철거 | C12: 1200 | D12: 1 | E12: nr | F12: =일위대가호표!I159 -> 6662986 | G12: =F12*D12 -> 6662986 | H12: =일위대가호표!K159 -> 4535894 | I12: =H12*D12 -> 4535894 | J12: =일위대가호표!M159 -> 3976473 | K12: =J12*D12 -> 3976473 | L12: =F12+H12+J12 -> 15175353 | M12: =L12*D12 -> 15175353 | O12: 신기술)기술내용
A13: 7 | B13: 플러깅/철거 | C13: 850 | D13: 1 | E13: nr | F13: =일위대가호표!I191 -> 5733850 | G13: =F13*D13 -> 5733850 | H13: =일위대가호표!K191 -> 1057108 | I13: =H13*D13 -> 1057108 | J13: =일위대가호표!M191 -> 733626 | K13: =J13*D13 -> 733626 | L13: =F13+H13+J13 -> 7524584 | M13: =L13*D13 -> 7524584 | O13: 연계)기술내용
A14: 8 | B14: 샌드위치 밸브 철거 | C14: 850 | D14: 1 | E14: nr | F14: =일위대가호표!I216 -> 0 | G14: =F14*D14 -> 0 | H14: =일위대가호표!K216 -> 200296 | I14: =H14*D14 -> 200296 | J14: =일위대가호표!M216 -> 69460 | K14: =J14*D14 -> 69460 | L14: =F14+H14+J14 -> 269756 | M14: =L14*D14 -> 269756 | O14: 연계)기술내용
A15: 9 | B15: 마개플랜지 부설 및 접합 | C15: 850 | D15: 1 | E15: nr | F15: =일위대가호표!I223 -> 1543570 | G15: =F15*D15 -> 1543570 | H15: =일위대가호표!K223 -> 253358 | I15: =H15*D15 -> 253358 | J15: =일위대가호표!M223 -> 22854 | K15: =J15*D15 -> 22854 | L15: =F15+H15+J15 -> 1819782 | M15: =L15*D15 -> 1819782 | O15: 연계)기술내용
A16: 10 | B16: 사전조사 | C16: 1200 | D16: 1 | E16: nr | F16: =일위대가호표!I238 -> 0 | G16: =F16*D16 -> 0 | H16: =일위대가호표!K238 -> 335379 | I16: =H16*D16 -> 335379 | J16: =일위대가호표!M238 -> 0 | K16: =J16*D16 -> 0 | L16: =F16+H16+J16 -> 335379 | M16: =L16*D16 -> 335379 | O16: 연계)기술내용
A17: 11 | B17: 장비운반비 | C17: 1200 | D17: 1 | E17: set | F17: =일위대가호표!I242 -> 0 | G17: =F17*D17 -> 0 | H17: =일위대가호표!K242 -> 0 | I17: =H17*D17 -> 0 | J17: =일위대가호표!M242 -> 5930000 | K17: =J17*D17 -> 5930000 | L17: =F17+H17+J17 -> 5930000 | M17: =L17*D17 -> 5930000 | O17: 연계)기술내용
A18: 12 | B18: 밸브개폐비 | C18: 850 | D18: 1 | E18: nr | F18: =일위대가호표!I246 -> 0 | G18: =F18*D18 -> 0 | H18: =일위대가호표!K246 -> 607048 | I18: =H18*D18 -> 607048 | J18: =일위대가호표!M246 -> 0 | K18: =J18*D18 -> 0 | L18: =F18+H18+J18 -> 607048 | M18: =L18*D18 -> 607048 | O18: 연계)기술내용
A22: 1. 제경비 및 부가세 별도 2. 기타사항(있을 경우 기재) 3. 신기술(NET 및 특허) 보호범위 공종은 신기술인증서, 특허원부의 해당 청구항 번호 작성, 연계공사가 필요한 공종은 “연계)”와 청구항 번호를 입력하고 증빙서류 등을 첨부하여 작성하여야 하며 미작성 시 기술사용료, 하도급 범위 등에 불이익이 있을 수 있음.
A26: ※ 세부 내역서 비목 구성을 1식 단가로 제출하거나 공사비내역서에 제출일 기준 90일 미만의 유효기간 기재 시 심사대상에서 제외될 수 있음 ※ ‘공사비내역서(물량)’과 ‘견적서 및 공사비내역서’간 오류 확인 시 선정 후 취소될 수 있음

Sheet 견적서
B2: 견 적 서
B5: 문 서 번 호 | G5: DH18-260519-01 | U5: 공 급 자 | W5: 등록번호 | Z5: 140-81-34127
B6: 수 신 | G6: K-water | W6: 상 호 | Z6: (주)대호스토퍼 | AG6: 대표 | AJ6: 이 영 호 | AP6: (인)
W7: 소 재 지 | Z7: 경기도 안산시 상록구 남산평길 126-4(팔곡일동)
B8: 담 당 자 | S8: 귀중 | W8: 업 태 | Z8: 제조업 외 | AG8: 종목 | AJ8: 상하수도설비공사 외
B9: 연 락 처 | W9: 회사전화 | Z9: 031-496-9488 | AG9: 회사팩스 | AJ9: 031-496-9349
B10: 작 성 일 | G10: 46161 | W10: 담 당 자 | Z10: 백승리 차장 | AG10: 휴대전화 | AJ10: 010-5013-7776
B11: 유 효 기 간 | G11: 12개월 | W11: E-Mail | Z11: dhcstopper@hanmail.net
B12: 견 적 명 | G12: 울산공업용수도 노후관 개량사업(3차) 및 추가사업 시설공사 중 부단수 차단 공사
B14: 합 계 금 액 | G14: 일금 | I14: =AB14 -> 95634992 | Y14: 원정 | AA14: ( | AB14: =AJ32 -> 95634992 | AL14: ) | AM14: (VAT별도)
B16: 아래와 같이 견적을 제출합니다.
B17: 품 명 | G17: 규 격 | L17: 단 위 | N17: 수량 | P17: 재 료 비 | U17: 노 무 비 | Z17: 경 비 | AE17: 소 계 | AJ17: 금 액 | AO17: 비고
B18: 부단수 차단 | G18: D1,200㎜ | L18: EA | N18: 1 | P18: =내역서!G6 -> 62922300 | U18: =내역서!I6 -> 14105559 | Z18: =내역서!K6 -> 18607133 | AE18: =P18+U18+Z18 -> 95634992 | AJ18: =AE18*N18 -> 95634992
B31: 단수정리
B32: 합 계(TOTAL) | AJ32: =SUM(AJ18:AN31) -> 95634992
B33: MEMO | D33: 1. 토공, 가시설공, 피팅부 관보호공(H빔 보강)등 부단수 차단 외 공종에 대한 공통 공사비 제외 2. 가배관 별도 3. 흄관-강관 연결 내부 라바벤드 자재 및 시공 별도 4. 흄관-강관 연결대 제작 및 설치 별도 5. 흄관 절단 와이어 커팅 1개소 별도 6. 납품방법 : 현장설치도

Sheet 일위대가목록
A1: 일위대가_목록
A2: 호 표 | B2: 공 종 명 | C2: 규 격 | D2: 단위 | E2: 합계 | F2: 재료비 | H2: 노무비 | J2: 경 비 | K2: 비 고
A3: 1 | B3: 부단수 차단(강관제) | C3: 차단관경, D1200mm | E3: =F3+H3+J3 -> 95634992 | F3: =내역서!G6 -> 62922300 | G3: =내역서!H6 -> 0 | H3: =내역서!I6 -> 14105559 | I3: =내역서!J6 -> 0 | J3: =내역서!K6 -> 18607133
A4: 2 | B4: 바탕처리(강관제) | C4: 차단관경, D1200mm | D4: nr | E4: =F4+H4+J4 -> 165088 | F4: =일위대가호표!I7 -> 656 | G4: =일위대가호표!J7 -> 0 | H4: =일위대가호표!K7 -> 163517 | I4: =일위대가호표!L7 -> 0 | J4: =일위대가호표!M7 -> 915
A5: 3 | B5: 강관 도복장 제거 | C5: 차단관경, D1200mm | D5: nr | E5: =F5+H5+J5 -> 133008 | F5: =일위대가호표!I5 -> 0 | G5: =일위대가호표!J5 -> 133008 | H5: =일위대가호표!K5 -> 133008 | I5: =일위대가호표!L5 -> 0 | J5: =일위대가호표!M5 -> 0
A6: 4 | B6: 표면정리 | C6: 차단관경, D1200mm | D6: nr | E6: =F6+H6+J6 -> 32080 | F6: =일위대가호표!I6 -> 656 | G6: =일위대가호표!J6 -> 30509 | H6: =일위대가호표!K6 -> 30509 | I6: =일위대가호표!L6 -> 915 | J6: =일위대가호표!M6 -> 915
A7: 5 | B7: 부단수 할정자관 부설 및 접합(강관제) | C7: 차단관경, D1200mm | D7: nr | E7: =F7+H7+J7 -> 35876986 | F7: =일위대가호표!I24 -> 31146687 | G7: =일위대가호표!J24 -> 0 | H7: =일위대가호표!K24 -> 3875021 | I7: =일위대가호표!L24 -> 0 | J7: =일위대가호표!M24 -> 855278
A8: 6 | B8: 부단수 할정자관 부설(강관제) | C8: 차단관경, D1200mm | D8: nr | E8: =F8+H8+J8 -> 1260597 | F8: =일위대가호표!I20 -> 0 | G8: =일위대가호표!J20 -> 1128623 | H8: =일위대가호표!K20 -> 1128623 | I8: =일위대가호표!L20 -> 131974 | J8: =일위대가호표!M20 -> 131974
A9: 7 | B9: 부단수 할정자관 접합(강관제) | C9: 차단관경, D1200mm | D9: nr | E9: =F9+H9+J9 -> 3275006 | F9: =일위대가호표!I21 -> 93639 | G9: =일위대가호표!J21 -> 2458063 | H9: =일위대가호표!K21 -> 2458063 | I9: =일위대가호표!L21 -> 723304 | J9: =일위대가호표!M21 -> 723304
A10: 8 | B10: 부단수 할정자관 접합부 도장 | C10: 차단관경, D1200mm | D10: nr | E10: =F10+H10+J10 -> 341383 | F10: =일위대가호표!I22 -> 53048 | G10: =일위대가호표!J22 -> 288335 | H10: =일위대가호표!K22 -> 288335 | I10: =일위대가호표!L22 -> 0 | J10: =일위대가호표!M22 -> 0
A11: 9 | B11: 샌드위치 밸브 부설 및 접합 | C11: 천공관경, D850mm | D11: nr | E11: =F11+H11+J11 -> 2218534 | F11: =일위대가호표!I52 -> 550910 | G11: =일위대가호표!J52 -> 0 | H11: =일위대가호표!K52 -> 498114 | I11: =일위대가호표!L52 -> 0 | J11: =일위대가호표!M52 -> 1169510
A12: 10 | B12: 샌드위치 밸브 부설 및 접합(손료제외) | C12: 천공관경, D850mm | D12: nr | E12: =F12+H12+J12 -> 670772 | F12: =일위대가호표!I49 -> 0 | G12: =일위대가호표!J49 -> 498114 | H12: =일위대가호표!K49 -> 498114 | I12: =일위대가호표!L49 -> 172658 | J12: =일위대가호표!M49 -> 172658
A13: 11 | B13: 샌드위치 밸브 손료 | C13: 천공관경, D850mm | D13: nr | E13: =F13+H13+J13 -> 996852 | F13: =일위대가호표!I50 -> 0 | G13: =일위대가호표!J50 -> 0 | H13: =일위대가호표!K50 -> 0 | I13: =일위대가호표!L50 -> 15768 | J13: =일위대가호표!M50 -> 996852
A14: 12 | B14: 부단수천공 분기점 분기/철거 | C14: 천공관경, D850mm | D14: nr | E14: =F14+H14+J14 -> 24911580 | F14: =일위대가호표!I73 -> 16802955 | G14: =일위대가호표!J73 -> 0 | H14: =일위대가호표!K73 -> 2344095 | I14: =일위대가호표!L73 -> 0 | J14: =일위대가호표!M73 -> 5764530
A15: 13 | B15: 부단수천공 분기점 분기(손료제외) | C15: 천공관경, D850mm | D15: nr | E15: =F15+H15+J15 -> 1829290 | F15: =일위대가호표!I61 -> 0 | G15: =일위대가호표!J61 -> 1237172 | H15: =일위대가호표!K61 -> 1237172 | I15: =일위대가호표!L61 -> 592118 | J15: =일위대가호표!M61 -> 592118
A16: 14 | B16: 부단수천공기 손료 | C16: 차단관경, D1200mm | D16: nr | E16: =F16+H16+J16 -> 4458780 | F16: =일위대가호표!I62 -> 0 | G16: =일위대가호표!J62 -> 0 | H16: =일위대가호표!K62 -> 0 | I16: =일위대가호표!L62 -> 70528 | J16: =일위대가호표!M62 -> 4458780
A17: 15 | B17: 부단수천공기 운전경비 | C17: 천공관경, D850mm | D17: nr | E17: =F17+H17+J17 -> 57202 | F17: =일위대가호표!I63 -> 57202 | G17: =일위대가호표!J63 -> 0 | H17: =일위대가호표!K63 -> 0 | I17: =일위대가호표!L63 -> 0 | J17: =일위대가호표!M63 -> 0
A18: 16 | B18: 기밀시험 | C18: 차단관경, D1200mm | D18: nr | E18: =F18+H18+J18 -> 95237 | F18: =일위대가호표!I64 -> 2773 | G18: =일위대가호표!J64 -> 92464 | H18: =일위대가호표!K64 -> 92464 | I18: =일위대가호표!L64 -> 0 | J18: =일위대가호표!M64 -> 0
A19: 17 | B19: 칩제거(손료제외) | C19: 천공관경, D850mm | D19: nr | E19: =F19+H19+J19 -> 549831 | F19: =일위대가호표!I65 -> 0 | G19: =일위대가호표!J65 -> 372377 | H19: =일위대가호표!K65 -> 372377 | I19: =일위대가호표!L65 -> 177454 | J19: =일위대가호표!M65 -> 177454
A20: 18 | B20: 칩제거기 손료 | C20: 차단관경, D1200mm | D20: nr | E20: =F20+H20+J20 -> 228350 | F20: =일위대가호표!I66 -> 0 | G20: =일위대가호표!J66 -> 0 | H20: =일위대가호표!K66 -> 0 | I20: =일위대가호표!L66 -> 3612 | J20: =일위대가호표!M66 -> 228350
A21: 19 | B21: 칩제거기 운전경비 | C21: 천공관경, D850mm | D21: nr | E21: =F21+H21+J21 -> 17160 | F21: =일위대가호표!I67 -> 17160 | G21: =일위대가호표!J67 -> 0 | H21: =일위대가호표!K67 -> 0 | I21: =일위대가호표!L67 -> 0 | J21: =일위대가호표!M67 -> 0
A22: 20 | B22: 부단수천공기 철거 | C22: 천공관경, D850mm | D22: nr | E22: =F22+H22+J22 -> 732250 | F22: =일위대가호표!I68 -> 0 | G22: =일위대가호표!J68 -> 495041 | H22: =일위대가호표!K68 -> 495041 | I22: =일위대가호표!L68 -> 237209 | J22: =일위대가호표!M68 -> 237209
A23: 21 | B23: 칩제거기 철거 | C23: 천공관경, D850mm | D23: nr | E23: =F23+H23+J23 -> 217660 | F23: =일위대가호표!I69 -> 0 | G23: =일위대가호표!J69 -> 147041 | H23: =일위대가호표!K69 -> 147041 | I23: =일위대가호표!L69 -> 70619 | J23: =일위대가호표!M69 -> 70619
A24: 22 | B24: 등압관 설치/철거 | C24: 등압관경, D100mm | D24: nr | E24: =F24+H24+J24 -> 800902 | F24: =일위대가호표!I127 -> 480686 | G24: =일위대가호표!J127 -> 0 | H24: =일위대가호표!K127 -> 235729 | I24: =일위대가호표!L127 -> 0 | J24: =일위대가호표!M127 -> 84487
A25: 23 | B25: 등압관 부단수 천공 | C25: 등압관경, D100mm | D25: nr | E25: =F25+H25+J25 -> 210523 | F25: =일위대가호표!I120 -> 0 | G25: =일위대가호표!J120 -> 135281 | H25: =일위대가호표!K120 -> 135281 | I25: =일위대가호표!L120 -> 75242 | J25: =일위대가호표!M120 -> 75242
A26: 24 | B26: 등압관 피팅 접합 | C26: 등압관경, D100mm | D26: nr | E26: =F26+H26+J26 -> 35678 | F26: =일위대가호표!I121 -> 686 | G26: =일위대가호표!J121 -> 31078 | H26: =일위대가호표!K121 -> 31078 | I26: =일위대가호표!L121 -> 3914 | J26: =일위대가호표!M121 -> 3914
A27: 25 | B27: 등압관 플러깅 | C27: 등압관경, D100mm | D27: nr | E27: =F27+H27+J27 -> 74701 | F27: =일위대가호표!I122 -> 0 | G27: =일위대가호표!J122 -> 69370 | H27: =일위대가호표!K122 -> 69370 | I27: =일위대가호표!L122 -> 5331 | J27: =일위대가호표!M122 -> 5331
A28: 26 | B28: 부단수차단/철거 | C28: 차단관경, D1200mm | D28: nr | E28: =F28+H28+J28 -> 15175353 | F28: =일위대가호표!I159 -> 6662986 | G28: =일위대가호표!J159 -> 0 | H28: =일위대가호표!K159 -> 4535894 | I28: =일위대가호표!L159 -> 0 | J28: =일위대가호표!M159 -> 3976473
A29: 27 | B29: 부단수차단(손료제외) | C29: 차단관경, D1200mm | D29: nr | E29: =F29+H29+J29 -> 3711356 | F29: =일위대가호표!I152 -> 0 | G29: =일위대가호표!J152 -> 2593046 | H29: =일위대가호표!K152 -> 2593046 | I29: =일위대가호표!L152 -> 1118310 | J29: =일위대가호표!M152 -> 1118310
A30: 28 | B30: 부단수차단기 손료 | C30: 차단관경, D1200mm | D30: nr | E30: =F30+H30+J30 -> 2410641 | F30: =일위대가호표!I153 -> 0 | G30: =일위대가호표!J153 -> 0 | H30: =일위대가호표!K153 -> 0 | I30: =일위대가호표!L153 -> 38131 | J30: =일위대가호표!M153 -> 2410641
A31: 29 | B31: 부단수차단기 운전경비 | C31: 차단관경, D1200mm | D31: nr | E31: =F31+H31+J31 -> 112076 | F31: =일위대가호표!I154 -> 112076 | G31: =일위대가호표!J154 -> 0 | H31: =일위대가호표!K154 -> 0 | I31: =일위대가호표!L154 -> 0 | J31: =일위대가호표!M154 -> 0
A32: 30 | B32: 현장대기 | C32: 차단관경, D1200mm | D32: nr | E32: =F32+H32+J32 -> 903888 | F32: =일위대가호표!I155 -> 0 | G32: =일위대가호표!J155 -> 43498 | H32: =일위대가호표!K155 -> 903888 | I32: =일위대가호표!L155 -> 0 | J32: =일위대가호표!M155 -> 0
A33: 31 | B33: 부단수차단기 철거 | C33: 차단관경, D1200mm | D33: nr | E33: =F33+H33+J33 -> 1486482 | F33: =일위대가호표!I156 -> 0 | G33: =일위대가호표!J156 -> 1038960 | H33: =일위대가호표!K156 -> 1038960 | I33: =일위대가호표!L156 -> 447522 | J33: =일위대가호표!M156 -> 447522
A34: 32 | B34: 플러깅/철거 | C34: 천공관경, D850mm | D34: nr | E34: =F34+H34+J34 -> 7524584 | F34: =일위대가호표!I191 -> 5733850 | G34: =일위대가호표!J191 -> 0 | H34: =일위대가호표!K191 -> 1057108 | I34: =일위대가호표!L191 -> 0 | J34: =일위대가호표!M191 -> 733626
A35: 33 | B35: 천공관 플러깅(손료제외) | C35: 천공관경, D850mm | D35: nr | E35: =F35+H35+J35 -> 1071216 | F35: =일위대가호표!I185 -> 0 | G35: =일위대가호표!J185 -> 754333 | H35: =일위대가호표!K185 -> 754333 | I35: =일위대가호표!L185 -> 316883 | J35: =일위대가호표!M185 -> 316883
A36: 34 | B36: 플러깅 손료 | C36: 차단관경, D1200mm | D36: nr | E36: =F36+H36+J36 -> 289990 | F36: =일위대가호표!I186 -> 0 | G36: =일위대가호표!J186 -> 0 | H36: =일위대가호표!K186 -> 0 | I36: =일위대가호표!L186 -> 4587 | J36: =일위대가호표!M186 -> 289990
A37: 35 | B37: 플러깅장비 운전경비 | C37: 천공관경, D850mm | D37: nr | E37: =F37+H37+J37 -> 32940 | F37: =일위대가호표!I187 -> 32940 | G37: =일위대가호표!J187 -> 0 | H37: =일위대가호표!K187 -> 0 | I37: =일위대가호표!L187 -> 0 | J37: =일위대가호표!M187 -> 0
A38: 36 | B38: 플러깅 장비 철거 | C38: 천공관경, D850mm | D38: nr | E38: =F38+H38+J38 -> 429528 | F38: =일위대가호표!I188 -> 0 | G38: =일위대가호표!J188 -> 302775 | H38: =일위대가호표!K188 -> 302775 | I38: =일위대가호표!L188 -> 126753 | J38: =일위대가호표!M188 -> 126753
A39: 37 | B39: 마개플랜지 부설 및 접합 | C39: 천공관경, D850mm | D39: nr | E39: =F39+H39+J39 -> 1819782 | F39: =일위대가호표!I223 -> 1543570 | G39: =일위대가호표!J223 -> 0 | H39: =일위대가호표!K223 -> 253358 | I39: =일위대가호표!L223 -> 0 | J39: =일위대가호표!M223 -> 22854
A40: 38 | B40: 마개플랜지 부설 | C40: 천공관경, D850mm | D40: nr | E40: =F40+H40+J40 -> 168187 | F40: =일위대가호표!I219 -> 0 | G40: =일위대가호표!J219 -> 145333 | H40: =일위대가호표!K219 -> 145333 | I40: =일위대가호표!L219 -> 22854 | J40: =일위대가호표!M219 -> 22854
...

Sheet 일위대가호표
B1: 일위대가_호표
A2: 호 표 | B2: 공 종 명 | C2: 규 격 | D2: 수량 | E2: 단위 | F2: 합 계 | H2: 재 료 비 | J2: 노 무 비 | L2: 경 비 | N2: 비 고
F3: 단 가 | G3: 금 액 | H3: 단 가 | I3: 금 액 | J3: 단 가 | K3: 금 액 | L3: 단 가 | M3: 금 액
A4: =1 -> 1 | B4: 바탕처리(강관제) | C4: 1200 | D4: 1 | E4: nr
B5: 강관 도복장 제거 | D5: 1 | E5: nr | F5: =H5+J5+L5 -> 133008 | G5: =F5*D5 -> 133008 | H5: 0 | I5: =TRUNC(H5*$D5,0) -> 0 | J5: =K11 -> 133008 | K5: =TRUNC(J5*$D5,0) -> 133008 | L5: 0 | M5: =TRUNC(L5*$D5,0) -> 0 | N5: =A9 -> 2
B6: 표면정리 | C6: #180 | D6: 1 | E6: nr | F6: =H6+J6+L6 -> 32080 | G6: =F6*D6 -> 32080 | H6: =I17 -> 656 | I6: =TRUNC(H6*$D6,0) -> 656 | J6: =K17 -> 30509 | K6: =TRUNC(J6*$D6,0) -> 30509 | L6: =M17 -> 915 | M6: =TRUNC(L6*$D6,0) -> 915 | N6: =A13 -> 3
B7: 계 | G7: =SUM(G5:G6) -> 165088 | I7: =SUM(I5:I6) -> 656 | K7: =SUM(K5:K6) -> 163517 | M7: =SUM(M5:M6) -> 915
A9: =A4+1 -> 2 | B9: 강관 도복장 제거 | C9: 1200 | D9: 1 | E9: nr
B10: 보통인부 | D10: 0.773 | E10: 인 | F10: =H10+J10+L10 -> 172068 | G10: =F10*D10 -> 133008.56 | I10: =TRUNC(H10*$D10,0) -> 0 | J10: =노임!$D$4 -> 172068 | K10: =TRUNC(J10*$D10,0) -> 133008 | M10: =TRUNC(L10*$D10,0) -> 0
B11: 계 | G11: =SUM(G10) -> 133008.56 | I11: =SUM(I10:I10) -> 0 | K11: =SUM(K10:K10) -> 133008 | M11: =SUM(M10:M10) -> 0
A13: =A9+1 -> 3 | B13: 표면정리 | C13: 1200 | D13: 1 | E13: nr
B14: 도장공 | D14: 0.116 | E14: 인 | F14: =H14+J14+L14 -> 263017 | G14: =F14*D14 -> 30509.972 | I14: =TRUNC(H14*$D14,0) -> 0 | J14: =노임!$D$6 -> 263017 | K14: =TRUNC(J14*$D14,0) -> 30509 | M14: =TRUNC(L14*$D14,0) -> 0
B15: 연마지 | C15: #180 | D15: 1.93 | E15: 매 | F15: =H15+J15+L15 -> 340 | G15: =F15*D15 -> 656.2 | H15: =자재!$D$4 -> 340 | I15: =TRUNC(H15*$D15,0) -> 656 | K15: =TRUNC(J15*$D15,0) -> 0 | M15: =TRUNC(L15*$D15,0) -> 0
B16: 공구손료 | C16: 도장공 인력품의 | D16: 0.03 | F16: =H16+J16+L16 -> 30509 | G16: =F16*D16 -> 915.27 | I16: =TRUNC(H16*$E16,0) -> 0 | K16: =TRUNC(J16*$E16,0) -> 0 | L16: =K17 -> 30509 | M16: =TRUNC(L16*$D16,0) -> 915
B17: 계 | G17: =SUM(G14:G16) -> 32081.442 | I17: =SUM(I14:I16) -> 656 | K17: =SUM(K14:K16) -> 30509 | M17: =SUM(M14:M16) -> 915
A19: =A13+1 -> 4 | B19: 부단수 할정자관 부설 및 접합(강관제) | C19: 1200 | D19: 1 | E19: nr
B20: 부단수 할정자관 부설(강관제) | C20: 1200 | D20: 1 | E20: nr | F20: =H20+J20+L20 -> 1260597 | G20: =F20*D20 -> 1260597 | H20: 0 | I20: =TRUNC(H20*$D20,0) -> 0 | J20: =K30 -> 1128623 | K20: =TRUNC(J20*$D20,0) -> 1128623 | L20: =M30 -> 131974 | M20: =TRUNC(L20*$D20,0) -> 131974 | N20: =A26 -> 5
B21: 부단수 할정자관 접합(강관제) | C21: 1200 | D21: 1 | E21: nr | F21: =H21+J21+L21 -> 3275006 | G21: =F21*D21 -> 3275006 | H21: =I37 -> 93639 | I21: =TRUNC(H21*$D21,0) -> 93639 | J21: =K37 -> 2458063 | K21: =TRUNC(J21*$D21,0) -> 2458063 | L21: =M37 -> 723304 | M21: =TRUNC(L21*$D21,0) -> 723304 | N21: =A32 -> 6
B22: 부단수 할정자관 접합부 도장 | C22: 1200 | D22: 1 | E22: nr | F22: =H22+J22+L22 -> 341383 | G22: =F22*D22 -> 341383 | H22: =I46 -> 53048 | I22: =TRUNC(H22*$D22,0) -> 53048 | J22: =K46 -> 288335 | K22: =TRUNC(J22*$D22,0) -> 288335 | L22: 0 | M22: =TRUNC(L22*$D22,0) -> 0 | N22: =A39 -> 7
B23: 부단수 할정자관 | C23: 1200 | D23: 1 | E23: nr | F23: =H23+J23+L23 -> 31000000 | G23: =F23*D23 -> 31000000 | H23: =자재견적서!AR18 -> 31000000 | I23: =TRUNC(H23*$D23,0) -> 31000000 | K23: =TRUNC(J23*$D23,0) -> 0 | M23: =TRUNC(L23*$D23,0) -> 0
B24: 계 | G24: =SUM(G20:G23) -> 35876986 | I24: =SUM(I20:I23) -> 31146687 | K24: =SUM(K20:K23) -> 3875021 | M24: =SUM(M20:M23) -> 855278
A26: =A19+1 -> 5 | B26: 부단수 할정자관 부설(강관제) | C26: 1200 | D26: 1 | E26: nr
B27: 배관공(수도) | D27: 2.85 | E27: 인 | F27: =H27+J27+L27 -> 262580 | G27: =F27*D27 -> 748353 | I27: =TRUNC(H27*$D27,0) -> 0 | J27: =노임!$D$8 -> 262580 | K27: =TRUNC(J27*$D27,0) -> 748353 | M27: =TRUNC(L27*$D27,0) -> 0
B28: 보통인부 | D28: 2.21 | E28: 인 | F28: =H28+J28+L28 -> 172068 | G28: =F28*D28 -> 380270.28 | I28: =TRUNC(H28*$D28,0) -> 0 | J28: =노임!$D$4 -> 172068 | K28: =TRUNC(J28*$D28,0) -> 380270 | M28: =TRUNC(L28*$D28,0) -> 0
B29: 트럭탑재형크레인 | C29: 15 | D29: 1.33 | E29: hr | F29: =H29+J29+L29 -> 99229 | G29: =F29*D29 -> 131974.57 | I29: =TRUNC(H29*$D29,0) -> 0 | K29: =TRUNC(J29*$D29,0) -> 0 | L29: =경비!$G$5 -> 99229 | M29: =TRUNC(L29*$D29,0) -> 131974
B30: 계 | G30: =SUM(G27:G29) -> 1260597.9 | I30: =SUM(I27:I29) -> 0 | K30: =SUM(K27:K29) -> 1128623 | M30: =SUM(M27:M29) -> 131974
A32: =A26+1 -> 6 | B32: 부단수 할정자관 접합(강관제) | C32: 1200 | D32: 1 | E32: nr
B33: 용접공 | D33: 8.7 | E33: 인 | F33: =H33+J33+L33 -> 282536 | G33: =F33*D33 -> 2458063.2 | I33: =TRUNC(H33*$D33,0) -> 0 | J33: =노임!$D$5 -> 282536 | K33: =TRUNC(J33*$D33,0) -> 2458063 | M33: =TRUNC(L33*$D33,0) -> 0
B34: 발전기(50KW) | D34: 12.93 | E34: hr | F34: =H34+J34+L34 -> 55756 | G34: =F34*D34 -> 720925.08 | I34: =TRUNC(H34*$D34,0) -> 0 | K34: =TRUNC(J34*$D34,0) -> 0 | L34: =경비!$G$8 -> 55756 | M34: =TRUNC(L34*$D34,0) -> 720925
B35: 용접기(200AMP) | D35: 25.86 | E35: hr | F35: =H35+J35+L35 -> 92 | G35: =F35*D35 -> 2379.12 | I35: =TRUNC(H35*$D35,0) -> 0 | K35: =TRUNC(J35*$D35,0) -> 0 | L35: =경비!$G$9 -> 92 | M35: =TRUNC(L35*$D35,0) -> 2379
B36: 용접봉(3.2㎜ KSE4301) | D36: 19.11 | E36: kg | F36: =H36+J36+L36 -> 4900 | G36: =F36*D36 -> 93639 | H36: =자재!$D$3 -> 4900 | I36: =TRUNC(H36*$D36,0) -> 93639 | K36: =TRUNC(J36*$D36,0) -> 0 | M36: =TRUNC(L36*$D36,0) -> 0
B37: 계 | G37: =SUM(G33:G36) -> 3275006.4 | I37: =SUM(I33:I36) -> 93639 | K37: =SUM(K33:K36) -> 2458063 | M37: =SUM(M33:M36) -> 723304
A39: =A32+1 -> 7 | B39: 부단수 할정자관 접합부 도장 | C39: 1200 | D39: 1 | E39: nr
B40: 도장공 | D40: 0.9 | E40: 인 | F40: =H40+J40+L40 -> 263017 | G40: =F40*D40 -> 236715.3 | I40: =TRUNC(H40*$D40,0) -> 0 | J40: =노임!$D$6 -> 263017 | K40: =TRUNC(J40*$D40,0) -> 236715 | M40: =TRUNC(L40*$D40,0) -> 0
B41: 보통인부 | D41: 0.3 | E41: 인 | F41: =H41+J41+L41 -> 172068 | G41: =F41*D41 -> 51620.4 | I41: =TRUNC(H41*$D41,0) -> 0 | J41: =노임!$D$4 -> 172068 | K41: =TRUNC(J41*$D41,0) -> 51620 | M41: =TRUNC(L41*$D41,0) -> 0
B42: 액상접착제 | C42: (16.8kg/18.9ℓ) CAN | D42: 0.84 | E42: kg | F42: =H42+J42+L42 -> 20746.667 | G42: =F42*D42 -> 17427.2 | H42: =자재!$D$5 -> 20746.667 | I42: =TRUNC(H42*$D42,0) -> 17427 | K42: =TRUNC(J42*$D42,0) -> 0 | M42: =TRUNC(L42*$D42,0) -> 0
B43: 매스틱 | C43: 3T x 40 x 6m | D43: 8.42 | E43: m | F43: =H43+J43+L43 -> 2800 | G43: =F43*D43 -> 23576 | H43: =자재!$D$6 -> 2800 | I43: =TRUNC(H43*$D43,0) -> 23576 | K43: =TRUNC(J43*$D43,0) -> 0 | M43: =TRUNC(L43*$D43,0) -> 0
B44: 안쪽층테이프 | C44: 0.508㎜ x 100㎜ x 30m | D44: 7.96 | E44: ㎡ | F44: =H44+J44+L44 -> 773.33333 | G44: =F44*D44 -> 6155.7333 | H44: =자재!$D$7 -> 773.33333 | I44: =TRUNC(H44*$D44,0) -> 6155 | K44: =TRUNC(J44*$D44,0) -> 0 | M44: =TRUNC(L44*$D44,0) -> 0
B45: 바깥층테이프 | C45: 0.381㎜ x 100㎜ x 30m | D45: 7.96 | E45: ㎡ | F45: =H45+J45+L45 -> 740 | G45: =F45*D45 -> 5890.4 | H45: =자재!$D$8 -> 740 | I45: =TRUNC(H45*$D45,0) -> 5890 | K45: =TRUNC(J45*$D45,0) -> 0 | M45: =TRUNC(L45*$D45,0) -> 0
B46: 계 | G46: =SUM(G40:G45) -> 341385.03 | I46: =SUM(I40:I45) -> 53048 | K46: =SUM(K40:K45) -> 288335 | M46: =SUM(M40:M41) -> 0
...

Sheet 중기사용료목록
A1: 중기사용료목록
A2: 공 종 명 | B2: 규 격 | C2: 수 량 | D2: 단 위 | E2: 재 료 비 | F2: 노 무 비 | G2: 경 비 | H2: 합 계 | I2: 비 고
A3: 부단수 천공기 손료 | B3: 차단관경, D80x80mm | C3: 1 | D3: hr | F3: 0 | G3: =중기사용료!$G$12 -> 41739 | H3: =E3+F3+G3 -> 41739 | J3: =HYPERLINK(K3, "중기사용료 시트 확인") -> 중기사용료 시트 확인 | K3: ="#중기사용료!"&L3&M3 -> #중기사용료!$A$3:$H$12 | L3: $A$3 | M3: :$H$12
A4: 부단수 천공기 손료 | B4: 차단관경, D100x100mm | C4: 1 | D4: hr | F4: 0 | G4: =중기사용료!$G$23 -> 40406 | H4: =E4+F4+G4 -> 40406 | J4: =HYPERLINK(K4, "중기사용료 시트 확인") -> 중기사용료 시트 확인 | K4: ="#중기사용료!"&L4&M4 -> #중기사용료!$A$14:$H$23 | L4: $A$14 | M4: :$H$23
A5: 부단수 천공기 손료 | B5: 차단관경, D150x150mm | C5: 1 | D5: hr | F5: 0 | G5: =중기사용료!$G$34 -> 152731 | H5: =E5+F5+G5 -> 152731 | J5: =HYPERLINK(K5, "중기사용료 시트 확인") -> 중기사용료 시트 확인 | K5: ="#중기사용료!"&L5&M5 -> #중기사용료!$A$25:$H$34 | L5: $A$25 | M5: :$H$34
A6: 부단수 천공기 손료 | B6: 차단관경, D200x200mm | C6: 1 | D6: hr | F6: 0 | G6: =중기사용료!$G$45 -> 111969 | H6: =E6+F6+G6 -> 111969 | J6: =HYPERLINK(K6, "중기사용료 시트 확인") -> 중기사용료 시트 확인 | K6: ="#중기사용료!"&L6&M6 -> #중기사용료!$A$36:$H$45 | L6: $A$36 | M6: :$H$45
A7: 부단수 천공기 손료 | B7: 차단관경, D250x250mm | C7: 1 | D7: hr | F7: 0 | G7: =중기사용료!$G$56 -> 105504 | H7: =E7+F7+G7 -> 105504 | J7: =HYPERLINK(K7, "중기사용료 시트 확인") -> 중기사용료 시트 확인 | K7: ="#중기사용료!"&L7&M7 -> #중기사용료!$A$47:$H$56 | L7: $A$47 | M7: :$H$56
A8: 부단수 천공기 손료 | B8: 차단관경, D300x300mm | C8: 1 | D8: hr | F8: 0 | G8: =중기사용료!$G$67 -> 100084 | H8: =E8+F8+G8 -> 100084 | J8: =HYPERLINK(K8, "중기사용료 시트 확인") -> 중기사용료 시트 확인 | K8: ="#중기사용료!"&L8&M8 -> #중기사용료!$A$58:$H$67 | L8: $A$58 | M8: :$H$67
A9: 부단수 천공기 손료 | B9: 차단관경, D350x350mm | C9: 1 | D9: hr | F9: 0 | G9: =중기사용료!$G$78 -> 84364 | H9: =E9+F9+G9 -> 84364 | J9: =HYPERLINK(K9, "중기사용료 시트 확인") -> 중기사용료 시트 확인 | K9: ="#중기사용료!"&L9&M9 -> #중기사용료!$A$69:$H$78 | L9: $A$69 | M9: :$H$78
A10: 부단수 천공기 손료 | B10: 차단관경, D400x400mm | C10: 1 | D10: hr | F10: 0 | G10: =중기사용료!$G$89 -> 86124 | H10: =E10+F10+G10 -> 86124 | J10: =HYPERLINK(K10, "중기사용료 시트 확인") -> 중기사용료 시트 확인 | K10: ="#중기사용료!"&L10&M10 -> #중기사용료!$A$80:$H$89 | L10: $A$80 | M10: :$H$89
A11: 부단수 천공기 손료 | B11: 차단관경, D450x400mm | C11: 1 | D11: hr | F11: 0 | G11: =중기사용료!$G$100 -> 84660 | H11: =E11+F11+G11 -> 84660 | J11: =HYPERLINK(K11, "중기사용료 시트 확인") -> 중기사용료 시트 확인 | K11: ="#중기사용료!"&L11&M11 -> #중기사용료!$A$91:$H$100 | L11: $A$91 | M11: :$H$100
A12: 부단수 천공기 손료 | B12: 차단관경, D500x400mm | C12: 1 | D12: hr | G12: =중기사용료!$G$111 -> 83304 | H12: =E12+F12+G12 -> 83304 | J12: =HYPERLINK(K12, "중기사용료 시트 확인") -> 중기사용료 시트 확인 | K12: ="#중기사용료!"&L12&M12 -> #중기사용료!$A$102:$H$111 | L12: $A$102 | M12: :$H$111
A13: 부단수 천공기 손료 | B13: 차단관경, D600x400mm | C13: 1 | D13: hr | G13: =중기사용료!$G$122 -> 80628 | H13: =E13+F13+G13 -> 80628 | J13: =HYPERLINK(K13, "중기사용료 시트 확인") -> 중기사용료 시트 확인 | K13: ="#중기사용료!"&L13&M13 -> #중기사용료!$A$113:$H$122 | L13: $A$113 | M13: :$H$122
A14: 부단수 천공기 손료 | B14: 차단관경, D700x600mm | C14: 1 | D14: hr | G14: =중기사용료!$G$133 -> 97785 | H14: =E14+F14+G14 -> 97785 | J14: =HYPERLINK(K14, "중기사용료 시트 확인") -> 중기사용료 시트 확인 | K14: ="#중기사용료!"&L14&M14 -> #중기사용료!$A$124:$H$133 | L14: $A$124 | M14: :$H$133
A15: 부단수 천공기 손료 | B15: 차단관경, D800x600mm | C15: 1 | D15: hr | G15: =중기사용료!$G$144 -> 94483 | H15: =E15+F15+G15 -> 94483 | J15: =HYPERLINK(K15, "중기사용료 시트 확인") -> 중기사용료 시트 확인 | K15: ="#중기사용료!"&L15&M15 -> #중기사용료!$A$135:$H$144 | L15: $A$135 | M15: :$H$144
A16: 부단수 천공기 손료 | B16: 차단관경, D900x600mm | C16: 1 | D16: hr | G16: =중기사용료!$G$155 -> 91123 | H16: =E16+F16+G16 -> 91123 | J16: =HYPERLINK(K16, "중기사용료 시트 확인") -> 중기사용료 시트 확인 | K16: ="#중기사용료!"&L16&M16 -> #중기사용료!$A$146:$H$155 | L16: $A$146 | M16: :$H$155
A17: 부단수 천공기 손료 | B17: 차단관경, D1000x900mm | C17: 1 | D17: hr | G17: =중기사용료!$G$166 -> 75054 | H17: =E17+F17+G17 -> 75054 | J17: =HYPERLINK(K17, "중기사용료 시트 확인") -> 중기사용료 시트 확인 | K17: ="#중기사용료!"&L17&M17 -> #중기사용료!$A$157:$H$166 | L17: $A$157 | M17: :$H$166
A18: 부단수 천공기 손료 | B18: 차단관경, D1100x900mm | C18: 1 | D18: hr | G18: =중기사용료!$G$177 -> 71241 | H18: =E18+F18+G18 -> 71241 | J18: =HYPERLINK(K18, "중기사용료 시트 확인") -> 중기사용료 시트 확인 | K18: ="#중기사용료!"&L18&M18 -> #중기사용료!$A$168:$H$177 | L18: $A$168 | M18: :$H$177
A19: 부단수 천공기 손료 | B19: 차단관경, D1200x850mm | C19: 1 | D19: hr | G19: =중기사용료!$G$188 -> 70528 | H19: =E19+F19+G19 -> 70528 | J19: =HYPERLINK(K19, "중기사용료 시트 확인") -> 중기사용료 시트 확인 | K19: ="#중기사용료!"&L19&M19 -> #중기사용료!$A$179:$H$188 | L19: $A$179 | M19: :$H$188
A20: 부단수 천공기 손료 | B20: 차단관경, D1200x900mm | C20: 1 | D20: hr | G20: =중기사용료!$G$199 -> 70528 | H20: =E20+F20+G20 -> 70528 | J20: =HYPERLINK(K20, "중기사용료 시트 확인") -> 중기사용료 시트 확인 | K20: ="#중기사용료!"&L20&M20 -> #중기사용료!$A$190:$H$199 | L20: $A$190 | M20: :$H$199
A21: 부단수 천공기 손료 | B21: 차단관경, D1350x900mm | C21: 1 | D21: hr | G21: =중기사용료!$G$210 -> 68191 | H21: =E21+F21+G21 -> 68191 | J21: =HYPERLINK(K21, "중기사용료 시트 확인") -> 중기사용료 시트 확인 | K21: ="#중기사용료!"&L21&M21 -> #중기사용료!$A$201:$H$210 | L21: $A$201 | M21: :$H$210
A22: 부단수 천공기 손료 | B22: 차단관경, D1500x1200mm | C22: 1 | D22: hr | G22: =중기사용료!$G$221 -> 278152 | H22: =E22+F22+G22 -> 278152 | J22: =HYPERLINK(K22, "중기사용료 시트 확인") -> 중기사용료 시트 확인 | K22: ="#중기사용료!"&L22&M22 -> #중기사용료!$A$212:$H$221 | L22: $A$212 | M22: :$H$221
A23: 부단수 천공기 손료 | B23: 차단관경, D1650x1200mm | C23: 1 | D23: hr | G23: =중기사용료!$G$232 -> 271657 | H23: =E23+F23+G23 -> 271657 | J23: =HYPERLINK(K23, "중기사용료 시트 확인") -> 중기사용료 시트 확인 | K23: ="#중기사용료!"&L23&M23 -> #중기사용료!$A$223:$H$232 | L23: $A$223 | M23: :$H$232
A24: 부단수 천공기 손료 | B24: 차단관경, D1800x1200mm | C24: 1 | D24: hr | G24: =중기사용료!$G$243 -> 260489 | H24: =E24+F24+G24 -> 260489 | J24: =HYPERLINK(K24, "중기사용료 시트 확인") -> 중기사용료 시트 확인 | K24: ="#중기사용료!"&L24&M24 -> #중기사용료!$A$234:$H$243 | L24: $A$234 | M24: :$H$243
A25: 부단수 천공기 손료 | B25: 차단관경, D2000x1650mm | C25: 1 | D25: hr | G25: =중기사용료!$G$254 -> 336664 | H25: =E25+F25+G25 -> 336664 | J25: =HYPERLINK(K25, "중기사용료 시트 확인") -> 중기사용료 시트 확인 | K25: ="#중기사용료!"&L25&M25 -> #중기사용료!$A$245:$H$254 | L25: $A$245 | M25: :$H$254
A26: 부단수 천공기 손료 | B26: 차단관경, D2100x1650mm | C26: 1 | D26: hr | G26: =중기사용료!$G$265 -> 330427 | H26: =E26+F26+G26 -> 330427 | J26: =HYPERLINK(K26, "중기사용료 시트 확인") -> 중기사용료 시트 확인 | K26: ="#중기사용료!"&L26&M26 -> #중기사용료!$A$256:$H$265 | L26: $A$256 | M26: :$H$265
A27: 부단수 천공기 손료 | B27: 차단관경, D2200x1650mm | C27: 1 | D27: hr | G27: =중기사용료!$G$276 -> 321981 | H27: =E27+F27+G27 -> 321981 | J27: =HYPERLINK(K27, "중기사용료 시트 확인") -> 중기사용료 시트 확인 | K27: ="#중기사용료!"&L27&M27 -> #중기사용료!$A$267:$H$276 | L27: $A$267 | M27: :$H$276
A28: 부단수 천공기 손료 | B28: 차단관경, D2300x1650mm | C28: 1 | D28: hr | G28: =중기사용료!$G$287 -> 315606 | H28: =E28+F28+G28 -> 315606 | J28: =HYPERLINK(K28, "중기사용료 시트 확인") -> 중기사용료 시트 확인 | K28: ="#중기사용료!"&L28&M28 -> #중기사용료!$A$278:$H$287 | L28: $A$278 | M28: :$H$287
A29: 부단수 천공기 손료 | B29: 차단관경, D2400x1650mm | C29: 1 | D29: hr | G29: =중기사용료!$G$298 -> 309451 | H29: =E29+F29+G29 -> 309451 | J29: =HYPERLINK(K29, "중기사용료 시트 확인") -> 중기사용료 시트 확인 | K29: ="#중기사용료!"&L29&M29 -> #중기사용료!$A$289:$H$298 | L29: $A$289 | M29: :$H$298
A30: 칩제거기 손료 | B30: 차단관경, D80x80mm | C30: 1 | D30: hr | G30: =중기사용료!$G$309 -> 1521 | H30: =E30+F30+G30 -> 1521 | J30: =HYPERLINK(K30, "중기사용료 시트 확인") -> 중기사용료 시트 확인 | K30: ="#중기사용료!"&L30&M30 -> #중기사용료!$A$300:$H$309 | L30: $A$300 | M30: :$H$309
A31: 칩제거기 손료 | B31: 차단관경, D100x100mm | C31: 1 | D31: hr | G31: =중기사용료!$G$320 -> 3156 | H31: =E31+F31+G31 -> 3156 | J31: =HYPERLINK(K31, "중기사용료 시트 확인") -> 중기사용료 시트 확인 | K31: ="#중기사용료!"&L31&M31 -> #중기사용료!$A$311:$H$320 | L31: $A$311 | M31: :$H$320
A32: 칩제거기 손료 | B32: 차단관경, D150x150mm | C32: 1 | D32: hr | G32: =중기사용료!$G$331 -> 3512 | H32: =E32+F32+G32 -> 3512 | J32: =HYPERLINK(K32, "중기사용료 시트 확인") -> 중기사용료 시트 확인 | K32: ="#중기사용료!"&L32&M32 -> #중기사용료!$A$322:$H$331 | L32: $A$322 | M32: :$H$331
A33: 칩제거기 손료 | B33: 차단관경, D200x200mm | C33: 1 | D33: hr | F33: 0 | G33: =중기사용료!$G$342 -> 2659 | H33: =E33+F33+G33 -> 2659 | J33: =HYPERLINK(K33, "중기사용료 시트 확인") -> 중기사용료 시트 확인 | K33: ="#중기사용료!"&L33&M33 -> #중기사용료!$A$333:$H$342 | L33: $A$333 | M33: :$H$342
A34: 칩제거기 손료 | B34: 차단관경, D250x250mm | C34: 1 | D34: hr | F34: 0 | G34: =중기사용료!$G$353 -> 3481 | H34: =E34+F34+G34 -> 3481 | J34: =HYPERLINK(K34, "중기사용료 시트 확인") -> 중기사용료 시트 확인 | K34: ="#중기사용료!"&L34&M34 -> #중기사용료!$A$344:$H$353 | L34: $A$344 | M34: :$H$353
A35: 칩제거기 손료 | B35: 차단관경, D300x300mm | C35: 1 | D35: hr | F35: 0 | G35: =중기사용료!$G$364 -> 3753 | H35: =E35+F35+G35 -> 3753 | J35: =HYPERLINK(K35, "중기사용료 시트 확인") -> 중기사용료 시트 확인 | K35: ="#중기사용료!"&L35&M35 -> #중기사용료!$A$355:$H$364 | L35: $A$355 | M35: :$H$364
A36: 칩제거기 손료 | B36: 차단관경, D350x350mm | C36: 1 | D36: hr | F36: 0 | G36: =중기사용료!$G$375 -> 4429 | H36: =E36+F36+G36 -> 4429 | J36: =HYPERLINK(K36, "중기사용료 시트 확인") -> 중기사용료 시트 확인 | K36: ="#중기사용료!"&L36&M36 -> #중기사용료!$A$366:$H$375 | L36: $A$366 | M36: :$H$375
A37: 칩제거기 손료 | B37: 차단관경, D400x400mm | C37: 1 | D37: hr | F37: 0 | G37: =중기사용료!$G$386 -> 2153 | H37: =E37+F37+G37 -> 2153 | J37: =HYPERLINK(K37, "중기사용료 시트 확인") -> 중기사용료 시트 확인 | K37: ="#중기사용료!"&L37&M37 -> #중기사용료!$A$377:$H$386 | L37: $A$377 | M37: :$H$386
A38: 칩제거기 손료 | B38: 차단관경, D450x400mm | C38: 1 | D38: hr | F38: 0 | G38: =중기사용료!$G$397 -> 2116 | H38: =E38+F38+G38 -> 2116 | J38: =HYPERLINK(K38, "중기사용료 시트 확인") -> 중기사용료 시트 확인 | K38: ="#중기사용료!"&L38&M38 -> #중기사용료!$A$388:$H$397 | L38: $A$388 | M38: :$H$397
A39: 칩제거기 손료 | B39: 차단관경, D500x400mm | C39: 1 | D39: hr | F39: 0 | G39: =중기사용료!$G$408 -> 2082 | H39: =E39+F39+G39 -> 2082 | J39: =HYPERLINK(K39, "중기사용료 시트 확인") -> 중기사용료 시트 확인 | K39: ="#중기사용료!"&L39&M39 -> #중기사용료!$A$399:$H$408 | L39: $A$399 | M39: :$H$408
A40: 칩제거기 손료 | B40: 차단관경, D600x400mm | C40: 1 | D40: hr | F40: 0 | G40: =중기사용료!$G$419 -> 2015 | H40: =E40+F40+G40 -> 2015 | J40: =HYPERLINK(K40, "중기사용료 시트 확인") -> 중기사용료 시트 확인 | K40: ="#중기사용료!"&L40&M40 -> #중기사용료!$A$410:$H$419 | L40: $A$410 | M40: :$H$419
...

Sheet 중기사용료
A1: 중기사용료
A3: 중 기 명 | B3: 부단수 천공기 손료 차단관경, D80x80mm
A4: 중기가격 | B4: 11,520 천원
A5: 명 칭 | C5: 규 격 | D5: 수 량 | E5: 단 위 | F5: 단 가 | G5: 금 액 | H5: 비 고 | I5: =HYPERLINK("#"&J5, "이전으로") -> 이전으로 | J5: 중기사용료목록!$G$3
A6: 경 비 | B6: 부단수 천공기 | C6: D80x80mm | D6: 3.6232 | E6: 천원 | F6: =중기기초자료!$G$39 -> 11520 | G6: =TRUNC(F6*D6, 1) -> 41739.2
B7: 소 계 | G7: =TRUNC(G6, 0) -> 41739
A8: 재 료 비
B9: 소 계
A10: 노 무 비
B11: 소 계
B12: 총 계 | G12: =TRUNC(G7+G9+G11, 0) -> 41739
A14: 중 기 명 | B14: 부단수 천공기 손료 차단관경, D100x100mm
A15: 중기가격 | B15: 11,520 천원
A16: 명 칭 | C16: 규 격 | D16: 수 량 | E16: 단 위 | F16: 단 가 | G16: 금 액 | H16: 비 고 | I16: =HYPERLINK("#"&J16, "이전으로") -> 이전으로 | J16: 중기사용료목록!$G$4
A17: 경 비 | B17: 부단수 천공기 | C17: D100x100mm | D17: 3.5075 | E17: 천원 | F17: =중기기초자료!$G$40 -> 11520 | G17: =TRUNC(F17*D17, 1) -> 40406.4
B18: 소 계 | G18: =TRUNC(G17, 0) -> 40406
A19: 재 료 비
B20: 소 계
A21: 노 무 비
B22: 소 계
B23: 총 계 | G23: =TRUNC(G18+G20+G22, 0) -> 40406
A25: 중 기 명 | B25: 부단수 천공기 손료 차단관경, D150x150mm
A26: 중기가격 | B26: 48,000 천원
A27: 명 칭 | C27: 규 격 | D27: 수 량 | E27: 단 위 | F27: 단 가 | G27: 금 액 | H27: 비 고 | I27: =HYPERLINK("#"&J27, "이전으로") -> 이전으로 | J27: 중기사용료목록!$G$5
A28: 경 비 | B28: 부단수 천공기 | C28: D150x150mm | D28: 3.1819 | E28: 천원 | F28: =중기기초자료!$G$41 -> 48000 | G28: =TRUNC(F28*D28, 1) -> 152731.2
B29: 소 계 | G29: =TRUNC(G28, 0) -> 152731
A30: 재 료 비
B31: 소 계
A32: 노 무 비
B33: 소 계
B34: 총 계 | G34: =TRUNC(G29+G31+G33, 0) -> 152731
A36: 중 기 명 | B36: 부단수 천공기 손료 차단관경, D200x200mm
A37: 중기가격 | B37: 48,000 천원
A38: 명 칭 | C38: 규 격 | D38: 수 량 | E38: 단 위 | F38: 단 가 | G38: 금 액 | H38: 비 고 | I38: =HYPERLINK("#"&J38, "이전으로") -> 이전으로 | J38: 중기사용료목록!$G$6
A39: 경 비 | B39: 부단수 천공기 | C39: D200x200mm | D39: 2.3327 | E39: 천원 | F39: =중기기초자료!$G$42 -> 48000 | G39: =TRUNC(F39*D39, 1) -> 111969.6
B40: 소 계 | G40: =TRUNC(G39, 0) -> 111969
A41: 재 료 비
B42: 소 계
A43: 노 무 비
B44: 소 계
...

Sheet 중기기초자료
A1: 중기기초자료
A2: 명 칭 | B2: 규 격 | C2: 단 위 | D2: 합 계 | E2: 노 무 비 | F2: 재 료 비 | G2: 경 비 | H2: 비 고
A3: 트럭탑제형 크레인 | B3: 5 TON | C3: HR | D3: =E3+F3+G3 -> 69255 | E3: 49698 | F3: 8440 | G3: 11117 | H3: 26년적산단가/765
A4: 트럭탑제형 크레인 | B4: 10 TON | C4: HR | D4: =E4+F4+G4 -> 90538 | E4: 49698 | F4: 17045 | G4: 23795 | H4: 26년적산단가/765
A5: 트럭탑제형 크레인 | B5: 15 TON | C5: HR | D5: =E5+F5+G5 -> 99229 | E5: 49698 | F5: 18204 | G5: 31327 | H5: 26년적산단가/765
A6: 트럭탑제형 크레인 | B6: 18 TON | C6: HR | D6: =E6+F6+G6 -> 101726 | E6: 49698 | F6: 18700 | G6: 33328 | H6: 26년적산단가/765
A7: 무한궤도 크레인 | B7: 20 ton (0.57 ㎥) | C7: HR | D7: =E7+F7+G7 -> 99933 | E7: 58925 | F7: 14232 | G7: 26776 | H7: 26년적산단가/762
A8: 발전기 | B8: 50 kw | C8: HR | D8: =E8+F8+G8 -> 55756 | E8: 36190 | F8: 14877 | G8: 4689 | H8: 26년적산단가/793
A9: 용접기 (교류) | B9: 200 amP | C9: HR | D9: =E9+F9+G9 -> 92 | E9: 0 | F9: 0 | G9: 92 | H9: 26년적산단가/794
A10: 상수도관 천공기 | C10: HR | D10: =E10+F10+G10 -> 597 | G10: 597 | H10: 26년적산단가/790
A11: 장비운반비 | B11: D1200mm(안산-울산) | C11: nr | D11: =E11+F11+G11 -> 5930000 | G11: 5930000 | H11: 장비운반비 산출근거
A12: 칩제거기 | B12: D80x80mm | C12: 천원 | D12: =E12+F12+G12 -> 420 | E12: 0 | F12: 0 | G12: 420 | H12: 수자원적산지침 토목공사 8차/153P
A13: 칩제거기 | B13: D100x100mm | C13: 천원 | D13: =E13+F13+G13 -> 900 | E13: 0 | F13: 0 | G13: 900 | H13: 수자원적산지침 토목공사 8차/153P
A14: 칩제거기 | B14: D150x150mm | C14: 천원 | D14: =E14+F14+G14 -> 1104 | E14: 0 | F14: 0 | G14: 1104 | H14: 수자원적산지침 토목공사 8차/153P
A15: 칩제거기 | B15: D200x200mm | C15: 천원 | D15: =E15+F15+G15 -> 1140 | E15: 0 | F15: 0 | G15: 1140 | H15: 수자원적산지침 토목공사 8차/153P
A16: 칩제거기 | B16: D250x250mm | C16: 천원 | D16: =E16+F16+G16 -> 1584 | E16: 0 | F16: 0 | G16: 1584 | H16: 수자원적산지침 토목공사 8차/153P
A17: 칩제거기 | B17: D300x300mm | C17: 천원 | D17: =E17+F17+G17 -> 1800 | E17: 0 | F17: 0 | G17: 1800 | H17: 수자원적산지침 토목공사 8차/153P
A18: 칩제거기 | B18: D350x350mm | C18: 천원 | D18: =E18+F18+G18 -> 2520 | E18: 0 | F18: 0 | G18: 2520 | H18: 수자원적산지침 토목공사 8차/153P
A19: 칩제거기 | B19: D400x400mm | C19: 천원 | D19: =E19+F19+G19 -> 3000 | E19: 0 | F19: 0 | G19: 3000 | H19: 수자원적산지침 토목공사 8차/153P
A20: 칩제거기 | B20: D450x400mm | C20: 천원 | D20: =E20+F20+G20 -> 3000 | E20: 0 | F20: 0 | G20: 3000 | H20: 수자원적산지침 토목공사 8차/153P
A21: 칩제거기 | B21: D500x400mm | C21: 천원 | D21: =E21+F21+G21 -> 3000 | E21: 0 | F21: 0 | G21: 3000 | H21: 수자원적산지침 토목공사 8차/153P
A22: 칩제거기 | B22: D600x400mm | C22: 천원 | D22: =E22+F22+G22 -> 3000 | E22: 0 | F22: 0 | G22: 3000 | H22: 수자원적산지침 토목공사 8차/153P
A23: 칩제거기 | B23: D700x600mm | C23: 천원 | D23: =E23+F23+G23 -> 6120 | E23: 0 | F23: 0 | G23: 6120 | H23: 수자원적산지침 토목공사 8차/153P
... A27: 칩제거기 | B27: D1100x900mm | C27: 천원 | D27: =E27+F27+G27 -> 12600 | E27: 0 | F27: 0 | G27: 12600 | H27: 수자원적산지침 토목공사 8차/153P
A28: 칩제거기 | B28: D1200x850mm | C28: 천원 | D28: =E28+F28+G28 -> 12600 | E28: 0 | F28: 0 | G28: =장비견적서!$U$20 / 1000 -> 12600 | H28: ㈜대호스토퍼 장비견적서
A29: 칩제거기 | B29: D1200x900mm | C29: 천원 | D29: =E29+F29+G29 -> 12600 | E29: 0 | F29: 0 | G29: 12600 | H29: 수자원적산지침 토목공사 8차/153P
A30: 칩제거기 | B30: D1350x900mm | C30: 천원 | D30: =E30+F30+G30 -> 12600 | E30: 0 | F30: 0 | G30: 12600 | H30: 수자원적산지침 토목공사 8차/153P
A31: 칩제거기 | B31: D1500x1200mm | C31: 천원 | D31: =E31+F31+G31 -> 14400 | E31: 0 | F31: 0 | G31: 14400 | H31: 수자원적산지침 토목공사 8차/153P
A32: 칩제거기 | B32: D1650x1200mm | C32: 천원 | D32: =E32+F32+G32 -> 14400 | E32: 0 | F32: 0 | G32: 14400 | H32: 수자원적산지침 토목공사 8차/153P
A33: 칩제거기 | B33: D1800x1200mm | C33: 천원 | D33: =E33+F33+G33 -> 14400 | E33: 0 | F33: 0 | G33: 14400 | H33: 수자원적산지침 토목공사 8차/153P
A34: 칩제거기 | B34: D2000x1650mm | C34: 천원 | D34: =E34+F34+G34 -> 24504 | E34: 0 | F34: 0 | G34: 24504 | H34: 수자원적산지침 토목공사 8차/153P
A35: 칩제거기 | B35: D2100x1650mm | C35: 천원 | D35: =E35+F35+G35 -> 24504 | E35: 0 | F35: 0 | G35: 24504 | H35: 수자원적산지침 토목공사 8차/153P
A36: 칩제거기 | B36: D2200x1650mm | C36: 천원 | D36: =E36+F36+G36 -> 24504 | E36: 0 | F36: 0 | G36: 24504 | H36: 수자원적산지침 토목공사 8차/153P
A37: 칩제거기 | B37: D2300x1650mm | C37: 천원 | D37: =E37+F37+G37 -> 24504 | E37: 0 | F37: 0 | G37: 24504 | H37: 수자원적산지침 토목공사 8차/153P
A38: 칩제거기 | B38: D2400mm | C38: 천원 | D38: =E38+F38+G38 -> 24504 | E38: 0 | F38: 0 | G38: 24504 | H38: 수자원적산지침 토목공사 8차/153P
A39: 부단수 천공기 | B39: D80x80mm | C39: 천원 | D39: =E39+F39+G39 -> 11520 | E39: 0 | F39: 0 | G39: 11520 | H39: 수자원적산지침 토목공사 8차/154P
A40: 부단수 천공기 | B40: D100x100mm | C40: 천원 | D40: =E40+F40+G40 -> 11520 | E40: 0 | F40: 0 | G40: 11520 | H40: 수자원적산지침 토목공사 8차/154P
... A54: 부단수 천공기 | B54: D1100x900mm | C54: 천원 | D54: =E54+F54+G54 -> 246000 | E54: 0 | F54: 0 | G54: 246000 | H54: 수자원적산지침 토목공사 8차/154P
A55: 부단수 천공기 | B55: D1200x850mm | C55: 천원 | D55: =E55+F55+G55 -> 246000 | E55: 0 | F55: 0 | G55: =장비견적서!$U$19 / 1000 -> 246000 | H55: ㈜대호스토퍼 장비견적서
A56: 부단수 천공기 | B56: D1200x900mm | C56: 천원 | D56: =E56+F56+G56 -> 246000 | E56: 0 | F56: 0 | G56: 246000 | H56: 수자원적산지침 토목공사 8차/154P
...

Sheet 자재
A1: 자재
A2: 명 칭 | B2: 규 격 | C2: 단 위 | D2: 단 가 | E2: 비 고
A3: 용접봉 | B3: (고장력강용)(3.2㎜) | C3: EA | D3: 4900 | E3: (26년)물가자료 상/ 1387
A4: 연마지 | B4: #180 | C4: EA | D4: 340 | E4: (26년)물가자료 상 / 1412
A5: 액상접착제 | B5: 1kg 기준 | C5: kg | D5: =311200/15 -> 20746.667 | E5: (26년)물가자료 상 / 723
A6: 매스틱 | B6: 3T x 40 x 1m | C6: EA | D6: =16800/6 -> 2800 | E6: (26년)물가자료 상 / 723
A7: 안쪽층테이프 | B7: 0.508mm x 100mm x 1m | C7: EA | D7: =23200/30 -> 773.33333 | E7: (26년)물가자료 상 / 723
A8: 바깥층테이프 | B8: 0.381mm x 100mm x 1m | C8: EA | D8: =22200/30 -> 740 | E8: (26년)물가자료 상 / 723
A9: 경유 | B9: 저유황 0.001% | C9: L | D9: 1596 | E9: (26년)물가자료 하 / 32

Sheet 노임
A1: 노임 | E1: 26년도 상반기(대한건설협회 시중노임)
A2: 명 칭 | B2: 규 격 | C2: 단 위 | D2: 단 가 | E2: 비 고
A3: 방수공 | B3: 일반공사 직종 | C3: 인 | D3: 228286
A4: 보통인부 | B4: 일반공사 직종 | C4: 인 | D4: 172068
A5: 용접공 | B5: 일반공사 직종 | C5: 인 | D5: 282536
A6: 도장공 | B6: 일반공사 직종 | C6: 인 | D6: 263017
A7: 일반기계운전사 | B7: 일반공사 직종 | C7: 인 | D7: 173995
A8: 배관공(수도) | B8: 일반공사 직종 | C8: 인 | D8: 262580
A9: 플랜트기계설치공 | B9: 일반공사 직종 | C9: 인 | D9: 230376
A10: 플랜트배관공 | B10: 일반공사 직종 | C10: 인 | D10: 320480
A11: 플랜트용접공 | B11: 일반공사 직종 | C11: 인 | D11: 292640
A12: 고급기술자 | B12: 기계 설비 | C12: 인 | D12: 335379 | E12: 26년 한국엔지니어링협회
A13: 고급품질관리원 | B13: 일반공사 직종 | C13: 인 | D13: 197788

Sheet 경비
A1: 경비
A2: 명 칭 | B2: 규 격 | C2: 단 위 | D2: 재 료 비 | E2: 노 무 비 | F2: 경 비 | G2: 합 계 | H2: 비 고
A3: 트럭탑제형 크레인 | B3: 5 TON | C3: HR | D3: =중기기초자료!F3 -> 8440 | E3: =중기기초자료!E3 -> 49698 | F3: =중기기초자료!G3 -> 11117 | G3: =D3+E3+F3 -> 69255
A4: 트럭탑제형 크레인 | B4: 10 TON | C4: HR | D4: =중기기초자료!F4 -> 17045 | E4: =중기기초자료!E4 -> 49698 | F4: =중기기초자료!G4 -> 23795 | G4: =D4+E4+F4 -> 90538
A5: 트럭탑제형 크레인 | B5: 15 TON | C5: HR | D5: =중기기초자료!F5 -> 18204 | E5: =중기기초자료!E5 -> 49698 | F5: =중기기초자료!G5 -> 31327 | G5: =D5+E5+F5 -> 99229
A6: 트럭탑제형 크레인 | B6: 18 TON | C6: HR | D6: =중기기초자료!F6 -> 18700 | E6: =중기기초자료!E6 -> 49698 | F6: =중기기초자료!G6 -> 33328 | G6: =D6+E6+F6 -> 101726
A7: 무한궤도 크레인 | B7: 20 TON | C7: HR | D7: =중기기초자료!F7 -> 14232 | E7: =중기기초자료!E7 -> 58925 | F7: =중기기초자료!G7 -> 26776 | G7: =D7+E7+F7 -> 99933
A8: 발전기 | B8: 50 KW | C8: HR | D8: =중기기초자료!F8 -> 14877 | E8: =중기기초자료!E8 -> 36190 | F8: =중기기초자료!G8 -> 4689 | G8: =D8+E8+F8 -> 55756
A9: 용접기 (교류) | B9: 200 AMP | C9: HR | D9: =중기기초자료!F9 -> 0 | E9: =중기기초자료!E9 -> 0 | F9: =중기기초자료!G9 -> 92 | G9: =D9+E9+F9 -> 92
A10: 상수도관 천공기 | C10: HR | D10: =중기기초자료!F10 -> 0 | E10: =중기기초자료!E10 -> 0 | F10: =중기기초자료!G10 -> 597 | G10: =D10+E10+F10 -> 597
A11: 장비운반비 | B11: D1200mm(안산-울산) | C11: nr | F11: 5930000 | G11: =D11+E11+F11 -> 5930000

Sheet 자재조서
A1: 자재조서 | O1: 00년도 00월
A2: 코 드 | B2: 명 칭 | C2: 규 격 | D2: 단위 | E2: 견적단가 | G2: 물가정보 | I2: 물가자료 | K2: 거래가격 | M2: 유통물가 | O2: 적용단가
E3: 단가 | F3: Page | G3: 단가 | H3: Page | I3: 단가 | J3: Page | K3: 단가 | L3: Page | M3: 단가 | N3: Page

Sheet 자재견적서
B2: 견 적 서
B5: 문 서 번 호 | Q5: 공 급 자 | S5: 등록번호 | V5: 140-81-34127
B6: 수 신 | G6: K-water | S6: 상 호 | V6: (주)대호스토퍼 | AB6: 대표 | AE6: 이 영 호 | AI6: (인)
S7: 소 재 지 | V7: 경기도 안산시 상록구 남산평길 126-4(팔곡일동)
B8: 담 당 자 | O8: 귀중 | S8: 업 태 | V8: 제조업 외 | AB8: 종목 | AE8: 상하수도설비공사 외
B9: 연 락 처 | S9: 회사전화 | V9: 031-496-9488 | AB9: 회사팩스 | AE9: 031-496-9349
B10: 작 성 일 | G10: 46155 | S10: 담 당 자 | V10: 백승리 차장 | AB10: 휴대전화 | AE10: 010-5013-7776
B11: 유 효 기 간 | G11: 12개월 | S11: E-Mail | V11: dhcstopper@hanmail.net
B12: 견 적 명 | G12: 울산공업용수도 노후관 개량사업(3차) 및 추가사업 시설공사 중 부단수 차단 자재
B14: 합 계 금 액 | G14: 일금 | I14: =W14 -> 69752120 | T14: 원정 | V14: ( | W14: =AA33 -> 69752120 | AE14: ) | AF14: (VAT 별도)
B16: 아래와 같이 견적을 제출합니다.
B17: 번호 | D17: 품 명 | K17: 규 격 | Q17: 단위 | S17: 수량 | U17: 단 가 | AA17: 금 액 | AG17: 비고
B18: 1 | D18: 부단수 할정자관 (상,하판 1Set) | K18: D1,200㎜ | Q18: EA | S18: 1 | U18: 31000000 | AA18: =U18*S18 -> 31000000 | AR18: =U18 -> 31000000
B19: 2 | D19: 플랜지접합부속 (가스켓, 볼트/너트등) | K19: D850㎜ | Q19: EA | S19: 6 | U19: 550910 | AA19: =U19*S19 -> 3305460 | AR19: =U19 -> 550910
B20: 3 | D20: 컷터 | K20: D850㎜ | Q20: EA | S20: 1 | U20: 15000000 | AA20: =U20*S20 -> 15000000 | AR20: =U20 -> 15000000
B21: 4 | D21: 드릴 | K21: D850㎜ | Q21: EA | S21: 1 | U21: 624000 | AA21: =U21*S21 -> 624000 | AR21: =U21 -> 624000
B22: 5 | D22: Seailng Element | K22: D1,200㎜ | Q22: EA | S22: 1 | U22: 6000000 | AA22: =U22*S22 -> 6000000 | AR22: =U22 -> 6000000
B23: 6 | D23: 플러그(천공관용) | K23: D850㎜ | Q23: EA | S23: 1 | U23: 5150000 | AA23: =U23*S23 -> 5150000 | AR23: =U23 -> 5150000
B24: 7 | D24: 마개플랜지 | K24: D850㎜ | Q24: EA | S24: 1 | U24: 992660 | AA24: =U24*S24 -> 992660 | AR24: =U24 -> 992660
B25: 8 | D25: 등압관 피팅 | K25: D100㎜ | Q25: EA | S25: 16 | U25: 150000 | AA25: =U25*S25 -> 2400000 | AR25: =U25 -> 150000
B26: 9 | D26: 볼밸브 | K26: D100㎜ | Q26: EA | S26: 16 | U26: 250000 | AA26: =U26*S26 -> 4000000 | AR26: =U26 -> 250000
B27: 10 | D27: 플러그(등압관용) | K27: D100㎜ | Q27: EA | S27: 16 | U27: 50000 | AA27: =U27*S27 -> 800000 | AR27: =U27 -> 50000
B28: 11 | D28: CAP(등압관용) | K28: D100㎜ | Q28: EA | S28: 16 | U28: 30000 | AA28: =U28*S28 -> 480000 | AR28: =U28 -> 30000
AR29: =U29 -> 0
AR30: =U30 -> 0
AR31: =U31 -> 0
AR32: =U32 -> 0
B33: 합 계(TOTAL) | AA33: =SUM(AA18:AF28) -> 69752120
B34: MEMO | D34: 1. VAT 별도
H699: =자재견적서!#REF! -> #REF!

Sheet 장비견적서
B2: 견 적 서
B5: 문 서 번 호 | Q5: 공 급 자 | S5: 등록번호 | V5: 140-81-34127
B6: 수 신 | G6: K-water | S6: 상 호 | V6: (주)대호스토퍼 | AB6: 대표 | AE6: 이 영 호 | AI6: (인)
S7: 소 재 지 | V7: 경기도 안산시 상록구 남산평길 126-4(팔곡일동)
B8: 담 당 자 | O8: 귀중 | S8: 업 태 | V8: 제조업 외 | AB8: 종목 | AE8: 상하수도설비공사 외
B9: 연 락 처 | S9: 회사전화 | V9: 031-496-9488 | AB9: 회사팩스 | AE9: 031-496-9349
B10: 작 성 일 | G10: 46161 | S10: 담 당 자 | V10: 백승리 차장 | AB10: 휴대전화 | AE10: 010-5013-7776
B11: 유 효 기 간 | G11: 12개월 | S11: E-Mail | V11: dhcstopper@hanmail.net
B12: 견 적 명 | G12: 울산공업용수도 노후관 개량사업(3차) 및 추가사업 시설공사 중 부단수 차단 장비
B14: 합 계 금 액 | G14: 일금 | I14: =W14 -> 462600000 | T14: 원정 | V14: ( | W14: =AA29 -> 462600000 | AE14: ) | AF14: (VAT 별도)
B16: 아래와 같이 견적을 제출합니다.
B17: 번호 | D17: 품 명 | K17: 규 격 | Q17: 단위 | S17: 수량 | U17: 단 가 | AA17: 금 액 | AG17: 비고
B18: 1 | D18: 샌드위치 밸브 | K18: D1,200*850㎜ | Q18: EA | S18: 1 | U18: 55000000 | AA18: =U18*S18 -> 55000000 | AR18: =U18 -> 55000000
B19: 2 | D19: 부단수천공기 | K19: D1,200*850㎜ | Q19: EA | S19: 1 | U19: 246000000 | AA19: =U19*S19 -> 246000000 | AR19: =U19 -> 246000000
B20: 3 | D20: 칩제거기 | K20: D1,200*850㎜ | Q20: EA | S20: 1 | U20: 12600000 | AA20: =U20*S20 -> 12600000 | AR20: =U20 -> 12600000
B21: 4 | D21: 부단수차단기 | K21: D1,200*850㎜ | Q21: EA | S21: 1 | U21: 133000000 | AA21: =U21*S21 -> 133000000 | AR21: =U21 -> 133000000
B22: 5 | D22: 플러깅 | K22: D1,200*850㎜ | Q22: EA | S22: 1 | U22: 16000000 | AA22: =U22*S22 -> 16000000 | AR22: =U22 -> 16000000
AR23: =U23 -> 0
AR24: =U24 -> 0
AR25: =U25 -> 0
AR26: =U26 -> 0
AR27: =U27 -> 0
AR28: =U28 -> 0
B29: 합 계(TOTAL) | AA29: =SUM(AA18:AF28) -> 462600000
B30: MEMO | D30: 1. VAT 별도
H695: =장비견적서!#REF! -> #REF!

Sheet 수량산출서
A1: 공종 | B1: 산출근거 | C1: 수량

Sheet 장비운반비 산출근거
