Workbook
Name _A146432: #REF!
Name _A146432: #REF!
Name _A146432: #REF!
Name _A146432: #REF!
Name _A146432: #REF!
Name _A146432: #REF!
Name _A146432: #REF!
Name _A69999: #REF!
Name _A69999: #REF!
Name _A69999: #REF!
Name _A69999: #REF!
Name _A69999: #REF!
Name _A69999: #REF!
Name _A69999: #REF!
Name _A70013: #REF!
Name _A70013: #REF!
Name _A70013: #REF!
Name _A70013: #REF!
Name _A70013: #REF!
Name _A70013: #REF!
Name _A70013: #REF!
Name _A946432: #REF!
Name _A946432: #REF!
Name _A946432: #REF!
Name _A946432: #REF!
Name _A946432: #REF!
Name _A946432: #REF!
Name _A946432: #REF!
Name _D800: #REF!
Name _D800: #REF!
Name _D800: #REF!
Name _D800: #REF!
Name _D800: #REF!
Name _D800: #REF!
Name _D800: #REF!
Name ¿i·Iº¹≫c: #REF!
Name ¿i·Iº¹≫c: #REF!
Name ¿i·Iº¹≫c: #REF!
Name ¿i·Iº¹≫c: #REF!
Name ¿i·Iº¹≫c: #REF!
Name ¿i·Iº¹≫c: #REF!
Name ¿i·Iº¹≫c: #REF!
Name a: #REF!
Name AI¼a: #REF!
Name AI¼a: #REF!
Name AI¼a: #REF!
Name AI¼a: #REF!
Name AI¼a: #REF!
Name AI¼a: #REF!
Name AI¼a: #REF!
Name ÀÎ¼â: #REF!
Name ÀÎ¼â: #REF!
Name ÀÎ¼â: #REF!
Name ÀÎ¼â: #REF!
Name ÀÎ¼â: #REF!
Name ÀÎ¼â: #REF!
Name ÀÎ¼â: #REF!
Name Ao¿i±a: #REF!
Name Ao¿i±a: #REF!
Name Ao¿i±a: #REF!

Sheet 내역서표지(용인)
B2: ='기성내역서(용인)'!A2 -> 공사명 : 2025년 열수송관 천공 및 차단공사(1권역)
B3: [용인 지사]
A9: 제 1회 기성내역서(용인)
E15: 총 공 사 비 : | F15: =F17+F18 -> 1475749000
E16: 구 분 | F16: 금 액
E17: 총 원 가 | F17: ='기성총괄표(용인)'!M34 -> 1341590000
E18: 부 가 세 | F18: =F17*0.1 -> 134159000
E19: 합 계 | F19: =F17+F18 -> 1475749000

Sheet 결과요약
B8: 계약명 | D8: 2025년 열수송관 천공 및 차단공사(1권역)
B9: 계약번호 | D9: 제100354-2025-C-024호
B10: 계약상대자 | D10: ㈜대호스토퍼
B11: 계약기간 | D11: 2025. 12. 15 ~ 2027. 03. 10
B12: 기성기간 | D12: 2025. 12. 15 ~ 2026. 05. 29
B13: 계정과목 | D13: 건가 | E13: ='시공사별 금액'!C5+'시공사별 금액'!C6+'시공사별 금액'!C7 -> 1102453000 | F13: =E13+E15 -> 1355376000
D14: 제조 | E14: ='시공사별 금액'!C8 -> 91938000
D15: 예수금 | E15: ='시공사별 금액'!C9 -> 252923000
D16: 중앙지사 | E16: ='시공사별 금액'!C4 -> 28435000
B17: 계약금액 | C17: 용인분 | D17: ='기성정산내역 (용인)'!J35 -> 5.3752969e+09 | E17: (부가가치세 포함)
B18: 기성금액 | C18: 금회 | D18: ='기성정산내역 (용인)'!L35 -> 1475749000 | E18: (10 %, 부가가치세 포함)
C19: 누계 | D19: ='기성정산내역 (용인)'!M35 -> 1475749000 | E19: (10 %, 부가가치세 포함)

Sheet 시공사별 금액
A1: 시공사별 금액
A2: 공사명 : 2025년 열수송관 천공 및 차단공사(1권역) | D2: (부가세 포함)
A3: 공 사 명 (예산과목) | B3: 전 회 | C3: 금 회 | D3: 누 계
A4: 중앙지사(2권역 대행) | B4: 0 | C4: ='기성정산내역(중앙_2권역 대행)'!K35 -> 28435000 | D4: =B4+C4 -> 28435000
A5: 수지-수원연계 지역난방 열배관공사 (건가) | B5: 0 | C5: ='기성정산내역(수지-수원_시티_건가)'!K35 -> 536635000 | D5: =B5+C5 -> 536635000
A6: 2025년 열수송관 천공 및 차단공사 (건가) | B6: 0 | C6: ='기성정산내역(2025열수송관_시티_건가)'!K35 -> 348150000 | D6: =B6+C6 -> 348150000
A7: 2024년 용인지사 열수송시설 유지보수공사 (건가) | B7: 0 | C7: ='기성정산내역(2024용인_지성_건가)'!K35 -> 217668000 | D7: =B7+C7 -> 217668000
A8: 2024년 용인지사 열수송시설 유지보수공사(제조) | B8: 0 | C8: ='기성정산내역(2024용인_지성_제조)'!K35 -> 91938000 | D8: =B8+C8 -> 91938000
A9: 2024년 용인지사 열수송시설 유지보수공사(예수금) | B9: 0 | C9: ='기성정산내역(2024용인_지성_예수금)'!K35 -> 252923000 | D9: =B9+C9 -> 252923000
A10: 합 계 | B10: =SUM(B4:B9) -> 0 | C10: =SUM(C4:C9) -> 1475749000 | D10: =SUM(D4:D9) -> 1475749000

Sheet 기성정산내역 (용인)
A1: 기 성 정 산 내 역 (용인)
A2: 공사명 : 2025년 열수송관 천공 및 차단공사(1권역)
B3: 공 종 | C3: 규 격 | D3: 수 량 | E3: 단 위 | F3: 산출내역 | J3: 계약금액 | K3: 전회까지 기 성 액 | L3: 금 회 기성액 | M3: 누계기성 금 액
A4: 1. 천공 및 차단 | J4: =기성집계표!G61 -> 4183120378 | K4: 0 | L4: =기성집계표!K61 -> 1204732090 | M4: =L4+K4 -> 1204732090
B8: 순공사비 계 | J8: =J4 -> 4183120378 | K8: =SUM(K4:K7) -> 0 | L8: =SUM(L4:L7) -> 1204732090 | M8: =SUM(M4:M7) -> 1204732090
B9: [공사비총괄표]
A10: 1. | B10: 재료비 | D10: 1 | E10: 식 | J10: 3503522580 | K10: 0 | L10: ='기성총괄표(용인)'!M12 -> 990810756 | M10: =K10+L10 -> 990810756
A11: 2. | B11: 노무비 | J11: 561527501 | K11: 0 | L11: ='기성총괄표(용인)'!M13 -> 175189110 | M11: =K11+L11 -> 175189110
B12: 가. 직접노무비 | D12: 1 | E12: 식 | J12: 495611206 | K12: 0 | L12: ='기성총괄표(용인)'!M14 -> 154624108 | M12: =K12+L12 -> 154624108
B13: 나. 간접노무비 | C13: 0.116 | D13: 1 | E13: 식 | F13: (직접노무비 x 요율) | J13: 65916295 | K13: 0 | L13: ='기성총괄표(용인)'!M15 -> 20565002 | M13: =K13+L13 -> 20565002
A14: 3. | B14: 경비 | J14: 601241493 | K14: 0 | L14: ='기성총괄표(용인)'!M16 -> 116275352 | M14: =K14+L14 -> 116275352
B15: 가. 기계경비 | D15: 1 | E15: 식 | J15: 190649344 | K15: 0 | L15: ='기성총괄표(용인)'!M17 -> 59297226 | M15: =K15+L15 -> 59297226
B16: 나. 보험료 | K16: 0 | L16: ='기성총괄표(용인)'!M18 -> 0 | M16: =K16+L16 -> 0
B17: 1) 산재보험료 | C17: 0.0356 | D17: 1 | E17: 식 | F17: [(직접노무비 + 간접노무비) x 요율] | J17: 19990385 | K17: 0 | L17: ='기성총괄표(용인)'!M19 -> 6236729 | M17: =K17+L17 -> 6236729
B18: 2) 고용보험료 | C18: 0.0101 | D18: 1 | E18: 식 | F18: [(직접노무비 + 간접노무비) x 요율] | J18: 5671431 | K18: 0 | L18: ='기성총괄표(용인)'!M20 -> 1769407 | M18: =K18+L18 -> 1769407
B19: 3) 연금보험료 | C19: 0.045 | D19: 1 | E19: 식 | F19: (직접노무비 x 요율) | J19: 23374814 | K19: 0 | L19: ='기성총괄표(용인)'!M21 -> 0 | M19: =K19+L19 -> 0 | N19: 실적정산
B20: 4) 건강보험료 | C20: 0.03545 | D20: 1 | E20: 식 | F20: (직접노무비 x 요율) | J20: 18414158 | K20: 0 | L20: ='기성총괄표(용인)'!M22 -> 0 | M20: =K20+L20 -> 0 | N20: 실적정산
B21: 5) 노인장기요양보험료 | C21: 0.1295 | D21: 1 | E21: 식 | F21: (건강보험료 x 요율) | J21: 2384638 | K21: 0 | L21: ='기성총괄표(용인)'!M23 -> 0 | M21: =K21+L21 -> 0 | N21: 실적정산
B22: 다. 건설근로자퇴직공제부금비 | C22: 0.023 | D22: 1 | E22: 식 | F22: (직접노무비) x 요율 | J22: 11947128 | K22: 0 | L22: ='기성총괄표(용인)'!M24 -> 0 | M22: =K22+L22 -> 0 | N22: 실적정산
B23: 라. 산업안전보건관리비 | C23: 0.0199 | D23: 1 | E23: 식 | F23: (재료비 + 직접노무비) x 요율 + 5,499,000 | J23: 120369428 | K23: 0 | L23: ='기성총괄표(용인)'!M25 -> 0 | M23: =K23+L23 -> 0 | N23: 실적정산
B24: 마. 기타경비 | C24: 0.048 | D24: 1 | E24: 식 | F24: [(재료비 + 직접노무비 + 간접노무비) x 요율] | J24: 170732109 | K24: 0 | L24: ='기성총괄표(용인)'!M26 -> 48971990 | M24: =K24+L24 -> 48971990
B25: 바. 환경보전비 | C25: 0.005 | D25: 1 | E25: 식 | F25: [(재료비 + 직접노무비 + 산출경비) x 요율] | J25: 20948919 | K25: 0 | L25: ='기성총괄표(용인)'!M27 -> 0 | M25: =K25+L25 -> 0 | N25: 실적정산
B26: 사. 지급보증서발급수수료 | K26: 0 | L26: ='기성총괄표(용인)'!M28 -> 0 | M26: =K26+L26 -> 0
B27: 1) 하도급대금 | C27: 0.00081 | D27: 1 | E27: 식 | F27: [(재료비 + 직접노무비 + 산출경비) x 요율] | J27: 3351829 | K27: 0 | L27: ='기성총괄표(용인)'!M29 -> 0 | M27: =K27+L27 -> 0 | N27: 실적정산
B28: 2) 건설기계대여대금 | C28: 0.0032 | D28: 1 | E28: 식 | F28: [(재료비 + 직접노무비 + 산출경비) x 요율] | J28: 13407310 | K28: 0 | L28: ='기성총괄표(용인)'!M30 -> 0 | M28: =K28+L28 -> 0 | N28: 실적정산
B29: 순 공 사 원 가 | J29: 4666291574 | K29: 0 | L29: ='기성총괄표(용인)'!M31 -> 1282275218 | M29: =K29+L29 -> 1282275218
A30: 4. | B30: 일반관리비 | C30: 0.04 | D30: 1 | E30: 식 | F30: [(재료비 + 노무비 + 경비) x 요율] | J30: 163320208 | K30: 0 | L30: ='기성총괄표(용인)'!M32 -> 44879629 | M30: =K30+L30 -> 44879629
A31: 5. | B31: 이윤 | C31: 0.05 | D31: 1 | E31: 식 | F31: [(노무비 + 경비 + 일반관리비) x 요율] | J31: 57021799 | K31: 0 | L31: ='기성총괄표(용인)'!M33 -> 14435153 | M31: =K31+L31 -> 14435153
B32: 공 사 원 가 | J32: 4886633581 | K32: 0 | L32: ='기성총괄표(용인)'!M34 -> 1341590000 | M32: =K32+L32 -> 1341590000
B33: 총 원 가 | J33: 4886633581 | K33: 0 | L33: ='기성총괄표(용인)'!M35 -> 1341590000 | M33: =K33+L33 -> 1341590000
B34: 부 가 세 | J34: 4.8866336e+08 | K34: 0 | L34: ='기성총괄표(용인)'!M36 -> 134159000 | M34: =K34+L34 -> 134159000
B35: 총 공 사 금 액 | J35: 5.3752969e+09 | K35: 0 | L35: ='기성총괄표(용인)'!M37 -> 1475749000 | M35: =K35+L35 -> 1475749000
J46: 1604455902
J47: 0
J48: 1604455902
J49: 1.6044559e+08
J50: 1.7649015e+09

Sheet 기성집계표
A1: 기 성 집 계 표 (용인)
A2: 공사명 : 2025년 열수송관 천공 및 차단공사(1권역)
A3: 공 종 | B3: 명 칭 | C3: 규 격 | D3: 단 가 | E3: 단위 | F3: 계약 수량 | H3: 전 회 | J3: 금 회 | L3: 누 계 | N3: 분류코드
F4: 수 량 | G4: 금 액 | H4: 수 량 | I4: 금 액 | J4: 수 량 | K4: 금 액 | L4: 수 량 | M4: 금 액
B5: 순공사비 | D5: 0
A6: 1. | B6: 천공 및 차단 | D6: 0
A7: 1) | B7: 천공 및 차단 | C7: T.O.R(50A) | D7: 850951 | E7: 공 | F7: 2 | G7: =D7*F7 -> 1701902 | I7: =D7*H7 -> 0 | J7: ='기성내역서(용인)'!D7 -> 0 | K7: =D7*J7 -> 0 | L7: =H7+J7 -> 0 | M7: =D7*L7 -> 0
A8: 2) | B8: 천공 및 차단 | C8: 65A | D8: 2808567 | E8: 공 | G8: =D8*F8 -> 0 | I8: =D8*H8 -> 0 | J8: ='기성내역서(용인)'!D8 -> 0 | K8: =D8*J8 -> 0 | L8: =H8+J8 -> 0 | M8: =D8*L8 -> 0
A9: 3) | B9: 천공 및 차단 | C9: 80A | D9: 3322411 | E9: 공 | G9: =D9*F9 -> 0 | I9: =D9*H9 -> 0 | J9: ='기성내역서(용인)'!D9 -> 0 | K9: =D9*J9 -> 0 | L9: =H9+J9 -> 0 | M9: =D9*L9 -> 0
A10: 4) | B10: 천공 및 차단 | C10: 100A | D10: 4103409 | E10: 공 | G10: =D10*F10 -> 0 | I10: =D10*H10 -> 0 | J10: ='기성내역서(용인)'!D10 -> 0 | K10: =D10*J10 -> 0 | L10: =H10+J10 -> 0 | M10: =D10*L10 -> 0
A11: 5) | B11: 천공 및 차단 | C11: 125A | D11: 4728620 | E11: 공 | G11: =D11*F11 -> 0 | I11: =D11*H11 -> 0 | J11: ='기성내역서(용인)'!D11 -> 0 | K11: =D11*J11 -> 0 | L11: =H11+J11 -> 0 | M11: =D11*L11 -> 0
A12: 6) | B12: 천공 및 차단 | C12: 150A | D12: 5760152 | E12: 공 | F12: 10 | G12: =D12*F12 -> 57601520 | I12: =D12*H12 -> 0 | J12: ='기성내역서(용인)'!D12 -> 6 | K12: =D12*J12 -> 34560912 | L12: =H12+J12 -> 6 | M12: =D12*L12 -> 34560912
A13: 7) | B13: 천공 및 차단 | C13: 200A | D13: 8775745 | E13: 공 | F13: 10 | G13: =D13*F13 -> 87757450 | I13: =D13*H13 -> 0 | J13: ='기성내역서(용인)'!D13 -> 2 | K13: =D13*J13 -> 17551490 | L13: =H13+J13 -> 2 | M13: =D13*L13 -> 17551490
A14: 8) | B14: 천공 및 차단 | C14: 250A | D14: 11452846 | E14: 공 | F14: 8 | G14: =D14*F14 -> 91622768 | I14: =D14*H14 -> 0 | J14: ='기성내역서(용인)'!D14 -> 0 | K14: =D14*J14 -> 0 | L14: =H14+J14 -> 0 | M14: =D14*L14 -> 0
A15: 9) | B15: 천공 및 차단 | C15: 300A | D15: 14159994 | E15: 공 | F15: 14 | G15: =D15*F15 -> 198239916 | I15: =D15*H15 -> 0 | J15: ='기성내역서(용인)'!D15 -> 0 | K15: =D15*J15 -> 0 | L15: =H15+J15 -> 0 | M15: =D15*L15 -> 0
A16: 10) | B16: 천공 및 차단 | C16: 350A | D16: 20841373 | E16: 공 | F16: 18 | G16: =D16*F16 -> 375144714 | I16: =D16*H16 -> 0 | J16: ='기성내역서(용인)'!D16 -> 0 | K16: =D16*J16 -> 0 | L16: =H16+J16 -> 0 | M16: =D16*L16 -> 0
A17: 11) | B17: 천공 및 차단 | C17: 400A | D17: 21749251 | E17: 공 | F17: 8 | G17: =D17*F17 -> 173994008 | I17: =D17*H17 -> 0 | J17: ='기성내역서(용인)'!D17 -> 0 | K17: =D17*J17 -> 0 | L17: =H17+J17 -> 0 | M17: =D17*L17 -> 0
A18: 12) | B18: 천공 및 차단 | C18: 450A | D18: 25578231 | E18: 공 | F18: 4 | G18: =D18*F18 -> 102312924 | I18: =D18*H18 -> 0 | J18: ='기성내역서(용인)'!D18 -> 0 | K18: =D18*J18 -> 0 | L18: =H18+J18 -> 0 | M18: =D18*L18 -> 0
A19: 13) | B19: 천공 및 차단 | C19: 500A | D19: 29546894 | E19: 공 | F19: 16 | G19: =D19*F19 -> 472750304 | I19: =D19*H19 -> 0 | J19: ='기성내역서(용인)'!D19 -> 2 | K19: =D19*J19 -> 59093788 | L19: =H19+J19 -> 2 | M19: =D19*L19 -> 59093788
A20: 14) | B20: 천공 및 차단 | C20: 550A | D20: 31886354 | E20: 공 | G20: =D20*F20 -> 0 | I20: =D20*H20 -> 0 | J20: ='기성내역서(용인)'!D20 -> 0 | K20: =D20*J20 -> 0 | L20: =H20+J20 -> 0 | M20: =D20*L20 -> 0
A21: 15) | B21: 천공 및 차단 | C21: 600A | D21: 39994404 | E21: 공 | F21: 10 | G21: =D21*F21 -> 399944040 | I21: =D21*H21 -> 0 | J21: ='기성내역서(용인)'!D21 -> 0 | K21: =D21*J21 -> 0 | L21: =H21+J21 -> 0 | M21: =D21*L21 -> 0
A22: 16) | B22: 천공 및 차단 | C22: 650A | D22: 42987637 | E22: 공 | G22: =D22*F22 -> 0 | I22: =D22*H22 -> 0 | J22: ='기성내역서(용인)'!D22 -> 0 | K22: =D22*J22 -> 0 | L22: =H22+J22 -> 0 | M22: =D22*L22 -> 0
A23: 17) | B23: 천공 및 차단 | C23: 700A | D23: 47404740 | E23: 공 | F23: 24 | G23: =D23*F23 -> 1137713760 | I23: =D23*H23 -> 0 | J23: ='기성내역서(용인)'!D23 -> 14 | K23: =D23*J23 -> 663666360 | L23: =H23+J23 -> 14 | M23: =D23*L23 -> 663666360
A24: 18) | B24: 천공 및 차단 | C24: 750A | D24: 55399674 | E24: 공 | G24: =D24*F24 -> 0 | I24: =D24*H24 -> 0 | J24: ='기성내역서(용인)'!D24 -> 0 | K24: =D24*J24 -> 0 | L24: =H24+J24 -> 0 | M24: =D24*L24 -> 0
A25: 19) | B25: 천공 및 차단 | C25: 800A | D25: 58689420 | E25: 공 | G25: =D25*F25 -> 0 | I25: =D25*H25 -> 0 | J25: ='기성내역서(용인)'!D25 -> 0 | K25: =D25*J25 -> 0 | L25: =H25+J25 -> 0 | M25: =D25*L25 -> 0
A26: 20) | B26: 천공 및 차단 | C26: 850A | D26: 68673718 | E26: 공 | G26: =D26*F26 -> 0 | I26: =D26*H26 -> 0 | J26: ='기성내역서(용인)'!D26 -> 0 | K26: =D26*J26 -> 0 | L26: =H26+J26 -> 0 | M26: =D26*L26 -> 0
A27: 21) | B27: 천공 및 차단 | C27: 900A | D27: 80265941 | E27: 공 | G27: =D27*F27 -> 0 | I27: =D27*H27 -> 0 | J27: ='기성내역서(용인)'!D27 -> 0 | K27: =D27*J27 -> 0 | L27: =H27+J27 -> 0 | M27: =D27*L27 -> 0
B28: 소계 | F28: =SUM(F7:F27) -> 124 | G28: =SUM(G7:G27) -> 3098783306 | H28: =SUM(H7:H27) -> 0 | I28: =SUM(I7:I27) -> 0 | J28: ='기성내역서(용인)'!D28 -> 24 | K28: =SUM(K7:K27) -> 774872550 | L28: =SUM(L7:L27) -> 24 | M28: =SUM(M7:M27) -> 774872550
A29: 2. | B29: 천공 및 차단(야간)
A30: 22) | B30: 천공 및 차단 | C30: T.O.R(50A) | D30: 1118925 | E30: 공 | F30: 0 | G30: =D30*F30 -> 0 | H30: 0 | I30: =D30*H30 -> 0 | J30: ='기성내역서(용인)'!D30 -> 0 | K30: =D30*J30 -> 0 | L30: =H30+J30 -> 0 | M30: =D30*L30 -> 0
A31: 23) | B31: 천공 및 차단 | C31: 65A | D31: 3333888 | E31: 공 | F31: 0 | G31: =D31*F31 -> 0 | H31: 0 | I31: =D31*H31 -> 0 | J31: ='기성내역서(용인)'!D31 -> 0 | K31: =D31*J31 -> 0 | L31: =H31+J31 -> 0 | M31: =D31*L31 -> 0
A32: 24) | B32: 천공 및 차단 | C32: 150A | D32: 6519805 | E32: 공 | F32: 4 | G32: =D32*F32 -> 26079220 | H32: 0 | I32: =D32*H32 -> 0 | J32: ='기성내역서(용인)'!D32 -> 0 | K32: =D32*J32 -> 0 | L32: =H32+J32 -> 0 | M32: =D32*L32 -> 0
A33: 25) | B33: 천공 및 차단 | C33: 200A | D33: 9824497 | E33: 공 | F33: 4 | G33: =D33*F33 -> 39297988 | H33: 0 | I33: =D33*H33 -> 0 | J33: ='기성내역서(용인)'!D33 -> 4 | K33: =D33*J33 -> 39297988 | L33: =H33+J33 -> 4 | M33: =D33*L33 -> 39297988
A34: 26) | B34: 천공 및 차단 | C34: 250A | D34: 12614703 | E34: 공 | F34: 0 | G34: =D34*F34 -> 0 | H34: 0 | I34: =D34*H34 -> 0 | J34: ='기성내역서(용인)'!D34 -> 0 | K34: =D34*J34 -> 0 | L34: =H34+J34 -> 0 | M34: =D34*L34 -> 0
A35: 27) | B35: 천공 및 차단 | C35: 300A | D35: 15451255 | E35: 공 | F35: 0 | G35: =D35*F35 -> 0 | H35: 0 | I35: =D35*H35 -> 0 | J35: ='기성내역서(용인)'!D35 -> 0 | K35: =D35*J35 -> 0 | L35: =H35+J35 -> 0 | M35: =D35*L35 -> 0
A36: 28) | B36: 천공 및 차단 | C36: 350A | D36: 22636931 | E36: 공 | F36: 8 | G36: =D36*F36 -> 181095448 | H36: 0 | I36: =D36*H36 -> 0 | J36: ='기성내역서(용인)'!D36 -> 8 | K36: =D36*J36 -> 181095448 | L36: =H36+J36 -> 8 | M36: =D36*L36 -> 181095448
A37: 29) | B37: 천공 및 차단 | C37: 400A | D37: 23875966 | E37: 공 | F37: 0 | G37: =D37*F37 -> 0 | H37: 0 | I37: =D37*H37 -> 0 | J37: ='기성내역서(용인)'!D37 -> 0 | K37: =D37*J37 -> 0 | L37: =H37+J37 -> 0 | M37: =D37*L37 -> 0
A38: 30) | B38: 천공 및 차단 | C38: 500A | D38: 32628494 | E38: 공 | F38: 0 | G38: =D38*F38 -> 0 | H38: 0 | I38: =D38*H38 -> 0 | J38: ='기성내역서(용인)'!D38 -> 0 | K38: =D38*J38 -> 0 | L38: =H38+J38 -> 0 | M38: =D38*L38 -> 0
A39: 31) | B39: 천공 및 차단 | C39: 550A | D39: 35302904 | E39: 공 | F39: 0 | G39: =D39*F39 -> 0 | H39: 0 | I39: =D39*H39 -> 0 | J39: ='기성내역서(용인)'!D39 -> 0 | K39: =D39*J39 -> 0 | L39: =H39+J39 -> 0 | M39: =D39*L39 -> 0
A40: 32) | B40: 천공 및 차단 | C40: 600A | D40: 44094659 | E40: 공 | F40: 0 | G40: =D40*F40 -> 0 | H40: 0 | I40: =D40*H40 -> 0 | J40: ='기성내역서(용인)'!D40 -> 0 | K40: =D40*J40 -> 0 | L40: =H40+J40 -> 0 | M40: =D40*L40 -> 0
...

Sheet 기성총괄표(용인)
A1: 기 성 총 괄 표 (용인)
A2: 공사명 : 2025년 열수송관 천공 및 차단공사(1권역)
B3: 공 종 | C3: 규 격 | D3: 수 량 | E3: 단 위 | F3: 재 료 비 | H3: 노 무 비 | J3: 경 비 | L3: 계 | N3: 비 고
F4: 단 가 | G4: 금 액 | H4: 단 가 | I4: 금 액 | J4: 단 가 | K4: 금 액 | L4: 단 가 | M4: 금 액
B5: Ⅰ. 열배관공사
A6: 1. 천공 및 차단 | G6: ='기성내역서(용인)'!G61 -> 990810756 | I6: ='기성내역서(용인)'!I61 -> 154624108 | K6: ='기성내역서(용인)'!K61 -> 59297226 | M6: =G6+I6+K6 -> 1204732090
B10: 순공사비 계 | G10: =SUM(G6:G9) -> 990810756 | I10: =SUM(I6:I9) -> 154624108 | K10: =SUM(K6:K9) -> 59297226 | M10: =SUM(M6:M9) -> 1204732090
B11: [공사비총괄표]
A12: 1. | B12: 재료비 | D12: 1 | E12: 식 | M12: =SUM('기성총괄표(중앙_2권역 대행)'!M12,'기성총괄표(수지-수원_시티_건가)'!M12,'기성총괄표(2025열수송관_시티_건가)'!M12,'기성총괄표(2024용인_지성_제조)'!M12,'기성총괄표(2024용인_지성_건가)'!M12,'기성총괄표(2024용인_지성_예수금)'!M12) -> 990810756
A13: 2. | B13: 노무비 | M13: =SUM('기성총괄표(중앙_2권역 대행)'!M13,'기성총괄표(수지-수원_시티_건가)'!M13,'기성총괄표(2025열수송관_시티_건가)'!M13,'기성총괄표(2024용인_지성_제조)'!M13,'기성총괄표(2024용인_지성_건가)'!M13,'기성총괄표(2024용인_지성_예수금)'!M13) -> 175189110
B14: 가. 직접노무비 | D14: 1 | E14: 식 | M14: =SUM('기성총괄표(중앙_2권역 대행)'!M14,'기성총괄표(수지-수원_시티_건가)'!M14,'기성총괄표(2025열수송관_시티_건가)'!M14,'기성총괄표(2024용인_지성_제조)'!M14,'기성총괄표(2024용인_지성_건가)'!M14,'기성총괄표(2024용인_지성_예수금)'!M14) -> 154624108
B15: 나. 간접노무비 | C15: 0.133 | D15: 1 | E15: 식 | F15: (직접노무비 x 요율) | M15: =SUM('기성총괄표(중앙_2권역 대행)'!M15,'기성총괄표(수지-수원_시티_건가)'!M15,'기성총괄표(2025열수송관_시티_건가)'!M15,'기성총괄표(2024용인_지성_제조)'!M15,'기성총괄표(2024용인_지성_건가)'!M15,'기성총괄표(2024용인_지성_예수금)'!M15) -> 20565002
A16: 3. | B16: 경비 | M16: =SUM('기성총괄표(중앙_2권역 대행)'!M16,'기성총괄표(수지-수원_시티_건가)'!M16,'기성총괄표(2025열수송관_시티_건가)'!M16,'기성총괄표(2024용인_지성_제조)'!M16,'기성총괄표(2024용인_지성_건가)'!M16,'기성총괄표(2024용인_지성_예수금)'!M16) -> 116275352
B17: 가. 기계경비 | D17: 1 | E17: 식 | M17: =SUM('기성총괄표(중앙_2권역 대행)'!M17,'기성총괄표(수지-수원_시티_건가)'!M17,'기성총괄표(2025열수송관_시티_건가)'!M17,'기성총괄표(2024용인_지성_제조)'!M17,'기성총괄표(2024용인_지성_건가)'!M17,'기성총괄표(2024용인_지성_예수금)'!M17) -> 59297226
B18: 나. 보험료 | M18: =SUM('기성총괄표(중앙_2권역 대행)'!M18,'기성총괄표(수지-수원_시티_건가)'!M18,'기성총괄표(2025열수송관_시티_건가)'!M18,'기성총괄표(2024용인_지성_제조)'!M18,'기성총괄표(2024용인_지성_건가)'!M18,'기성총괄표(2024용인_지성_예수금)'!M18) -> 0
B19: 1) 산재보험료 | C19: 0.0356 | D19: 1 | E19: 식 | F19: [(직접노무비 + 간접노무비) x 요율] | M19: =SUM('기성총괄표(중앙_2권역 대행)'!M19,'기성총괄표(수지-수원_시티_건가)'!M19,'기성총괄표(2025열수송관_시티_건가)'!M19,'기성총괄표(2024용인_지성_제조)'!M19,'기성총괄표(2024용인_지성_건가)'!M19,'기성총괄표(2024용인_지성_예수금)'!M19) -> 6236729
B20: 2) 고용보험료 | C20: 0.0101 | D20: 1 | E20: 식 | F20: [(직접노무비 + 간접노무비) x 요율] | M20: =SUM('기성총괄표(중앙_2권역 대행)'!M20,'기성총괄표(수지-수원_시티_건가)'!M20,'기성총괄표(2025열수송관_시티_건가)'!M20,'기성총괄표(2024용인_지성_제조)'!M20,'기성총괄표(2024용인_지성_건가)'!M20,'기성총괄표(2024용인_지성_예수금)'!M20) -> 1769407
B21: 3) 연금보험료 | C21: 0.045 | D21: 1 | E21: 식 | F21: (직접노무비 x 요율) | M21: =SUM('기성총괄표(중앙_2권역 대행)'!M21,'기성총괄표(수지-수원_시티_건가)'!M21,'기성총괄표(2025열수송관_시티_건가)'!M21,'기성총괄표(2024용인_지성_제조)'!M21,'기성총괄표(2024용인_지성_건가)'!M21,'기성총괄표(2024용인_지성_예수금)'!M21) -> 0 | N21: 실적정산
B22: 4) 건강보험료 | C22: 0.03545 | D22: 1 | E22: 식 | F22: (직접노무비 x 요율) | M22: =SUM('기성총괄표(중앙_2권역 대행)'!M22,'기성총괄표(수지-수원_시티_건가)'!M22,'기성총괄표(2025열수송관_시티_건가)'!M22,'기성총괄표(2024용인_지성_제조)'!M22,'기성총괄표(2024용인_지성_건가)'!M22,'기성총괄표(2024용인_지성_예수금)'!M22) -> 0 | N22: 실적정산
B23: 5) 노인장기요양보험료 | C23: 0.1295 | D23: 1 | E23: 식 | F23: (건강보험료 x 요율) | M23: =SUM('기성총괄표(중앙_2권역 대행)'!M23,'기성총괄표(수지-수원_시티_건가)'!M23,'기성총괄표(2025열수송관_시티_건가)'!M23,'기성총괄표(2024용인_지성_제조)'!M23,'기성총괄표(2024용인_지성_건가)'!M23,'기성총괄표(2024용인_지성_예수금)'!M23) -> 0 | N23: 실적정산
B24: 다. 건설근로자퇴직공제부금비 | C24: 0.023 | D24: 1 | E24: 식 | F24: (직접노무비 x 요율) | M24: =SUM('기성총괄표(중앙_2권역 대행)'!M24,'기성총괄표(수지-수원_시티_건가)'!M24,'기성총괄표(2025열수송관_시티_건가)'!M24,'기성총괄표(2024용인_지성_제조)'!M24,'기성총괄표(2024용인_지성_건가)'!M24,'기성총괄표(2024용인_지성_예수금)'!M24) -> 0 | N24: 실적정산
B25: 라. 산업안전보건관리비 | C25: 0.026 | D25: 1 | E25: 식 | F25: (재료비 + 직접노무비) x 요율 | M25: =SUM('기성총괄표(중앙_2권역 대행)'!M25,'기성총괄표(수지-수원_시티_건가)'!M25,'기성총괄표(2025열수송관_시티_건가)'!M25,'기성총괄표(2024용인_지성_제조)'!M25,'기성총괄표(2024용인_지성_건가)'!M25,'기성총괄표(2024용인_지성_예수금)'!M25) -> 0 | N25: 실적정산
B26: 마. 기타경비 | C26: 0.042 | D26: 1 | E26: 식 | F26: [(재료비 + 직접노무비 + 간접노무비) x 요율] | M26: =SUM('기성총괄표(중앙_2권역 대행)'!M26,'기성총괄표(수지-수원_시티_건가)'!M26,'기성총괄표(2025열수송관_시티_건가)'!M26,'기성총괄표(2024용인_지성_제조)'!M26,'기성총괄표(2024용인_지성_건가)'!M26,'기성총괄표(2024용인_지성_예수금)'!M26) -> 48971990
B27: 바. 환경보전비 | C27: 0.005 | D27: 1 | E27: 식 | F27: [(재료비 + 직접노무비 + 산출경비) x 요율] | M27: =SUM('기성총괄표(중앙_2권역 대행)'!M27,'기성총괄표(수지-수원_시티_건가)'!M27,'기성총괄표(2025열수송관_시티_건가)'!M27,'기성총괄표(2024용인_지성_제조)'!M27,'기성총괄표(2024용인_지성_건가)'!M27,'기성총괄표(2024용인_지성_예수금)'!M27) -> 0 | N27: 실적정산
B28: 사. 지급보증서발급수수료 | M28: =SUM('기성총괄표(중앙_2권역 대행)'!M28,'기성총괄표(수지-수원_시티_건가)'!M28,'기성총괄표(2025열수송관_시티_건가)'!M28,'기성총괄표(2024용인_지성_제조)'!M28) -> 0
B29: 1) 하도급대금 | C29: 0.0008 | D29: 1 | E29: 식 | F29: [(재료비 + 직접노무비 + 산출경비) x 요율] | M29: =SUM('기성총괄표(중앙_2권역 대행)'!M29,'기성총괄표(수지-수원_시티_건가)'!M29,'기성총괄표(2025열수송관_시티_건가)'!M29,'기성총괄표(2024용인_지성_제조)'!M29,'기성총괄표(2024용인_지성_건가)'!M29,'기성총괄표(2024용인_지성_예수금)'!M29) -> 0 | N29: 실적정산
B30: 2) 건설기계대여대금 | C30: 0.0032 | D30: 1 | E30: 식 | F30: [(재료비 + 직접노무비 + 산출경비) x 요율] | M30: =SUM('기성총괄표(중앙_2권역 대행)'!M30,'기성총괄표(수지-수원_시티_건가)'!M30,'기성총괄표(2025열수송관_시티_건가)'!M30,'기성총괄표(2024용인_지성_제조)'!M30,'기성총괄표(2024용인_지성_건가)'!M30,'기성총괄표(2024용인_지성_예수금)'!M30) -> 0 | N30: 실적정산
B31: 순 공 사 원 가 | M31: =SUM('기성총괄표(중앙_2권역 대행)'!M31,'기성총괄표(수지-수원_시티_건가)'!M31,'기성총괄표(2025열수송관_시티_건가)'!M31,'기성총괄표(2024용인_지성_제조)'!M31,'기성총괄표(2024용인_지성_건가)'!M31,'기성총괄표(2024용인_지성_예수금)'!M31) -> 1282275218
A32: 4. | B32: 일반관리비 | C32: 0.035 | D32: 1 | E32: 식 | F32: [(재료비 + 노무비 + 경비) x 요율] | M32: =SUM('기성총괄표(중앙_2권역 대행)'!M32,'기성총괄표(수지-수원_시티_건가)'!M32,'기성총괄표(2025열수송관_시티_건가)'!M32,'기성총괄표(2024용인_지성_제조)'!M32,'기성총괄표(2024용인_지성_건가)'!M32,'기성총괄표(2024용인_지성_예수금)'!M32) -> 44879629
A33: 5. | B33: 이윤 | C33: 0.043 | D33: 1 | E33: 식 | F33: [(노무비 + 경비 + 일반관리비) x 요율] | J33: 산출금액 : | K33: =INT((M13+M16+M32)*C33) -> 14462795 | M33: =SUM('기성총괄표(중앙_2권역 대행)'!M33,'기성총괄표(수지-수원_시티_건가)'!M33,'기성총괄표(2025열수송관_시티_건가)'!M33,'기성총괄표(2024용인_지성_제조)'!M33,'기성총괄표(2024용인_지성_건가)'!M33,'기성총괄표(2024용인_지성_예수금)'!M33) -> 14435153
B34: 공 사 원 가 | M34: =SUM('기성총괄표(중앙_2권역 대행)'!M34,'기성총괄표(수지-수원_시티_건가)'!M34,'기성총괄표(2025열수송관_시티_건가)'!M34,'기성총괄표(2024용인_지성_제조)'!M34,'기성총괄표(2024용인_지성_건가)'!M34,'기성총괄표(2024용인_지성_예수금)'!M34) -> 1341590000
B35: 총 원 가 | M35: =SUM('기성총괄표(중앙_2권역 대행)'!M35,'기성총괄표(수지-수원_시티_건가)'!M35,'기성총괄표(2025열수송관_시티_건가)'!M35,'기성총괄표(2024용인_지성_제조)'!M35,'기성총괄표(2024용인_지성_건가)'!M35,'기성총괄표(2024용인_지성_예수금)'!M35) -> 1341590000
B36: 부 가 세 | M36: =SUM('기성총괄표(중앙_2권역 대행)'!M36,'기성총괄표(수지-수원_시티_건가)'!M36,'기성총괄표(2025열수송관_시티_건가)'!M36,'기성총괄표(2024용인_지성_제조)'!M36,'기성총괄표(2024용인_지성_건가)'!M36,'기성총괄표(2024용인_지성_예수금)'!M36) -> 134159000
B37: 총 공 사 금 액 | M37: =SUM('기성총괄표(중앙_2권역 대행)'!M37,'기성총괄표(수지-수원_시티_건가)'!M37,'기성총괄표(2025열수송관_시티_건가)'!M37,'기성총괄표(2024용인_지성_제조)'!M37,'기성총괄표(2024용인_지성_건가)'!M37,'기성총괄표(2024용인_지성_예수금)'!M37) -> 1475749000

Sheet 기성내역서(용인)
A1: 기 성 내 역 서 (용인) | P1: 0.8624291
A2: 공사명 : 2025년 열수송관 천공 및 차단공사(1권역)
A3: 공 종 | B3: 명 칭 | C3: 규 격 | D3: 수 량 | E3: 단위 | F3: 재 료 비 | H3: 노 무 비 | J3: 경 비 | L3: 합 계 | N3: 분류코드
F4: 단 가 | G4: 금 액 | H4: 단 가 | I4: 금 액 | J4: 단 가 | K4: 금 액 | L4: 단 가 | M4: 금 액 | V4: 0.998
B5: 순공사비 | D5: 0 | V5: ='기성총괄표(용인)'!M41 -> 0
A6: 1. | B6: 천공 및 차단 | D6: 0 | V6: 0.85038297
A7: 1) | B7: 천공 및 차단 | C7: T.O.R(50A) | D7: ='기성내역서(중앙_2권역 대행)'!D7+'기성내역서(수지-수원_시티_건가)'!D7+'기성내역서(2025열수송관_시티_건가)'!D7+'기성내역서(2024용인_지성_제조)'!D7+'기성내역서(2024용인_지성_건가)'!D7+'기성내역서(2024용인_지성_예수금)'!D7 -> 0 | E7: 공 | F7: =W7 -> 473488 | G7: =F7*D7 -> 0 | H7: =Y7 -> 364249 | I7: =D7*H7 -> 0 | J7: =AA7 -> 13214 | K7: =D7*J7 -> 0 | L7: =F7+H7+J7 -> 850951 | M7: =L7*D7 -> 0 | P7: 556795 | Q7: 11135900 | R7: 364979 | S7: 7299580 | T7: 15540 | U7: 310800 | W7: =INT(P7*$V$6) -> 473488 | X7: =INT(Q7*$V$6) -> 9469779 | Y7: =INT(R7*$V$4) -> 364249 | Z7: =INT(S7*$V$6) -> 6207438 | AA7: =INT(T7*$V$6) -> 13214 | AB7: =INT(U7*$V$6) -> 264299
A8: 2) | B8: 천공 및 차단 | C8: 65A | D8: ='기성내역서(중앙_2권역 대행)'!D8+'기성내역서(수지-수원_시티_건가)'!D8+'기성내역서(2025열수송관_시티_건가)'!D8+'기성내역서(2024용인_지성_제조)'!D8+'기성내역서(2024용인_지성_건가)'!D8+'기성내역서(2024용인_지성_예수금)'!D8 -> 0 | E8: 공 | F8: =W8 -> 2096059 | G8: =F8*D8 -> 0 | H8: =Y8 -> 651150 | I8: =D8*H8 -> 0 | J8: =AA8 -> 61358 | K8: =D8*J8 -> 0 | L8: =F8+H8+J8 -> 2808567 | M8: =L8*D8 -> 0 | P8: 2464842 | Q8: 9859368 | R8: 652455 | S8: 2609820 | T8: 72154 | U8: 288616 | W8: =INT(P8*$V$6) -> 2096059 | X8: =INT(Q8*$V$6) -> 8384238 | Y8: =INT(R8*$V$4) -> 651150 | Z8: =INT(S8*$V$6) -> 2219346 | AA8: =INT(T8*$V$6) -> 61358 | AB8: =INT(U8*$V$6) -> 245434
A9: 3) | B9: 천공 및 차단 | C9: 80A | D9: ='기성내역서(중앙_2권역 대행)'!D9+'기성내역서(수지-수원_시티_건가)'!D9+'기성내역서(2025열수송관_시티_건가)'!D9+'기성내역서(2024용인_지성_제조)'!D9+'기성내역서(2024용인_지성_건가)'!D9+'기성내역서(2024용인_지성_예수금)'!D9 -> 0 | E9: 공 | F9: =W9 -> 2525128 | G9: =F9*D9 -> 0 | H9: =Y9 -> 732040 | I9: =D9*H9 -> 0 | J9: =AA9 -> 65243 | K9: =D9*J9 -> 0 | L9: =F9+H9+J9 -> 3322411 | M9: =L9*D9 -> 0 | P9: 2969401 | Q9: 11877604 | R9: 733508 | S9: 2934032 | T9: 76722 | U9: 306888 | W9: =INT(P9*$V$6) -> 2525128 | X9: =INT(Q9*$V$6) -> 10100512 | Y9: =INT(R9*$V$4) -> 732040 | Z9: =INT(S9*$V$6) -> 2495050 | AA9: =INT(T9*$V$6) -> 65243 | AB9: =INT(U9*$V$6) -> 260972
A10: 4) | B10: 천공 및 차단 | C10: 100A | D10: ='기성내역서(중앙_2권역 대행)'!D10+'기성내역서(수지-수원_시티_건가)'!D10+'기성내역서(2025열수송관_시티_건가)'!D10+'기성내역서(2024용인_지성_제조)'!D10+'기성내역서(2024용인_지성_건가)'!D10+'기성내역서(2024용인_지성_예수금)'!D10 -> 0 | E10: 공 | F10: =W10 -> 3251378 | G10: =F10*D10 -> 0 | H10: =Y10 -> 774354 | I10: =D10*H10 -> 0 | J10: =AA10 -> 77677 | K10: =D10*J10 -> 0 | L10: =F10+H10+J10 -> 4103409 | M10: =L10*D10 -> 0 | P10: 3823428 | Q10: 15293712 | R10: 775906 | S10: 3103624 | T10: 91344 | U10: 365376 | W10: =INT(P10*$V$6) -> 3251378 | X10: =INT(Q10*$V$6) -> 13005512 | Y10: =INT(R10*$V$4) -> 774354 | Z10: =INT(S10*$V$6) -> 2639268 | AA10: =INT(T10*$V$6) -> 77677 | AB10: =INT(U10*$V$6) -> 310709
A11: 5) | B11: 천공 및 차단 | C11: 125A | D11: ='기성내역서(중앙_2권역 대행)'!D11+'기성내역서(수지-수원_시티_건가)'!D11+'기성내역서(2025열수송관_시티_건가)'!D11+'기성내역서(2024용인_지성_제조)'!D11+'기성내역서(2024용인_지성_건가)'!D11+'기성내역서(2024용인_지성_예수금)'!D11 -> 0 | E11: 공 | F11: =W11 -> 3767327 | G11: =F11*D11 -> 0 | H11: =Y11 -> 835058 | I11: =D11*H11 -> 0 | J11: =AA11 -> 126235 | K11: =D11*J11 -> 0 | L11: =F11+H11+J11 -> 4728620 | M11: =L11*D11 -> 0 | P11: 4430154 | Q11: 53161848 | R11: 836732 | S11: 10040784 | T11: 148445 | U11: 1781340 | W11: =INT(P11*$V$6) -> 3767327 | X11: =INT(Q11*$V$6) -> 45207930 | Y11: =INT(R11*$V$4) -> 835058 | Z11: =INT(S11*$V$6) -> 8538511 | AA11: =INT(T11*$V$6) -> 126235 | AB11: =INT(U11*$V$6) -> 1514821
A12: 6) | B12: 천공 및 차단 | C12: 150A | D12: ='기성내역서(중앙_2권역 대행)'!D12+'기성내역서(수지-수원_시티_건가)'!D12+'기성내역서(2025열수송관_시티_건가)'!D12+'기성내역서(2024용인_지성_제조)'!D12+'기성내역서(2024용인_지성_건가)'!D12+'기성내역서(2024용인_지성_예수금)'!D12 -> 6 | E12: 공 | F12: =W12 -> 4688285 | G12: =F12*D12 -> 28129710 | H12: =Y12 -> 938836 | I12: =D12*H12 -> 5633016 | J12: =AA12 -> 133031 | K12: =D12*J12 -> 798186 | L12: =F12+H12+J12 -> 5760152 | M12: =L12*D12 -> 34560912 | P12: 5513146 | Q12: 176420672 | R12: 940718 | S12: 30102976 | T12: 156437 | U12: 5005984 | W12: =INT(P12*$V$6) -> 4688285 | X12: =INT(Q12*$V$6) -> 150025135 | Y12: =INT(R12*$V$4) -> 938836 | Z12: =INT(S12*$V$6) -> 25599058 | AA12: =INT(T12*$V$6) -> 133031 | AB12: =INT(U12*$V$6) -> 4257003
A13: 7) | B13: 천공 및 차단 | C13: 200A | D13: ='기성내역서(중앙_2권역 대행)'!D13+'기성내역서(수지-수원_시티_건가)'!D13+'기성내역서(2025열수송관_시티_건가)'!D13+'기성내역서(2024용인_지성_제조)'!D13+'기성내역서(2024용인_지성_건가)'!D13+'기성내역서(2024용인_지성_예수금)'!D13 -> 2 | E13: 공 | F13: =W13 -> 7175084 | G13: =F13*D13 -> 14350168 | H13: =Y13 -> 1344035 | I13: =D13*H13 -> 2688070 | J13: =AA13 -> 256626 | K13: =D13*J13 -> 513252 | L13: =F13+H13+J13 -> 8775745 | M13: =L13*D13 -> 17551490 | P13: 8437474 | Q13: 269999168 | R13: 1346729 | S13: 43095328 | T13: 301777 | U13: 9656864 | W13: =INT(P13*$V$6) -> 7175084 | X13: =INT(Q13*$V$6) -> 229602694 | Y13: =INT(R13*$V$4) -> 1344035 | Z13: =INT(S13*$V$6) -> 36647533 | AA13: =INT(T13*$V$6) -> 256626 | AB13: =INT(U13*$V$6) -> 8212032
A14: 8) | B14: 천공 및 차단 | C14: 250A | D14: ='기성내역서(중앙_2권역 대행)'!D14+'기성내역서(수지-수원_시티_건가)'!D14+'기성내역서(2025열수송관_시티_건가)'!D14+'기성내역서(2024용인_지성_제조)'!D14+'기성내역서(2024용인_지성_건가)'!D14+'기성내역서(2024용인_지성_예수금)'!D14 -> 0 | E14: 공 | F14: =W14 -> 9658162 | G14: =F14*D14 -> 0 | H14: =Y14 -> 1485827 | I14: =D14*H14 -> 0 | J14: =AA14 -> 308857 | K14: =D14*J14 -> 0 | L14: =F14+H14+J14 -> 11452846 | M14: =L14*D14 -> 0 | P14: 11357427 | Q14: 204433686 | R14: 1488805 | S14: 26798490 | T14: 363198 | U14: 6537564 | W14: =INT(P14*$V$6) -> 9658162 | X14: =INT(Q14*$V$6) -> 173846925 | Y14: =INT(R14*$V$4) -> 1485827 | Z14: =INT(S14*$V$6) -> 22788979 | AA14: =INT(T14*$V$6) -> 308857 | AB14: =INT(U14*$V$6) -> 5559433
A15: 9) | B15: 천공 및 차단 | C15: 300A | D15: ='기성내역서(중앙_2권역 대행)'!D15+'기성내역서(수지-수원_시티_건가)'!D15+'기성내역서(2025열수송관_시티_건가)'!D15+'기성내역서(2024용인_지성_제조)'!D15+'기성내역서(2024용인_지성_건가)'!D15+'기성내역서(2024용인_지성_예수금)'!D15 -> 0 | E15: 공 | F15: =W15 -> 12169198 | G15: =F15*D15 -> 0 | H15: =Y15 -> 1649432 | I15: =D15*H15 -> 0 | J15: =AA15 -> 341364 | K15: =D15*J15 -> 0 | L15: =F15+H15+J15 -> 14159994 | M15: =L15*D15 -> 0 | P15: 14310256 | Q15: 601030752 | R15: 1652738 | S15: 69414996 | T15: 401425 | U15: 16859850 | W15: =INT(P15*$V$6) -> 12169198 | X15: =INT(Q15*$V$6) -> 511106316 | Y15: =INT(R15*$V$4) -> 1649432 | Z15: =INT(S15*$V$6) -> 59029330 | AA15: =INT(T15*$V$6) -> 341364 | AB15: =INT(U15*$V$6) -> 14337329
A16: 10) | B16: 천공 및 차단 | C16: 350A | D16: ='기성내역서(중앙_2권역 대행)'!D16+'기성내역서(수지-수원_시티_건가)'!D16+'기성내역서(2025열수송관_시티_건가)'!D16+'기성내역서(2024용인_지성_제조)'!D16+'기성내역서(2024용인_지성_건가)'!D16+'기성내역서(2024용인_지성_예수금)'!D16 -> 0 | E16: 공 | F16: =W16 -> 17976469 | G16: =F16*D16 -> 0 | H16: =Y16 -> 2270083 | I16: =D16*H16 -> 0 | J16: =AA16 -> 594821 | K16: =D16*J16 -> 0 | L16: =F16+H16+J16 -> 20841373 | M16: =L16*D16 -> 0 | P16: 21139263 | Q16: 465063786 | R16: 2274633 | S16: 50041926 | T16: 699475 | U16: 15388450 | W16: =INT(P16*$V$6) -> 17976469 | X16: =INT(Q16*$V$6) -> 395482324 | Y16: =INT(R16*$V$4) -> 2270083 | Z16: =INT(S16*$V$6) -> 42554801 | AA16: =INT(T16*$V$6) -> 594821 | AB16: =INT(U16*$V$6) -> 13086075
A17: 11) | B17: 천공 및 차단 | C17: 400A | D17: ='기성내역서(중앙_2권역 대행)'!D17+'기성내역서(수지-수원_시티_건가)'!D17+'기성내역서(2025열수송관_시티_건가)'!D17+'기성내역서(2024용인_지성_제조)'!D17+'기성내역서(2024용인_지성_건가)'!D17+'기성내역서(2024용인_지성_예수금)'!D17 -> 0 | E17: 공 | F17: =W17 -> 18408234 | G17: =F17*D17 -> 0 | H17: =Y17 -> 2676868 | I17: =D17*H17 -> 0 | J17: =AA17 -> 664149 | K17: =D17*J17 -> 0 | L17: =F17+H17+J17 -> 21749251 | M17: =L17*D17 -> 0 | P17: 21646993 | Q17: 519527832 | R17: 2682233 | S17: 64373592 | T17: 781000 | U17: 18744000 | W17: =INT(P17*$V$6) -> 18408234 | X17: =INT(Q17*$V$6) -> 441797621 | Y17: =INT(R17*$V$4) -> 2676868 | Z17: =INT(S17*$V$6) -> 54742206 | AA17: =INT(T17*$V$6) -> 664149 | AB17: =INT(U17*$V$6) -> 15939578
A18: 12) | B18: 천공 및 차단 | C18: 450A | D18: ='기성내역서(중앙_2권역 대행)'!D18+'기성내역서(수지-수원_시티_건가)'!D18+'기성내역서(2025열수송관_시티_건가)'!D18+'기성내역서(2024용인_지성_제조)'!D18+'기성내역서(2024용인_지성_건가)'!D18+'기성내역서(2024용인_지성_예수금)'!D18 -> 0 | E18: 공 | F18: =W18 -> 21589104 | G18: =F18*D18 -> 0 | H18: =Y18 -> 3082851 | I18: =D18*H18 -> 0 | J18: =AA18 -> 906276 | K18: =D18*J18 -> 0 | L18: =F18+H18+J18 -> 25578231 | M18: =L18*D18 -> 0 | P18: 25387508 | Q18: 304650096 | R18: 3089030 | S18: 37068360 | T18: 1065728 | U18: 12788736 | W18: =INT(P18*$V$6) -> 21589104 | X18: =INT(Q18*$V$6) -> 259069253 | Y18: =INT(R18*$V$4) -> 3082851 | Z18: =INT(S18*$V$6) -> 31522302 | AA18: =INT(T18*$V$6) -> 906276 | AB18: =INT(U18*$V$6) -> 10875323
... A27: 21) | B27: 천공 및 차단 | C27: 900A | D27: ='기성내역서(중앙_2권역 대행)'!D27+'기성내역서(수지-수원_시티_건가)'!D27+'기성내역서(2025열수송관_시티_건가)'!D27+'기성내역서(2024용인_지성_제조)'!D27+'기성내역서(2024용인_지성_건가)'!D27+'기성내역서(2024용인_지성_예수금)'!D27 -> 0 | E27: 공 | F27: =W27 -> 67252461 | G27: =F27*D27 -> 0 | H27: =Y27 -> 7451208 | I27: =D27*H27 -> 0 | J27: =AA27 -> 5562272 | K27: =D27*J27 -> 0 | L27: =F27+H27+J27 -> 80265941 | M27: =L27*D27 -> 0 | P27: 79084911 | Q27: 0 | R27: 7466141 | S27: 0 | T27: 6540903 | U27: 0 | W27: =INT(P27*$V$6) -> 67252461 | X27: =INT(Q27*$V$6) -> 0 | Y27: =INT(R27*$V$4) -> 7451208 | Z27: =INT(S27*$V$6) -> 0 | AA27: =INT(T27*$V$6) -> 5562272 | AB27: =INT(U27*$V$6) -> 0
B28: 소계 | D28: ='기성내역서(수지-수원_시티_건가)'!D28+'기성내역서(2025열수송관_시티_건가)'!D28+'기성내역서(2024용인_지성_제조)'!D28+'기성내역서(중앙_2권역 대행)'!D28 -> 24 | G28: =SUM(G7:G27) -> 635174350 | I28: =SUM(I7:I27) -> 99018174 | K28: =SUM(K7:K27) -> 40680026 | M28: =SUM(M7:M27) -> 774872550 | Q28: 6048633596 | S28: 794466200 | U28: 289886458
A29: 2. | B29: 천공 및 차단(야간)
A30: 22) | B30: 천공 및 차단 | C30: T.O.R(50A) | D30: ='기성내역서(중앙_2권역 대행)'!D30+'기성내역서(수지-수원_시티_건가)'!D30+'기성내역서(2025열수송관_시티_건가)'!D30+'기성내역서(2024용인_지성_제조)'!D30+'기성내역서(2024용인_지성_건가)'!D30+'기성내역서(2024용인_지성_예수금)'!D30 -> 0 | E30: 공 | F30: =W30 -> 473488 | G30: =F30*D30 -> 0 | H30: =Y30 -> 632217 | I30: =D30*H30 -> 0 | J30: =AA30 -> 13220 | K30: =D30*J30 -> 0 | L30: =F30+H30+J30 -> 1118925 | M30: =L30*D30 -> 0 | P30: 556795 | Q30: 0 | R30: 633484 | S30: 0 | T30: 15547 | U30: 0 | W30: =INT(P30*$V$6) -> 473488 | X30: =INT(Q30*$V$6) -> 0 | Y30: =INT(R30*$V$4) -> 632217 | Z30: =INT(S30*$V$6) -> 0 | AA30: =INT(T30*$V$6) -> 13220 | AB30: =INT(U30*$V$6) -> 0
A31: 23) | B31: 천공 및 차단 | C31: 65A | D31: ='기성내역서(중앙_2권역 대행)'!D31+'기성내역서(수지-수원_시티_건가)'!D31+'기성내역서(2025열수송관_시티_건가)'!D31+'기성내역서(2024용인_지성_제조)'!D31+'기성내역서(2024용인_지성_건가)'!D31+'기성내역서(2024용인_지성_예수금)'!D31 -> 0 | E31: 공 | F31: =W31 -> 2096059 | G31: =F31*D31 -> 0 | H31: =Y31 -> 1176471 | I31: =D31*H31 -> 0 | J31: =AA31 -> 61358 | K31: =D31*J31 -> 0 | L31: =F31+H31+J31 -> 3333888 | M31: =L31*D31 -> 0 | P31: 2464842 | Q31: 0 | R31: 1178829 | S31: 0 | T31: 72154 | U31: 0 | W31: =INT(P31*$V$6) -> 2096059 | X31: =INT(Q31*$V$6) -> 0 | Y31: =INT(R31*$V$4) -> 1176471 | Z31: =INT(S31*$V$6) -> 0 | AA31: =INT(T31*$V$6) -> 61358 | AB31: =INT(U31*$V$6) -> 0
A32: 24) | B32: 천공 및 차단 | C32: 150A | D32: ='기성내역서(중앙_2권역 대행)'!D32+'기성내역서(수지-수원_시티_건가)'!D32+'기성내역서(2025열수송관_시티_건가)'!D32+'기성내역서(2024용인_지성_제조)'!D32+'기성내역서(2024용인_지성_건가)'!D32+'기성내역서(2024용인_지성_예수금)'!D32 -> 0 | E32: 공 | F32: =W32 -> 4688285 | G32: =F32*D32 -> 0 | H32: =Y32 -> 1698490 | I32: =D32*H32 -> 0 | J32: =AA32 -> 133030 | K32: =D32*J32 -> 0 | L32: =F32+H32+J32 -> 6519805 | M32: =L32*D32 -> 0 | P32: 5513146 | Q32: 22052584 | R32: 1701894 | S32: 6807576 | T32: 156436 | U32: 625744 | W32: =INT(P32*$V$6) -> 4688285 | X32: =INT(Q32*$V$6) -> 18753141 | Y32: =INT(R32*$V$4) -> 1698490 | Z32: =INT(S32*$V$6) -> 5789046 | AA32: =INT(T32*$V$6) -> 133030 | AB32: =INT(U32*$V$6) -> 532122
A33: 25) | B33: 천공 및 차단 | C33: 200A | D33: ='기성내역서(중앙_2권역 대행)'!D33+'기성내역서(수지-수원_시티_건가)'!D33+'기성내역서(2025열수송관_시티_건가)'!D33+'기성내역서(2024용인_지성_제조)'!D33+'기성내역서(2024용인_지성_건가)'!D33+'기성내역서(2024용인_지성_예수금)'!D33 -> 4 | E33: 공 | F33: =W33 -> 7175084 | G33: =F33*D33 -> 28700336 | H33: =Y33 -> 2392787 | I33: =D33*H33 -> 9571148 | J33: =AA33 -> 256626 | K33: =D33*J33 -> 1026504 | L33: =F33+H33+J33 -> 9824497 | M33: =L33*D33 -> 39297988 | P33: 8437474 | Q33: 33749896 | R33: 2397583 | S33: 9590332 | T33: 301778 | U33: 1207112 | W33: =INT(P33*$V$6) -> 7175084 | X33: =INT(Q33*$V$6) -> 28700336 | Y33: =INT(R33*$V$4) -> 2392787 | Z33: =INT(S33*$V$6) -> 8155455 | AA33: =INT(T33*$V$6) -> 256626 | AB33: =INT(U33*$V$6) -> 1026507
A34: 26) | B34: 천공 및 차단 | C34: 250A | D34: ='기성내역서(중앙_2권역 대행)'!D34+'기성내역서(수지-수원_시티_건가)'!D34+'기성내역서(2025열수송관_시티_건가)'!D34+'기성내역서(2024용인_지성_제조)'!D34+'기성내역서(2024용인_지성_건가)'!D34+'기성내역서(2024용인_지성_예수금)'!D34 -> 0 | E34: 공 | F34: =W34 -> 9658163 | G34: =F34*D34 -> 0 | H34: =Y34 -> 2647683 | I34: =D34*H34 -> 0 | J34: =AA34 -> 308857 | K34: =D34*J34 -> 0 | L34: =F34+H34+J34 -> 12614703 | M34: =L34*D34 -> 0 | P34: 11357428 | Q34: 0 | R34: 2652989 | S34: 0 | T34: 363198 | U34: 0 | W34: =INT(P34*$V$6) -> 9658163 | X34: =INT(Q34*$V$6) -> 0 | Y34: =INT(R34*$V$4) -> 2647683 | Z34: =INT(S34*$V$6) -> 0 | AA34: =INT(T34*$V$6) -> 308857 | AB34: =INT(U34*$V$6) -> 0
A35: 27) | B35: 천공 및 차단 | C35: 300A | D35: ='기성내역서(중앙_2권역 대행)'!D35+'기성내역서(수지-수원_시티_건가)'!D35+'기성내역서(2025열수송관_시티_건가)'!D35+'기성내역서(2024용인_지성_제조)'!D35+'기성내역서(2024용인_지성_건가)'!D35+'기성내역서(2024용인_지성_예수금)'!D35 -> 0 | E35: 공 | F35: =W35 -> 12169198 | G35: =F35*D35 -> 0 | H35: =Y35 -> 2940693 | I35: =D35*H35 -> 0 | J35: =AA35 -> 341364 | K35: =D35*J35 -> 0 | L35: =F35+H35+J35 -> 15451255 | M35: =L35*D35 -> 0 | P35: 14310256 | Q35: 0 | R35: 2946587 | S35: 0 | T35: 401425 | U35: 0 | W35: =INT(P35*$V$6) -> 12169198 | X35: =INT(Q35*$V$6) -> 0 | Y35: =INT(R35*$V$4) -> 2940693 | Z35: =INT(S35*$V$6) -> 0 | AA35: =INT(T35*$V$6) -> 341364 | AB35: =INT(U35*$V$6) -> 0
A36: 28) | B36: 천공 및 차단 | C36: 350A | D36: ='기성내역서(중앙_2권역 대행)'!D36+'기성내역서(수지-수원_시티_건가)'!D36+'기성내역서(2025열수송관_시티_건가)'!D36+'기성내역서(2024용인_지성_제조)'!D36+'기성내역서(2024용인_지성_건가)'!D36+'기성내역서(2024용인_지성_예수금)'!D36 -> 8 | E36: 공 | F36: =W36 -> 17976470 | G36: =F36*D36 -> 143811760 | H36: =Y36 -> 4065640 | I36: =D36*H36 -> 32525120 | J36: =AA36 -> 594821 | K36: =D36*J36 -> 4758568 | L36: =F36+H36+J36 -> 22636931 | M36: =L36*D36 -> 181095448 | P36: 21139264 | Q36: 169114112 | R36: 4073788 | S36: 32590304 | T36: 699475 | U36: 5595800 | W36: =INT(P36*$V$6) -> 17976470 | X36: =INT(Q36*$V$6) -> 143811761 | Y36: =INT(R36*$V$4) -> 4065640 | Z36: =INT(S36*$V$6) -> 27714239 | AA36: =INT(T36*$V$6) -> 594821 | AB36: =INT(U36*$V$6) -> 4758573
A37: 29) | B37: 천공 및 차단 | C37: 400A | D37: ='기성내역서(중앙_2권역 대행)'!D37+'기성내역서(수지-수원_시티_건가)'!D37+'기성내역서(2025열수송관_시티_건가)'!D37+'기성내역서(2024용인_지성_제조)'!D37+'기성내역서(2024용인_지성_건가)'!D37+'기성내역서(2024용인_지성_예수금)'!D37 -> 0 | E37: 공 | F37: =W37 -> 18408234 | G37: =F37*D37 -> 0 | H37: =Y37 -> 4803583 | I37: =D37*H37 -> 0 | J37: =AA37 -> 664149 | K37: =D37*J37 -> 0 | L37: =F37+H37+J37 -> 23875966 | M37: =L37*D37 -> 0 | P37: 21646993 | Q37: 0 | R37: 4813210 | S37: 0 | T37: 781000 | U37: 0 | W37: =INT(P37*$V$6) -> 18408234 | X37: =INT(Q37*$V$6) -> 0 | Y37: =INT(R37*$V$4) -> 4803583 | Z37: =INT(S37*$V$6) -> 0 | AA37: =INT(T37*$V$6) -> 664149 | AB37: =INT(U37*$V$6) -> 0
A38: 30) | B38: 천공 및 차단 | C38: 500A | D38: ='기성내역서(중앙_2권역 대행)'!D38+'기성내역서(수지-수원_시티_건가)'!D38+'기성내역서(2025열수송관_시티_건가)'!D38+'기성내역서(2024용인_지성_제조)'!D38+'기성내역서(2024용인_지성_건가)'!D38+'기성내역서(2024용인_지성_예수금)'!D38 -> 0 | E38: 공 | F38: =W38 -> 24638400 | G38: =F38*D38 -> 0 | H38: =Y38 -> 6942629 | I38: =D38*H38 -> 0 | J38: =AA38 -> 1047465 | K38: =D38*J38 -> 0 | L38: =F38+H38+J38 -> 32628494 | M38: =L38*D38 -> 0 | P38: 28973300 | Q38: 0 | R38: 6956543 | S38: 0 | T38: 1231757 | U38: 0 | W38: =INT(P38*$V$6) -> 24638400 | X38: =INT(Q38*$V$6) -> 0 | Y38: =INT(R38*$V$4) -> 6942629 | Z38: =INT(S38*$V$6) -> 0 | AA38: =INT(T38*$V$6) -> 1047465 | AB38: =INT(U38*$V$6) -> 0
A39: 31) | B39: 천공 및 차단 | C39: 550A | D39: ='기성내역서(중앙_2권역 대행)'!D39+'기성내역서(수지-수원_시티_건가)'!D39+'기성내역서(2025열수송관_시티_건가)'!D39+'기성내역서(2024용인_지성_제조)'!D39+'기성내역서(2024용인_지성_건가)'!D39+'기성내역서(2024용인_지성_예수금)'!D39 -> 0 | E39: 공 | F39: =W39 -> 25877998 | G39: =F39*D39 -> 0 | H39: =Y39 -> 7691243 | I39: =D39*H39 -> 0 | J39: =AA39 -> 1733663 | K39: =D39*J39 -> 0 | L39: =F39+H39+J39 -> 35302904 | M39: =L39*D39 -> 0 | P39: 30430993 | Q39: 0 | R39: 7706657 | S39: 0 | T39: 2038686 | U39: 0 | W39: =INT(P39*$V$6) -> 25877998 | X39: =INT(Q39*$V$6) -> 0 | Y39: =INT(R39*$V$4) -> 7691243 | Z39: =INT(S39*$V$6) -> 0 | AA39: =INT(T39*$V$6) -> 1733663 | AB39: =INT(U39*$V$6) -> 0
A40: 32) | B40: 천공 및 차단 | C40: 600A | D40: ='기성내역서(중앙_2권역 대행)'!D40+'기성내역서(수지-수원_시티_건가)'!D40+'기성내역서(2025열수송관_시티_건가)'!D40+'기성내역서(2024용인_지성_제조)'!D40+'기성내역서(2024용인_지성_건가)'!D40+'기성내역서(2024용인_지성_예수금)'!D40 -> 0 | E40: 공 | F40: =W40 -> 32881624 | G40: =F40*D40 -> 0 | H40: =Y40 -> 9231123 | I40: =D40*H40 -> 0 | J40: =AA40 -> 1981912 | K40: =D40*J40 -> 0 | L40: =F40+H40+J40 -> 44094659 | M40: =L40*D40 -> 0 | P40: 38666843 | Q40: 0 | R40: 9249623 | S40: 0 | T40: 2330612 | U40: 0 | W40: =INT(P40*$V$6) -> 32881624 | X40: =INT(Q40*$V$6) -> 0 | Y40: =INT(R40*$V$4) -> 9231123 | Z40: =INT(S40*$V$6) -> 0 | AA40: =INT(T40*$V$6) -> 1981912 | AB40: =INT(U40*$V$6) -> 0
A41: 33) | B41: 천공 및 차단 | C41: 750A | D41: ='기성내역서(중앙_2권역 대행)'!D41+'기성내역서(수지-수원_시티_건가)'!D41+'기성내역서(2025열수송관_시티_건가)'!D41+'기성내역서(2024용인_지성_제조)'!D41+'기성내역서(2024용인_지성_건가)'!D41+'기성내역서(2024용인_지성_예수금)'!D41 -> 0 | E41: 공 | F41: =W41 -> 44317123 | G41: =F41*D41 -> 0 | H41: =Y41 -> 11562746 | I41: =D41*H41 -> 0 | J41: =AA41 -> 4659138 | K41: =D41*J41 -> 0 | L41: =F41+H41+J41 -> 60539007 | M41: =L41*D41 -> 0 | P41: 52114312 | Q41: 0 | R41: 11585918 | S41: 0 | T41: 5478871 | U41: 0 | W41: =INT(P41*$V$6) -> 44317123 | X41: =INT(Q41*$V$6) -> 0 | Y41: =INT(R41*$V$4) -> 11562746 | Z41: =INT(S41*$V$6) -> 0 | AA41: =INT(T41*$V$6) -> 4659138 | AB41: =INT(U41*$V$6) -> 0
... A43: 35) | B43: 천공 및 차단 | C43: 850A | D43: ='기성내역서(중앙_2권역 대행)'!D43+'기성내역서(수지-수원_시티_건가)'!D43+'기성내역서(2025열수송관_시티_건가)'!D43+'기성내역서(2024용인_지성_제조)'!D43+'기성내역서(2024용인_지성_건가)'!D43+'기성내역서(2024용인_지성_예수금)'!D43 -> 0 | E43: 공 | F43: =W43 -> 56158837 | G43: =F43*D43 -> 0 | H43: =Y43 -> 12875632 | I43: =D43*H43 -> 0 | J43: =AA43 -> 5363775 | K43: =D43*J43 -> 0 | L43: =F43+H43+J43 -> 74398244 | M43: =L43*D43 -> 0 | P43: 66039466 | Q43: 0 | R43: 12901435 | S43: 0 | T43: 6307482 | U43: 0 | W43: =INT(P43*$V$6) -> 56158837 | X43: =INT(Q43*$V$6) -> 0 | Y43: =INT(R43*$V$4) -> 12875632 | Z43: =INT(S43*$V$6) -> 0 | AA43: =INT(T43*$V$6) -> 5363775 | AB43: =INT(U43*$V$6) -> 0
B44: 소계 | D44: =SUM(D30:D43) -> 12 | G44: =SUM(G30:G43) -> 172512096 | I44: =SUM(I30:I43) -> 42096268 | K44: =SUM(K30:K43) -> 5785072 | M44: =SUM(M30:M43) -> 220393436 | Q44: 224916592 | S44: 48988212 | U44: 7428656
A45: 3. | B45: 천공 및 차단(25bar) | D45: 0
A46: 36) | B46: 천공 및 차단(25bar) | C46: 300A | D46: ='기성내역서(중앙_2권역 대행)'!D46+'기성내역서(수지-수원_시티_건가)'!D46+'기성내역서(2025열수송관_시티_건가)'!D46+'기성내역서(2024용인_지성_제조)'!D46+'기성내역서(2024용인_지성_건가)'!D46+'기성내역서(2024용인_지성_예수금)'!D46 -> 0 | E46: 공 | F46: =W46 -> 26432884 | G46: =F46*D46 -> 0 | H46: =Y46 -> 1649432 | I46: =D46*H46 -> 0 | J46: =AA46 -> 419928 | K46: =D46*J46 -> 0 | L46: =F46+H46+J46 -> 28502244 | M46: =L46*D46 -> 0 | P46: 31083506 | Q46: 0 | R46: 1652738 | S46: 0 | T46: 493811 | U46: 0 | W46: =INT(P46*$V$6) -> 26432884 | X46: =INT(Q46*$V$6) -> 0 | Y46: =INT(R46*$V$4) -> 1649432 | Z46: =INT(S46*$V$6) -> 0 | AA46: =INT(T46*$V$6) -> 419928 | AB46: =INT(U46*$V$6) -> 0
A47: 37) | B47: 천공 및 차단(25bar) | C47: 600A | D47: ='기성내역서(중앙_2권역 대행)'!D47+'기성내역서(수지-수원_시티_건가)'!D47+'기성내역서(2025열수송관_시티_건가)'!D47+'기성내역서(2024용인_지성_제조)'!D47+'기성내역서(2024용인_지성_건가)'!D47+'기성내역서(2024용인_지성_예수금)'!D47 -> 0 | E47: 공 | F47: =W47 -> 58301697 | G47: =F47*D47 -> 0 | H47: =Y47 -> 5130868 | I47: =D47*H47 -> 0 | J47: =AA47 -> 2543989 | K47: =D47*J47 -> 0 | L47: =F47+H47+J47 -> 65976554 | M47: =L47*D47 -> 0 | P47: 68559343 | Q47: 0 | R47: 5141151 | S47: 0 | T47: 2991581 | U47: 0 | W47: =INT(P47*$V$6) -> 58301697 | X47: =INT(Q47*$V$6) -> 0 | Y47: =INT(R47*$V$4) -> 5130868 | Z47: =INT(S47*$V$6) -> 0 | AA47: =INT(T47*$V$6) -> 2543989 | AB47: =INT(U47*$V$6) -> 0
A48: 38) | B48: 천공 및 차단(25bar) | C48: 700A | D48: ='기성내역서(중앙_2권역 대행)'!D48+'기성내역서(수지-수원_시티_건가)'!D48+'기성내역서(2025열수송관_시티_건가)'!D48+'기성내역서(2024용인_지성_제조)'!D48+'기성내역서(2024용인_지성_건가)'!D48+'기성내역서(2024용인_지성_예수금)'!D48 -> 0 | E48: 공 | F48: =W48 -> 67170931 | G48: =F48*D48 -> 0 | H48: =Y48 -> 5926788 | I48: =D48*H48 -> 0 | J48: =AA48 -> 5128336 | K48: =D48*J48 -> 0 | L48: =F48+H48+J48 -> 78226055 | M48: =L48*D48 -> 0 | P48: 78989036 | Q48: 0 | R48: 5938666 | S48: 0 | T48: 6030620 | U48: 0 | W48: =INT(P48*$V$6) -> 67170931 | X48: =INT(Q48*$V$6) -> 0 | Y48: =INT(R48*$V$4) -> 5926788 | Z48: =INT(S48*$V$6) -> 0 | AA48: =INT(T48*$V$6) -> 5128336 | AB48: =INT(U48*$V$6) -> 0
A49: 39) | B49: 천공 및 차단(25bar) | C49: 800A | D49: ='기성내역서(중앙_2권역 대행)'!D49+'기성내역서(수지-수원_시티_건가)'!D49+'기성내역서(2025열수송관_시티_건가)'!D49+'기성내역서(2024용인_지성_제조)'!D49+'기성내역서(2024용인_지성_건가)'!D49+'기성내역서(2024용인_지성_예수금)'!D49 -> 2 | E49: 공 | F49: =W49 -> 91562155 | G49: =F49*D49 -> 183124310 | H49: =Y49 -> 6754833 | I49: =D49*H49 -> 13509666 | J49: =AA49 -> 6416064 | K49: =D49*J49 -> 12832128 | L49: =F49+H49+J49 -> 104733052 | M49: =L49*D49 -> 209466104 | P49: 107671671 | Q49: 861373368 | R49: 6768370 | S49: 54146960 | T49: 7544912 | U49: 60359296 | W49: =INT(P49*$V$6) -> 91562155 | X49: =INT(Q49*$V$6) -> 732497243 | Y49: =INT(R49*$V$4) -> 6754833 | Z49: =INT(S49*$V$6) -> 46045652 | AA49: =INT(T49*$V$6) -> 6416064 | AB49: =INT(U49*$V$6) -> 51328517
...

Sheet 기성정산내역(중앙_2권역 대행)
A1: 기 성 정 산 내 역 (2권역 대행)
A2: 공사명 : 2025년 열수송관 천공 및 차단공사(1권역) | M2: 시티에너지
B3: 공 종 | C3: 규 격 | D3: 수 량 | E3: 단 위 | F3: 산출내역 | J3: 전회까지 기 성 액 | K3: 금 회 기성액 | L3: 누계기성 금 액
A4: 1. 천공 및 차단 | J4: 0 | K4: ='기성총괄표(중앙_2권역 대행)'!M10 -> 23040608 | L4: =J4+K4 -> 23040608
J8: =SUM(J4:J7) -> 0 | K8: =SUM(K4:K7) -> 23040608 | L8: =SUM(L4:L7) -> 23040608
A10: 1. | B10: 재료비 | D10: 1 | E10: 식 | J10: 0 | K10: ='기성총괄표(중앙_2권역 대행)'!M12 -> 18753140 | L10: =J10+K10 -> 18753140
A11: 2. | B11: 노무비 | J11: 0 | K11: ='기성총괄표(중앙_2권역 대행)'!M13 -> 4254804 | L11: =J11+K11 -> 4254804
B12: 가. 직접노무비 | E12: 식 | J12: 0 | K12: ='기성총괄표(중앙_2권역 대행)'!M14 -> 3755344 | L12: =J12+K12 -> 3755344
B13: 나. 간접노무비 | C13: 0.116 | E13: 식 | F13: (직접노무비 x 요율) | J13: 0 | K13: ='기성총괄표(중앙_2권역 대행)'!M15 -> 499460 | L13: =J13+K13 -> 499460
A14: 3. | B14: 경비 | J14: 0 | K14: ='기성총괄표(중앙_2권역 대행)'!M16 -> 1692901 | L14: =J14+K14 -> 1692901
B15: 가. 기계경비 | E15: 식 | J15: 0 | K15: ='기성총괄표(중앙_2권역 대행)'!M17 -> 532124 | L15: =J15+K15 -> 532124
B16: 나. 보험료 | J16: 0 | K16: ='기성총괄표(중앙_2권역 대행)'!M18 -> 0 | L16: =J16+K16 -> 0
B17: 1) 산재보험료 | C17: 0.0356 | D17: 1 | E17: 식 | F17: [(직접노무비 + 간접노무비) x 요율] | J17: 0 | K17: ='기성총괄표(중앙_2권역 대행)'!M19 -> 151471 | L17: =J17+K17 -> 151471
B18: 2) 고용보험료 | C18: 0.0101 | D18: 1 | E18: 식 | F18: [(직접노무비 + 간접노무비) x 요율] | J18: 0 | K18: ='기성총괄표(중앙_2권역 대행)'!M20 -> 42973 | L18: =J18+K18 -> 42973
B19: 3) 연금보험료 | C19: 0.045 | D19: 1 | E19: 식 | F19: (직접노무비 x 요율) | J19: 0 | K19: ='기성총괄표(중앙_2권역 대행)'!M21 -> 0 | L19: =J19+K19 -> 0 | M19: 실적정산
B20: 4) 건강보험료 | C20: 0.03545 | D20: 1 | E20: 식 | F20: (직접노무비 x 요율) | J20: 0 | K20: ='기성총괄표(중앙_2권역 대행)'!M22 -> 0 | L20: =J20+K20 -> 0 | M20: 실적정산
B21: 5) 노인장기요양보험료 | C21: 0.1295 | D21: 1 | E21: 식 | F21: (건강보험료 x 요율) | J21: 0 | K21: ='기성총괄표(중앙_2권역 대행)'!M23 -> 0 | L21: =J21+K21 -> 0 | M21: 실적정산
B22: 다. 건설근로자퇴직공제부금비 | C22: 0.023 | D22: 1 | E22: 식 | F22: (직접노무비) x 요율 | J22: 0 | K22: ='기성총괄표(중앙_2권역 대행)'!M24 -> 0 | L22: =J22+K22 -> 0 | M22: 실적정산
B23: 라. 산업안전보건관리비 | C23: 0.0199 | D23: 1 | E23: 식 | F23: (재료비 + 직접노무비) x 요율 + 5,499,000 | J23: 0 | K23: ='기성총괄표(중앙_2권역 대행)'!M25 -> 0 | L23: =J23+K23 -> 0 | M23: 실적정산
B24: 마. 기타경비 | C24: 0.048 | D24: 1 | E24: 식 | F24: [(재료비 + 직접노무비 + 간접노무비) x 요율] | J24: 0 | K24: ='기성총괄표(중앙_2권역 대행)'!M26 -> 966333 | L24: =J24+K24 -> 966333
B25: 바. 환경보전비 | C25: 0.005 | D25: 1 | E25: 식 | F25: [(재료비 + 직접노무비 + 산출경비) x 요율] | J25: 0 | K25: ='기성총괄표(중앙_2권역 대행)'!M27 -> 0 | L25: =J25+K25 -> 0 | M25: 실적정산
B26: 사. 지급보증서발급수수료 | J26: 0 | K26: ='기성총괄표(중앙_2권역 대행)'!M28 -> 0 | L26: =J26+K26 -> 0
B27: 1) 하도급대금 | C27: 0.00081 | D27: 1 | E27: 식 | F27: [(재료비 + 직접노무비 + 산출경비) x 요율] | J27: 0 | K27: ='기성총괄표(중앙_2권역 대행)'!M29 -> 0 | L27: =J27+K27 -> 0 | M27: 실적정산
B28: 2) 건설기계대여대금 | C28: 0.0032 | D28: 1 | E28: 식 | F28: [(재료비 + 직접노무비 + 산출경비) x 요율] | J28: 0 | K28: ='기성총괄표(중앙_2권역 대행)'!M30 -> 0 | L28: =J28+K28 -> 0 | M28: 실적정산
B29: 순 공 사 원 가 | J29: 0 | K29: ='기성총괄표(중앙_2권역 대행)'!M31 -> 24700845 | L29: =J29+K29 -> 24700845
A30: 4. | B30: 일반관리비 | C30: 0.04 | D30: 1 | E30: 식 | F30: [(재료비 + 노무비 + 경비) x 요율] | J30: 0 | K30: ='기성총괄표(중앙_2권역 대행)'!M32 -> 864529 | L30: =J30+K30 -> 864529
A31: 5. | B31: 이윤 | C31: 0.05 | D31: 1 | E31: 식 | F31: [(노무비 + 경비 + 일반관리비) x 요율] | J31: 0 | K31: ='기성총괄표(중앙_2권역 대행)'!M33 -> 284626 | L31: =J31+K31 -> 284626
B32: 공 사 원 가 | J32: 0 | K32: ='기성총괄표(중앙_2권역 대행)'!M34 -> 25850000 | L32: =J32+K32 -> 25850000
B33: 총 원 가 | J33: 0 | K33: ='기성총괄표(중앙_2권역 대행)'!M35 -> 25850000 | L33: =J33+K33 -> 25850000
B34: 부 가 세 | J34: 0 | K34: ='기성총괄표(중앙_2권역 대행)'!M36 -> 2585000 | L34: =J34+K34 -> 2585000
B35: 총 공 사 금 액 | J35: 0 | K35: ='기성총괄표(중앙_2권역 대행)'!M37 -> 28435000 | L35: =J35+K35 -> 28435000

Sheet 기성총괄표(중앙_2권역 대행)
A1: 기 성 총 괄 표 (2권역 대행)
A2: 공사명 : 2025년 열수송관 천공 및 차단공사(1권역) | N2: 시티에너지
B3: 공 종 | C3: 규 격 | D3: 수 량 | E3: 단 위 | F3: 재 료 비 | H3: 노 무 비 | J3: 경 비 | L3: 계 | N3: 비 고
F4: 단 가 | G4: 금 액 | H4: 단 가 | I4: 금 액 | J4: 단 가 | K4: 금 액 | L4: 단 가 | M4: 금 액
A6: 1. 천공 및 차단 | G6: ='기성내역서(중앙_2권역 대행)'!G61 -> 18753140 | I6: ='기성내역서(중앙_2권역 대행)'!I61 -> 3755344 | K6: ='기성내역서(중앙_2권역 대행)'!K61 -> 532124 | M6: =G6+I6+K6 -> 23040608
B10: 순공사비 계 | G10: =SUM(G6:G9) -> 18753140 | I10: =SUM(I6:I9) -> 3755344 | K10: =SUM(K6:K9) -> 532124 | M10: =SUM(M6:M9) -> 23040608
B11: [공사비총괄표]
A12: 1. | B12: 재료비 | E12: 식 | M12: =G10 -> 18753140
A13: 2. | B13: 노무비 | M13: =SUM(M14:M15) -> 4254804
B14: 가. 직접노무비 | E14: 식 | M14: =I10 -> 3755344
B15: 나. 간접노무비 | C15: 0.133 | E15: 식 | F15: (직접노무비 x 요율) | M15: =INT(I10*C15) -> 499460
A16: 3. | B16: 경비 | M16: =SUM(M17:M30) -> 1692901
B17: 가. 기계경비 | D17: 1 | E17: 식 | M17: =K10 -> 532124
B18: 나. 보험료
B19: 1) 산재보험료 | C19: 0.0356 | D19: 1 | E19: 식 | F19: [(직접노무비 + 간접노무비) x 요율] | M19: =INT((I10+M15)*C19) -> 151471
B20: 2) 고용보험료 | C20: 0.0101 | D20: 1 | E20: 식 | F20: [(직접노무비 + 간접노무비) x 요율] | M20: =INT((M15+I10)*C20) -> 42973
B21: 3) 연금보험료 | C21: 0.045 | D21: 1 | E21: 식 | F21: (직접노무비 x 요율) | M21: 0 | N21: 실적정산
B22: 4) 건강보험료 | C22: 0.03545 | D22: 1 | E22: 식 | F22: (직접노무비 x 요율) | M22: 0 | N22: 실적정산
B23: 5) 노인장기요양보험료 | C23: 0.1295 | D23: 1 | E23: 식 | F23: (건강보험료 x 요율) | M23: 0 | N23: 실적정산
B24: 다. 건설근로자퇴직공제부금비 | C24: 0.023 | D24: 1 | E24: 식 | F24: (직접노무비 x 요율) | M24: 0 | N24: 실적정산
B25: 라. 산업안전보건관리비 | C25: 0.026 | D25: 1 | E25: 식 | F25: (재료비 + 직접노무비) x 요율 | M25: 0 | N25: 실적정산
B26: 마. 기타경비 | C26: 0.042 | D26: 1 | E26: 식 | F26: [(재료비 + 직접노무비 + 간접노무비) x 요율] | M26: =INT(($G$10+$I$10+$M$15)*C26) -> 966333
B27: 바. 환경보전비 | C27: 0.005 | D27: 1 | E27: 식 | F27: [(재료비 + 직접노무비 + 산출경비) x 요율] | M27: 0 | N27: 실적정산
B28: 사. 지급보증서발급수수료
B29: 1) 하도급대금 | C29: 0.0008 | D29: 1 | E29: 식 | F29: [(재료비 + 직접노무비 + 산출경비) x 요율] | M29: 0 | N29: 실적정산
B30: 2) 건설기계대여대금 | C30: 0.0032 | D30: 1 | E30: 식 | F30: [(재료비 + 직접노무비 + 산출경비) x 요율] | M30: 0 | N30: 실적정산
B31: 순 공 사 원 가 | M31: =M12+M13+M16 -> 24700845
A32: 4. | B32: 일반관리비 | C32: 0.035 | D32: 1 | E32: 식 | F32: [(재료비 + 노무비 + 경비) x 요율] | M32: =INT((M12+M13+M16)*C32) -> 864529
A33: 5. | B33: 이윤 | C33: 0.043 | E33: 식 | F33: [(노무비 + 경비 + 일반관리비) x 요율] | J33: 산출금액 : | K33: =INT((M13+M16+M32)*C33) -> 292926 | M33: =INT((M13+M16+M32)*C33)-N33 -> 284626 | N33: 8300
B34: 공 사 원 가 | M34: =SUM(M31:M33) -> 25850000
B35: 총 원 가 | M35: =M34 -> 25850000
B36: 부 가 세 | M36: =M35*0.1 -> 2585000
B37: 총 공 사 금 액 | M37: =M35+M36 -> 28435000
M39: =ROUND(M37/M10,5) -> 1.23413

Sheet 기성내역서(중앙_2권역 대행)
A1: 기 성 내 역 서 (2권역 대행)
A2: 공사명 : 2025년 열수송관 천공 및 차단공사(1권역) | M2: 시티에너지
A3: 공 종 | B3: 명 칭 | C3: 규 격 | D3: 수 량 | E3: 단위 | F3: 재 료 비 | H3: 노 무 비 | J3: 경 비 | L3: 합 계 | N3: 분류코드
F4: 단 가 | G4: 금 액 | H4: 단 가 | I4: 금 액 | J4: 단 가 | K4: 금 액 | L4: 단 가 | M4: 금 액
B5: 순공사비 | D5: 0
A6: 1. | B6: 천공 및 차단 | D6: 0
A7: 1) | B7: 천공 및 차단 | C7: T.O.R(50A) | E7: 공 | F7: 473488 | G7: =D7*F7 -> 0 | H7: 364249 | I7: =D7*H7 -> 0 | J7: 13214 | K7: =D7*J7 -> 0 | L7: =F7+H7+J7 -> 850951 | M7: =D7*L7 -> 0
A8: 2) | B8: 천공 및 차단 | C8: 65A | E8: 공 | F8: 2096059 | G8: =D8*F8 -> 0 | H8: 651150 | I8: =D8*H8 -> 0 | J8: 61358 | K8: =D8*J8 -> 0 | L8: =F8+H8+J8 -> 2808567 | M8: =D8*L8 -> 0
A9: 3) | B9: 천공 및 차단 | C9: 80A | E9: 공 | F9: 2525128 | G9: =D9*F9 -> 0 | H9: 732040 | I9: =D9*H9 -> 0 | J9: 65243 | K9: =D9*J9 -> 0 | L9: =F9+H9+J9 -> 3322411 | M9: =D9*L9 -> 0
A10: 4) | B10: 천공 및 차단 | C10: 100A | E10: 공 | F10: 3251378 | G10: =D10*F10 -> 0 | H10: 774354 | I10: =D10*H10 -> 0 | J10: 77677 | K10: =D10*J10 -> 0 | L10: =F10+H10+J10 -> 4103409 | M10: =D10*L10 -> 0
A11: 5) | B11: 천공 및 차단 | C11: 125A | E11: 공 | F11: 3767327 | G11: =D11*F11 -> 0 | H11: 835058 | I11: =D11*H11 -> 0 | J11: 126235 | K11: =D11*J11 -> 0 | L11: =F11+H11+J11 -> 4728620 | M11: =D11*L11 -> 0
A12: 6) | B12: 천공 및 차단 | C12: 150A | D12: 4 | E12: 공 | F12: 4688285 | G12: =D12*F12 -> 18753140 | H12: 938836 | I12: =D12*H12 -> 3755344 | J12: 133031 | K12: =D12*J12 -> 532124 | L12: =F12+H12+J12 -> 5760152 | M12: =D12*L12 -> 23040608
A13: 7) | B13: 천공 및 차단 | C13: 200A | E13: 공 | F13: 7175084 | G13: =D13*F13 -> 0 | H13: 1344035 | I13: =D13*H13 -> 0 | J13: 256626 | K13: =D13*J13 -> 0 | L13: =F13+H13+J13 -> 8775745 | M13: =D13*L13 -> 0
A14: 8) | B14: 천공 및 차단 | C14: 250A | E14: 공 | F14: 9658162 | G14: =D14*F14 -> 0 | H14: 1485827 | I14: =D14*H14 -> 0 | J14: 308857 | K14: =D14*J14 -> 0 | L14: =F14+H14+J14 -> 11452846 | M14: =D14*L14 -> 0
A15: 9) | B15: 천공 및 차단 | C15: 300A | E15: 공 | F15: 12169198 | G15: =D15*F15 -> 0 | H15: 1649432 | I15: =D15*H15 -> 0 | J15: 341364 | K15: =D15*J15 -> 0 | L15: =F15+H15+J15 -> 14159994 | M15: =D15*L15 -> 0
A16: 10) | B16: 천공 및 차단 | C16: 350A | E16: 공 | F16: 17976469 | G16: =D16*F16 -> 0 | H16: 2270083 | I16: =D16*H16 -> 0 | J16: 594821 | K16: =D16*J16 -> 0 | L16: =F16+H16+J16 -> 20841373 | M16: =D16*L16 -> 0
A17: 11) | B17: 천공 및 차단 | C17: 400A | E17: 공 | F17: 18408234 | G17: =D17*F17 -> 0 | H17: 2676868 | I17: =D17*H17 -> 0 | J17: 664149 | K17: =D17*J17 -> 0 | L17: =F17+H17+J17 -> 21749251 | M17: =D17*L17 -> 0
A18: 12) | B18: 천공 및 차단 | C18: 450A | E18: 공 | F18: 21589104 | G18: =D18*F18 -> 0 | H18: 3082851 | I18: =D18*H18 -> 0 | J18: 906276 | K18: =D18*J18 -> 0 | L18: =F18+H18+J18 -> 25578231 | M18: =D18*L18 -> 0
A19: 13) | B19: 천공 및 차단 | C19: 500A | E19: 공 | F19: 24638400 | G19: =D19*F19 -> 0 | H19: 3861028 | I19: =D19*H19 -> 0 | J19: 1047466 | K19: =D19*J19 -> 0 | L19: =F19+H19+J19 -> 29546894 | M19: =D19*L19 -> 0
A20: 14) | B20: 천공 및 차단 | C20: 550A | E20: 공 | F20: 25877998 | G20: =D20*F20 -> 0 | H20: 4274693 | I20: =D20*H20 -> 0 | J20: 1733663 | K20: =D20*J20 -> 0 | L20: =F20+H20+J20 -> 31886354 | M20: =D20*L20 -> 0
A21: 15) | B21: 천공 및 차단 | C21: 600A | E21: 공 | F21: 32881624 | G21: =D21*F21 -> 0 | H21: 5130868 | I21: =D21*H21 -> 0 | J21: 1981912 | K21: =D21*J21 -> 0 | L21: =F21+H21+J21 -> 39994404 | M21: =D21*L21 -> 0
A22: 16) | B22: 천공 및 차단 | C22: 650A | E22: 공 | F22: 34983928 | G22: =D22*F22 -> 0 | H22: 5548044 | I22: =D22*H22 -> 0 | J22: 2455665 | K22: =D22*J22 -> 0 | L22: =F22+H22+J22 -> 42987637 | M22: =D22*L22 -> 0
A23: 17) | B23: 천공 및 차단 | C23: 700A | E23: 공 | F23: 38815548 | G23: =D23*F23 -> 0 | H23: 5926788 | I23: =D23*H23 -> 0 | J23: 2662404 | K23: =D23*J23 -> 0 | L23: =F23+H23+J23 -> 47404740 | M23: =D23*L23 -> 0
A24: 18) | B24: 천공 및 차단 | C24: 750A | E24: 공 | F24: 44317123 | G24: =D24*F24 -> 0 | H24: 6423413 | I24: =D24*H24 -> 0 | J24: 4659138 | K24: =D24*J24 -> 0 | L24: =F24+H24+J24 -> 55399674 | M24: =D24*L24 -> 0
... A27: 21) | B27: 천공 및 차단 | C27: 900A | E27: 공 | F27: 67252461 | G27: =D27*F27 -> 0 | H27: 7451208 | I27: =D27*H27 -> 0 | J27: 5562272 | K27: =D27*J27 -> 0 | L27: =F27+H27+J27 -> 80265941 | M27: =D27*L27 -> 0
B28: 소계 | D28: =SUM(D7:D27) -> 4 | G28: =SUM(G7:G27) -> 18753140 | I28: =SUM(I7:I27) -> 3755344 | K28: =SUM(K7:K27) -> 532124 | M28: =SUM(M7:M27) -> 23040608
A29: 2. | B29: 천공 및 차단(야간) | D29: 0
A30: 22) | B30: 천공 및 차단 | C30: T.O.R(50A) | D30: 0 | E30: 공 | F30: 473488 | G30: =D30*F30 -> 0 | H30: 632217 | I30: =D30*H30 -> 0 | J30: 13220 | K30: =D30*J30 -> 0 | L30: =F30+H30+J30 -> 1118925 | M30: =D30*L30 -> 0
A31: 23) | B31: 천공 및 차단 | C31: 65A | E31: 공 | F31: 2096059 | G31: =D31*F31 -> 0 | H31: 1176471 | I31: =D31*H31 -> 0 | J31: 61358 | K31: =D31*J31 -> 0 | L31: =F31+H31+J31 -> 3333888 | M31: =D31*L31 -> 0
A32: 24) | B32: 천공 및 차단 | C32: 150A | E32: 공 | F32: 4688285 | G32: =D32*F32 -> 0 | H32: 1698490 | I32: =D32*H32 -> 0 | J32: 133030 | K32: =D32*J32 -> 0 | L32: =F32+H32+J32 -> 6519805 | M32: =D32*L32 -> 0
A33: 25) | B33: 천공 및 차단 | C33: 200A | E33: 공 | F33: 7175084 | G33: =D33*F33 -> 0 | H33: 2392787 | I33: =D33*H33 -> 0 | J33: 256626 | K33: =D33*J33 -> 0 | L33: =F33+H33+J33 -> 9824497 | M33: =D33*L33 -> 0
A34: 26) | B34: 천공 및 차단 | C34: 250A | E34: 공 | F34: 9658163 | G34: =D34*F34 -> 0 | H34: 2647683 | I34: =D34*H34 -> 0 | J34: 308857 | K34: =D34*J34 -> 0 | L34: =F34+H34+J34 -> 12614703 | M34: =D34*L34 -> 0
A35: 27) | B35: 천공 및 차단 | C35: 300A | E35: 공 | F35: 12169198 | G35: =D35*F35 -> 0 | H35: 2940693 | I35: =D35*H35 -> 0 | J35: 341364 | K35: =D35*J35 -> 0 | L35: =F35+H35+J35 -> 15451255 | M35: =D35*L35 -> 0
A36: 28) | B36: 천공 및 차단 | C36: 350A | E36: 공 | F36: 17976470 | G36: =D36*F36 -> 0 | H36: 4065640 | I36: =D36*H36 -> 0 | J36: 594821 | K36: =D36*J36 -> 0 | L36: =F36+H36+J36 -> 22636931 | M36: =D36*L36 -> 0
A37: 29) | B37: 천공 및 차단 | C37: 400A | E37: 공 | F37: 18408234 | G37: =D37*F37 -> 0 | H37: 4803583 | I37: =D37*H37 -> 0 | J37: 664149 | K37: =D37*J37 -> 0 | L37: =F37+H37+J37 -> 23875966 | M37: =D37*L37 -> 0
A38: 30) | B38: 천공 및 차단 | C38: 500A | E38: 공 | F38: 24638400 | G38: =D38*F38 -> 0 | H38: 6942629 | I38: =D38*H38 -> 0 | J38: 1047465 | K38: =D38*J38 -> 0 | L38: =F38+H38+J38 -> 32628494 | M38: =D38*L38 -> 0
A39: 31) | B39: 천공 및 차단 | C39: 550A | E39: 공 | F39: 25877998 | G39: =D39*F39 -> 0 | H39: 7691243 | I39: =D39*H39 -> 0 | J39: 1733663 | K39: =D39*J39 -> 0 | L39: =F39+H39+J39 -> 35302904 | M39: =D39*L39 -> 0
A40: 32) | B40: 천공 및 차단 | C40: 600A | E40: 공 | F40: 32881624 | G40: =D40*F40 -> 0 | H40: 9231123 | I40: =D40*H40 -> 0 | J40: 1981912 | K40: =D40*J40 -> 0 | L40: =F40+H40+J40 -> 44094659 | M40: =D40*L40 -> 0
A41: 33) | B41: 천공 및 차단 | C41: 750A | E41: 공 | F41: 44317123 | G41: =D41*F41 -> 0 | H41: 11562746 | I41: =D41*H41 -> 0 | J41: 4659138 | K41: =D41*J41 -> 0 | L41: =F41+H41+J41 -> 60539007 | M41: =D41*L41 -> 0
A42: 34) | B42: 천공 및 차단 | C42: 800A | E42: 공 | F42: 47002938 | G42: =D42*F42 -> 0 | H42: 12161036 | I42: =D42*H42 -> 0 | J42: 4931649 | K42: =D42*J42 -> 0 | L42: =F42+H42+J42 -> 64095623 | M42: =D42*L42 -> 0
...

Sheet 수량산출서(중앙_2권역 대행)
A1: 수 량 산 출 서 (2권역 대행)
A2: 공사명 : 2025년 열수송관 천공 및 차단공사(1권역) | I2: 시티에너지
A3: 구분 | B3: 공사종류 | C3: 연도 | D3: 공사기간 | E3: 관경 | F3: 수량 | G3: 단위 | H3: 위치 | I3: 비고
A4: 유지보수 | B4: 천공및차단 | C4: 2025 | D4: 2025.12.26~2025.12.29 | E4: 150 | F4: 4 | G4: 공 | H4: 선우아파트
F12: =SUM(F4:F11) -> 4

Sheet 기성정산내역(수지-수원_시티_건가)
A1: 기 성 정 산 내 역 (수지-수원연계 지역난방 열배관공사)
A2: 공사명 : 2025년 열수송관 천공 및 차단공사(1권역) | M2: 시티에너지 (건가)
B3: 공 종 | C3: 규 격 | D3: 수 량 | E3: 단 위 | F3: 산출내역 | J3: 전회까지 기 성 액 | K3: 금 회 기성액 | L3: 누계기성 금 액
A4: 1. 천공 및 차단 | J4: ='기성정산내역(수지-수원_시티_건가)'!J4 -> 0 | K4: ='기성총괄표(수지-수원_시티_건가)'!M10 -> 438331708 | L4: =J4+K4 -> 438331708
B8: 순공사비 계 | J8: =SUM(J4:J7) -> 0 | K8: =SUM(K4:K7) -> 438331708 | L8: =SUM(L4:L7) -> 438331708
B9: [공사비총괄표]
A10: 1. | B10: 재료비 | D10: 1 | E10: 식 | J10: 0 | K10: ='기성총괄표(수지-수원_시티_건가)'!M12 -> 359801184 | L10: =J10+K10 -> 359801184
A11: 2. | B11: 노무비 | J11: 0 | K11: ='기성총괄표(수지-수원_시티_건가)'!M13 -> 62469495 | L11: =J11+K11 -> 62469495
B12: 가. 직접노무비 | D12: 1 | E12: 식 | J12: 0 | K12: ='기성총괄표(수지-수원_시티_건가)'!M14 -> 55136360 | L12: =J12+K12 -> 55136360
B13: 나. 간접노무비 | C13: 0.116 | D13: 1 | E13: 식 | F13: (직접노무비 x 요율) | J13: 0 | K13: ='기성총괄표(수지-수원_시티_건가)'!M15 -> 7333135 | L13: =J13+K13 -> 7333135
A14: 3. | B14: 경비 | J14: 0 | K14: ='기성총괄표(수지-수원_시티_건가)'!M16 -> 43984387 | L14: =J14+K14 -> 43984387
B15: 가. 기계경비 | D15: 1 | E15: 식 | J15: 0 | K15: ='기성총괄표(수지-수원_시티_건가)'!M17 -> 23394164 | L15: =J15+K15 -> 23394164
B16: 나. 보험료 | J16: 0 | K16: ='기성총괄표(수지-수원_시티_건가)'!M18 -> 0 | L16: =J16+K16 -> 0
B17: 1) 산재보험료 | C17: 0.0356 | D17: 1 | E17: 식 | F17: [(직접노무비 + 간접노무비) x 요율] | J17: 0 | K17: ='기성총괄표(수지-수원_시티_건가)'!M19 -> 2223914 | L17: =J17+K17 -> 2223914
B18: 2) 고용보험료 | C18: 0.0101 | D18: 1 | E18: 식 | F18: [(직접노무비 + 간접노무비) x 요율] | J18: 0 | K18: ='기성총괄표(수지-수원_시티_건가)'!M20 -> 630941 | L18: =J18+K18 -> 630941
B19: 3) 연금보험료 | C19: 0.045 | D19: 1 | E19: 식 | F19: (직접노무비 x 요율) | J19: 0 | K19: ='기성총괄표(수지-수원_시티_건가)'!M21 -> 0 | L19: =J19+K19 -> 0 | M19: 실적정산
B20: 4) 건강보험료 | C20: 0.03545 | D20: 1 | E20: 식 | F20: (직접노무비 x 요율) | J20: 0 | K20: ='기성총괄표(수지-수원_시티_건가)'!M22 -> 0 | L20: =J20+K20 -> 0 | M20: 실적정산
B21: 5) 노인장기요양보험료 | C21: 0.1295 | D21: 1 | E21: 식 | F21: (건강보험료 x 요율) | J21: 0 | K21: ='기성총괄표(수지-수원_시티_건가)'!M23 -> 0 | L21: =J21+K21 -> 0 | M21: 실적정산
B22: 다. 건설근로자퇴직공제부금비 | C22: 0.023 | D22: 1 | E22: 식 | F22: (직접노무비) x 요율 | J22: 0 | K22: ='기성총괄표(수지-수원_시티_건가)'!M24 -> 0 | L22: =J22+K22 -> 0 | M22: 실적정산
B23: 라. 산업안전보건관리비 | C23: 0.0199 | D23: 1 | E23: 식 | F23: (재료비 + 직접노무비) x 요율 + 5,499,000 | J23: 0 | K23: ='기성총괄표(수지-수원_시티_건가)'!M25 -> 0 | L23: =J23+K23 -> 0 | M23: 실적정산
B24: 마. 기타경비 | C24: 0.048 | D24: 1 | E24: 식 | F24: [(재료비 + 직접노무비 + 간접노무비) x 요율] | J24: 0 | K24: ='기성총괄표(수지-수원_시티_건가)'!M26 -> 17735368 | L24: =J24+K24 -> 17735368
B25: 바. 환경보전비 | C25: 0.005 | D25: 1 | E25: 식 | F25: [(재료비 + 직접노무비 + 산출경비) x 요율] | J25: 0 | K25: ='기성총괄표(수지-수원_시티_건가)'!M27 -> 0 | L25: =J25+K25 -> 0 | M25: 실적정산
B26: 사. 지급보증서발급수수료 | J26: 0 | K26: ='기성총괄표(수지-수원_시티_건가)'!M28 -> 0 | L26: =J26+K26 -> 0
B27: 1) 하도급대금 | C27: 0.00081 | D27: 1 | E27: 식 | F27: [(재료비 + 직접노무비 + 산출경비) x 요율] | J27: 0 | K27: ='기성총괄표(수지-수원_시티_건가)'!M29 -> 0 | L27: =J27+K27 -> 0 | M27: 실적정산
B28: 2) 건설기계대여대금 | C28: 0.0032 | D28: 1 | E28: 식 | F28: [(재료비 + 직접노무비 + 산출경비) x 요율] | J28: 0 | K28: ='기성총괄표(수지-수원_시티_건가)'!M30 -> 0 | L28: =J28+K28 -> 0 | M28: 실적정산
B29: 순 공 사 원 가 | J29: 0 | K29: ='기성총괄표(수지-수원_시티_건가)'!M31 -> 466255066 | L29: =J29+K29 -> 466255066
A30: 4. | B30: 일반관리비 | C30: 0.04 | D30: 1 | E30: 식 | F30: [(재료비 + 노무비 + 경비) x 요율] | J30: 0 | K30: ='기성총괄표(수지-수원_시티_건가)'!M32 -> 16318927 | L30: =J30+K30 -> 16318927
A31: 5. | B31: 이윤 | C31: 0.05 | D31: 1 | E31: 식 | F31: [(노무비 + 경비 + 일반관리비) x 요율] | J31: 0 | K31: ='기성총괄표(수지-수원_시티_건가)'!M33 -> 5276007 | L31: =J31+K31 -> 5276007
B32: 공 사 원 가 | J32: 0 | K32: ='기성총괄표(수지-수원_시티_건가)'!M34 -> 487850000 | L32: =J32+K32 -> 487850000
B33: 총 원 가 | J33: 0 | K33: ='기성총괄표(수지-수원_시티_건가)'!M35 -> 487850000 | L33: =J33+K33 -> 487850000
B34: 부 가 세 | J34: 0 | K34: ='기성총괄표(수지-수원_시티_건가)'!M36 -> 48785000 | L34: =J34+K34 -> 48785000
B35: 총 공 사 금 액 | J35: 0 | K35: ='기성총괄표(수지-수원_시티_건가)'!M37 -> 536635000 | L35: =J35+K35 -> 536635000

Sheet 기성총괄표(수지-수원_시티_건가)
A1: 기 성 총 괄 표 (수지-수원연계 지역난방 열배관공사)
A2: 공사명 : 2025년 열수송관 천공 및 차단공사(1권역) | M2: 시티에너지 (건가)
B3: 공 종 | C3: 규 격 | D3: 수 량 | E3: 단 위 | F3: 재 료 비 | H3: 노 무 비 | J3: 경 비 | L3: 계 | N3: 비 고
F4: 단 가 | G4: 금 액 | H4: 단 가 | I4: 금 액 | J4: 단 가 | K4: 금 액 | L4: 단 가 | M4: 금 액
B5: Ⅰ. 열배관공사
A6: 1. 천공 및 차단 | G6: ='기성내역서(수지-수원_시티_건가)'!G61 -> 359801184 | I6: ='기성내역서(수지-수원_시티_건가)'!I61 -> 55136360 | K6: ='기성내역서(수지-수원_시티_건가)'!K61 -> 23394164 | M6: =G6+I6+K6 -> 438331708
