Workbook
Name _15A: [2]가격조사서!$D$4:$D$11
Name _B22: [3]일위대가!$1400:$1413=[3]일위대가!$A$1400
Name _DAN2: [4]단가조사서!$M$1:$N$65536
Name _JIP1: [4]집계표!$A$1:$K$65536
Name _K02: [3]일위대가!$732:$745=[3]일위대가!$A$732
Name _O03: [3]일위대가!$1516:$1529=[3]일위대가!$A$1516
Name _QTY1: [7]SHEET2!$F$3:$F$101
Name _RAN5: [8]토목품셈!$D$1:$AI$146
Name _RAN6: [8]토목품셈!$BO$1:$BZ$25
Name _RAN7: [8]토목품셈!$CB$1:$CJ$24
Name ABCD: [9]CABdata!$E$22:$F$46
Name A노임단가: '[10]노무비(DB)'!$A$1:$D$208
Name bdfgdgr: [11]!Macro8
Name BLDG: [12]LEGEND!$D$8
Name CABDIA: [9]MOTOR!$A$86:$B$408
Name CABLEA: [9]MOTOR!$B$66:$C$82
Name CABLEB: [9]MOTOR!$D$66:$E$82
Name CABLED: [9]MOTOR!$F$66:$G$82
Name CABLEE: [9]MOTOR!$H$66:$I$82
Name CAB허용: [9]MOTOR!$J$66:$N$81
Name cds: [0]!cds
Name cds가로등: [0]!cds가로등
Name CIRCUIT: [13]Sheet1!$C$4:$D$10
Name CLIENT: [12]LEGEND!$D$6
Name CTC: [14]DATA!$H$30:$I$57
Name DANGA_: '[15]Y-WORK'!$D$19:$D$19,'[15]Y-WORK'!$F$19:$BD$19
Name DAT: [16]MCC제원!$A$5:$AG$80
Name ddd가로등: [0]!ddd가로등
Name dfffffs: [0]!dfffffs
Name dffffs가로등: [0]!dffffs가로등
Name dfs가로등: [0]!dfs가로등
Name df가로등: [0]!df가로등
Name DGS: [17]data!$S$4:$T$32
Name EJ: [18]소비자가!$I$46:$J$1593
Name EssAliasTable: "Default"
Name EssOptions: "A1100000000130001000001100000_0000"
Name hidden: [20]TABLE!$H$1,[20]TABLE!$J$1,[20]TABLE!$K$1
Name HIT: '[21]2F 회의실견적(5_14 일대)'!$J$31
Name IEC: '[16]허용전류-IEC DATA'!$A$1:$E$352
Name ilch: [22]ilch!$A$3:$M$25
Name JODO: [17]data!$AA$4:$AE$14
Name KO: '[23]D-RMIL'!$B$7:$C$19
Name KYNGSADO: [24]!KYNGSADO
Name KYNGSAYL: [25]!KYNGSAYL
Name LI: [26]Sheet2!$A$2:$B$48
Name list1: '[27]일위대가(원본)'!$A$159:$Q$1426
Name ListItem01: [28]발신정보!$C$4
Name ListItem02: [28]발신정보!$C$5
Name ListItem04: [28]발신정보!$C$7
Name ListItem07: [28]발신정보!$C$11
Name LOCATION: [12]LEGEND!$D$7
Name LOP: [29]LOPCALC!$A$4:$J$8
Name LX: [7]SHEET2!$K$5:$N$23
Name Macro1: [30]!Macro1
Name Macro10: [31]!Macro10
Name Macro11: [30]!Macro11
Name Macro12: [31]!Macro12
Name Macro13: [31]!Macro13
Name Macro14: [31]!Macro14
Name Macro2: [31]!Macro2

Sheet 내역서
A1: 공사비 내역서 제출 양식
A3: 연번 | B3: 공종명 | C3: 규격 | D3: 수량 | E3: 단위 | F3: 내역금액 | N3: 비고 | O3: 신기술 보호범위
F4: 재료비 | H4: 노무비 | J4: 경비 | L4: 합계
F5: 단가 | G5: 금액 | H5: 단가 | I5: 금액 | J5: 단가 | K5: 금액 | L5: 단가 | M5: 금액
B6: 부단수 차단(강관제) | C6: 1650 | G6: =INT(SUM(G7:G18)) -> 64355438 | I6: =INT(SUM(I7:I18)) -> 23197389 | K6: =INT(SUM(K7:K18)) -> 78601995 | M6: =G6+I6+K6 -> 166154822
A7: 1 | B7: 바탕처리(강관제) | C7: 1650 | D7: 1 | E7: nr | F7: =일위대가호표!I7 -> 1145 | G7: =F7*D7 -> 1145 | H7: =일위대가호표!K7 -> 285076 | I7: =H7*D7 -> 285076 | J7: =일위대가호표!M7 -> 1593 | K7: =J7*D7 -> 1593 | L7: =F7+H7+J7 -> 287814 | M7: =L7*D7 -> 287814 | O7: 연계)기술내용
A8: 2 | B8: 부단수 할정자관 부설 및 접합(강관제) | C8: 1650 | D8: 1 | E8: nr | F8: =일위대가호표!I24 -> 24268813 | G8: =F8*D8 -> 24268813 | H8: =일위대가호표!K24 -> 5724877 | I8: =H8*D8 -> 5724877 | J8: =일위대가호표!M24 -> 1104132 | K8: =J8*D8 -> 1104132 | L8: =F8+H8+J8 -> 31097822 | M8: =L8*D8 -> 31097822 | O8: 연계)기술내용
A9: 3 | B9: 샌드위치 밸브 부설 및 접합 | C9: 1200 | D9: 1 | E9: nr | F9: =일위대가호표!I52 -> 550910 | G9: =F9*D9 -> 550910 | H9: =일위대가호표!K52 -> 606955 | I9: =H9*D9 -> 606955 | J9: =일위대가호표!M52 -> 9877407 | K9: =J9*D9 -> 9877407 | L9: =F9+H9+J9 -> 11035272 | M9: =L9*D9 -> 11035272 | O9: 연계)기술내용
A10: 4 | B10: 부단수천공 분기점 분기/철거 | C10: 1200 | D10: 1 | E10: nr | F10: =일위대가호표!I73 -> 9013133 | G10: =F10*D10 -> 9013133 | H10: =일위대가호표!K73 -> 4725036 | I10: =H10*D10 -> 4725036 | J10: =일위대가호표!M73 -> 27205035 | K10: =J10*D10 -> 27205035 | L10: =F10+H10+J10 -> 40943204 | M10: =L10*D10 -> 40943204 | O10: 연계)기술내용
A11: 5 | B11: 등압관 설치/철거 | C11: 100 | D11: 1 | E11: nr | F11: =일위대가호표!I127 -> 480686 | G11: =F11*D11 -> 480686 | H11: =일위대가호표!K127 -> 235729 | I11: =H11*D11 -> 235729 | J11: =일위대가호표!M127 -> 84487 | K11: =J11*D11 -> 84487 | L11: =F11+H11+J11 -> 800902 | M11: =L11*D11 -> 800902 | O11: 연계)기술내용
A12: 6 | B12: 부단수차단/철거 | C12: 1650 | D12: 1 | E12: nr | F12: =일위대가호표!I159 -> 17753893 | G12: =F12*D12 -> 17753893 | H12: =일위대가호표!K159 -> 7959982 | I12: =H12*D12 -> 7959982 | J12: =일위대가호표!M159 -> 31516671 | K12: =J12*D12 -> 31516671 | L12: =F12+H12+J12 -> 57230546 | M12: =L12*D12 -> 57230546 | O12: 신기술)기술내용
A13: 7 | B13: 플러깅/철거 | C13: 1200 | D13: 1 | E13: nr | F13: =일위대가호표!I191 -> 9606948 | G13: =F13*D13 -> 9606948 | H13: =일위대가호표!K191 -> 1819462 | I13: =H13*D13 -> 1819462 | J13: =일위대가호표!M191 -> 3200624 | K13: =J13*D13 -> 3200624 | L13: =F13+H13+J13 -> 14627034 | M13: =L13*D13 -> 14627034 | O13: 연계)기술내용
A14: 8 | B14: 샌드위치 밸브 철거 | C14: 1200 | D14: 1 | E14: nr | F14: =일위대가호표!I216 -> 0 | G14: =F14*D14 -> 0 | H14: =일위대가호표!K216 -> 242945 | I14: =H14*D14 -> 242945 | J14: =일위대가호표!M216 -> 84344 | K14: =J14*D14 -> 84344 | L14: =F14+H14+J14 -> 327289 | M14: =L14*D14 -> 327289 | O14: 연계)기술내용
A15: 9 | B15: 마개플랜지 부설 및 접합 | C15: 1200 | D15: 1 | E15: nr | F15: =일위대가호표!I223 -> 2679910 | G15: =F15*D15 -> 2679910 | H15: =일위대가호표!K223 -> 481452 | I15: =H15*D15 -> 481452 | J15: =일위대가호표!M223 -> 27702 | K15: =J15*D15 -> 27702 | L15: =F15+H15+J15 -> 3189064 | M15: =L15*D15 -> 3189064 | O15: 연계)기술내용
A16: 10 | B16: 사전조사 | C16: 1650 | D16: 1 | E16: nr | F16: =일위대가호표!I238 -> 0 | G16: =F16*D16 -> 0 | H16: =일위대가호표!K238 -> 335379 | I16: =H16*D16 -> 335379 | J16: =일위대가호표!M238 -> 0 | K16: =J16*D16 -> 0 | L16: =F16+H16+J16 -> 335379 | M16: =L16*D16 -> 335379 | O16: 연계)기술내용
A17: 11 | B17: 장비운반비 | C17: 1650 | D17: 1 | E17: set | F17: =일위대가호표!I242 -> 0 | G17: =F17*D17 -> 0 | H17: =일위대가호표!K242 -> 0 | I17: =H17*D17 -> 0 | J17: =일위대가호표!M242 -> 5500000 | K17: =J17*D17 -> 5500000 | L17: =F17+H17+J17 -> 5500000 | M17: =L17*D17 -> 5500000 | O17: 연계)기술내용
A18: 12 | B18: 밸브개폐비 | C18: 1200 | D18: 1 | E18: nr | F18: =일위대가호표!I246 -> 0 | G18: =F18*D18 -> 0 | H18: =일위대가호표!K246 -> 780496 | I18: =H18*D18 -> 780496 | J18: =일위대가호표!M246 -> 0 | K18: =J18*D18 -> 0 | L18: =F18+H18+J18 -> 780496 | M18: =L18*D18 -> 780496 | O18: 연계)기술내용
B19: 부단수 차단(강관제) | C19: 1200 | G19: =INT(SUM(G20:G31)) -> 20113144 | I19: =INT(SUM(I20:I31)) -> 8728948 | K19: =INT(SUM(K20:K31)) -> 12369650 | M19: =G19+I19+K19 -> 41211742
A20: 13 | B20: 바탕처리(강관제) | C20: 1200 | D20: 1 | E20: nr | F20: =일위대가호표!I256 -> 408 | G20: =F20*D20 -> 408 | H20: =일위대가호표!K256 -> 101185 | I20: =H20*D20 -> 101185 | J20: =일위대가호표!M256 -> 568 | K20: =J20*D20 -> 568 | L20: =F20+H20+J20 -> 102161 | M20: =L20*D20 -> 102161 | O20: 연계)기술내용
A21: 14 | B21: 부단수 할정자관 부설 및 접합(강관제) | C21: 1200 | D21: 1 | E21: nr | F21: =일위대가호표!I273 -> 8273059 | G21: =F21*D21 -> 8273059 | H21: =일위대가호표!K273 -> 2252413 | I21: =H21*D21 -> 2252413 | J21: =일위대가호표!M273 -> 628995 | K21: =J21*D21 -> 628995 | L21: =F21+H21+J21 -> 11154467 | M21: =L21*D21 -> 11154467 | O21: 연계)기술내용
A22: 15 | B22: 샌드위치 밸브 부설 및 접합 | C22: 850 | D22: 1 | E22: nr | F22: =일위대가호표!I301 -> 48970 | G22: =F22*D22 -> 48970 | H22: =일위대가호표!K301 -> 345719 | I22: =H22*D22 -> 345719 | J22: =일위대가호표!M301 -> 636099 | K22: =J22*D22 -> 636099 | L22: =F22+H22+J22 -> 1030788 | M22: =L22*D22 -> 1030788 | O22: 연계)기술내용
A23: 16 | B23: 부단수천공 분기점 분기/철거 | C23: 850 | D23: 1 | E23: nr | F23: =일위대가호표!I322 -> 2188345 | G23: =F23*D23 -> 2188345 | H23: =일위대가호표!K322 -> 1376841 | I23: =H23*D23 -> 1376841 | J23: =일위대가호표!M322 -> 4274334 | K23: =J23*D23 -> 4274334 | L23: =F23+H23+J23 -> 7839520 | M23: =L23*D23 -> 7839520 | O23: 연계)기술내용
A24: 17 | B24: 등압관 설치/철거 | C24: 100 | D24: 1 | E24: nr | F24: =일위대가호표!I376 -> 480686 | G24: =F24*D24 -> 480686 | H24: =일위대가호표!K376 -> 235729 | I24: =H24*D24 -> 235729 | J24: =일위대가호표!M376 -> 84487 | K24: =J24*D24 -> 84487 | L24: =F24+H24+J24 -> 800902 | M24: =L24*D24 -> 800902 | O24: 연계)기술내용
A25: 18 | B25: 부단수차단/철거 | C25: 1200 | D25: 1 | E25: nr | F25: =일위대가호표!I408 -> 5764654 | G25: =F25*D25 -> 5764654 | H25: =일위대가호표!K408 -> 2852803 | I25: =H25*D25 -> 2852803 | J25: =일위대가호표!M408 -> 2905362 | K25: =J25*D25 -> 2905362 | L25: =F25+H25+J25 -> 11522819 | M25: =L25*D25 -> 11522819 | O25: 신기술)기술내용
A26: 19 | B26: 플러깅/철거 | C26: 850 | D26: 1 | E26: nr | F26: =일위대가호표!I440 -> 2758052 | G26: =F26*D26 -> 2758052 | H26: =일위대가호표!K440 -> 496549 | I26: =H26*D26 -> 496549 | J26: =일위대가호표!M440 -> 403709 | K26: =J26*D26 -> 403709 | L26: =F26+H26+J26 -> 3658310 | M26: =L26*D26 -> 3658310 | O26: 연계)기술내용
A27: 20 | B27: 샌드위치 밸브 철거 | C27: 850 | D27: 1 | E27: nr | F27: =일위대가호표!I229 -> 0 | G27: =F27*D27 -> 0 | H27: =일위대가호표!K465 -> 138450 | I27: =H27*D27 -> 138450 | J27: =일위대가호표!M465 -> 38090 | K27: =J27*D27 -> 38090 | L27: =F27+H27+J27 -> 176540 | M27: =L27*D27 -> 176540 | O27: 연계)기술내용
A28: 21 | B28: 마개플랜지 부설 및 접합 | C28: 850 | D28: 1 | E28: nr | F28: =일위대가호표!I472 -> 598970 | G28: =F28*D28 -> 598970 | H28: =일위대가호표!K472 -> 160272 | I28: =H28*D28 -> 160272 | J28: =일위대가호표!M472 -> 18006 | K28: =J28*D28 -> 18006 | L28: =F28+H28+J28 -> 777248 | M28: =L28*D28 -> 777248 | O28: 연계)기술내용
A29: 22 | B29: 사전조사 | C29: 1200 | D29: 1 | E29: nr | F29: =일위대가호표!I487 -> 0 | G29: =F29*D29 -> 0 | H29: =일위대가호표!K487 -> 335379 | I29: =H29*D29 -> 335379 | J29: =일위대가호표!M487 -> 0 | K29: =J29*D29 -> 0 | L29: =F29+H29+J29 -> 335379 | M29: =L29*D29 -> 335379 | O29: 연계)기술내용
A30: 23 | B30: 장비운반비 | C30: 1200 | D30: 1 | E30: set | F30: =일위대가호표!I491 -> 0 | G30: =F30*D30 -> 0 | H30: =일위대가호표!K491 -> 0 | I30: =H30*D30 -> 0 | J30: =일위대가호표!M491 -> 3380000 | K30: =J30*D30 -> 3380000 | L30: =F30+H30+J30 -> 3380000 | M30: =L30*D30 -> 3380000 | O30: 연계)기술내용
A31: 24 | B31: 밸브개폐비 | C31: 850 | D31: 1 | E31: nr | F31: =일위대가호표!I495 -> 0 | G31: =F31*D31 -> 0 | H31: =일위대가호표!K495 -> 433608 | I31: =H31*D31 -> 433608 | J31: =일위대가호표!M495 -> 0 | K31: =J31*D31 -> 0 | L31: =F31+H31+J31 -> 433608 | M31: =L31*D31 -> 433608 | O31: 연계)기술내용
A35: 1. 제경비 및 부가세 별도 2. 기타사항(있을 경우 기재) 3. 신기술(NET 및 특허) 보호범위 공종은 신기술인증서, 특허원부의 해당 청구항 번호 작성, 연계공사가 필요한 공종은 “연계)”와 청구항 번호를 입력하고 증빙서류 등을 첨부하여 작성하여야 하며 미작성 시 기술사용료, 하도급 범위 등에 불이익이 있을 수 있음.
A39: ※ 세부 내역서 비목 구성을 1식 단가로 제출하거나 공사비내역서에 제출일 기준 90일 미만의 유효기간 기재 시 심사대상에서 제외될 수 있음 ※ ‘공사비내역서(물량)’과 ‘견적서 및 공사비내역서’간 오류 확인 시 선정 후 취소될 수 있음

Sheet 견적서
B2: 견 적 서
B5: 문 서 번 호 | G5: DH18-260422-01 | U5: 공 급 자 | W5: 등록번호 | Z5: 140-81-34127
B6: 수 신 | G6: K-water | W6: 상 호 | Z6: (주)대호스토퍼 | AG6: 대표 | AJ6: 이 영 호 | AP6: (인)
W7: 소 재 지 | Z7: 경기도 안산시 상록구 남산평길 126-4(팔곡일동)
B8: 담 당 자 | S8: 귀중 | W8: 업 태 | Z8: 제조업 외 | AG8: 종목 | AJ8: 상하수도설비공사 외
B9: 연 락 처 | W9: 회사전화 | Z9: 031-496-9488 | AG9: 회사팩스 | AJ9: 031-496-9349
B10: 작 성 일 | G10: 46134 | W10: 담 당 자 | Z10: 백승리 차장 | AG10: 휴대전화 | AJ10: 010-5013-7776
B11: 유 효 기 간 | G11: 12개월 | W11: E-Mail | Z11: dhcstopper@hanmail.net
B12: 견 적 명 | G12: 광양산단 비상 공급시설 설치사업 중 부단수 차단 공사
B14: 합 계 금 액 | G14: 일금 | I14: =AB14 -> 747042772 | Y14: 원정 | AA14: ( | AB14: =AJ32 -> 747042772 | AL14: ) | AM14: (VAT별도)
B16: 아래와 같이 견적을 제출합니다.
B17: 품 명 | G17: 규 격 | L17: 단 위 | N17: 수량 | P17: 재 료 비 | U17: 노 무 비 | Z17: 경 비 | AE17: 소 계 | AJ17: 금 액 | AO17: 비고
B18: 부단수 차단 | G18: D1,650㎜ | L18: EA | N18: 4 | P18: =내역서!G6 -> 64355438 | U18: =내역서!I6 -> 23197389 | Z18: =내역서!K6 -> 78601995 | AE18: =P18+U18+Z18 -> 166154822 | AJ18: =AE18*N18 -> 664619288
B19: " | G19: D900㎜ | L19: EA | N19: 2 | P19: =내역서!G19 -> 20113144 | U19: =내역서!I19 -> 8728948 | Z19: =내역서!K19 -> 12369650 | AE19: =P19+U19+Z19 -> 41211742 | AJ19: =AE19*N19 -> 82423484
B31: 단수정리
B32: 합 계(TOTAL) | AJ32: =SUM(AJ18:AN31) -> 747042772
B33: MEMO | D33: 1. 토공, 가시설공, 피팅부 관보호공등 부단수 차단 외 공종에 대한 공통 공사비 제외 2. 가배관 별도 3. 납품방법 : 현장설치도

Sheet 일위대가목록
A1: 일위대가_목록
A2: 호 표 | B2: 공 종 명 | C2: 규 격 | D2: 단위 | E2: 합계 | F2: 재료비 | H2: 노무비 | J2: 경 비 | K2: 비 고
A3: 1 | B3: 부단수 차단(강관제) | C3: 차단관경, D1650mm | E3: =F3+H3+J3 -> 166154822 | F3: =내역서!G6 -> 64355438 | H3: =내역서!I6 -> 23197389 | J3: =내역서!K6 -> 78601995
A4: 2 | B4: 바탕처리(강관제) | C4: 차단관경, D1650mm | D4: nr | E4: =F4+H4+J4 -> 287814 | F4: =일위대가호표!I7 -> 1145 | G4: =일위대가호표!J7 -> 0 | H4: =일위대가호표!K7 -> 285076 | I4: =일위대가호표!L7 -> 0 | J4: =일위대가호표!M7 -> 1593
A5: 3 | B5: 강관 도복장 제거 | C5: 차단관경, D1650mm | D5: nr | E5: =F5+H5+J5 -> 231947 | F5: =일위대가호표!I5 -> 0 | G5: =일위대가호표!J5 -> 231947 | H5: =일위대가호표!K5 -> 231947 | I5: =일위대가호표!L5 -> 0 | J5: =일위대가호표!M5 -> 0
A6: 4 | B6: 표면정리 | C6: 차단관경, D1650mm | D6: nr | E6: =F6+H6+J6 -> 55867 | F6: =일위대가호표!I6 -> 1145 | G6: =일위대가호표!J6 -> 53129 | H6: =일위대가호표!K6 -> 53129 | I6: =일위대가호표!L6 -> 1593 | J6: =일위대가호표!M6 -> 1593
A7: 5 | B7: 부단수 할정자관 부설 및 접합(강관제) | C7: 차단관경, D1650mm | D7: nr | E7: =F7+H7+J7 -> 31097822 | F7: =일위대가호표!I24 -> 24268813 | G7: =일위대가호표!J24 -> 0 | H7: =일위대가호표!K24 -> 5724877 | I7: =일위대가호표!L24 -> 0 | J7: =일위대가호표!M24 -> 1104132
A8: 6 | B8: 부단수 할정자관 부설(강관제) | C8: 차단관경, D1650mm | D8: nr | E8: =F8+H8+J8 -> 2076866 | F8: =일위대가호표!I20 -> 0 | G8: =일위대가호표!J20 -> 1909169 | H8: =일위대가호표!K20 -> 1909169 | I8: =일위대가호표!L20 -> 167697 | J8: =일위대가호표!M20 -> 167697
A9: 7 | B9: 부단수 할정자관 접합(강관제) | C9: 차단관경, D1650mm | D9: nr | E9: =F9+H9+J9 -> 4612967 | F9: =일위대가호표!I21 -> 192864 | G9: =일위대가호표!J21 -> 3483668 | H9: =일위대가호표!K21 -> 3483668 | I9: =일위대가호표!L21 -> 936435 | J9: =일위대가호표!M21 -> 936435
A10: 8 | B10: 부단수 할정자관 접합부 도장 | C10: 차단관경, D1650mm | D10: nr | E10: =F10+H10+J10 -> 407989 | F10: =일위대가호표!I22 -> 75949 | G10: =일위대가호표!J22 -> 332040 | H10: =일위대가호표!K22 -> 332040 | I10: =일위대가호표!L22 -> 0 | J10: =일위대가호표!M22 -> 0
A11: 9 | B11: 샌드위치 밸브 부설 및 접합 | C11: 천공관경, D1200mm | D11: nr | E11: =F11+H11+J11 -> 11035272 | F11: =일위대가호표!I52 -> 550910 | G11: =일위대가호표!J52 -> 0 | H11: =일위대가호표!K52 -> 606955 | I11: =일위대가호표!L52 -> 0 | J11: =일위대가호표!M52 -> 9877407
A12: 10 | B12: 샌드위치 밸브 부설 및 접합(손료제외) | C12: 천공관경, D1200mm | D12: nr | E12: =F12+H12+J12 -> 817320 | F12: =일위대가호표!I49 -> 0 | G12: =일위대가호표!J49 -> 606955 | H12: =일위대가호표!K49 -> 606955 | I12: =일위대가호표!L49 -> 210365 | J12: =일위대가호표!M49 -> 210365
A13: 11 | B13: 샌드위치 밸브 손료 | C13: 천공관경, D1200mm | D13: nr | E13: =F13+H13+J13 -> 9667042 | F13: =일위대가호표!I50 -> 0 | G13: =일위대가호표!J50 -> 0 | H13: =일위대가호표!K50 -> 0 | I13: =일위대가호표!L50 -> 110430 | J13: =일위대가호표!M50 -> 9667042
A14: 12 | B14: 부단수천공 분기점 분기/철거 | C14: 천공관경, D1200mm | D14: nr | E14: =F14+H14+J14 -> 40943204 | F14: =일위대가호표!I73 -> 9013133 | G14: =일위대가호표!J73 -> 0 | H14: =일위대가호표!K73 -> 4725036 | I14: =일위대가호표!L73 -> 0 | J14: =일위대가호표!M73 -> 27205035
A15: 13 | B15: 부단수천공 분기점 분기(손료제외) | C15: 천공관경, D1200mm | D15: nr | E15: =F15+H15+J15 -> 3383995 | F15: =일위대가호표!I61 -> 0 | G15: =일위대가호표!J61 -> 2267669 | H15: =일위대가호표!K61 -> 2267669 | I15: =일위대가호표!L61 -> 1116326 | J15: =일위대가호표!M61 -> 1116326
A16: 14 | B16: 부단수천공기 손료 | C16: 차단관경, D1650mm | D16: nr | E16: =F16+H16+J16 -> 23780853 | F16: =일위대가호표!I62 -> 0 | G16: =일위대가호표!J62 -> 0 | H16: =일위대가호표!K62 -> 0 | I16: =일위대가호표!L62 -> 271657 | J16: =일위대가호표!M62 -> 23780853
A17: 15 | B17: 부단수천공기 운전경비 | C17: 천공관경, D1200mm | D17: nr | E17: =F17+H17+J17 -> 102596 | F17: =일위대가호표!I63 -> 102596 | G17: =일위대가호표!J63 -> 0 | H17: =일위대가호표!K63 -> 0 | I17: =일위대가호표!L63 -> 0 | J17: =일위대가호표!M63 -> 0
A18: 16 | B18: 기밀시험 | C18: 차단관경, D1650mm | D18: nr | E18: =F18+H18+J18 -> 616640 | F18: =일위대가호표!I64 -> 17960 | G18: =일위대가호표!J64 -> 598680 | H18: =일위대가호표!K64 -> 598680 | I18: =일위대가호표!L64 -> 0 | J18: =일위대가호표!M64 -> 0
A19: 17 | B19: 칩제거(손료제외) | C19: 천공관경, D1200mm | D19: nr | E19: =F19+H19+J19 -> 1015870 | F19: =일위대가호표!I65 -> 0 | G19: =일위대가호표!J65 -> 680476 | H19: =일위대가호표!K65 -> 680476 | I19: =일위대가호표!L65 -> 335394 | J19: =일위대가호표!M65 -> 335394
A20: 18 | B20: 칩제거기 손료 | C20: 차단관경, D1650mm | D20: nr | E20: =F20+H20+J20 -> 1391973 | F20: =일위대가호표!I66 -> 0 | G20: =일위대가호표!J66 -> 0 | H20: =일위대가호표!K66 -> 0 | I20: =일위대가호표!L66 -> 15901 | J20: =일위대가호표!M66 -> 1391973
A21: 19 | B21: 칩제거기 운전경비 | C21: 천공관경, D1200mm | D21: nr | E21: =F21+H21+J21 -> 30757 | F21: =일위대가호표!I67 -> 30757 | G21: =일위대가호표!J67 -> 0 | H21: =일위대가호표!K67 -> 0 | I21: =일위대가호표!L67 -> 0 | J21: =일위대가호표!M67 -> 0
A22: 20 | B22: 부단수천공기 철거 | C22: 천공관경, D1200mm | D22: nr | E22: =F22+H22+J22 -> 1351506 | F22: =일위대가호표!I68 -> 0 | G22: =일위대가호표!J68 -> 904976 | H22: =일위대가호표!K68 -> 904976 | I22: =일위대가호표!L68 -> 446530 | J22: =일위대가호표!M68 -> 446530
A23: 21 | B23: 칩제거기 철거 | C23: 천공관경, D1200mm | D23: nr | E23: =F23+H23+J23 -> 407194 | F23: =일위대가호표!I69 -> 0 | G23: =일위대가호표!J69 -> 273235 | H23: =일위대가호표!K69 -> 273235 | I23: =일위대가호표!L69 -> 133959 | J23: =일위대가호표!M69 -> 133959
A24: 22 | B24: 등압관 설치/철거 | C24: 등압관경, D100mm | D24: nr | E24: =F24+H24+J24 -> 800902 | F24: =일위대가호표!I127 -> 480686 | G24: =일위대가호표!J127 -> 0 | H24: =일위대가호표!K127 -> 235729 | I24: =일위대가호표!L127 -> 0 | J24: =일위대가호표!M127 -> 84487
A25: 23 | B25: 등압관 부단수 천공 | C25: 등압관경, D100mm | D25: nr | E25: =F25+H25+J25 -> 210523 | F25: =일위대가호표!H120 -> 0 | G25: =일위대가호표!I120 -> 0 | H25: =일위대가호표!J120 -> 135281 | I25: =일위대가호표!K120 -> 135281 | J25: =일위대가호표!L120 -> 75242
A26: 24 | B26: 등압관 피팅 접합 | C26: 등압관경, D100mm | D26: nr | E26: =F26+H26+J26 -> 35678 | F26: =일위대가호표!H121 -> 686 | G26: =일위대가호표!I121 -> 686 | H26: =일위대가호표!J121 -> 31078 | I26: =일위대가호표!K121 -> 31078 | J26: =일위대가호표!L121 -> 3914
A27: 25 | B27: 등압관 플러깅 | C27: 등압관경, D100mm | D27: nr | E27: =F27+H27+J27 -> 74701 | F27: =일위대가호표!H122 -> 0 | G27: =일위대가호표!I122 -> 0 | H27: =일위대가호표!J122 -> 69370 | I27: =일위대가호표!K122 -> 69370 | J27: =일위대가호표!L122 -> 5331
A28: 26 | B28: 부단수차단/철거 | C28: 차단관경, D1650mm | D28: nr | E28: =F28+H28+J28 -> 57230546 | F28: =일위대가호표!I159 -> 17753893 | G28: =일위대가호표!J159 -> 0 | H28: =일위대가호표!K159 -> 7959982 | I28: =일위대가호표!L159 -> 0 | J28: =일위대가호표!M159 -> 31516671
A29: 27 | B29: 부단수차단(손료제외) | C29: 차단관경, D1650mm | D29: nr | E29: =F29+H29+J29 -> 6835955 | F29: =일위대가호표!I152 -> 0 | G29: =일위대가호표!J152 -> 4804487 | H29: =일위대가호표!K152 -> 4804487 | I29: =일위대가호표!L152 -> 2031468 | J29: =일위대가호표!M152 -> 2031468
A30: 28 | B30: 부단수차단기 손료 | C30: 차단관경, D1650mm | D30: nr | E30: =F30+H30+J30 -> 28672413 | F30: =일위대가호표!I153 -> 0 | G30: =일위대가호표!J153 -> 0 | H30: =일위대가호표!K153 -> 0 | I30: =일위대가호표!L153 -> 327535 | J30: =일위대가호표!M153 -> 28672413
A31: 29 | B31: 부단수차단기 운전경비 | C31: 차단관경, D1650mm | D31: nr | E31: =F31+H31+J31 -> 202983 | F31: =일위대가호표!I154 -> 202983 | G31: =일위대가호표!J154 -> 0 | H31: =일위대가호표!K154 -> 0 | I31: =일위대가호표!L154 -> 0 | J31: =일위대가호표!M154 -> 0
A32: 30 | B32: 현장대기 | C32: 차단관경, D1650mm | D32: nr | E32: =F32+H32+J32 -> 1233168 | F32: =일위대가호표!I155 -> 0 | G32: =일위대가호표!J155 -> 43498 | H32: =일위대가호표!K155 -> 1233168 | I32: =일위대가호표!L155 -> 0 | J32: =일위대가호표!M155 -> 0
A33: 31 | B33: 부단수차단기 철거 | C33: 차단관경, D1650mm | D33: nr | E33: =F33+H33+J33 -> 2735117 | F33: =일위대가호표!I156 -> 0 | G33: =일위대가호표!J156 -> 1922327 | H33: =일위대가호표!K156 -> 1922327 | I33: =일위대가호표!L156 -> 812790 | J33: =일위대가호표!M156 -> 812790
A34: 32 | B34: 플러깅/철거 | C34: 천공관경, D1200mm | D34: nr | E34: =F34+H34+J34 -> 14627034 | F34: =일위대가호표!I191 -> 9606948 | G34: =일위대가호표!J191 -> 0 | H34: =일위대가호표!K191 -> 1819462 | I34: =일위대가호표!L191 -> 0 | J34: =일위대가호표!M191 -> 3200624
A35: 33 | B35: 천공관 플러깅(손료제외) | C35: 천공관경, D1200mm | D35: nr | E35: =F35+H35+J35 -> 1857903 | F35: =일위대가호표!I185 -> 0 | G35: =일위대가호표!J185 -> 1298252 | H35: =일위대가호표!K185 -> 1298252 | I35: =일위대가호표!L185 -> 559651 | J35: =일위대가호표!M185 -> 559651
A36: 34 | B36: 플러깅 손료 | C36: 차단관경, D1650mm | D36: nr | E36: =F36+H36+J36 -> 2416716 | F36: =일위대가호표!I186 -> 0 | G36: =일위대가호표!J186 -> 0 | H36: =일위대가호표!K186 -> 0 | I36: =일위대가호표!L186 -> 27607 | J36: =일위대가호표!M186 -> 2416716
A37: 35 | B37: 플러깅장비 운전경비 | C37: 천공관경, D1200mm | D37: nr | E37: =F37+H37+J37 -> 56038 | F37: =일위대가호표!I187 -> 56038 | G37: =일위대가호표!J187 -> 0 | H37: =일위대가호표!K187 -> 0 | I37: =일위대가호표!L187 -> 0 | J37: =일위대가호표!M187 -> 0
A38: 36 | B38: 플러깅 장비 철거 | C38: 천공관경, D1200mm | D38: nr | E38: =F38+H38+J38 -> 745467 | F38: =일위대가호표!I188 -> 0 | G38: =일위대가호표!J188 -> 521210 | H38: =일위대가호표!K188 -> 521210 | I38: =일위대가호표!L188 -> 224257 | J38: =일위대가호표!M188 -> 224257
A39: 37 | B39: 마개플랜지 부설 및 접합 | C39: 천공관경, D1200mm | D39: nr | E39: =F39+H39+J39 -> 3189064 | F39: =일위대가호표!I223 -> 2679910 | G39: =일위대가호표!J223 -> 0 | H39: =일위대가호표!K223 -> 481452 | I39: =일위대가호표!L223 -> 0 | J39: =일위대가호표!M223 -> 27702
A40: 38 | B40: 마개플랜지 부설 | C40: 천공관경, D1200mm | D40: nr | E40: =F40+H40+J40 -> 367084 | F40: =일위대가호표!I219 -> 0 | G40: =일위대가호표!J219 -> 339382 | H40: =일위대가호표!K219 -> 339382 | I40: =일위대가호표!L219 -> 27702 | J40: =일위대가호표!M219 -> 27702
...

Sheet 일위대가호표
B1: 일위대가_호표
A2: 호 표 | B2: 공 종 명 | C2: 규 격 | D2: 수량 | E2: 단위 | F2: 합 계 | H2: 재 료 비 | J2: 노 무 비 | L2: 경 비 | N2: 비 고
F3: 단 가 | G3: 금 액 | H3: 단 가 | I3: 금 액 | J3: 단 가 | K3: 금 액 | L3: 단 가 | M3: 금 액
A4: 1 | B4: 바탕처리(강관제) | C4: 1650 | D4: 1 | E4: nr
B5: 강관 도복장 제거 | D5: 1 | E5: nr | F5: =H5+J5+L5 -> 231947 | G5: =F5*D5 -> 231947 | H5: =I11 -> 0 | I5: =TRUNC(H5*$D5,0) -> 0 | J5: =K11 -> 231947 | K5: =TRUNC(J5*$D5,0) -> 231947 | L5: =M11 -> 0 | M5: =TRUNC(L5*$D5,0) -> 0 | N5: =A9 -> 2
B6: 표면정리 | C6: #180 | D6: 1 | E6: nr | F6: =H6+J6+L6 -> 55867 | G6: =F6*D6 -> 55867 | H6: =I17 -> 1145 | I6: =TRUNC(H6*$D6,0) -> 1145 | J6: =K17 -> 53129 | K6: =TRUNC(J6*$D6,0) -> 53129 | L6: =M17 -> 1593 | M6: =TRUNC(L6*$D6,0) -> 1593 | N6: =A13 -> 3
B7: 계 | G7: =SUM(G5:G6) -> 287814 | I7: =SUM(I5:I6) -> 1145 | K7: =SUM(K5:K6) -> 285076 | M7: =SUM(M5:M6) -> 1593
A9: =A4+1 -> 2 | B9: 강관 도복장 제거 | C9: 1650 | D9: 1 | E9: nr
B10: 보통인부 | D10: 1.348 | E10: 인 | F10: =H10+J10+L10 -> 172068 | G10: =F10*D10 -> 231947.66 | I10: =TRUNC(H10*$D10,0) -> 0 | J10: =노임!$D$4 -> 172068 | K10: =TRUNC(J10*$D10,0) -> 231947 | M10: =TRUNC(L10*$D10,0) -> 0
B11: 계 | G11: =SUM(G10) -> 231947.66 | I11: =SUM(I10:I10) -> 0 | K11: =SUM(K10:K10) -> 231947 | M11: =SUM(M10:M10) -> 0
A13: =A9+1 -> 3 | B13: 표면정리 | C13: 1650 | D13: 1 | E13: nr
B14: 도장공 | D14: 0.202 | E14: 인 | F14: =H14+J14+L14 -> 263017 | G14: =F14*D14 -> 53129.434 | I14: =TRUNC(H14*$D14,0) -> 0 | J14: =노임!$D$6 -> 263017 | K14: =TRUNC(J14*$D14,0) -> 53129 | M14: =TRUNC(L14*$D14,0) -> 0
B15: 연마지 | C15: #180 | D15: 3.37 | E15: 매 | F15: =H15+J15+L15 -> 340 | G15: =F15*D15 -> 1145.8 | H15: =자재!$D$4 -> 340 | I15: =TRUNC(H15*$D15,0) -> 1145 | K15: =TRUNC(J15*$D15,0) -> 0 | M15: =TRUNC(L15*$D15,0) -> 0
B16: 공구손료 | C16: 도장공 인력품의 | D16: 0.03 | F16: =H16+J16+L16 -> 53129 | G16: =F16*D16 -> 1593.87 | I16: =TRUNC(H16*$E16,0) -> 0 | K16: =TRUNC(J16*$E16,0) -> 0 | L16: =K14 -> 53129 | M16: =TRUNC(L16*$D16,0) -> 1593
B17: 계 | G17: =SUM(G14:G16) -> 55869.104 | I17: =SUM(I14:I16) -> 1145 | K17: =SUM(K14:K16) -> 53129 | M17: =SUM(M14:M16) -> 1593
A19: =A13+1 -> 4 | B19: 부단수 할정자관 부설 및 접합(강관제) | C19: 1650 | D19: 1 | E19: nr
B20: 부단수 할정자관 부설(강관제) | C20: 1650 | D20: 1 | E20: nr | F20: =H20+J20+L20 -> 2076866 | G20: =F20*D20 -> 2076866 | H20: 0 | I20: =TRUNC(H20*$D20,0) -> 0 | J20: =K30 -> 1909169 | K20: =TRUNC(J20*$D20,0) -> 1909169 | L20: =M30 -> 167697 | M20: =TRUNC(L20*$D20,0) -> 167697 | N20: =A26 -> 5
B21: 부단수 할정자관 접합(강관제) | C21: 1650 | D21: 1 | E21: nr | F21: =H21+J21+L21 -> 4612967 | G21: =F21*D21 -> 4612967 | H21: =I37 -> 192864 | I21: =TRUNC(H21*$D21,0) -> 192864 | J21: =K37 -> 3483668 | K21: =TRUNC(J21*$D21,0) -> 3483668 | L21: =M37 -> 936435 | M21: =TRUNC(L21*$D21,0) -> 936435 | N21: =A32 -> 6
B22: 부단수 할정자관 접합부 도장 | C22: 1650 | D22: 1 | E22: nr | F22: =H22+J22+L22 -> 407989 | G22: =F22*D22 -> 407989 | H22: =I46 -> 75949 | I22: =TRUNC(H22*$D22,0) -> 75949 | J22: =K46 -> 332040 | K22: =TRUNC(J22*$D22,0) -> 332040 | L22: 0 | M22: =TRUNC(L22*$D22,0) -> 0 | N22: =A39 -> 7
B23: 부단수 할정자관 | C23: 1650 | D23: 1 | E23: nr | F23: =H23+J23+L23 -> 24000000 | G23: =F23*D23 -> 24000000 | H23: =자재견적서!AR18 -> 24000000 | I23: =TRUNC(H23*$D23,0) -> 24000000 | K23: =TRUNC(J23*$D23,0) -> 0 | M23: =TRUNC(L23*$D23,0) -> 0
B24: 계 | G24: =SUM(G20:G23) -> 31097822 | I24: =SUM(I20:I23) -> 24268813 | K24: =SUM(K20:K23) -> 5724877 | M24: =SUM(M20:M23) -> 1104132
A26: =A19+1 -> 5 | B26: 부단수 할정자관 부설(강관제) | C26: 1650 | D26: 1 | E26: nr
B27: 배관공(수도) | D27: 4.82 | E27: 인 | F27: =H27+J27+L27 -> 262580 | G27: =F27*D27 -> 1265635.6 | I27: =TRUNC(H27*$D27,0) -> 0 | J27: =노임!$D$8 -> 262580 | K27: =TRUNC(J27*$D27,0) -> 1265635 | M27: =TRUNC(L27*$D27,0) -> 0
B28: 보통인부 | D28: 3.74 | E28: 인 | F28: =H28+J28+L28 -> 172068 | G28: =F28*D28 -> 643534.32 | I28: =TRUNC(H28*$D28,0) -> 0 | J28: =노임!$D$4 -> 172068 | K28: =TRUNC(J28*$D28,0) -> 643534 | M28: =TRUNC(L28*$D28,0) -> 0
B29: 트럭탑재형크레인 | C29: 15 | D29: 1.69 | E29: hr | F29: =H29+J29+L29 -> 99229 | G29: =F29*D29 -> 167697.01 | I29: =TRUNC(H29*$D29,0) -> 0 | K29: =TRUNC(J29*$D29,0) -> 0 | L29: =경비!$G$5 -> 99229 | M29: =TRUNC(L29*$D29,0) -> 167697
B30: 계 | G30: =SUM(G27:G29) -> 2076866.9 | I30: =SUM(I27:I29) -> 0 | K30: =SUM(K27:K29) -> 1909169 | M30: =SUM(M27:M29) -> 167697
A32: =A26+1 -> 6 | B32: 부단수 할정자관 접합(강관제) | C32: 1650 | D32: 1 | E32: nr
B33: 용접공 | D33: 12.33 | E33: 인 | F33: =H33+J33+L33 -> 282536 | G33: =F33*D33 -> 3483668.9 | I33: =TRUNC(H33*$D33,0) -> 0 | J33: =노임!$D$5 -> 282536 | K33: =TRUNC(J33*$D33,0) -> 3483668 | M33: =TRUNC(L33*$D33,0) -> 0
B34: 발전기(50KW) | D34: 16.74 | E34: hr | F34: =H34+J34+L34 -> 55756 | G34: =F34*D34 -> 933355.44 | I34: =TRUNC(H34*$D34,0) -> 0 | K34: =TRUNC(J34*$D34,0) -> 0 | L34: =경비!$G$8 -> 55756 | M34: =TRUNC(L34*$D34,0) -> 933355
B35: 용접기(200AMP) | D35: 33.48 | E35: hr | F35: =H35+J35+L35 -> 92 | G35: =F35*D35 -> 3080.16 | I35: =TRUNC(H35*$D35,0) -> 0 | K35: =TRUNC(J35*$D35,0) -> 0 | L35: =경비!$G$9 -> 92 | M35: =TRUNC(L35*$D35,0) -> 3080
B36: 용접봉(3.2㎜ KSE4301) | D36: 39.36 | E36: kg | F36: =H36+J36+L36 -> 4900 | G36: =F36*D36 -> 192864 | H36: =자재!$D$3 -> 4900 | I36: =TRUNC(H36*$D36,0) -> 192864 | K36: =TRUNC(J36*$D36,0) -> 0 | M36: =TRUNC(L36*$D36,0) -> 0
B37: 계 | G37: =SUM(G33:G36) -> 4612968.5 | I37: =SUM(I33:I36) -> 192864 | K37: =SUM(K33:K36) -> 3483668 | M37: =SUM(M33:M36) -> 936435
A39: =A32+1 -> 7 | B39: 부단수 할정자관 접합부 도장 | C39: 1650 | D39: 1 | E39: nr
B40: 도장공 | D40: 1.04 | E40: 인 | F40: =H40+J40+L40 -> 263017 | G40: =F40*D40 -> 273537.68 | I40: =TRUNC(H40*$D40,0) -> 0 | J40: =노임!$D$6 -> 263017 | K40: =TRUNC(J40*$D40,0) -> 273537 | M40: =TRUNC(L40*$D40,0) -> 0
B41: 보통인부 | D41: 0.34 | E41: 인 | F41: =H41+J41+L41 -> 172068 | G41: =F41*D41 -> 58503.12 | I41: =TRUNC(H41*$D41,0) -> 0 | J41: =노임!$D$4 -> 172068 | K41: =TRUNC(J41*$D41,0) -> 58503 | M41: =TRUNC(L41*$D41,0) -> 0
B42: 액상접착제 | C42: (16.8kg/18.9ℓ) CAN | D42: 1.3 | E42: kg | F42: =H42+J42+L42 -> 20746.667 | G42: =F42*D42 -> 26970.667 | H42: =자재!$D$5 -> 20746.667 | I42: =TRUNC(H42*$D42,0) -> 26970 | K42: =TRUNC(J42*$D42,0) -> 0 | M42: =TRUNC(L42*$D42,0) -> 0
B43: 매스틱 | C43: 3T x 40 x 6m | D43: 11.58 | E43: m | F43: =H43+J43+L43 -> 2800 | G43: =F43*D43 -> 32424 | H43: =자재!$D$6 -> 2800 | I43: =TRUNC(H43*$D43,0) -> 32424 | K43: =TRUNC(J43*$D43,0) -> 0 | M43: =TRUNC(L43*$D43,0) -> 0
B44: 안쪽층테이프 | C44: 0.508㎜ x 100㎜ x 30m | D44: 10.94 | E44: ㎡ | F44: =H44+J44+L44 -> 773.33333 | G44: =F44*D44 -> 8460.2667 | H44: =자재!$D$7 -> 773.33333 | I44: =TRUNC(H44*$D44,0) -> 8460 | K44: =TRUNC(J44*$D44,0) -> 0 | M44: =TRUNC(L44*$D44,0) -> 0
B45: 바깥층테이프 | C45: 0.381㎜ x 100㎜ x 30m | D45: 10.94 | E45: ㎡ | F45: =H45+J45+L45 -> 740 | G45: =F45*D45 -> 8095.6 | H45: =자재!$D$8 -> 740 | I45: =TRUNC(H45*$D45,0) -> 8095 | K45: =TRUNC(J45*$D45,0) -> 0 | M45: =TRUNC(L45*$D45,0) -> 0
B46: 계 | G46: =SUM(G40:G45) -> 407991.33 | I46: =SUM(I40:I45) -> 75949 | K46: =SUM(K40:K45) -> 332040 | M46: =SUM(M40:M41) -> 0
...

Sheet 중기사용료목록
A1: 중기사용료목록
A2: 공 종 명 | B2: 규 격 | C2: 수 량 | D2: 단 위 | E2: 재 료 비 | F2: 노 무 비 | G2: 경 비 | H2: 합 계 | I2: 비 고
A3: 부단수 천공기 손료 | B3: 차단관경, D80x80mm | C3: 1 | D3: hr | F3: 0 | G3: =중기사용료!$G$12 -> 41739 | H3: =E3+F3+G3 -> 41739
A4: 부단수 천공기 손료 | B4: 차단관경, D100x100mm | C4: 1 | D4: hr | F4: 0 | G4: =중기사용료!$G$24 -> 40406 | H4: =E4+F4+G4 -> 40406
A5: 부단수 천공기 손료 | B5: 차단관경, D150x150mm | C5: 1 | D5: hr | F5: 0 | G5: =중기사용료!$G$36 -> 152731 | H5: =E5+F5+G5 -> 152731
A6: 부단수 천공기 손료 | B6: 차단관경, D200x200mm | C6: 1 | D6: hr | F6: 0 | G6: =중기사용료!$G$48 -> 111969 | H6: =E6+F6+G6 -> 111969
A7: 부단수 천공기 손료 | B7: 차단관경, D250x250mm | C7: 1 | D7: hr | F7: 0 | G7: =중기사용료!$G$60 -> 105504 | H7: =E7+F7+G7 -> 105504
A8: 부단수 천공기 손료 | B8: 차단관경, D300x300mm | C8: 1 | D8: hr | F8: 0 | G8: =중기사용료!$G$72 -> 100084 | H8: =E8+F8+G8 -> 100084
A9: 부단수 천공기 손료 | B9: 차단관경, D350x350mm | C9: 1 | D9: hr | F9: 0 | G9: =중기사용료!$G$84 -> 84364 | H9: =E9+F9+G9 -> 84364
A10: 부단수 천공기 손료 | B10: 차단관경, D400x400mm | C10: 1 | D10: hr | F10: 0 | G10: =중기사용료!$G$96 -> 86124 | H10: =E10+F10+G10 -> 86124
A11: 부단수 천공기 손료 | B11: 차단관경, D450x400mm | C11: 1 | D11: hr | F11: 0 | G11: =중기사용료!$G$108 -> 84660 | H11: =E11+F11+G11 -> 84660
A12: 부단수 천공기 손료 | B12: 차단관경, D500x400mm | C12: 1 | D12: hr | G12: =중기사용료!$G$119 -> 83304 | H12: =E12+F12+G12 -> 83304
A13: 부단수 천공기 손료 | B13: 차단관경, D600x400mm | C13: 1 | D13: hr | G13: =중기사용료!$G$130 -> 80628 | H13: =E13+F13+G13 -> 80628
A14: 부단수 천공기 손료 | B14: 차단관경, D700x600mm | C14: 1 | D14: hr | G14: 97785 | H14: =E14+F14+G14 -> 97785
A15: 부단수 천공기 손료 | B15: 차단관경, D800x600mm | C15: 1 | D15: hr | G15: 94483 | H15: =E15+F15+G15 -> 94483
A16: 부단수 천공기 손료 | B16: 차단관경, D900x600mm | C16: 1 | D16: hr | G16: 91123 | H16: =E16+F16+G16 -> 91123
A17: 부단수 천공기 손료 | B17: 차단관경, D1000x900mm | C17: 1 | D17: hr | G17: 75054 | H17: =E17+F17+G17 -> 75054
A18: 부단수 천공기 손료 | B18: 차단관경, D1100x900mm | C18: 1 | D18: hr | G18: 71241 | H18: =E18+F18+G18 -> 71241
A19: 부단수 천공기 손료 | B19: 차단관경, D1200x900mm | C19: 1 | D19: hr | G19: 70528 | H19: =E19+F19+G19 -> 70528
A20: 부단수 천공기 손료 | B20: 차단관경, D1350x900mm | C20: 1 | D20: hr | G20: 68191 | H20: =E20+F20+G20 -> 68191
A21: 부단수 천공기 손료 | B21: 차단관경, D1500x1200mm | C21: 1 | D21: hr | G21: 278152 | H21: =E21+F21+G21 -> 278152
A22: 부단수 천공기 손료 | B22: 차단관경, D1650x1200mm | C22: 1 | D22: hr | G22: 271657 | H22: =E22+F22+G22 -> 271657
A23: 부단수 천공기 손료 | B23: 차단관경, D1800x1200mm | C23: 1 | D23: hr | G23: 260489 | H23: =E23+F23+G23 -> 260489
A24: 부단수 천공기 손료 | B24: 차단관경, D2000x1650mm | C24: 1 | D24: hr | G24: 336664 | H24: =E24+F24+G24 -> 336664
A25: 부단수 천공기 손료 | B25: 차단관경, D2100x1650mm | C25: 1 | D25: hr | G25: 330427 | H25: =E25+F25+G25 -> 330427
... A31: 칩제거기 손료 | B31: 차단관경, D150x150mm | C31: 1 | D31: hr | G31: 3512 | H31: =E31+F31+G31 -> 3512
A32: 칩제거기 손료 | B32: 차단관경, D200x200mm | C32: 1 | D32: hr | F32: 0 | G32: 2659 | H32: =E32+F32+G32 -> 2659
A33: 칩제거기 손료 | B33: 차단관경, D250x250mm | C33: 1 | D33: hr | F33: 0 | G33: 3481 | H33: =E33+F33+G33 -> 3481
A34: 칩제거기 손료 | B34: 차단관경, D300x300mm | C34: 1 | D34: hr | F34: 0 | G34: 3753 | H34: =E34+F34+G34 -> 3753
A35: 칩제거기 손료 | B35: 차단관경, D350x350mm | C35: 1 | D35: hr | F35: 0 | G35: 4429 | H35: =E35+F35+G35 -> 4429
A36: 칩제거기 손료 | B36: 차단관경, D400x400mm | C36: 1 | D36: hr | F36: 0 | G36: 2153 | H36: =E36+F36+G36 -> 2153
A37: 칩제거기 손료 | B37: 차단관경, D450x400mm | C37: 1 | D37: hr | F37: 0 | G37: 2116 | H37: =E37+F37+G37 -> 2116
A38: 칩제거기 손료 | B38: 차단관경, D500x400mm | C38: 1 | D38: hr | F38: 0 | G38: 2082 | H38: =E38+F38+G38 -> 2082
A39: 칩제거기 손료 | B39: 차단관경, D600x400mm | C39: 1 | D39: hr | F39: 0 | G39: 2015 | H39: =E39+F39+G39 -> 2015
A40: 칩제거기 손료 | B40: 차단관경, D700x600mm | C40: 1 | D40: hr | F40: 0 | G40: 3116 | H40: =E40+F40+G40 -> 3116
A41: 칩제거기 손료 | B41: 차단관경, D800x600mm | C41: 1 | D41: hr | F41: 0 | G41: 3011 | H41: =E41+F41+G41 -> 3011
A42: 칩제거기 손료 | B42: 차단관경, D900x600mm | C42: 1 | D42: hr | F42: 0 | G42: 2904 | H42: =E42+F42+G42 -> 2904
A43: 칩제거기 손료 | B43: 차단관경, D1000x900mm | C43: 1 | D43: hr | F43: 0 | G43: 3844 | H43: =E43+F43+G43 -> 3844
... A132: 샌드위치 밸브 | B132: D2400x1650mm | C132: 1 | D132: hr | F132: 0 | G132: 145756 | H132: =E132+F132+G132 -> 145756

Sheet 중기사용료
A1: 중기사용료
A3: 중 기 명 | B3: 부단수 천공기 손료 차단관경, D80x80mm
A4: 중기가격 | B4: 11,520 천원
A5: 명 칭 | C5: 규 격 | D5: 수 량 | E5: 단 위 | F5: 단 가 | G5: 금 액 | H5: 비 고
A6: 경 비 | B6: 부단수 천공기 | C6: D80x80mm | D6: 3.6232 | E6: 천원 | F6: =중기기초자료!G37 -> 11520 | G6: =TRUNC(F6*D6, 1) -> 41739.2
B7: 소 계 | G7: =TRUNC(G6, 0) -> 41739
A8: 재 료 비
B9: 소 계
A10: 노 무 비
B11: 소 계
B12: 총 계 | G12: =TRUNC(G7+G9+G11, 0) -> 41739
A15: 중 기 명 | B15: 부단수 천공기 손료 차단관경, D100x100mm
A16: 중기가격 | B16: 11,520 천원
A17: 명 칭 | C17: 규 격 | D17: 수 량 | E17: 단 위 | F17: 단 가 | G17: 금 액 | H17: 비 고
A18: 경 비 | B18: 부단수 천공기 | C18: D100x100mm | D18: 3.5075 | E18: 천원 | F18: =중기기초자료!G38 -> 11520 | G18: =TRUNC(F18*D18, 1) -> 40406.4
B19: 소 계 | G19: =TRUNC(G18, 0) -> 40406
A20: 재 료 비
B21: 소 계
A22: 노 무 비
B23: 소 계
B24: 총 계 | G24: =TRUNC(G19+G21+G23, 0) -> 40406
A27: 중 기 명 | B27: 부단수 천공기 손료 차단관경, D150x150mm
A28: 중기가격 | B28: 48,000 천원
A29: 명 칭 | C29: 규 격 | D29: 수 량 | E29: 단 위 | F29: 단 가 | G29: 금 액 | H29: 비 고
A30: 경 비 | B30: 부단수 천공기 | C30: D150x150mm | D30: 3.1819 | E30: 천원 | F30: =중기기초자료!G39 -> 48000 | G30: =TRUNC(F30*D30, 1) -> 152731.2
B31: 소 계 | G31: =TRUNC(G30, 0) -> 152731
A32: 재 료 비
B33: 소 계
A34: 노 무 비
B35: 소 계
B36: 총 계 | G36: =TRUNC(G31+G33+G35, 0) -> 152731
A39: 중 기 명 | B39: 부단수 천공기 손료 차단관경, D200x200mm
A40: 중기가격 | B40: 48,000 천원
A41: 명 칭 | C41: 규 격 | D41: 수 량 | E41: 단 위 | F41: 단 가 | G41: 금 액 | H41: 비 고
A42: 경 비 | B42: 부단수 천공기 | C42: D200x200mm | D42: 2.3327 | E42: 천원 | F42: =중기기초자료!G40 -> 48000 | G42: =TRUNC(F42*D42, 1) -> 111969.6
B43: 소 계 | G43: =TRUNC(G42, 0) -> 111969
A44: 재 료 비
B45: 소 계
A46: 노 무 비
B47: 소 계
...

Sheet 중기기초자료
A1: 중기기초자료
A2: 명 칭 | B2: 규 격 | C2: 단 위 | D2: 합 계 | E2: 노 무 비 | F2: 재 료 비 | G2: 경 비 | H2: 비 고
A3: 트럭탑제형 크레인 | B3: 5 TON | C3: HR | D3: =E3+F3+G3 -> 69255 | E3: 49698 | F3: 8440 | G3: 11117 | H3: 26년적산단가/765
A4: 트럭탑제형 크레인 | B4: 10 TON | C4: HR | D4: =E4+F4+G4 -> 90538 | E4: 49698 | F4: 17045 | G4: 23795 | H4: 26년적산단가/765
A5: 트럭탑제형 크레인 | B5: 15 TON | C5: HR | D5: =E5+F5+G5 -> 99229 | E5: 49698 | F5: 18204 | G5: 31327 | H5: 26년적산단가/765
A6: 트럭탑제형 크레인 | B6: 18 TON | C6: HR | D6: =E6+F6+G6 -> 101726 | E6: 49698 | F6: 18700 | G6: 33328 | H6: 26년적산단가/765
A7: 무한궤도 크레인 | B7: 20 ton (0.57 ㎥) | C7: HR | D7: =E7+F7+G7 -> 99933 | E7: 58925 | F7: 14232 | G7: 26776 | H7: 26년적산단가/762
A8: 발전기 | B8: 50 kw | C8: HR | D8: =E8+F8+G8 -> 55756 | E8: 36190 | F8: 14877 | G8: 4689 | H8: 26년적산단가/793
A9: 용접기 (교류) | B9: 200 amP | C9: HR | D9: =E9+F9+G9 -> 92 | E9: 0 | F9: 0 | G9: 92 | H9: 26년적산단가/794
A10: 상수도관 천공기 | C10: HR | D10: =E10+F10+G10 -> 597 | G10: 597 | H10: 26년적산단가/790
A11: 칩제거기 | B11: D80x80mm | C11: 천원 | D11: 420 | E11: 0 | F11: 0 | G11: 420 | H11: 수자원적산지침 토목공사 8차/153P
A12: 칩제거기 | B12: D100x100mm | C12: 천원 | D12: 900 | E12: 0 | F12: 0 | G12: 900 | H12: 수자원적산지침 토목공사 8차/153P
A13: 칩제거기 | B13: D150x150mm | C13: 천원 | D13: 1104 | E13: 0 | F13: 0 | G13: 1104 | H13: 수자원적산지침 토목공사 8차/153P
A14: 칩제거기 | B14: D200x200mm | C14: 천원 | D14: 1140 | E14: 0 | F14: 0 | G14: 1140 | H14: 수자원적산지침 토목공사 8차/153P
A15: 칩제거기 | B15: D250x250mm | C15: 천원 | D15: 1584 | E15: 0 | F15: 0 | G15: 1584 | H15: 수자원적산지침 토목공사 8차/153P
A16: 칩제거기 | B16: D300x300mm | C16: 천원 | D16: 1800 | E16: 0 | F16: 0 | G16: 1800 | H16: 수자원적산지침 토목공사 8차/153P
A17: 칩제거기 | B17: D350x350mm | C17: 천원 | D17: 2520 | E17: 0 | F17: 0 | G17: 2520 | H17: 수자원적산지침 토목공사 8차/153P
A18: 칩제거기 | B18: D400x400mm | C18: 천원 | D18: 3000 | E18: 0 | F18: 0 | G18: 3000 | H18: 수자원적산지침 토목공사 8차/153P
A19: 칩제거기 | B19: D450x400mm | C19: 천원 | D19: 3000 | E19: 0 | F19: 0 | G19: 3000 | H19: 수자원적산지침 토목공사 8차/153P
A20: 칩제거기 | B20: D500x400mm | C20: 천원 | D20: 3000 | E20: 0 | F20: 0 | G20: 3000 | H20: 수자원적산지침 토목공사 8차/153P
A21: 칩제거기 | B21: D600x400mm | C21: 천원 | D21: 3000 | E21: 0 | F21: 0 | G21: 3000 | H21: 수자원적산지침 토목공사 8차/153P
A22: 칩제거기 | B22: D700x600mm | C22: 천원 | D22: 6120 | E22: 0 | F22: 0 | G22: 6120 | H22: 수자원적산지침 토목공사 8차/153P
... A112: 샌드위치 밸브 | B112: D1650mm | C112: 천원 | D112: 130000 | E112: 0 | F112: 0 | G112: 130000 | H112: 수자원적산지침 토목공사 8차/153P

Sheet 자재
A1: 자재
A2: 명 칭 | B2: 규 격 | C2: 단 위 | D2: 단 가 | E2: 비 고
A3: 용접봉 | B3: (고장력강용)(3.2㎜) | C3: EA | D3: 4900 | E3: (26년)물가자료 상/ 1387
A4: 연마지 | B4: #180 | C4: EA | D4: 340 | E4: (26년)물가자료 상 / 1412
A5: 액상접착제 | B5: 1kg 기준 | C5: kg | D5: =311200/15 -> 20746.667 | E5: (26년)물가자료 상 / 723
A6: 매스틱 | B6: 3T x 40 x 1m | C6: EA | D6: =16800/6 -> 2800 | E6: (26년)물가자료 상 / 723
A7: 안쪽층테이프 | B7: 0.508mm x 100mm x 1m | C7: EA | D7: =23200/30 -> 773.33333 | E7: (26년)물가자료 상 / 723
A8: 바깥층테이프 | B8: 0.381mm x 100mm x 1m | C8: EA | D8: =22200/30 -> 740 | E8: (26년)물가자료 상 / 723
A9: 경유 | B9: 저유황 0.001% | C9: L | D9: 1596 | E9: (26년)물가자료 하 / 32

Sheet 노임
A1: 노임 | E1: 26년도 상반기(대한건설협회 시중노임)
A2: 명 칭 | B2: 규 격 | C2: 단 위 | D2: 단 가 | E2: 비 고
A3: 방수공 | B3: 일반공사 직종 | C3: 인 | D3: 228286
A4: 보통인부 | B4: 일반공사 직종 | C4: 인 | D4: 172068
A5: 용접공 | B5: 일반공사 직종 | C5: 인 | D5: 282536
A6: 도장공 | B6: 일반공사 직종 | C6: 인 | D6: 263017
A7: 일반기계운전사 | B7: 일반공사 직종 | C7: 인 | D7: 173995
A8: 배관공(수도) | B8: 일반공사 직종 | C8: 인 | D8: 262580
A9: 플랜트기계설치공 | B9: 일반공사 직종 | C9: 인 | D9: 230376
A10: 플랜트배관공 | B10: 일반공사 직종 | C10: 인 | D10: 320480
A11: 플랜트용접공 | B11: 일반공사 직종 | C11: 인 | D11: 292640
A12: 고급기술자 | B12: 기계 설비 | C12: 인 | D12: 335379 | E12: 26년 한국엔지니어링협회
A13: 고급품질관리원 | B13: 일반공사 직종 | C13: 인 | D13: 197788

Sheet 경비
A1: 경비
A2: 명 칭 | B2: 규 격 | C2: 단 위 | D2: 재 료 비 | E2: 노 무 비 | F2: 경 비 | G2: 합 계 | H2: 비 고
A3: 트럭탑제형 크레인 | B3: 5 TON | C3: HR | D3: =중기기초자료!F3 -> 8440 | E3: =중기기초자료!E3 -> 49698 | F3: =중기기초자료!G3 -> 11117 | G3: =D3+E3+F3 -> 69255
A4: 트럭탑제형 크레인 | B4: 10 TON | C4: HR | D4: =중기기초자료!F4 -> 17045 | E4: =중기기초자료!E4 -> 49698 | F4: =중기기초자료!G4 -> 23795 | G4: =D4+E4+F4 -> 90538
A5: 트럭탑제형 크레인 | B5: 15 TON | C5: HR | D5: =중기기초자료!F5 -> 18204 | E5: =중기기초자료!E5 -> 49698 | F5: =중기기초자료!G5 -> 31327 | G5: =D5+E5+F5 -> 99229
A6: 트럭탑제형 크레인 | B6: 18 TON | C6: HR | D6: =중기기초자료!F6 -> 18700 | E6: =중기기초자료!E6 -> 49698 | F6: =중기기초자료!G6 -> 33328 | G6: =D6+E6+F6 -> 101726
A7: 무한궤도 크레인 | B7: 20 ton (0.57 ㎥) | C7: HR | D7: =중기기초자료!F7 -> 14232 | E7: =중기기초자료!E7 -> 58925 | F7: =중기기초자료!G7 -> 26776 | G7: =D7+E7+F7 -> 99933
A8: 발전기 | B8: 50 KW | C8: HR | D8: =중기기초자료!F8 -> 14877 | E8: =중기기초자료!E8 -> 36190 | F8: =중기기초자료!G8 -> 4689 | G8: =D8+E8+F8 -> 55756
A9: 용접기 (교류) | B9: 200 AMP | C9: HR | D9: =중기기초자료!F9 -> 0 | E9: =중기기초자료!E9 -> 0 | F9: =중기기초자료!G9 -> 92 | G9: =D9+E9+F9 -> 92
A10: 상수도관 천공기 | C10: HR | D10: =중기기초자료!F10 -> 0 | E10: =중기기초자료!E10 -> 0 | F10: =중기기초자료!G10 -> 597 | G10: =D10+E10+F10 -> 597
A11: 장비운반비 | B11: D1650mm(안산-광양) | C11: nr | F11: 5500000 | G11: =D11+E11+F11 -> 5500000
A12: 장비운반비 | B12: D900mm(안산-광양) | C12: nr | F12: 3380000 | G12: =D12+E12+F12 -> 3380000

Sheet 자재조서
A1: 자재조서 | O1: 00년도 00월
A2: 코 드 | B2: 명 칭 | C2: 규 격 | D2: 단위 | E2: 견적단가 | G2: 물가정보 | I2: 물가자료 | K2: 거래가격 | M2: 유통물가 | O2: 적용단가
E3: 단가 | F3: Page | G3: 단가 | H3: Page | I3: 단가 | J3: Page | K3: 단가 | L3: Page | M3: 단가 | N3: Page

Sheet 자재견적서
B2: 견 적 서
B5: 문 서 번 호 | Q5: 공 급 자 | S5: 등록번호 | V5: 140-81-34127
B6: 수 신 | G6: K-water | S6: 상 호 | V6: (주)대호스토퍼 | AB6: 대표 | AE6: 이 영 호 | AI6: (인)
S7: 소 재 지 | V7: 경기도 안산시 상록구 남산평길 126-4(팔곡일동)
B8: 담 당 자 | O8: 귀중 | S8: 업 태 | V8: 제조업 외 | AB8: 종목 | AE8: 상하수도설비공사 외
B9: 연 락 처 | S9: 회사전화 | V9: 031-496-9488 | AB9: 회사팩스 | AE9: 031-496-9349
B10: 작 성 일 | G10: 46134 | S10: 담 당 자 | V10: 백승리 차장 | AB10: 휴대전화 | AE10: 010-5013-7776
B11: 유 효 기 간 | G11: 12개월 | S11: E-Mail | V11: dhcstopper@hanmail.net
B12: 견 적 명 | G12: 광양산단 비상 공급시설 설치사업 중 부단수 차단 자재
B14: 합 계 금 액 | G14: 일금 | I14: =W14 -> 294573480 | T14: 원정 | V14: ( | W14: =AA36 -> 294573480 | AE14: ) | AF14: (VAT 별도)
B16: 아래와 같이 견적을 제출합니다.
B17: 번호 | D17: 품 명 | K17: 규 격 | Q17: 단위 | S17: 수량 | U17: 단 가 | AA17: 금 액 | AG17: 비고
B18: 1 | D18: 부단수 할정자관 (상,하판 1Set) | K18: D1,650㎜ | Q18: EA | S18: 4 | U18: 24000000 | AA18: =U18*S18 -> 96000000 | AR18: =U18 -> 24000000
B19: 2 | D19: 플랜지접합부속 (가스켓, 볼트/너트등) | K19: D1,200㎜ | Q19: EA | S19: 24 | U19: 550910 | AA19: =U19*S19 -> 13221840 | AR19: =U19 -> 550910
B20: 3 | D20: 컷터 | K20: D1,200㎜ | Q20: EA | S20: 4 | U20: 6800000 | AA20: =U20*S20 -> 27200000 | AR20: =U20 -> 6800000
B21: 4 | D21: 드릴 | K21: D1,200㎜ | Q21: EA | S21: 4 | U21: 960000 | AA21: =U21*S21 -> 3840000 | AR21: =U21 -> 960000
B22: 5 | D22: Seailng Element | K22: D1,650㎜ | Q22: EA | S22: 4 | U22: 17000000 | AA22: =U22*S22 -> 68000000 | AR22: =U22 -> 17000000
B23: 6 | D23: 플러그(천공관용) | K23: D1,200㎜ | Q23: EA | S23: 4 | U23: 9000000 | AA23: =U23*S23 -> 36000000 | AR23: =U23 -> 9000000
B24: 7 | D24: 마개플랜지 | K24: D1,200㎜ | Q24: EA | S24: 4 | U24: 2129000 | AA24: =U24*S24 -> 8516000 | AR24: =U24 -> 2129000
B25: 8 | D25: 부단수 할정자관 (상,하판 1Set) | K25: D900㎜ | Q25: EA | S25: 2 | U25: 8200000 | AA25: =U25*S25 -> 16400000 | AR25: =U25 -> 8200000
B26: 9 | D26: 플랜지접합부속 (가스켓, 볼트/너트등) | K26: D600㎜ | Q26: EA | S26: 12 | U26: 48970 | AA26: =U26*S26 -> 587640 | AR26: =U26 -> 48970
B27: 10 | D27: 컷터 | K27: D600㎜ | Q27: EA | S27: 2 | U27: 1680000 | AA27: =U27*S27 -> 3360000 | AR27: =U27 -> 1680000
B28: 11 | D28: 드릴 | K28: D600㎜ | Q28: EA | S28: 2 | U28: 384000 | AA28: =U28*S28 -> 768000 | AR28: =U28 -> 384000
B29: 12 | D29: Seailng Element | K29: D900㎜ | Q29: EA | S29: 2 | U29: 5650000 | AA29: =U29*S29 -> 11300000 | AR29: =U29 -> 5650000
... B35: 25 | D35: CAP(등압관용) | K35: D100㎜ | Q35: EA | S35: 6 | U35: 30000 | AA35: =U35*S35 -> 180000 | AR35: =U35 -> 30000
B36: 합 계(TOTAL) | AA36: =SUM(AA18:AF35) -> 294573480
B37: MEMO | D37: 1. VAT 별도
H702: =자재견적서!#REF! -> #REF!

Sheet 수량산출서
A1: 공종 | B1: 산출근거 | C1: 수량

Sheet 장비운반비 산출근거
