Workbook
Name _15A: [2]가격조사서!$D$4:$D$11
Name _B22: [3]일위대가!$1400:$1413=[3]일위대가!$A$1400
Name _DAN2: [4]단가조사서!$M$1:$N$65536
Name _JIP1: [4]집계표!$A$1:$K$65536
Name _K02: [3]일위대가!$732:$745=[3]일위대가!$A$732
Name _O03: [3]일위대가!$1516:$1529=[3]일위대가!$A$1516
Name _QTY1: [7]SHEET2!$F$3:$F$101
Name _RAN5: [8]토목품셈!$D$1:$AI$146
Name _RAN6: [8]토목품셈!$BO$1:$BZ$25
Name _RAN7: [8]토목품셈!$CB$1:$CJ$24
Name ABCD: [9]CABdata!$E$22:$F$46
Name A노임단가: '[10]노무비(DB)'!$A$1:$D$208
Name bdfgdgr: [11]!Macro8
Name bdfgdgr: [11]!Macro8
Name bdfgdgr: [11]!Macro8
Name BLDG: [12]LEGEND!$D$8
Name CABDIA: [9]MOTOR!$A$86:$B$408
Name CABLEA: [9]MOTOR!$B$66:$C$82
Name CABLEB: [9]MOTOR!$D$66:$E$82
Name CABLED: [9]MOTOR!$F$66:$G$82
Name CABLEE: [9]MOTOR!$H$66:$I$82
Name CAB허용: [9]MOTOR!$J$66:$N$81
Name cds: 자재견적서!cds
Name cds: [0]!cds
Name cds가로등: 자재견적서!cds가로등
Name cds가로등: [0]!cds가로등
Name CIRCUIT: [13]Sheet1!$C$4:$D$10
Name CLIENT: [12]LEGEND!$D$6
Name CTC: [14]DATA!$H$30:$I$57
Name DANGA_: '[15]Y-WORK'!$D$19:$D$19,'[15]Y-WORK'!$F$19:$BD$19
Name DAT: [16]MCC제원!$A$5:$AG$80
Name ddd가로등: 자재견적서!ddd가로등
Name ddd가로등: [0]!ddd가로등
Name dfffffs: 자재견적서!dfffffs
Name dfffffs: [0]!dfffffs
Name dffffs가로등: 자재견적서!dffffs가로등
Name dffffs가로등: [0]!dffffs가로등
Name dfs가로등: 자재견적서!dfs가로등
Name dfs가로등: [0]!dfs가로등
Name df가로등: 자재견적서!df가로등
Name df가로등: [0]!df가로등
Name DGS: [17]data!$S$4:$T$32
Name EJ: [18]소비자가!$I$46:$J$1593
Name EssAliasTable: "Default"
Name EssOptions: "A1100000000130001000001100000_0000"
Name hidden: [20]TABLE!$H$1,[20]TABLE!$J$1,[20]TABLE!$K$1
Name HIT: '[21]2F 회의실견적(5_14 일대)'!$J$31
Name IEC: '[16]허용전류-IEC DATA'!$A$1:$E$352
Name ilch: [22]ilch!$A$3:$M$25
Name JODO: [17]data!$AA$4:$AE$14
Name KO: '[23]D-RMIL'!$B$7:$C$19
Name KYNGSADO: [24]!KYNGSADO
Name KYNGSADO: [24]!KYNGSADO
Name KYNGSADO: [24]!KYNGSADO
Name KYNGSAYL: [25]!KYNGSAYL
Name KYNGSAYL: [25]!KYNGSAYL
Name KYNGSAYL: [25]!KYNGSAYL
Name LI: [26]Sheet2!$A$2:$B$48
Name list1: '[27]일위대가(원본)'!$A$159:$Q$1426
Name ListItem01: [28]발신정보!$C$4

Sheet 견적서
B2: 견 적 서
B5: 문 서 번 호 | G5: DH18-260508-01 | U5: 공 급 자 | W5: 등록번호 | Z5: 140-81-34127
B6: 수 신 | G6: 한국토지주택공사 | W6: 상 호 | Z6: (주)대호스토퍼 | AG6: 대표 | AJ6: 이 영 호 | AP6: (인)
W7: 소 재 지 | Z7: 경기도 안산시 단원구 시우로 114(초지동)
B8: 담 당 자 | S8: 귀중 | W8: 업 태 | Z8: 제조업 외 | AG8: 종목 | AJ8: 상하수도설비공사 외
B9: 연 락 처 | W9: 회사전화 | Z9: 031-496-9488 | AG9: 회사팩스 | AJ9: 031-496-9349
B10: 작 성 일 | G10: 46150 | W10: 담 당 자 | Z10: 백승리 차장 | AG10: 휴대전화 | AJ10: 010-5013-7776
B11: 유 효 기 간 | G11: 12개월 | W11: E-Mail | Z11: dhcstopper@hanmail.net
B12: 견 적 명 | G12: 광명하안2 공공주택지구 조성공사 중 부단수 차단
B14: 합 계 금 액 | G14: 일금 | I14: =AB14 -> 434402276 | Y14: 원정 | AA14: ( | AB14: =AJ34 -> 434402276 | AL14: ) | AM14: (VAT별도)
B16: 아래와 같이 견적을 제출합니다.
B17: 품 명 | G17: 규 격 | L17: 수량 | N17: 단 위 | P17: 재 료 비 | U17: 노 무 비 | Z17: 경 비 | AE17: 소 계 | AJ17: 금 액 | AO17: 비고
B18: 부단수 차단 | G18: 600 | L18: 4 | N18: EA | P18: ='내역서(600)'!H5 -> 11814348 | U18: ='내역서(600)'!J5 -> 4313849 | Z18: ='내역서(600)'!L5 -> 5928981 | AE18: =P18+U18+Z18 -> 22057178 | AJ18: =AE18*L18 -> 88228712 | AO18: 주철관제
B19: 부단수 차단 | G19: 700 | L19: 4 | N19: EA | P19: ='내역서(700)'!H5 -> 17790853 | U19: ='내역서(700)'!J5 -> 6225792 | Z19: ='내역서(700)'!L5 -> 8067650 | AE19: =P19+U19+Z19 -> 32084295 | AJ19: =AE19*L19 -> 128337180 | AO19: 주철관제
B20: 부단수 차단 | G20: 1000 | L20: 4 | N20: EA | P20: ='내역서(1000)'!H5 -> 30135868 | U20: ='내역서(1000)'!J5 -> 11847041 | Z20: ='내역서(1000)'!L5 -> 12476187 | AE20: =P20+U20+Z20 -> 54459096 | AJ20: =AE20*L20 -> 217836384 | AO20: 강관제
B33: ⓓ 단수정리
B34: (ⓐ+ⓑ+ⓒ) 공급가액 | AJ34: =SUM(AJ18:AN33) -> 434402276
B35: MEMO | D35: 1. 토공, 가시설공, 피팅부 관보호공등 부단수 차단 외 공종에 대한 공통 공사비 제외 2. '26년 기준 단가 적용 3. 납품방법 : 현장설치도

Sheet 내역서(600)
B1: 부단수 차단공사 설계서
B2: <순공사비내역서>
B3: 공 종 명 | D3: 규 격 | E3: 수량 | F3: 단위 | G3: 재 료 비 | I3: 노 무 비 | K3: 경 비 | M3: 합 계 | O3: 비 고
G4: 단 가 | H4: 금 액 | I4: 단 가 | J4: 금 액 | K4: 단 가 | L4: 금 액 | M4: 단 가 | N4: 금 액
C5: 라인스토핑(주철관제) | D5: 600 | H5: =SUM(H6:H17) -> 11814348 | J5: =SUM(J6:J17) -> 4313849 | L5: =SUM(L6:L17) -> 5928981 | N5: =H5+J5+L5 -> 22057178
B6: 1 | C6: 바탕처리(주철관제) | D6: 600 | E6: 1 | F6: nr | G6: =H25 -> 231 | H6: =TRUNC(G6*$E6,0) -> 231 | I6: =J25 -> 57413 | J6: =TRUNC(I6*$E6,0) -> 57413 | K6: =L25 -> 323 | L6: =TRUNC(K6*$E6,0) -> 323 | M6: =G6+I6+K6 -> 57967 | N6: =H6+J6+L6 -> 57967 | O6: =B31 -> 3
B7: 2 | C7: 부단수 할정자관 부설 및 접합(주철관제) | D7: 600 | E7: 1 | F7: nr | G7: =H40 -> 6155000 | H7: =TRUNC(G7*$E7,0) -> 6155000 | I7: =J40 -> 385199 | J7: =TRUNC(I7*$E7,0) -> 385199 | K7: =L40 -> 115435 | L7: =TRUNC(K7*$E7,0) -> 115435 | M7: =G7+I7+K7 -> 6655634 | N7: =H7+J7+L7 -> 6655634 | O7: =B37 -> 4
B8: 3 | C8: 샌드위치 밸브 부설 및 접합 | D8: 400 | E8: 1 | F8: nr | G8: =H52 -> 48970 | H8: =TRUNC(G8*$E8,0) -> 48970 | I8: =J52 -> 193323 | J8: =TRUNC(I8*$E8,0) -> 193323 | K8: =L52 -> 454578 | L8: =TRUNC(K8*$E8,0) -> 454578 | M8: =G8+I8+K8 -> 696871 | N8: =H8+J8+L8 -> 696871 | O8: =B48 -> 6
B9: 4 | C9: 부단수천공 분기점 분기/철거 | D9: 400 | E9: 1 | F9: nr | G9: =H73 -> 1029216 | H9: =TRUNC(G9*$E9,0) -> 1029216 | I9: =J73 -> 823684 | J9: =TRUNC(I9*$E9,0) -> 823684 | K9: =L73 -> 2903852 | L9: =TRUNC(K9*$E9,0) -> 2903852 | M9: =G9+I9+K9 -> 4756752 | N9: =H9+J9+L9 -> 4756752 | O9: =B60 -> 8
B10: 5 | C10: 등압관 설치/철거 | D10: 50 | E10: 1 | F10: nr | G10: =H126 -> 441000 | H10: =TRUNC(G10*$E10,0) -> 441000 | I10: =J126 -> 166348 | J10: =TRUNC(I10*$E10,0) -> 166348 | K10: =L126 -> 5020 | L10: =TRUNC(K10*$E10,0) -> 5020 | M10: =G10+I10+K10 -> 612368 | N10: =H10+J10+L10 -> 612368 | O10: =B119 -> 16
B11: 6 | C11: 부단수차단/철거 | D11: 600 | E11: 1 | F11: nr | G11: =H151 -> 2579644 | H11: =TRUNC(G11*$E11,0) -> 2579644 | I11: =J151 -> 1567259 | J11: =TRUNC(I11*$E11,0) -> 1567259 | K11: =L151 -> 1885345 | L11: =TRUNC(K11*$E11,0) -> 1885345 | M11: =G11+I11+K11 -> 6032248 | N11: =H11+J11+L11 -> 6032248 | O11: =B143 -> 19
B12: 7 | C12: 플러깅/철거 | D12: 400 | E12: 1 | F12: nr | G12: =H183 -> 1310317 | H12: =TRUNC(G12*$E12,0) -> 1310317 | I12: =J183 -> 283456 | J12: =TRUNC(I12*$E12,0) -> 283456 | K12: =L183 -> 306273 | L12: =TRUNC(K12*$E12,0) -> 306273 | M12: =G12+I12+K12 -> 1900046 | N12: =H12+J12+L12 -> 1900046 | O12: =B176 -> 24
B13: 8 | C13: 샌드위치 밸브 철거 | D13: 400 | E13: 1 | F13: nr | G13: =H208 -> 0 | H13: =TRUNC(G13*$E13,0) -> 0 | I13: =J208 -> 77509 | J13: =TRUNC(I13*$E13,0) -> 77509 | K13: =L208 -> 32549 | L13: =TRUNC(K13*$E13,0) -> 32549 | M13: =G13+I13+K13 -> 110058 | N13: =H13+J13+L13 -> 110058 | O13: =B204 -> 28
B14: 9 | C14: 마개플랜지 부설 및 접합 | D14: 400 | E14: 1 | F14: nr | G14: =H215 -> 249970 | H14: =TRUNC(G14*$E14,0) -> 249970 | I14: =J215 -> 106303 | J14: =TRUNC(I14*$E14,0) -> 106303 | K14: =L215 -> 14543 | L14: =TRUNC(K14*$E14,0) -> 14543 | M14: =G14+I14+K14 -> 370816 | N14: =H14+J14+L14 -> 370816 | O14: =B210 -> 29
B15: 10 | C15: 사전조사 | D15: 600 | E15: 1 | F15: nr | G15: =H230 -> 0 | H15: =TRUNC(G15*$E15,0) -> 0 | I15: =J230 -> 335379 | J15: =TRUNC(I15*$E15,0) -> 335379 | K15: =L230 -> 0 | L15: =TRUNC(K15*$E15,0) -> 0 | M15: =G15+I15+K15 -> 335379 | N15: =H15+J15+L15 -> 335379 | O15: =B228 -> 32
B16: 11 | C16: 장비운반비 | D16: 600 | E16: 1 | F16: set | G16: =H234 -> 0 | H16: =TRUNC(G16*$E16,0) -> 0 | I16: =J234 -> 0 | J16: =TRUNC(I16*$E16,0) -> 0 | K16: =L234 -> 211063 | L16: =TRUNC(K16*$E16,0) -> 211063 | M16: =G16+I16+K16 -> 211063 | N16: =H16+J16+L16 -> 211063 | O16: =B232 -> 33
B17: 12 | C17: 밸브개폐비 | D17: 400 | E17: 1 | F17: nr | G17: =H238 -> 0 | H17: =TRUNC(G17*$E17,0) -> 0 | I17: =J238 -> 317976 | J17: =TRUNC(I17*$E17,0) -> 317976 | K17: =L238 -> 0 | L17: =TRUNC(K17*$E17,0) -> 0 | M17: =G17+I17+K17 -> 317976 | N17: =H17+J17+L17 -> 317976 | O17: =B236 -> 34
B19: <일위대가표>
B20: 공 종 명 | D20: 규 격 | E20: 수량 | F20: 단위 | G20: 재 료 비 | I20: 노 무 비 | K20: 경 비 | M20: 합 계 | O20: 비 고
G21: 단 가 | H21: 금 액 | I21: 단 가 | J21: 금 액 | K21: 단 가 | L21: 금 액 | M21: 단 가 | N21: 금 액
B22: 1 | C22: 바탕처리(주철관제) | D22: 600 | E22: 1 | F22: nr
C23: 주철관 도복장 제거 | E23: 1 | F23: nr | G23: 0 | H23: =TRUNC(G23*$E23,0) -> 0 | I23: 46630 | J23: =TRUNC(I23*$E23,0) -> 46630 | K23: 0 | L23: =TRUNC(K23*$E23,0) -> 0 | M23: =G23+I23+K23 -> 46630 | N23: =H23+J23+L23 -> 46630 | O23: =B27 -> 2
C24: 표면정리 | D24: #180 | E24: 1 | F24: nr | G24: 231 | H24: =TRUNC(G24*$E24,0) -> 231 | I24: 10783 | J24: =TRUNC(I24*$E24,0) -> 10783 | K24: 323 | L24: =TRUNC(K24*$E24,0) -> 323 | M24: =G24+I24+K24 -> 11337 | N24: =H24+J24+L24 -> 11337 | O24: =B31 -> 3
C25: 계 | H25: =SUM(H23:H24) -> 231 | J25: =SUM(J23:J24) -> 57413 | L25: =SUM(L23:L24) -> 323 | N25: =H25+J25+L25 -> 57967
B27: =B22+1 -> 2 | C27: 주철관 도복장 제거 | D27: 600 | E27: 1 | F27: nr
C28: 보통인부 | E28: 0.271 | F28: 인 | H28: =TRUNC(G28*$E28,0) -> 0 | I28: 172068 | J28: =TRUNC(I28*$E28,0) -> 46630 | L28: =TRUNC(K28*$E28,0) -> 0 | M28: =G28+I28+K28 -> 172068 | N28: =H28+J28+L28 -> 46630
C29: 계 | H29: =SUM(H28:H28) -> 0 | J29: =SUM(J28:J28) -> 46630 | L29: =SUM(L28:L28) -> 0 | N29: =H29+J29+L29 -> 46630
B31: =B27+1 -> 3 | C31: 표면정리 | D31: 600 | E31: 1 | F31: nr
C32: 도장공 | E32: 0.041 | F32: 인 | H32: =TRUNC(G32*$E32,0) -> 0 | I32: 263017 | J32: =TRUNC(I32*$E32,0) -> 10783 | L32: =TRUNC(K32*$E32,0) -> 0 | M32: =G32+I32+K32 -> 263017 | N32: =H32+J32+L32 -> 10783
C33: 연마지 | D33: #180 | E33: 0.68 | F33: 매 | G33: 340 | H33: =TRUNC(G33*$E33,0) -> 231 | J33: =TRUNC(I33*$E33,0) -> 0 | L33: =TRUNC(K33*$E33,0) -> 0 | M33: =G33+I33+K33 -> 340 | N33: =H33+J33+L33 -> 231
C34: 공구손료 | D34: 도장공 인력품의 | E34: 0.03 | H34: =TRUNC(G34*$E34,0) -> 0 | J34: =TRUNC(I34*$E34,0) -> 0 | K34: 10783 | L34: =TRUNC(K34*$E34,0) -> 323 | M34: =G34+I34+K34 -> 10783 | N34: =H34+J34+L34 -> 323
C35: 계 | H35: =SUM(H32:H34) -> 231 | J35: =SUM(J32:J34) -> 10783 | L35: =SUM(L32:L34) -> 323 | N35: =H35+J35+L35 -> 11337
B37: =B31+1 -> 4 | C37: 부단수 할정자관 부설 및 접합(주철관제) | D37: 600 | E37: 1 | F37: nr
C38: 부단수 할정자관 부설(주철관제) | D38: 600 | E38: 1 | F38: nr | G38: 0 | H38: =TRUNC(G38*$E38,0) -> 0 | I38: 385199 | J38: =TRUNC(I38*$E38,0) -> 385199 | K38: 115435 | L38: =TRUNC(K38*$E38,0) -> 115435 | M38: =G38+I38+K38 -> 500634 | N38: =H38+J38+L38 -> 500634 | O38: =B42 -> 5
C39: 부단수 할정자관 | D39: 600 | E39: 1 | F39: nr | G39: 6155000 | H39: =TRUNC(G39*$E39,0) -> 6155000 | J39: =TRUNC(I39*$E39,0) -> 0 | L39: =TRUNC(K39*$E39,0) -> 0 | M39: =G39+I39+K39 -> 6155000 | N39: =H39+J39+L39 -> 6155000
C40: 계 | H40: =SUM(H38:H39) -> 6155000 | J40: =SUM(J38:J39) -> 385199 | L40: =SUM(L38:L39) -> 115435 | N40: =H40+J40+L40 -> 6655634
B42: =B37+1 -> 5 | C42: 부단수 할정자관 부설(주철관제) | D42: 600 | E42: 1 | F42: nr
C43: 배관공(수도) | E43: 1.005 | F43: 인 | H43: =TRUNC(G43*$E43,0) -> 0 | I43: 262580 | J43: =TRUNC(I43*$E43,0) -> 263892 | L43: =TRUNC(K43*$E43,0) -> 0 | M43: =G43+I43+K43 -> 262580 | N43: =H43+J43+L43 -> 263892 | Q43: 강관*1.5
C44: 보통인부 | E44: 0.705 | F44: 인 | H44: =TRUNC(G44*$E44,0) -> 0 | I44: 172068 | J44: =TRUNC(I44*$E44,0) -> 121307 | L44: =TRUNC(K44*$E44,0) -> 0 | M44: =G44+I44+K44 -> 172068 | N44: =H44+J44+L44 -> 121307
C45: 트럭탑재형크레인 | D45: 10 | E45: 1.275 | F45: hr | H45: =TRUNC(G45*$E45,0) -> 0 | J45: =TRUNC(I45*$E45,0) -> 0 | K45: 90538 | L45: =TRUNC(K45*$E45,0) -> 115435 | M45: =G45+I45+K45 -> 90538 | N45: =H45+J45+L45 -> 115435
...

Sheet 내역서(700)
B1: 부단수 차단공사 설계서
B2: <순공사비내역서>
B3: 공 종 명 | D3: 규 격 | E3: 수량 | F3: 단위 | G3: 재 료 비 | I3: 노 무 비 | K3: 경 비 | M3: 합 계 | O3: 비 고
G4: 단 가 | H4: 금 액 | I4: 단 가 | J4: 금 액 | K4: 단 가 | L4: 금 액 | M4: 단 가 | N4: 금 액
C5: 라인스토핑(주철관제) | D5: 700 | H5: =SUM(H6:H17) -> 17790853 | J5: =SUM(J6:J17) -> 6225792 | L5: =SUM(L6:L17) -> 8067650 | N5: =H5+J5+L5 -> 32084295
B6: 1 | C6: 바탕처리(주철관제) | D6: 700 | E6: 1 | F6: nr | G6: =H25 -> 282 | H6: =TRUNC(G6*$E6,0) -> 282 | I6: =J25 -> 70448 | J6: =TRUNC(I6*$E6,0) -> 70448 | K6: =L25 -> 394 | L6: =TRUNC(K6*$E6,0) -> 394 | M6: =G6+I6+K6 -> 71124 | N6: =H6+J6+L6 -> 71124 | O6: =B31 -> 3
B7: 2 | C7: 부단수 할정자관 부설 및 접합(주철관제) | D7: 700 | E7: 1 | F7: nr | G7: =H40 -> 7828000 | H7: =TRUNC(G7*$E7,0) -> 7828000 | I7: =J40 -> 740074 | J7: =TRUNC(I7*$E7,0) -> 740074 | K7: =L40 -> 84200 | L7: =TRUNC(K7*$E7,0) -> 84200 | M7: =G7+I7+K7 -> 8652274 | N7: =H7+J7+L7 -> 8652274 | O7: =B37 -> 4
B8: 3 | C8: 샌드위치 밸브 부설 및 접합 | D8: 600 | E8: 1 | F8: nr | G8: =H52 -> 136480 | H8: =TRUNC(G8*$E8,0) -> 136480 | I8: =J52 -> 345719 | J8: =TRUNC(I8*$E8,0) -> 345719 | K8: =L52 -> 636188 | L8: =TRUNC(K8*$E8,0) -> 636188 | M8: =G8+I8+K8 -> 1118387 | N8: =H8+J8+L8 -> 1118387 | O8: =B48 -> 6
B9: 4 | C9: 부단수천공 분기점 분기/철거 | D9: 600 | E9: 1 | F9: nr | G9: =H73 -> 2363365 | H9: =TRUNC(G9*$E9,0) -> 2363365 | I9: =J73 -> 1376841 | J9: =TRUNC(I9*$E9,0) -> 1376841 | K9: =L73 -> 4274817 | L9: =TRUNC(K9*$E9,0) -> 4274817 | M9: =G9+I9+K9 -> 8015023 | N9: =H9+J9+L9 -> 8015023 | O9: =B60 -> 8
B10: 5 | C10: 등압관 설치/철거 | D10: 50 | E10: 1 | F10: nr | G10: =H126 -> 441000 | H10: =TRUNC(G10*$E10,0) -> 441000 | I10: =J126 -> 166348 | J10: =TRUNC(I10*$E10,0) -> 166348 | K10: =L126 -> 5229 | L10: =TRUNC(K10*$E10,0) -> 5229 | M10: =G10+I10+K10 -> 612577 | N10: =H10+J10+L10 -> 612577 | O10: =B119 -> 16
B11: 6 | C11: 부단수차단/철거 | D11: 700 | E11: 1 | F11: nr | G11: =H151 -> 3391044 | H11: =TRUNC(G11*$E11,0) -> 3391044 | I11: =J151 -> 1962104 | J11: =TRUNC(I11*$E11,0) -> 1962104 | K11: =L151 -> 2303647 | L11: =TRUNC(K11*$E11,0) -> 2303647 | M11: =G11+I11+K11 -> 7656795 | N11: =H11+J11+L11 -> 7656795 | O11: =B143 -> 19
B12: 7 | C12: 플러깅/철거 | D12: 600 | E12: 1 | F12: nr | G12: =H183 -> 2939562 | H12: =TRUNC(G12*$E12,0) -> 2939562 | I12: =J183 -> 496549 | J12: =TRUNC(I12*$E12,0) -> 496549 | K12: =L183 -> 403725 | L12: =TRUNC(K12*$E12,0) -> 403725 | M12: =G12+I12+K12 -> 3839836 | N12: =H12+J12+L12 -> 3839836 | O12: =B176 -> 24
B13: 8 | C13: 샌드위치 밸브 철거 | D13: 600 | E13: 1 | F13: nr | G13: =H208 -> 0 | H13: =TRUNC(G13*$E13,0) -> 0 | I13: =J208 -> 138450 | J13: =TRUNC(I13*$E13,0) -> 138450 | K13: =L208 -> 38090 | L13: =TRUNC(K13*$E13,0) -> 38090 | M13: =G13+I13+K13 -> 176540 | N13: =H13+J13+L13 -> 176540 | O13: =B204 -> 28
B14: 9 | C14: 마개플랜지 부설 및 접합 | D14: 600 | E14: 1 | F14: nr | G14: =H215 -> 691120 | H14: =TRUNC(G14*$E14,0) -> 691120 | I14: =J215 -> 160272 | J14: =TRUNC(I14*$E14,0) -> 160272 | K14: =L215 -> 18006 | L14: =TRUNC(K14*$E14,0) -> 18006 | M14: =G14+I14+K14 -> 869398 | N14: =H14+J14+L14 -> 869398 | O14: =B210 -> 29
B15: 10 | C15: 사전조사 | D15: 700 | E15: 1 | F15: nr | G15: =H230 -> 0 | H15: =TRUNC(G15*$E15,0) -> 0 | I15: =J230 -> 335379 | J15: =TRUNC(I15*$E15,0) -> 335379 | K15: =L230 -> 0 | L15: =TRUNC(K15*$E15,0) -> 0 | M15: =G15+I15+K15 -> 335379 | N15: =H15+J15+L15 -> 335379 | O15: =B228 -> 32
B16: 11 | C16: 장비운반비 | D16: 700 | E16: 1 | F16: set | G16: =H234 -> 0 | H16: =TRUNC(G16*$E16,0) -> 0 | I16: =J234 -> 0 | J16: =TRUNC(I16*$E16,0) -> 0 | K16: =L234 -> 303354 | L16: =TRUNC(K16*$E16,0) -> 303354 | M16: =G16+I16+K16 -> 303354 | N16: =H16+J16+L16 -> 303354 | O16: =B232 -> 33
B17: 12 | C17: 밸브개폐비 | D17: 600 | E17: 1 | F17: nr | G17: =H238 -> 0 | H17: =TRUNC(G17*$E17,0) -> 0 | I17: =J238 -> 433608 | J17: =TRUNC(I17*$E17,0) -> 433608 | K17: =L238 -> 0 | L17: =TRUNC(K17*$E17,0) -> 0 | M17: =G17+I17+K17 -> 433608 | N17: =H17+J17+L17 -> 433608 | O17: =B236 -> 34
B19: <일위대가표>
B20: 공 종 명 | D20: 규 격 | E20: 수량 | F20: 단위 | G20: 재 료 비 | I20: 노 무 비 | K20: 경 비 | M20: 합 계 | O20: 비 고
G21: 단 가 | H21: 금 액 | I21: 단 가 | J21: 금 액 | K21: 단 가 | L21: 금 액 | M21: 단 가 | N21: 금 액
B22: 1 | C22: 바탕처리(주철관제) | D22: 700 | E22: 1 | F22: nr
C23: 주철관 도복장 제거 | E23: 1 | F23: nr | G23: 0 | H23: =TRUNC(G23*$E23,0) -> 0 | I23: 57298 | J23: =TRUNC(I23*$E23,0) -> 57298 | K23: 0 | L23: =TRUNC(K23*$E23,0) -> 0 | M23: =G23+I23+K23 -> 57298 | N23: =H23+J23+L23 -> 57298 | O23: =B27 -> 2
C24: 표면정리 | D24: #180 | E24: 1 | F24: nr | G24: 282 | H24: =TRUNC(G24*$E24,0) -> 282 | I24: 13150 | J24: =TRUNC(I24*$E24,0) -> 13150 | K24: 394 | L24: =TRUNC(K24*$E24,0) -> 394 | M24: =G24+I24+K24 -> 13826 | N24: =H24+J24+L24 -> 13826 | O24: =B31 -> 3
C25: 계 | H25: =SUM(H23:H24) -> 282 | J25: =SUM(J23:J24) -> 70448 | L25: =SUM(L23:L24) -> 394 | N25: =H25+J25+L25 -> 71124
B27: =B22+1 -> 2 | C27: 주철관 도복장 제거 | D27: 700 | E27: 1 | F27: nr
C28: 보통인부 | E28: 0.333 | F28: 인 | H28: =TRUNC(G28*$E28,0) -> 0 | I28: 172068 | J28: =TRUNC(I28*$E28,0) -> 57298 | L28: =TRUNC(K28*$E28,0) -> 0 | M28: =G28+I28+K28 -> 172068 | N28: =H28+J28+L28 -> 57298
C29: 계 | H29: =SUM(H28:H28) -> 0 | J29: =SUM(J28:J28) -> 57298 | L29: =SUM(L28:L28) -> 0 | N29: =H29+J29+L29 -> 57298
B31: =B27+1 -> 3 | C31: 표면정리 | D31: 700 | E31: 1 | F31: nr
C32: 도장공 | E32: 0.05 | F32: 인 | H32: =TRUNC(G32*$E32,0) -> 0 | I32: 263017 | J32: =TRUNC(I32*$E32,0) -> 13150 | L32: =TRUNC(K32*$E32,0) -> 0 | M32: =G32+I32+K32 -> 263017 | N32: =H32+J32+L32 -> 13150
C33: 연마지 | D33: #180 | E33: 0.83 | F33: 매 | G33: 340 | H33: =TRUNC(G33*$E33,0) -> 282 | J33: =TRUNC(I33*$E33,0) -> 0 | L33: =TRUNC(K33*$E33,0) -> 0 | M33: =G33+I33+K33 -> 340 | N33: =H33+J33+L33 -> 282
C34: 공구손료 | D34: 도장공 인력품의 | E34: 0.03 | H34: =TRUNC(G34*$E34,0) -> 0 | J34: =TRUNC(I34*$E34,0) -> 0 | K34: 13150 | L34: =TRUNC(K34*$E34,0) -> 394 | M34: =G34+I34+K34 -> 13150 | N34: =H34+J34+L34 -> 394
C35: 계 | H35: =SUM(H32:H34) -> 282 | J35: =SUM(J32:J34) -> 13150 | L35: =SUM(L32:L34) -> 394 | N35: =H35+J35+L35 -> 13826
B37: =B31+1 -> 4 | C37: 부단수 할정자관 부설 및 접합(주철관제) | D37: 700 | E37: 1 | F37: nr
C38: 부단수 할정자관 부설(주철관제) | D38: 700 | E38: 1 | F38: nr | G38: 0 | H38: =TRUNC(G38*$E38,0) -> 0 | I38: 740074 | J38: =TRUNC(I38*$E38,0) -> 740074 | K38: 84200 | L38: =TRUNC(K38*$E38,0) -> 84200 | M38: =G38+I38+K38 -> 824274 | N38: =H38+J38+L38 -> 824274 | O38: =B42 -> 5
C39: 부단수 할정자관 | D39: 800 | E39: 1 | F39: nr | G39: 7828000 | H39: =TRUNC(G39*$E39,0) -> 7828000 | J39: =TRUNC(I39*$E39,0) -> 0 | L39: =TRUNC(K39*$E39,0) -> 0 | M39: =G39+I39+K39 -> 7828000 | N39: =H39+J39+L39 -> 7828000
C40: 계 | H40: =SUM(H38:H39) -> 7828000 | J40: =SUM(J38:J39) -> 740074 | L40: =SUM(L38:L39) -> 84200 | N40: =H40+J40+L40 -> 8652274
B42: =B37+1 -> 5 | C42: 부단수 할정자관 부설(주철관제) | D42: 700 | E42: 1 | F42: nr
C43: 배관공(수도) | E43: 1.77 | F43: 인 | H43: =TRUNC(G43*$E43,0) -> 0 | I43: 262580 | J43: =TRUNC(I43*$E43,0) -> 464766 | L43: =TRUNC(K43*$E43,0) -> 0 | M43: =G43+I43+K43 -> 262580 | N43: =H43+J43+L43 -> 464766
C44: 보통인부 | E44: 1.6 | F44: 인 | H44: =TRUNC(G44*$E44,0) -> 0 | I44: 172068 | J44: =TRUNC(I44*$E44,0) -> 275308 | L44: =TRUNC(K44*$E44,0) -> 0 | M44: =G44+I44+K44 -> 172068 | N44: =H44+J44+L44 -> 275308
C45: 트럭탑재형크레인 | D45: 10 | E45: 0.93 | F45: hr | H45: =TRUNC(G45*$E45,0) -> 0 | J45: =TRUNC(I45*$E45,0) -> 0 | K45: 90538 | L45: =TRUNC(K45*$E45,0) -> 84200 | M45: =G45+I45+K45 -> 90538 | N45: =H45+J45+L45 -> 84200
...

Sheet 내역서(1000)
B1: 부단수 차단공사 설계서
B2: <순공사비내역서>
B3: 공 종 명 | D3: 규 격 | E3: 수량 | F3: 단위 | G3: 재 료 비 | I3: 노 무 비 | K3: 경 비 | M3: 합 계 | O3: 비 고
G4: 단 가 | H4: 금 액 | I4: 단 가 | J4: 금 액 | K4: 단 가 | L4: 금 액 | M4: 단 가 | N4: 금 액
C5: 라인스토핑(강관제) | D5: 1000 | H5: =SUM(H6:H17) -> 30135868 | J5: =SUM(J6:J17) -> 11847041 | L5: =SUM(L6:L17) -> 12476187 | N5: =H5+J5+L5 -> 54459096
B6: 1 | C6: 바탕처리(강관제) | D6: 1000 | E6: 1 | F6: nr | G6: =H25 -> 547 | H6: =TRUNC(G6*$E6,0) -> 547 | I6: =J25 -> 136323 | J6: =TRUNC(I6*$E6,0) -> 136323 | K6: =L25 -> 765 | L6: =TRUNC(K6*$E6,0) -> 765 | M6: =G6+I6+K6 -> 137635 | N6: =H6+J6+L6 -> 137635 | O6: =B31 -> 3
B7: 2 | C7: 부단수 할정자관 부설 및 접합(강관제) | D7: 1000 | E7: 1 | F7: nr | G7: =H42 -> 10727047 | H7: =TRUNC(G7*$E7,0) -> 10727047 | I7: =J42 -> 2839426 | J7: =TRUNC(I7*$E7,0) -> 2839426 | K7: =L42 -> 750456 | L7: =TRUNC(K7*$E7,0) -> 750456 | M7: =G7+I7+K7 -> 14316929 | N7: =H7+J7+L7 -> 14316929 | O7: =B37 -> 4
B8: 3 | C8: 샌드위치 밸브 부설 및 접합 | D8: 900 | E8: 1 | F8: nr | G8: =H70 -> 303010 | H8: =TRUNC(G8*$E8,0) -> 303010 | I8: =J70 -> 498114 | J8: =TRUNC(I8*$E8,0) -> 498114 | K8: =L70 -> 1169557 | L8: =TRUNC(K8*$E8,0) -> 1169557 | M8: =G8+I8+K8 -> 1970681 | N8: =H8+J8+L8 -> 1970681 | O8: =B66 -> 8
B9: 4 | C9: 부단수천공 분기점 분기/철거 | D9: 900 | E9: 1 | F9: nr | G9: =H91 -> 4907155 | H9: =TRUNC(G9*$E9,0) -> 4907155 | I9: =J91 -> 2344095 | J9: =TRUNC(I9*$E9,0) -> 2344095 | K9: =L91 -> 5764730 | L9: =TRUNC(K9*$E9,0) -> 5764730 | M9: =G9+I9+K9 -> 13015980 | N9: =H9+J9+L9 -> 13015980 | O9: =B78 -> 10
B10: 5 | C10: 등압관 설치/철거 | D10: 100 | E10: 1 | F10: nr | G10: =H145 -> 480686 | H10: =TRUNC(G10*$E10,0) -> 480686 | I10: =J145 -> 235729 | J10: =TRUNC(I10*$E10,0) -> 235729 | K10: =L145 -> 84487 | L10: =TRUNC(K10*$E10,0) -> 84487 | M10: =G10+I10+K10 -> 800902 | N10: =H10+J10+L10 -> 800902 | O10: =B137 -> 18
B11: 6 | C11: 부단수차단/철거 | D11: 1000 | E11: 1 | F11: nr | G11: =H177 -> 6935803 | H11: =TRUNC(G11*$E11,0) -> 6935803 | I11: =J177 -> 3340165 | J11: =TRUNC(I11*$E11,0) -> 3340165 | K11: =L177 -> 3261875 | L11: =TRUNC(K11*$E11,0) -> 3261875 | M11: =G11+I11+K11 -> 13537843 | N11: =H11+J11+L11 -> 13537843 | O11: =B169 -> 22
B12: 7 | C12: 플러깅/철거 | D12: 900 | E12: 1 | F12: nr | G12: =H209 -> 5485950 | H12: =TRUNC(G12*$E12,0) -> 5485950 | I12: =J209 -> 1057108 | J12: =TRUNC(I12*$E12,0) -> 1057108 | K12: =L209 -> 733616 | L12: =TRUNC(K12*$E12,0) -> 733616 | M12: =G12+I12+K12 -> 7276674 | N12: =H12+J12+L12 -> 7276674 | O12: =B202 -> 27
B13: 8 | C13: 샌드위치 밸브 철거 | D13: 900 | E13: 1 | F13: nr | G13: =H234 -> 0 | H13: =TRUNC(G13*$E13,0) -> 0 | I13: =J234 -> 200296 | J13: =TRUNC(I13*$E13,0) -> 200296 | K13: =L234 -> 69460 | L13: =TRUNC(K13*$E13,0) -> 69460 | M13: =G13+I13+K13 -> 269756 | N13: =H13+J13+L13 -> 269756 | O13: =B230 -> 31
B14: 9 | C14: 마개플랜지 부설 및 접합 | D14: 900 | E14: 1 | F14: nr | G14: =H241 -> 1295670 | H14: =TRUNC(G14*$E14,0) -> 1295670 | I14: =J241 -> 253358 | J14: =TRUNC(I14*$E14,0) -> 253358 | K14: =L241 -> 22854 | L14: =TRUNC(K14*$E14,0) -> 22854 | M14: =G14+I14+K14 -> 1571882 | N14: =H14+J14+L14 -> 1571882 | O14: =B236 -> 32
B15: 10 | C15: 사전조사 | D15: 1000 | E15: 1 | F15: nr | G15: =H256 -> 0 | H15: =TRUNC(G15*$E15,0) -> 0 | I15: =J256 -> 335379 | J15: =TRUNC(I15*$E15,0) -> 335379 | K15: =L256 -> 0 | L15: =TRUNC(K15*$E15,0) -> 0 | M15: =G15+I15+K15 -> 335379 | N15: =H15+J15+L15 -> 335379 | O15: =B254 -> 35
B16: 11 | C16: 장비운반비 | D16: 1000 | E16: 1 | F16: set | G16: =H260 -> 0 | H16: =TRUNC(G16*$E16,0) -> 0 | I16: =J260 -> 0 | J16: =TRUNC(I16*$E16,0) -> 0 | K16: =L260 -> 618387 | L16: =TRUNC(K16*$E16,0) -> 618387 | M16: =G16+I16+K16 -> 618387 | N16: =H16+J16+L16 -> 618387 | O16: =B258 -> 36
B17: 12 | C17: 밸브개폐비 | D17: 900 | E17: 1 | F17: nr | G17: =H264 -> 0 | H17: =TRUNC(G17*$E17,0) -> 0 | I17: =J264 -> 607048 | J17: =TRUNC(I17*$E17,0) -> 607048 | K17: =L264 -> 0 | L17: =TRUNC(K17*$E17,0) -> 0 | M17: =G17+I17+K17 -> 607048 | N17: =H17+J17+L17 -> 607048 | O17: =B262 -> 37
B19: <일위대가표>
B20: 공 종 명 | D20: 규 격 | E20: 수량 | F20: 단위 | G20: 재 료 비 | I20: 노 무 비 | K20: 경 비 | M20: 합 계 | O20: 비 고
G21: 단 가 | H21: 금 액 | I21: 단 가 | J21: 금 액 | K21: 단 가 | L21: 금 액 | M21: 단 가 | N21: 금 액
B22: 1 | C22: 바탕처리(강관제) | D22: 1000 | E22: 1 | F22: nr
C23: 강관 도복장 제거 | E23: 1 | F23: nr | G23: 0 | H23: =TRUNC(G23*$E23,0) -> 0 | I23: 110811 | J23: =TRUNC(I23*$E23,0) -> 110811 | K23: 0 | L23: =TRUNC(K23*$E23,0) -> 0 | M23: =G23+I23+K23 -> 110811 | N23: =H23+J23+L23 -> 110811 | O23: =B27 -> 2
C24: 표면정리 | D24: #180 | E24: 1 | F24: nr | G24: 547 | H24: =TRUNC(G24*$E24,0) -> 547 | I24: 25512 | J24: =TRUNC(I24*$E24,0) -> 25512 | K24: 765 | L24: =TRUNC(K24*$E24,0) -> 765 | M24: =G24+I24+K24 -> 26824 | N24: =H24+J24+L24 -> 26824 | O24: =B31 -> 3
C25: 계 | H25: =SUM(H23:H24) -> 547 | J25: =SUM(J23:J24) -> 136323 | L25: =SUM(L23:L24) -> 765 | N25: =H25+J25+L25 -> 137635
B27: =B22+1 -> 2 | C27: 강관 도복장 제거 | D27: 1000 | E27: 1 | F27: nr
C28: 보통인부 | E28: 0.644 | F28: 인 | H28: =TRUNC(G28*$E28,0) -> 0 | I28: 172068 | J28: =TRUNC(I28*$E28,0) -> 110811 | L28: =TRUNC(K28*$E28,0) -> 0 | M28: =G28+I28+K28 -> 172068 | N28: =H28+J28+L28 -> 110811
C29: 계 | H29: =SUM(H28:H28) -> 0 | J29: =SUM(J28:J28) -> 110811 | L29: =SUM(L28:L28) -> 0 | N29: =H29+J29+L29 -> 110811
B31: =B27+1 -> 3 | C31: 표면정리 | D31: 1000 | E31: 1 | F31: nr
C32: 도장공 | E32: 0.097 | F32: 인 | H32: =TRUNC(G32*$E32,0) -> 0 | I32: 263017 | J32: =TRUNC(I32*$E32,0) -> 25512 | L32: =TRUNC(K32*$E32,0) -> 0 | M32: =G32+I32+K32 -> 263017 | N32: =H32+J32+L32 -> 25512
C33: 연마지 | D33: #180 | E33: 1.61 | F33: 매 | G33: 340 | H33: =TRUNC(G33*$E33,0) -> 547 | J33: =TRUNC(I33*$E33,0) -> 0 | L33: =TRUNC(K33*$E33,0) -> 0 | M33: =G33+I33+K33 -> 340 | N33: =H33+J33+L33 -> 547
C34: 공구손료 | D34: 도장공 인력품의 | E34: 0.03 | H34: =TRUNC(G34*$E34,0) -> 0 | J34: =TRUNC(I34*$E34,0) -> 0 | K34: 25512 | L34: =TRUNC(K34*$E34,0) -> 765 | M34: =G34+I34+K34 -> 25512 | N34: =H34+J34+L34 -> 765
C35: 계 | H35: =SUM(H32:H34) -> 547 | J35: =SUM(J32:J34) -> 25512 | L35: =SUM(L32:L34) -> 765 | N35: =H35+J35+L35 -> 26824
B37: =B31+1 -> 4 | C37: 부단수 할정자관 부설 및 접합(강관제) | D37: 1000 | E37: 1 | F37: nr
C38: 부단수 할정자관 부설(강관제) | D38: 1000 | E38: 1 | F38: nr | G38: 0 | H38: =TRUNC(G38*$E38,0) -> 0 | I38: 617826 | J38: =TRUNC(I38*$E38,0) -> 617826 | K38: 116097 | L38: =TRUNC(K38*$E38,0) -> 116097 | M38: =G38+I38+K38 -> 733923 | N38: =H38+J38+L38 -> 733923 | O38: =B44 -> 5
C39: 부단수 할정자관 접합(강관제) | D39: 1000 | E39: 1 | F39: nr | G39: 50127 | H39: =TRUNC(G39*$E39,0) -> 50127 | I39: 1966450 | J39: =TRUNC(I39*$E39,0) -> 1966450 | K39: 634359 | L39: =TRUNC(K39*$E39,0) -> 634359 | M39: =G39+I39+K39 -> 2650936 | N39: =H39+J39+L39 -> 2650936 | O39: =B50 -> 6
C40: 부단수 할정자관 접합부 도장 | D40: 1000 | E40: 1 | F40: nr | G40: 41920 | H40: =TRUNC(G40*$E40,0) -> 41920 | I40: 255150 | J40: =TRUNC(I40*$E40,0) -> 255150 | K40: 0 | L40: =TRUNC(K40*$E40,0) -> 0 | M40: =G40+I40+K40 -> 297070 | N40: =H40+J40+L40 -> 297070 | O40: =B57 -> 7
C41: 부단수 할정자관 | D41: 1000 | E41: 1 | F41: nr | G41: 10635000 | H41: =TRUNC(G41*$E41,0) -> 10635000 | J41: =TRUNC(I41*$E41,0) -> 0 | L41: =TRUNC(K41*$E41,0) -> 0 | M41: =G41+I41+K41 -> 10635000 | N41: =H41+J41+L41 -> 10635000
C42: 계 | H42: =SUM(H38:H41) -> 10727047 | J42: =SUM(J38:J41) -> 2839426 | L42: =SUM(L38:L41) -> 750456 | N42: =H42+J42+L42 -> 14316929
B44: =B37+1 -> 5 | C44: 부단수 할정자관 부설(강관제) | D44: 1000 | E44: 1 | F44: nr
C45: 배관공(수도) | E45: 1.56 | F45: 인 | H45: =TRUNC(G45*$E45,0) -> 0 | I45: 262580 | J45: =TRUNC(I45*$E45,0) -> 409624 | L45: =TRUNC(K45*$E45,0) -> 0 | M45: =G45+I45+K45 -> 262580 | N45: =H45+J45+L45 -> 409624
...

Sheet 자재견적서
B2: 견 적 서
B5: 문 서 번 호 | Q5: 공 급 자 | S5: 등록번호 | V5: 140-81-34127
B6: 수 신 | G6: 한국토지주택공사 | S6: 상 호 | V6: (주)대호스토퍼 | AB6: 대표 | AE6: 이 영 호 | AI6: (인)
S7: 소 재 지 | V7: 경기도 안산시 상록구 남산평길 126-4(팔곡일동)
B8: 담 당 자 | O8: 귀중 | S8: 업 태 | V8: 제조업 외 | AB8: 종목 | AE8: 상하수도설비공사 외
B9: 연 락 처 | S9: 회사전화 | V9: 031-496-9488 | AB9: 회사팩스 | AE9: 031-496-9349
B10: 작 성 일 | G10: 46150 | S10: 담 당 자 | V10: 백승리 차장 | AB10: 휴대전화 | AE10: 010-5013-7776
B11: 유 효 기 간 | G11: 12개월 | S11: E-Mail | V11: dhcstopper@hanmail.net
B12: 견 적 명 | G12: 광명하안2 공공주택지구 조성공사 중 부단수 차단 자재
B14: 합 계 금 액 | G14: 일금 | I14: =W14 -> 0 | T14: 원정 | V14: ( | W14: =AA59 -> 0 | AE14: ) | AF14: (VAT 별도)
B16: 아래와 같이 견적을 제출합니다.
B17: 번호 | D17: 품 명 | K17: 규 격 | Q17: 단위 | S17: 수량 | U17: 단 가 | AA17: 금 액 | AG17: 비고
B18: 1 | D18: 부단수 할정자관 (상,하판 1Set) | K18: D600㎜ | Q18: EA | S18: 1 | U18: 6155000 | AA18: =U18*S18 -> 6155000 | AR18: =U18 -> 6155000
B19: 2 | D19: 플랜지접합부속 (가스켓, 볼트/너트등) | K19: D400㎜ | Q19: EA | S19: 1 | U19: 48970 | AA19: =U19*S19 -> 48970 | AR19: =U19 -> 48970
B20: 3 | D20: 컷터 | K20: D400㎜ | Q20: EA | S20: 1 | U20: 720000 | AA20: =U20*S20 -> 720000 | AR20: =U20 -> 720000
B21: 4 | D21: 드릴 | K21: D400㎜ | Q21: EA | S21: 1 | U21: 192000 | AA21: =U21*S21 -> 192000 | AR21: =U21 -> 192000
B22: 5 | D22: Seailng Element | K22: D600㎜ | Q22: EA | S22: 1 | U22: 2425000 | AA22: =U22*S22 -> 2425000 | AR22: =U22 -> 2425000
B23: 6 | D23: 플러그(천공관용) | K23: D400㎜ | Q23: EA | S23: 1 | U23: 1255000 | AA23: =U23*S23 -> 1255000 | AR23: =U23 -> 1255000
B24: 7 | D24: 마개플랜지 | K24: D400㎜ | Q24: EA | S24: 1 | U24: 201000 | AA24: =U24*S24 -> 201000 | AR24: =U24 -> 201000
B25: 8 | D25: 부단수 할정자관 (상,하판 1Set) | K25: D700㎜ | Q25: EA | S25: 1 | U25: 7828000 | AA25: =U25*S25 -> 7828000 | AR25: =U25 -> 7828000
B26: 9 | D26: 플랜지접합부속 (가스켓, 볼트/너트등) | K26: D600㎜ | Q26: EA | S26: 1 | U26: 136480 | AA26: =U26*S26 -> 136480 | AR26: =U26 -> 136480
B27: 10 | D27: 컷터 | K27: D600㎜ | Q27: EA | S27: 1 | U27: 1680000 | AA27: =U27*S27 -> 1680000 | AR27: =U27 -> 1680000
B28: 11 | D28: 드릴 | K28: D600㎜ | Q28: EA | S28: 1 | U28: 384000 | AA28: =U28*S28 -> 384000 | AR28: =U28 -> 384000
B29: 12 | D29: Seailng Element | K29: D700㎜ | Q29: EA | S29: 1 | U29: 3209000 | AA29: =U29*S29 -> 3209000 | AR29: =U29 -> 3209000
... B46: 29 | D46: CAP(등압관용) | K46: D50㎜ | Q46: EA | S46: 1 | U46: 30000 | AA46: =U46*S46 -> 30000 | AR46: =U46 -> 30000
B59: 합 계(TOTAL)
B60: MEMO | D60: 1. VAT 별도
H725: =자재견적서!#REF! -> #REF!

Sheet 중기사용료목록
A1: 중기사용료목록
A2: 공 종 명 | B2: 규 격 | C2: 수 량 | D2: 단 위 | E2: 재 료 비 | F2: 노 무 비 | G2: 경 비 | H2: 합 계 | I2: 비 고
A3: 부단수 천공기 손료 | B3: 차단관경, D80x80mm | C3: 1 | D3: hr | F3: 0 | G3: =중기사용료!$G$12 -> 41739 | H3: =E3+F3+G3 -> 41739
A4: 부단수 천공기 손료 | B4: 차단관경, D100x100mm | C4: 1 | D4: hr | F4: 0 | G4: =중기사용료!$G$24 -> 40406 | H4: =E4+F4+G4 -> 40406
A5: 부단수 천공기 손료 | B5: 차단관경, D150x150mm | C5: 1 | D5: hr | F5: 0 | G5: =중기사용료!$G$36 -> 152731 | H5: =E5+F5+G5 -> 152731
A6: 부단수 천공기 손료 | B6: 차단관경, D200x200mm | C6: 1 | D6: hr | F6: 0 | G6: =중기사용료!$G$48 -> 111969 | H6: =E6+F6+G6 -> 111969
A7: 부단수 천공기 손료 | B7: 차단관경, D250x250mm | C7: 1 | D7: hr | F7: 0 | G7: =중기사용료!$G$60 -> 105504 | H7: =E7+F7+G7 -> 105504
A8: 부단수 천공기 손료 | B8: 차단관경, D300x300mm | C8: 1 | D8: hr | F8: 0 | G8: =중기사용료!$G$72 -> 100084 | H8: =E8+F8+G8 -> 100084
A9: 부단수 천공기 손료 | B9: 차단관경, D350x350mm | C9: 1 | D9: hr | F9: 0 | G9: =중기사용료!$G$84 -> 84364 | H9: =E9+F9+G9 -> 84364
A10: 부단수 천공기 손료 | B10: 차단관경, D400x400mm | C10: 1 | D10: hr | F10: 0 | G10: =중기사용료!$G$96 -> 86124 | H10: =E10+F10+G10 -> 86124
A11: 부단수 천공기 손료 | B11: 차단관경, D450x400mm | C11: 1 | D11: hr | F11: 0 | G11: =중기사용료!$G$108 -> 84660 | H11: =E11+F11+G11 -> 84660
A12: 부단수 천공기 손료 | B12: 차단관경, D500x400mm | C12: 1 | D12: hr | G12: =중기사용료!$G$119 -> 83304 | H12: =E12+F12+G12 -> 83304
A13: 부단수 천공기 손료 | B13: 차단관경, D600x400mm | C13: 1 | D13: hr | G13: =중기사용료!$G$130 -> 80628 | H13: =E13+F13+G13 -> 80628
A14: 부단수 천공기 손료 | B14: 차단관경, D700x600mm | C14: 1 | D14: hr | G14: 97785 | H14: =E14+F14+G14 -> 97785
A15: 부단수 천공기 손료 | B15: 차단관경, D800x600mm | C15: 1 | D15: hr | G15: 94483 | H15: =E15+F15+G15 -> 94483
A16: 부단수 천공기 손료 | B16: 차단관경, D900x600mm | C16: 1 | D16: hr | G16: 91123 | H16: =E16+F16+G16 -> 91123
A17: 부단수 천공기 손료 | B17: 차단관경, D1000x900mm | C17: 1 | D17: hr | G17: 75054 | H17: =E17+F17+G17 -> 75054
A18: 부단수 천공기 손료 | B18: 차단관경, D1100x900mm | C18: 1 | D18: hr | G18: 71241 | H18: =E18+F18+G18 -> 71241
A19: 부단수 천공기 손료 | B19: 차단관경, D1200x900mm | C19: 1 | D19: hr | G19: 70528 | H19: =E19+F19+G19 -> 70528
A20: 부단수 천공기 손료 | B20: 차단관경, D1350x900mm | C20: 1 | D20: hr | G20: 68191 | H20: =E20+F20+G20 -> 68191
A21: 부단수 천공기 손료 | B21: 차단관경, D1500x1200mm | C21: 1 | D21: hr | G21: 278152 | H21: =E21+F21+G21 -> 278152
A22: 부단수 천공기 손료 | B22: 차단관경, D1650x1200mm | C22: 1 | D22: hr | G22: 271657 | H22: =E22+F22+G22 -> 271657
A23: 부단수 천공기 손료 | B23: 차단관경, D1800x1200mm | C23: 1 | D23: hr | G23: 260489 | H23: =E23+F23+G23 -> 260489
A24: 부단수 천공기 손료 | B24: 차단관경, D2000x1650mm | C24: 1 | D24: hr | G24: 336664 | H24: =E24+F24+G24 -> 336664
A25: 부단수 천공기 손료 | B25: 차단관경, D2100x1650mm | C25: 1 | D25: hr | G25: 330427 | H25: =E25+F25+G25 -> 330427
... A31: 칩제거기 손료 | B31: 차단관경, D150x150mm | C31: 1 | D31: hr | G31: 3512 | H31: =E31+F31+G31 -> 3512
A32: 칩제거기 손료 | B32: 차단관경, D200x200mm | C32: 1 | D32: hr | F32: 0 | G32: 2659 | H32: =E32+F32+G32 -> 2659
A33: 칩제거기 손료 | B33: 차단관경, D250x250mm | C33: 1 | D33: hr | F33: 0 | G33: 3481 | H33: =E33+F33+G33 -> 3481
A34: 칩제거기 손료 | B34: 차단관경, D300x300mm | C34: 1 | D34: hr | F34: 0 | G34: 3753 | H34: =E34+F34+G34 -> 3753
A35: 칩제거기 손료 | B35: 차단관경, D350x350mm | C35: 1 | D35: hr | F35: 0 | G35: 4429 | H35: =E35+F35+G35 -> 4429
A36: 칩제거기 손료 | B36: 차단관경, D400x400mm | C36: 1 | D36: hr | F36: 0 | G36: 2153 | H36: =E36+F36+G36 -> 2153
A37: 칩제거기 손료 | B37: 차단관경, D450x400mm | C37: 1 | D37: hr | F37: 0 | G37: 2116 | H37: =E37+F37+G37 -> 2116
A38: 칩제거기 손료 | B38: 차단관경, D500x400mm | C38: 1 | D38: hr | F38: 0 | G38: 2082 | H38: =E38+F38+G38 -> 2082
A39: 칩제거기 손료 | B39: 차단관경, D600x400mm | C39: 1 | D39: hr | F39: 0 | G39: 2015 | H39: =E39+F39+G39 -> 2015
A40: 칩제거기 손료 | B40: 차단관경, D700x600mm | C40: 1 | D40: hr | F40: 0 | G40: 3116 | H40: =E40+F40+G40 -> 3116
A41: 칩제거기 손료 | B41: 차단관경, D800x600mm | C41: 1 | D41: hr | F41: 0 | G41: 3011 | H41: =E41+F41+G41 -> 3011
A42: 칩제거기 손료 | B42: 차단관경, D900x600mm | C42: 1 | D42: hr | F42: 0 | G42: 2904 | H42: =E42+F42+G42 -> 2904
A43: 칩제거기 손료 | B43: 차단관경, D1000x900mm | C43: 1 | D43: hr | F43: 0 | G43: 3844 | H43: =E43+F43+G43 -> 3844
... A132: 샌드위치 밸브 | B132: D2400x1650mm | C132: 1 | D132: hr | F132: 0 | G132: 145756 | H132: =E132+F132+G132 -> 145756

Sheet 중기사용료
A1: 중기사용료
A3: 중 기 명 | B3: 부단수 천공기 손료 차단관경, D80x80mm
A4: 중기가격 | B4: 11,520 천원
A5: 명 칭 | C5: 규 격 | D5: 수 량 | E5: 단 위 | F5: 단 가 | G5: 금 액 | H5: 비 고
A6: 경 비 | B6: 부단수 천공기 | C6: D80x80mm | D6: 3.6232 | E6: 천원 | F6: =중기기초자료!G37 -> 11520 | G6: =TRUNC(F6*D6, 1) -> 41739.2
B7: 소 계 | G7: =TRUNC(G6, 0) -> 41739
A8: 재 료 비
B9: 소 계
A10: 노 무 비
B11: 소 계
B12: 총 계 | G12: =TRUNC(G7+G9+G11, 0) -> 41739
A15: 중 기 명 | B15: 부단수 천공기 손료 차단관경, D100x100mm
A16: 중기가격 | B16: 11,520 천원
A17: 명 칭 | C17: 규 격 | D17: 수 량 | E17: 단 위 | F17: 단 가 | G17: 금 액 | H17: 비 고
A18: 경 비 | B18: 부단수 천공기 | C18: D100x100mm | D18: 3.5075 | E18: 천원 | F18: =중기기초자료!G38 -> 11520 | G18: =TRUNC(F18*D18, 1) -> 40406.4
B19: 소 계 | G19: =TRUNC(G18, 0) -> 40406
A20: 재 료 비
B21: 소 계
A22: 노 무 비
B23: 소 계
B24: 총 계 | G24: =TRUNC(G19+G21+G23, 0) -> 40406
A27: 중 기 명 | B27: 부단수 천공기 손료 차단관경, D150x150mm
A28: 중기가격 | B28: 48,000 천원
A29: 명 칭 | C29: 규 격 | D29: 수 량 | E29: 단 위 | F29: 단 가 | G29: 금 액 | H29: 비 고
A30: 경 비 | B30: 부단수 천공기 | C30: D150x150mm | D30: 3.1819 | E30: 천원 | F30: =중기기초자료!G39 -> 48000 | G30: =TRUNC(F30*D30, 1) -> 152731.2
B31: 소 계 | G31: =TRUNC(G30, 0) -> 152731
A32: 재 료 비
B33: 소 계
A34: 노 무 비
B35: 소 계
B36: 총 계 | G36: =TRUNC(G31+G33+G35, 0) -> 152731
A39: 중 기 명 | B39: 부단수 천공기 손료 차단관경, D200x200mm
A40: 중기가격 | B40: 48,000 천원
A41: 명 칭 | C41: 규 격 | D41: 수 량 | E41: 단 위 | F41: 단 가 | G41: 금 액 | H41: 비 고
A42: 경 비 | B42: 부단수 천공기 | C42: D200x200mm | D42: 2.3327 | E42: 천원 | F42: =중기기초자료!G40 -> 48000 | G42: =TRUNC(F42*D42, 1) -> 111969.6
B43: 소 계 | G43: =TRUNC(G42, 0) -> 111969
A44: 재 료 비
B45: 소 계
A46: 노 무 비
B47: 소 계
...

Sheet 중기기초자료
A1: 중기기초자료
A2: 명 칭 | B2: 규 격 | C2: 단 위 | D2: 합 계 | E2: 노 무 비 | F2: 재 료 비 | G2: 경 비 | H2: 비 고
A3: 트럭탑제형 크레인 | B3: 5 TON | C3: HR | D3: =E3+F3+G3 -> 69255 | E3: 49698 | F3: 8440 | G3: 11117 | H3: 26년적산단가/765
A4: 트럭탑제형 크레인 | B4: 10 TON | C4: HR | D4: =E4+F4+G4 -> 90538 | E4: 49698 | F4: 17045 | G4: 23795 | H4: 26년적산단가/765
A5: 트럭탑제형 크레인 | B5: 15 TON | C5: HR | D5: =E5+F5+G5 -> 99229 | E5: 49698 | F5: 18204 | G5: 31327 | H5: 26년적산단가/765
A6: 트럭탑제형 크레인 | B6: 18 TON | C6: HR | D6: =E6+F6+G6 -> 101726 | E6: 49698 | F6: 18700 | G6: 33328 | H6: 26년적산단가/765
A7: 무한궤도 크레인 | B7: 20 ton (0.57 ㎥) | C7: HR | D7: =E7+F7+G7 -> 99933 | E7: 58925 | F7: 14232 | G7: 26776 | H7: 26년적산단가/762
A8: 발전기 | B8: 50 kw | C8: HR | D8: =E8+F8+G8 -> 55756 | E8: 36190 | F8: 14877 | G8: 4689 | H8: 26년적산단가/793
A9: 용접기 (교류) | B9: 200 amP | C9: HR | D9: =E9+F9+G9 -> 92 | E9: 0 | F9: 0 | G9: 92 | H9: 26년적산단가/794
A10: 상수도관 천공기 | C10: HR | D10: =E10+F10+G10 -> 597 | G10: 597 | H10: 26년적산단가/790
A11: 칩제거기 | B11: D80x80mm | C11: 천원 | D11: 420 | E11: 0 | F11: 0 | G11: 420 | H11: 수자원적산지침 토목공사 8차/153P
A12: 칩제거기 | B12: D100x100mm | C12: 천원 | D12: 900 | E12: 0 | F12: 0 | G12: 900 | H12: 수자원적산지침 토목공사 8차/153P
A13: 칩제거기 | B13: D150x150mm | C13: 천원 | D13: 1104 | E13: 0 | F13: 0 | G13: 1104 | H13: 수자원적산지침 토목공사 8차/153P
A14: 칩제거기 | B14: D200x200mm | C14: 천원 | D14: 1140 | E14: 0 | F14: 0 | G14: 1140 | H14: 수자원적산지침 토목공사 8차/153P
A15: 칩제거기 | B15: D250x250mm | C15: 천원 | D15: 1584 | E15: 0 | F15: 0 | G15: 1584 | H15: 수자원적산지침 토목공사 8차/153P
A16: 칩제거기 | B16: D300x300mm | C16: 천원 | D16: 1800 | E16: 0 | F16: 0 | G16: 1800 | H16: 수자원적산지침 토목공사 8차/153P
A17: 칩제거기 | B17: D350x350mm | C17: 천원 | D17: 2520 | E17: 0 | F17: 0 | G17: 2520 | H17: 수자원적산지침 토목공사 8차/153P
A18: 칩제거기 | B18: D400x400mm | C18: 천원 | D18: 3000 | E18: 0 | F18: 0 | G18: 3000 | H18: 수자원적산지침 토목공사 8차/153P
A19: 칩제거기 | B19: D450x400mm | C19: 천원 | D19: 3000 | E19: 0 | F19: 0 | G19: 3000 | H19: 수자원적산지침 토목공사 8차/153P
A20: 칩제거기 | B20: D500x400mm | C20: 천원 | D20: 3000 | E20: 0 | F20: 0 | G20: 3000 | H20: 수자원적산지침 토목공사 8차/153P
A21: 칩제거기 | B21: D600x400mm | C21: 천원 | D21: 3000 | E21: 0 | F21: 0 | G21: 3000 | H21: 수자원적산지침 토목공사 8차/153P
A22: 칩제거기 | B22: D700x600mm | C22: 천원 | D22: 6120 | E22: 0 | F22: 0 | G22: 6120 | H22: 수자원적산지침 토목공사 8차/153P
... A112: 샌드위치 밸브 | B112: D1650mm | C112: 천원 | D112: 130000 | E112: 0 | F112: 0 | G112: 130000 | H112: 수자원적산지침 토목공사 8차/153P

Sheet 자재
A1: 자재
A2: 명 칭 | B2: 규 격 | C2: 단 위 | D2: 단 가 | E2: 비 고
A3: 용접봉 | B3: (고장력강용)(3.2㎜) | C3: EA | D3: 4900 | E3: (26년)물가자료 상/ 1387
A4: 연마지 | B4: #180 | C4: EA | D4: 340 | E4: (26년)물가자료 상 / 1412
A5: 액상접착제 | B5: 1kg 기준 | C5: kg | D5: =311200/15 -> 20746.667 | E5: (26년)물가자료 상 / 723
A6: 매스틱 | B6: 3T x 40 x 1m | C6: EA | D6: =16800/6 -> 2800 | E6: (26년)물가자료 상 / 723
A7: 안쪽층테이프 | B7: 0.508mm x 100mm x 1m | C7: EA | D7: =23200/30 -> 773.33333 | E7: (26년)물가자료 상 / 723
A8: 바깥층테이프 | B8: 0.381mm x 100mm x 1m | C8: EA | D8: =22200/30 -> 740 | E8: (26년)물가자료 상 / 723
A9: 경유 | B9: 저유황 0.001% | C9: L | D9: 1596 | E9: (26년)물가자료 하 / 32

Sheet 노임
A1: 노임 | E1: 26년도 상반기(대한건설협회 시중노임)
A2: 명 칭 | B2: 규 격 | C2: 단 위 | D2: 단 가 | E2: 비 고
A3: 방수공 | B3: 일반공사 직종 | C3: 인 | D3: 228286
A4: 보통인부 | B4: 일반공사 직종 | C4: 인 | D4: 172068
A5: 용접공 | B5: 일반공사 직종 | C5: 인 | D5: 282536
A6: 도장공 | B6: 일반공사 직종 | C6: 인 | D6: 263017
A7: 일반기계운전사 | B7: 일반공사 직종 | C7: 인 | D7: 173995
A8: 배관공(수도) | B8: 일반공사 직종 | C8: 인 | D8: 262580
A9: 플랜트기계설치공 | B9: 일반공사 직종 | C9: 인 | D9: 230376
A10: 플랜트배관공 | B10: 일반공사 직종 | C10: 인 | D10: 320480
A11: 플랜트용접공 | B11: 일반공사 직종 | C11: 인 | D11: 292640
A12: 고급기술자 | B12: 기계 설비 | C12: 인 | D12: 335379 | E12: 26년 한국엔지니어링협회
A13: 고급품질관리원 | B13: 일반공사 직종 | C13: 인 | D13: 197788

Sheet 경비 (2)
A1: 경비
A2: 명 칭 | B2: 규 격 | C2: 단 위 | D2: 재 료 비 | E2: 노 무 비 | F2: 경 비 | G2: 합 계 | H2: 비 고
A3: 트럭탑제형 크레인 | B3: 5 TON | C3: HR | D3: =중기기초자료!F3 -> 8440 | E3: =중기기초자료!E3 -> 49698 | F3: =중기기초자료!G3 -> 11117 | G3: =D3+E3+F3 -> 69255
A4: 트럭탑제형 크레인 | B4: 10 TON | C4: HR | D4: =중기기초자료!F4 -> 17045 | E4: =중기기초자료!E4 -> 49698 | F4: =중기기초자료!G4 -> 23795 | G4: =D4+E4+F4 -> 90538
A5: 트럭탑제형 크레인 | B5: 15 TON | C5: HR | D5: =중기기초자료!F5 -> 18204 | E5: =중기기초자료!E5 -> 49698 | F5: =중기기초자료!G5 -> 31327 | G5: =D5+E5+F5 -> 99229
A6: 트럭탑제형 크레인 | B6: 18 TON | C6: HR | D6: =중기기초자료!F6 -> 18700 | E6: =중기기초자료!E6 -> 49698 | F6: =중기기초자료!G6 -> 33328 | G6: =D6+E6+F6 -> 101726
A7: 무한궤도 크레인 | B7: 20 ton (0.57 ㎥) | C7: HR | D7: =중기기초자료!F7 -> 14232 | E7: =중기기초자료!E7 -> 58925 | F7: =중기기초자료!G7 -> 26776 | G7: =D7+E7+F7 -> 99933
A8: 발전기 | B8: 50 KW | C8: HR | D8: =중기기초자료!F8 -> 14877 | E8: =중기기초자료!E8 -> 36190 | F8: =중기기초자료!G8 -> 4689 | G8: =D8+E8+F8 -> 55756
A9: 용접기 (교류) | B9: 200 AMP | C9: HR | D9: =중기기초자료!F9 -> 0 | E9: =중기기초자료!E9 -> 0 | F9: =중기기초자료!G9 -> 92 | G9: =D9+E9+F9 -> 92
A10: 상수도관 천공기 | C10: HR | D10: =중기기초자료!F10 -> 0 | E10: =중기기초자료!E10 -> 0 | F10: =중기기초자료!G10 -> 597 | G10: =D10+E10+F10 -> 597
A11: 장비운반비 | B11: D1650mm(안산-광양) | C11: nr | F11: 5500000 | G11: =D11+E11+F11 -> 5500000
A12: 장비운반비 | B12: D900mm(안산-광양) | C12: nr | F12: 3380000 | G12: =D12+E12+F12 -> 3380000

Sheet 장비운반비 산출근거

Sheet KP접합
A1: 일위대가_호표_KP메커니컬접합
A2: 공 종 명 | C2: 규 격 | D2: 수량 | E2: 단위 | F2: 합 계 | H2: 재 료 비 | J2: 노 무 비 | L2: 경 비 | N2: 비 고
F3: 단 가 | G3: 금 액 | H3: 단 가 | I3: 금 액 | J3: 단 가 | K3: 금 액 | L3: 단 가 | M3: 금 액
A5: =#REF!+1 -> #REF! | B5: KP메카니컬접합 | C5: D80㎜ | D5: 1 | E5: 개소 | G5: =I5+K5+M5 -> #REF! | I5: =TRUNC(I6+I7+I8,0) -> 0 | K5: =TRUNC(K6+K7+K8,0) -> #REF! | M5: =TRUNC(M6+M7+M8,0) -> #REF! | N5: 삭제
B6: 배 관 공 | C6: 수도 | E6: 인 | F6: =H6+J6+L6 -> #REF! | G6: =I6+K6+M6 -> #REF! | H6: 0 | J6: =#REF! -> #REF! | K6: =TRUNC(J6*D6,1) -> #REF! | L6: 0
B7: 보통인부 | E7: 인 | F7: =H7+J7+L7 -> #REF! | G7: =I7+K7+M7 -> #REF! | H7: 0 | J7: =#REF! -> #REF! | K7: =TRUNC(J7*D7,1) -> #REF! | L7: 0
B8: 공구손료 및 잡재료 | C8: 노무비의 % | D8: 2 | E8: % | F8: =H8+J8+L8 -> 0 | G8: =I8+K8+M8 -> #REF! | M8: =TRUNC((K6+K7)*D8%,1) -> #REF!
A10: =A5+1 -> #REF! | B10: KP메카니컬접합 | C10: D100㎜이하 | D10: 1 | E10: 개소 | G10: =I10+K10+M10 -> #REF! | I10: =TRUNC(I11+I12+I13,0) -> 0 | K10: =TRUNC(K11+K12+K13,0) -> #REF! | M10: =TRUNC(M11+M12+M13,0) -> #REF! | N10: 토목6-2-3
B11: 배 관 공 | C11: 수도 | D11: 0.08 | E11: 인 | F11: =H11+J11+L11 -> #REF! | G11: =I11+K11+M11 -> #REF! | H11: 0 | J11: =#REF! -> #REF! | K11: =TRUNC(J11*D11,1) -> #REF! | L11: 0
B12: 보통인부 | D12: 0.04 | E12: 인 | F12: =H12+J12+L12 -> #REF! | G12: =I12+K12+M12 -> #REF! | H12: 0 | J12: =#REF! -> #REF! | K12: =TRUNC(J12*D12,1) -> #REF! | L12: 0
B13: 공구손료 및 잡재료 | C13: 노무비의 % | D13: 2 | E13: % | F13: =H13+J13+L13 -> 0 | G13: =I13+K13+M13 -> #REF! | M13: =TRUNC((K11+K12)*D13%,1) -> #REF!
A15: =A10+1 -> #REF! | B15: KP메카니컬접합 | C15: D150㎜ | D15: 1 | E15: 개소 | G15: =I15+K15+M15 -> #REF! | I15: =TRUNC(I16+I17+I18,0) -> 0 | K15: =TRUNC(K16+K17+K18,0) -> #REF! | M15: =TRUNC(M16+M17+M18,0) -> #REF! | N15: =N10 -> 토목6-2-3
B16: 배 관 공 | C16: 수도 | D16: 0.1 | E16: 인 | F16: =H16+J16+L16 -> #REF! | G16: =I16+K16+M16 -> #REF! | H16: 0 | J16: =#REF! -> #REF! | K16: =TRUNC(J16*D16,1) -> #REF! | L16: 0
B17: 보통인부 | D17: 0.05 | E17: 인 | F17: =H17+J17+L17 -> #REF! | G17: =I17+K17+M17 -> #REF! | H17: 0 | J17: =#REF! -> #REF! | K17: =TRUNC(J17*D17,1) -> #REF! | L17: 0
B18: 공구손료 및 잡재료 | C18: 노무비의 % | D18: 2 | E18: % | F18: =H18+J18+L18 -> 0 | G18: =I18+K18+M18 -> #REF! | M18: =TRUNC((K16+K17)*D18%,1) -> #REF!
A20: =A15+1 -> #REF! | B20: KP메카니컬접합 | C20: D200㎜ | D20: 1 | E20: 개소 | G20: =I20+K20+M20 -> #REF! | I20: =TRUNC(I21+I22+I23,0) -> 0 | K20: =TRUNC(K21+K22+K23,0) -> #REF! | M20: =TRUNC(M21+M22+M23,0) -> #REF! | N20: =N15 -> 토목6-2-3
B21: 배 관 공 | C21: 수도 | D21: 0.13 | E21: 인 | F21: =H21+J21+L21 -> #REF! | G21: =I21+K21+M21 -> #REF! | H21: 0 | J21: =#REF! -> #REF! | K21: =TRUNC(J21*D21,1) -> #REF! | L21: 0
B22: 보통인부 | D22: 0.07 | E22: 인 | F22: =H22+J22+L22 -> #REF! | G22: =I22+K22+M22 -> #REF! | H22: 0 | J22: =#REF! -> #REF! | K22: =TRUNC(J22*D22,1) -> #REF! | L22: 0
B23: 공구손료 및 잡재료 | C23: 노무비의 % | D23: 2 | E23: % | F23: =H23+J23+L23 -> 0 | G23: =I23+K23+M23 -> #REF! | M23: =TRUNC((K21+K22)*D23%,1) -> #REF!
A25: =A20+1 -> #REF! | B25: KP메카니컬접합 | C25: D250㎜ | D25: 1 | E25: 개소 | G25: =I25+K25+M25 -> #REF! | I25: =TRUNC(I26+I27+I28,0) -> 0 | K25: =TRUNC(K26+K27+K28,0) -> #REF! | M25: =TRUNC(M26+M27+M28,0) -> #REF! | N25: =N20 -> 토목6-2-3
B26: 배 관 공 | C26: 수도 | D26: 0.15 | E26: 인 | F26: =H26+J26+L26 -> #REF! | G26: =I26+K26+M26 -> #REF! | H26: 0 | J26: =#REF! -> #REF! | K26: =TRUNC(J26*D26,1) -> #REF! | L26: 0
B27: 보통인부 | D27: 0.08 | E27: 인 | F27: =H27+J27+L27 -> #REF! | G27: =I27+K27+M27 -> #REF! | H27: 0 | J27: =#REF! -> #REF! | K27: =TRUNC(J27*D27,1) -> #REF! | L27: 0
B28: 공구손료 및 잡재료 | C28: 노무비의 % | D28: 2 | E28: % | F28: =H28+J28+L28 -> 0 | G28: =I28+K28+M28 -> #REF! | M28: =TRUNC((K26+K27)*D28%,1) -> #REF!
A30: =A25+1 -> #REF! | B30: KP메카니컬접합 | C30: D300㎜ | D30: 1 | E30: 개소 | G30: =I30+K30+M30 -> #REF! | I30: =TRUNC(I31+I32+I33,0) -> 0 | K30: =TRUNC(K31+K32+K33,0) -> #REF! | M30: =TRUNC(M31+M32+M33,0) -> #REF! | N30: =N25 -> 토목6-2-3
B31: 배 관 공 | C31: 수도 | D31: 0.18 | E31: 인 | F31: =H31+J31+L31 -> #REF! | G31: =I31+K31+M31 -> #REF! | H31: 0 | J31: =#REF! -> #REF! | K31: =TRUNC(J31*D31,1) -> #REF! | L31: 0
B32: 보통인부 | D32: 0.1 | E32: 인 | F32: =H32+J32+L32 -> #REF! | G32: =I32+K32+M32 -> #REF! | H32: 0 | J32: =#REF! -> #REF! | K32: =TRUNC(J32*D32,1) -> #REF! | L32: 0
B33: 공구손료 및 잡재료 | C33: 노무비의 % | D33: 2 | E33: % | F33: =H33+J33+L33 -> 0 | G33: =I33+K33+M33 -> #REF! | M33: =TRUNC((K31+K32)*D33%,1) -> #REF!
A35: =A30+1 -> #REF! | B35: KP메카니컬접합 | C35: D350㎜ | D35: 1 | E35: 개소 | G35: =I35+K35+M35 -> #REF! | I35: =TRUNC(I36+I37+I38,0) -> 0 | K35: =TRUNC(K36+K37+K38,0) -> #REF! | M35: =TRUNC(M36+M37+M38,0) -> #REF! | N35: =N30 -> 토목6-2-3
B36: 배 관 공 | C36: 수도 | D36: 0.21 | E36: 인 | F36: =H36+J36+L36 -> #REF! | G36: =I36+K36+M36 -> #REF! | H36: 0 | J36: =#REF! -> #REF! | K36: =TRUNC(J36*D36,1) -> #REF! | L36: 0
B37: 보통인부 | D37: 0.11 | E37: 인 | F37: =H37+J37+L37 -> #REF! | G37: =I37+K37+M37 -> #REF! | H37: 0 | J37: =#REF! -> #REF! | K37: =TRUNC(J37*D37,1) -> #REF! | L37: 0
B38: 공구손료 및 잡재료 | C38: 노무비의 % | D38: 2 | E38: % | F38: =H38+J38+L38 -> 0 | G38: =I38+K38+M38 -> #REF! | M38: =TRUNC((K36+K37)*D38%,1) -> #REF!
A40: =A35+1 -> #REF! | B40: KP메카니컬접합 | C40: D400㎜ | D40: 1 | E40: 개소 | G40: =I40+K40+M40 -> #REF! | I40: =TRUNC(I41+I42+I43,0) -> 0 | K40: =TRUNC(K41+K42+K43,0) -> #REF! | M40: =TRUNC(M41+M42+M43,0) -> #REF! | N40: =N35 -> 토목6-2-3
B41: 배 관 공 | C41: 수도 | D41: 0.23 | E41: 인 | F41: =H41+J41+L41 -> #REF! | G41: =I41+K41+M41 -> #REF! | H41: 0 | J41: =#REF! -> #REF! | K41: =TRUNC(J41*D41,1) -> #REF! | L41: 0
B42: 보통인부 | D42: 0.12 | E42: 인 | F42: =H42+J42+L42 -> #REF! | G42: =I42+K42+M42 -> #REF! | H42: 0 | J42: =#REF! -> #REF! | K42: =TRUNC(J42*D42,1) -> #REF! | L42: 0
B43: 공구손료 및 잡재료 | C43: 노무비의 % | D43: 2 | E43: % | F43: =H43+J43+L43 -> 0 | G43: =I43+K43+M43 -> #REF! | M43: =TRUNC((K41+K42)*D43%,1) -> #REF!
A45: =A40+1 -> #REF! | B45: KP메카니컬접합 | C45: D450㎜ | D45: 1 | E45: 개소 | G45: =I45+K45+M45 -> #REF! | I45: =TRUNC(I46+I47+I48,0) -> 0 | K45: =TRUNC(K46+K47+K48,0) -> #REF! | M45: =TRUNC(M46+M47+M48,0) -> #REF! | N45: =N40 -> 토목6-2-3
B46: 배 관 공 | C46: 수도 | D46: 0.26 | E46: 인 | F46: =H46+J46+L46 -> #REF! | G46: =I46+K46+M46 -> #REF! | H46: 0 | J46: =#REF! -> #REF! | K46: =TRUNC(J46*D46,1) -> #REF! | L46: 0
B47: 보통인부 | D47: 0.14 | E47: 인 | F47: =H47+J47+L47 -> #REF! | G47: =I47+K47+M47 -> #REF! | H47: 0 | J47: =#REF! -> #REF! | K47: =TRUNC(J47*D47,1) -> #REF! | L47: 0
B48: 공구손료 및 잡재료 | C48: 노무비의 % | D48: 2 | E48: % | F48: =H48+J48+L48 -> 0 | G48: =I48+K48+M48 -> #REF! | M48: =TRUNC((K46+K47)*D48%,1) -> #REF!
A50: =A45+1 -> #REF! | B50: KP메카니컬접합 | C50: D500㎜ | D50: 1 | E50: 개소 | G50: =I50+K50+M50 -> #REF! | I50: =TRUNC(I51+I52+I53,0) -> 0 | K50: =TRUNC(K51+K52+K53,0) -> #REF! | M50: =TRUNC(M51+M52+M53,0) -> #REF! | N50: =N45 -> 토목6-2-3
...

Sheet 잡철물
A1: 일위대가_호표_잡철물
A2: 공 종 명 | C2: 규 격 | D2: 수량 | E2: 단위 | F2: 합 계 | H2: 재 료 비 | J2: 노 무 비 | L2: 경 비 | N2: 비 고
F3: 단 가 | G3: 금 액 | H3: 단 가 | I3: 금 액 | J3: 단 가 | K3: 금 액 | L3: 단 가 | M3: 금 액
A5: =#REF!+1 -> #REF! | B5: 잡철물 제작 및 설치 | C5: 제품 설치 | D5: 1 | E5: ton | G5: =I5+K5+M5 -> #REF! | I5: =SUM(I6:I11) -> 0 | K5: =SUM(K6:K11) -> #REF! | M5: =SUM(M6:M11) -> #REF! | N5: 건축8-3-1
B6: 철 공 | D6: 2.85 | E6: 인 | F6: =H6+J6+L6 -> #REF! | G6: =I6+K6+M6 -> #REF! | H6: 0 | J6: =#REF! -> #REF! | K6: =TRUNC(J6*D6,1) -> #REF! | L6: 0
B7: 용 접 공 | D7: 1.04 | E7: 인 | F7: =H7+J7+L7 -> #REF! | G7: =I7+K7+M7 -> #REF! | H7: 0 | J7: =#REF! -> #REF! | K7: =TRUNC(J7*D7,1) -> #REF! | L7: 0
B8: 특별인부 | D8: 0.78 | E8: 인 | F8: =H8+J8+L8 -> #REF! | G8: =I8+K8+M8 -> #REF! | J8: =#REF! -> #REF! | K8: =TRUNC(J8*D8,1) -> #REF!
B9: 보통인부 | D9: 0.52 | E9: 인 | F9: =H9+J9+L9 -> #REF! | G9: =I9+K9+M9 -> #REF! | I9: =TRUNC(H9*D9,1) -> 0 | J9: =#REF! -> #REF! | K9: =TRUNC(J9*D9,1) -> #REF! | M9: =TRUNC(L9*D9,1) -> 0
B10: 공구손료 및 기계경비 | C10: 노무비의 % | D10: 5 | E10: % | F10: =H10+J10+L10 -> 0 | G10: =I10+K10+M10 -> #REF! | M10: =TRUNC((K6+K7+K8+K9)*D10%,1) -> #REF!
B11: 잡재료 | C11: 노무비의 % | D11: 3 | E11: % | G11: =I11+K11+M11 -> #REF! | M11: =TRUNC((K6+K7+K8+K9)*D11%,1) -> #REF!
A13: =A5+1 -> #REF! | B13: 잡철물 제작 및 설치 | C13: 규격철물 설치 | D13: 1 | E13: ton | G13: =I13+K13+M13 -> #REF! | I13: =SUM(I14:I19) -> 0 | K13: =SUM(K14:K19) -> #REF! | M13: =SUM(M14:M19) -> #REF! | N13: 건축8-3-1
B14: 철 공 | D14: 7.05 | E14: 인 | F14: =H14+J14+L14 -> #REF! | G14: =I14+K14+M14 -> #REF! | H14: 0 | J14: =#REF! -> #REF! | K14: =TRUNC(J14*D14,1) -> #REF! | L14: 0
B15: 용 접 공 | D15: 2.57 | E15: 인 | F15: =H15+J15+L15 -> #REF! | G15: =I15+K15+M15 -> #REF! | H15: 0 | J15: =#REF! -> #REF! | K15: =TRUNC(J15*D15,1) -> #REF! | L15: 0
B16: 특별인부 | D16: 1.92 | E16: 인 | F16: =H16+J16+L16 -> #REF! | G16: =I16+K16+M16 -> #REF! | J16: =#REF! -> #REF! | K16: =TRUNC(J16*D16,1) -> #REF!
B17: 보통인부 | D17: 1.28 | E17: 인 | F17: =H17+J17+L17 -> #REF! | G17: =I17+K17+M17 -> #REF! | I17: =TRUNC(H17*D17,1) -> 0 | J17: =#REF! -> #REF! | K17: =TRUNC(J17*D17,1) -> #REF! | M17: =TRUNC(L17*D17,1) -> 0
B18: 공구손료 및 기계경비 | C18: 노무비의 % | D18: 5 | E18: % | F18: =H18+J18+L18 -> 0 | G18: =I18+K18+M18 -> #REF! | M18: =TRUNC((K14+K15+K16+K17)*D18%,1) -> #REF!
B19: 잡재료 | C19: 노무비의 % | D19: 3 | E19: % | G19: =I19+K19+M19 -> #REF! | M19: =TRUNC((K14+K15+K16+K17)*D19%,1) -> #REF!
A21: =A13+1 -> #REF! | B21: 잡철물 제작 및 설치 | C21: 현장제작 설치 | D21: 1 | E21: ton | G21: =I21+K21+M21 -> #REF! | I21: =SUM(I22:I27) -> 0 | K21: =SUM(K22:K27) -> #REF! | M21: =SUM(M22:M27) -> #REF! | N21: 건축8-3-1
B22: 철 공 | D22: 12.38 | E22: 인 | F22: =H22+J22+L22 -> #REF! | G22: =I22+K22+M22 -> #REF! | H22: 0 | J22: =#REF! -> #REF! | K22: =TRUNC(J22*D22,1) -> #REF! | L22: 0
B23: 용 접 공 | D23: 3.38 | E23: 인 | F23: =H23+J23+L23 -> #REF! | G23: =I23+K23+M23 -> #REF! | H23: 0 | J23: =#REF! -> #REF! | K23: =TRUNC(J23*D23,1) -> #REF! | L23: 0
B24: 특별인부 | D24: 4.5 | E24: 인 | F24: =H24+J24+L24 -> #REF! | G24: =I24+K24+M24 -> #REF! | J24: =#REF! -> #REF! | K24: =TRUNC(J24*D24,1) -> #REF!
B25: 보통인부 | D25: 2.25 | E25: 인 | F25: =H25+J25+L25 -> #REF! | G25: =I25+K25+M25 -> #REF! | I25: =TRUNC(H25*D25,1) -> 0 | J25: =#REF! -> #REF! | K25: =TRUNC(J25*D25,1) -> #REF! | M25: =TRUNC(L25*D25,1) -> 0
B26: 공구손료 및 기계경비 | C26: 노무비의 % | D26: 5 | E26: % | F26: =H26+J26+L26 -> 0 | G26: =I26+K26+M26 -> #REF! | M26: =TRUNC((K22+K23+K24+K25)*D26%,1) -> #REF!
B27: 잡재료 | C27: 노무비의 % | D27: 3 | E27: % | G27: =I27+K27+M27 -> #REF! | M27: =TRUNC((K22+K23+K24+K25)*D27%,1) -> #REF!

Sheet 경비
A1: 경비
A2: 명 칭 | B2: 규 격 | C2: 단 위 | D2: 재 료 비 | E2: 노 무 비 | F2: 경 비 | G2: 합 계 | H2: 비 고
A3: 하차비(기계하역료) | B3: 도착료 | C3: TON | D3: 0 | E3: 0 | F3: 1530 | G3: =D3+E3+F3 -> 1530 | J3: G002800
A4: 구역화물(10.5ton) | B4: 20km이내 | C4: 원 | D4: 0 | E4: 0 | F4: 111240 | G4: =D4+E4+F4 -> 111240 | J4: GTR105020

Sheet 전역변수
A1: 전역변수
A2: 변 수 명 | B2: 형 식 | C2: 값 | D2: 비 고 | E2: 적용단위

Sheet 중기전역변수
A1: 중기전역변수
A2: 변 수 명 | B2: 형 식 | C2: 값 | D2: 비 고
A3: QCODE | B3: 문자 | C3: 100000000001
A4: QUS2WON | B4: 숫자 | C4: 1142.5 | D4: 환율(장비가격10만불이하)
A5: QUS2WON1 | B5: 숫자 | C5: 1142.5 | D5: 환율(장비가격10만불이상)
A6: QYEN2WON | B6: 숫자 | C6: 13.2 | D6: 환율(엔화)
A7: QDM2WON | B7: 숫자 | C7: 724.05 | D7: 환율(마르크화)
A8: QSDR2WON | B8: 숫자 | C8: 1000 | D8: 환율(IMF특별인출권)
A9: QECU2WON | B9: 숫자 | C9: 1580 | D9: 환율(유로화)
A10: QEQTY1 | B10: 문자 | C10: (SANG + JUNG + KWAN)*10^-4 | D10: 중기주간경비산출계수
A11: QEQTY2 | B11: 문자 | C11: (SANG + JUNG + KWAN)*10^-4 | D11: 중기야간경비산출계수
A12: QEQTY3 | B12: 문자 | C12: (SANG + JUNG + int(KWAN/3))*10^-4 | D12: 중기주야간경비산출계수
A13: QEINC2 | B13: 숫자 | C13: 1.25 | D13: 중기야간할증계수
A14: QEINC3 | B14: 숫자 | C14: 1.071 | D14: 중기주야간할증계수
A15: QDECPEQ | B15: 문자 | C15: 0 | D15: 경비단가소숫점
A16: QDECCEQ | B16: 문자 | C16: 0 | D16: 경비금액소숫점
A17: QDECEQ | B17: 문자 | C17: 0 | D17: 경비계금액소숫점
A18: QH1 | B18: 문자 | C18: =25/20 * 16/12 * 1/8 -> 0.20833333 | D18: 시간당노임산출계수(일반구간)
A19: QH2 | B19: 문자 | C19: =25/20 * 16/12 * 1/8 -> 0.20833333 | D19: 시간당노임산출계수(터널구간)
A20: QH21 | B20: 문자 | C20: =25/20 * 16/12 * 1/8 -> 0.20833333 | D20: 시간당노임산출계수(장대터널)
A21: QH31 | B21: 문자 | C21: =25/20 * 16/12 * 1/8 -> 0.20833333 | D21: 시간당노임산출계수(해상장비:펌프준설선)
A22: QH32 | B22: 문자 | C22: =25/20 * 16/12 * 1/8 -> 0.20833333 | D22: 시간당노임산출계수(해상장비:GRAB준설선)
A23: QH33 | B23: 문자 | C23: =25/20 * 16/12 * 1/8 -> 0.20833333 | D23: 시간당노임산출계수(해상장비:버켓준설선)
A24: QLINC1 | B24: 숫자 | C24: 1 | D24: 노임할증계수(일반구간:주간)
A25: QLINC2 | B25: 숫자 | C25: 1.5 | D25: 노임할증계수(일반구간:야간)
A26: QLINC3 | B26: 숫자 | C26: 1.16 | D26: 노임할증계수(일반구간:주야간)
A27: QLINCA | B27: 숫자 | C27: 1.6 | D27: 노임할증계수(터널구간:주간)
A28: QLINCB | B28: 숫자 | C28: 1.6 | D28: 노임할증계수(터널구간:야간)
A29: QLINCC | B29: 숫자 | C29: 1.6 | D29: 노임할증계수(터널구간:주야간)
A30: QLINCD | B30: 숫자 | C30: 1.94 | D30: 노임할증계수(장대터널:주간)
A31: QLINCE | B31: 숫자 | C31: 1.94 | D31: 노임할증계수(장대터널:야간)
A32: QLINCF | B32: 숫자 | C32: 1.94 | D32: 노임할증계수(장대터널:주야간)
A33: QLINCX | B33: 숫자 | C33: 1 | D33: 노임할증계수(해상장비:주간)
A34: QLINCY | B34: 숫자 | C34: 1 | D34: 노임할증계수(해상장비:야간)
A35: QLINCZ | B35: 숫자 | C35: 1 | D35: 노임할증계수(해상장비:주야간)
A36: QDECPLA | B36: 문자 | C36: 0 | D36: 노임단가소숫점
A37: QDECCLA | B37: 문자 | C37: 0 | D37: 노임금액소숫점
A38: QDECLA | B38: 문자 | C38: 0 | D38: 노임계금액소숫점
A39: QMINC2 | B39: 숫자 | C39: 1.11 | D39: 재료비할증계수(야간)
A40: QMINC3 | B40: 숫자 | C40: 1.12 | D40: 재료비할증계수(주야간)
...
