Workbook
Name anscount: 1
Name asp두께: 0.15
Name HTML1_10: "Marihan@hitel.kol.co.kr"
Name HTML1_11: 1
Name HTML1_2: 1
Name HTML1_3: "엑셀 프로젝트"
Name HTML1_4: "인터넷 어시스턴트"
Name HTML1_6: 1
Name HTML1_7: 1
Name HTML1_8: "97-10-09"
Name HTML1_9: "김종완/어린왕자"
Name HTMLCount: 1
Name 계약여부: #REF!
Name 공사명: #REF!
Name 공사명: #REF!
Name 공사명: #REF!
Name 공사명: #REF!
Name 공사명: #REF!
Name 공사명: #REF!
Name 공사명: #REF!
Name 공사명: #REF!
Name 공사명: #REF!
Name 공사명: #REF!
Name 공사명: #REF!
Name 공사명: #REF!
Name 공사형태: #REF!
Name 다짐계수: 0.875
Name ㅁ1: #REF!
Name ㅁ1: #REF!
Name ㅁ1: #REF!
Name ㅁ1: #REF!
Name ㅁ1: #REF!
Name ㅁ1: #REF!
Name ㅁ1: #REF!
Name ㅁ1: #REF!
Name ㅁ1: #REF!
Name ㅁ1: #REF!
Name ㅁ1: #REF!
Name 보조기층두께: 0.2
Name 비목1: #REF!
Name 비목1: #REF!
Name 비목1: #REF!
Name 비목1: #REF!
Name 비목1: #REF!
Name 비목1: #REF!
Name 비목1: #REF!
Name 비목1: #REF!
Name 비목1: #REF!
Name 비목1: #REF!
Name 비목1: #REF!
Name 비목1: #REF!
Name 비목2: #REF!
Name 비목2: #REF!
Name 비목2: #REF!
Name 비목2: #REF!
Name 비목2: #REF!
Name 비목2: #REF!
Name 비목2: #REF!
Name 비목2: #REF!
Name 비목2: #REF!

Sheet 갑지
A2: 공사명 : 2026년~2027년 양지사 열수송관 천공 및 부단수 공사
A4: 공사 총괄 원가계산서
K6: (단위:원)
B7: 구분 | C7: 1차 | F7: 2차 | I7: 합계
C8: 서부 | D8: 동부 | E8: 합계 | F8: 서부 | G8: 동부 | H8: 합계 | I8: 서부 | J8: 동부 | K8: 합계
B9: 공 급 가 액 : | C9: ='원가계산서(서부지사)'!I29 -> 569863700 | D9: ='원가계산서(동부지사)'!I29 -> 539841582 | E9: ='원가계산서(양지사)'!I29 -> 1109705282 | F9: ='원가계산서(서부지사)'!N29 -> 0 | G9: ='원가계산서(동부지사)'!N29 -> 193833809 | H9: ='원가계산서(양지사)'!N29 -> 193833809 | I9: ='원가계산서(서부지사)'!D29 -> 569863700 | J9: ='원가계산서(동부지사)'!D29 -> 733675391 | K9: ='원가계산서(양지사)'!D29 -> 1303539091
B10: 부가 가치세 : | C10: ='원가계산서(서부지사)'!I30 -> 56986370 | D10: ='원가계산서(동부지사)'!I30 -> 53984158 | E10: ='원가계산서(양지사)'!I30 -> 110970528 | F10: ='원가계산서(서부지사)'!N30 -> 0 | G10: ='원가계산서(동부지사)'!N30 -> 19383381 | H10: ='원가계산서(양지사)'!N30 -> 19383381 | I10: ='원가계산서(서부지사)'!D30 -> 56986370 | J10: ='원가계산서(동부지사)'!D30 -> 73367539 | K10: ='원가계산서(양지사)'!D30 -> 130353909
B11: 합 계 금 액 : | C11: =C9+C10 -> 626850070 | D11: ='원가계산서(동부지사)'!I31 -> 593825740 | E11: ='원가계산서(양지사)'!I31 -> 1220675810 | F11: ='원가계산서(서부지사)'!N31 -> 0 | G11: ='원가계산서(동부지사)'!N31 -> 213217190 | H11: ='원가계산서(양지사)'!N31 -> 213217190 | I11: ='원가계산서(서부지사)'!D31 -> 626850070 | J11: ='원가계산서(동부지사)'!D31 -> 807042930 | K11: ='원가계산서(양지사)'!D31 -> 1433893000

Sheet 설계서표지
B2: 공사명 : 2026년~2027년 양지사 열수송관 천공 및 부단수 공사
E4: 감독원 경유: | F4: 문 태 준 | G4: (인)
A9: 산 출 내 역 서
E11: 총 공 사 비 : | F11: =F14+F15 -> 1433893000 | L11: 1466520000 | M11: 총원가
L12: 146652000 | M12: 총부가세
E13: 구 분 | F13: 금 액 | I13: 추정금액 | J13: 1613172000 | L13: =L12+L11 -> 1613172000 | M13: 합계
E14: 공 급 가 액 | F14: ='원가계산서(양지사)'!D29 -> 1303539091 | I14: 순공사원가 | J14: 1440443356 | L14: =INT(L15*1.1) -> 1440443356 | M14: 순공사원가
E15: 부 가 가 치 세 | F15: ='원가계산서(양지사)'!D30 -> 130353909 | J15: 1309493960 | L15: 1309493960 | M15: 순공사 공급가액
I16: 기초금액 | J16: 1440443356
I17: (부가세포함)
H20: 입찰가격에 조정없이 반영 | I20: A값 대상 | J20: 연금보험료 | K20: 5976106
J21: 건강보험료 | K21: 4522968
J22: 노인장기요양보험료 | K22: 594316
J23: 퇴직공제부금비 | K23: 2893693
J24: 산업안전보건관리비 | K24: 30446538
J25: 품질시험관리비 | K25: 2825360
J26: 합계 | K26: =SUM(K20:K25) -> 47258981
I27: A값 비대상 | J27: 환경보전비 | K27: 3517591

Sheet 원가계산서(양지사)
A1: 공 사 원 가 계 산 서 | F1: 공 사 원 가 계 산 서 | K1: 공 사 원 가 계 산 서
A2: □ 2026년~2027년 양지사 열수송관 천공 및 부단수 공사(양지사) 총차 | F2: □ 2026년~2027년 양지사 열수송관 천공 및 부단수 공사(양지사) 1차 | K2: □ 2026년~2027년 양지사 열수송관 천공 및 부단수 공사(양지사) 2차
E3: (단위:원) | J3: (단위:원) | O3: (단위:원)
A4: 구 분 | D4: 금 액 | E4: 비 고 | F4: 구 분 | I4: 금 액 | J4: 비 고 | K4: 구 분 | N4: 금 액 | O4: 비 고
A6: 1. 공 사 원 가 | B6: 가. 재료비 | C6: 1 ) 직접재료비 | D6: ='원가계산서(서부지사)'!D6+'원가계산서(동부지사)'!D6 -> 900532746 | F6: 1. 공 사 원 가 | G6: 가. 재료비 | H6: 1 ) 직접재료비 | I6: ='원가계산서(서부지사)'!I6+'원가계산서(동부지사)'!I6 -> 774223894 | K6: 1. 공 사 원 가 | L6: 가. 재료비 | M6: 1 ) 직접재료비 | N6: ='원가계산서(서부지사)'!N6+'원가계산서(동부지사)'!N6 -> 126308852
C7: 2 ) 간접재료비 | D7: ='원가계산서(서부지사)'!D7+'원가계산서(동부지사)'!D7 -> 0 | H7: 2 ) 간접재료비 | I7: ='원가계산서(서부지사)'!I7+'원가계산서(동부지사)'!I7 -> 0 | M7: 2 ) 간접재료비 | N7: ='원가계산서(서부지사)'!N7+'원가계산서(동부지사)'!N7 -> 0
C8: 소 계 | D8: ='원가계산서(서부지사)'!D8+'원가계산서(동부지사)'!D8 -> 900532746 | H8: 소 계 | I8: ='원가계산서(서부지사)'!I8+'원가계산서(동부지사)'!I8 -> 774223894 | M8: 소 계 | N8: ='원가계산서(서부지사)'!N8+'원가계산서(동부지사)'!N8 -> 126308852
B9: 나. 노무비 | C9: 1 ) 직접노무비 | D9: ='원가계산서(서부지사)'!D9+'원가계산서(동부지사)'!D9 -> 111091290 | G9: 나. 노무비 | H9: 1 ) 직접노무비 | I9: ='원가계산서(서부지사)'!I9+'원가계산서(동부지사)'!I9 -> 91113622 | L9: 나. 노무비 | M9: 1 ) 직접노무비 | N9: ='원가계산서(서부지사)'!N9+'원가계산서(동부지사)'!N9 -> 19977668
C10: 2 ) 간접노무비 | D10: ='원가계산서(서부지사)'!D10+'원가계산서(동부지사)'!D10 -> 16774783 | E10: 나 1)의 15.1% | H10: 2 ) 간접노무비 | I10: ='원가계산서(서부지사)'!I10+'원가계산서(동부지사)'!I10 -> 13758156 | J10: =E10 -> 나 1)의 15.1% | M10: 2 ) 간접노무비 | N10: ='원가계산서(서부지사)'!N10+'원가계산서(동부지사)'!N10 -> 3016627 | O10: =E10 -> 나 1)의 15.1% | P10: 0.151
C11: 소 계 | D11: ='원가계산서(서부지사)'!D11+'원가계산서(동부지사)'!D11 -> 127866073 | H11: 소 계 | I11: ='원가계산서(서부지사)'!I11+'원가계산서(동부지사)'!I11 -> 104871778 | M11: 소 계 | N11: ='원가계산서(서부지사)'!N11+'원가계산서(동부지사)'!N11 -> 22994295
B12: 다. 경 비 | C12: 1 ) 기계경비 | D12: ='원가계산서(서부지사)'!D12+'원가계산서(동부지사)'!D12 -> 23707460 | G12: 다. 경 비 | H12: 1 ) 기계경비 | I12: ='원가계산서(서부지사)'!I12+'원가계산서(동부지사)'!I12 -> 17775496 | L12: 다. 경 비 | M12: 1 ) 기계경비 | N12: ='원가계산서(서부지사)'!N12+'원가계산서(동부지사)'!N12 -> 5931964
C13: 2 ) 산재보험료 | D13: ='원가계산서(서부지사)'!D13+'원가계산서(동부지사)'!D13 -> 4552031 | E13: 나 ) 의 3.56% | H13: 2 ) 산재보험료 | I13: ='원가계산서(서부지사)'!I13+'원가계산서(동부지사)'!I13 -> 3733435 | J13: =E13 -> 나 ) 의 3.56% | M13: 2 ) 산재보험료 | N13: ='원가계산서(서부지사)'!N13+'원가계산서(동부지사)'!N13 -> 818596 | O13: =E13 -> 나 ) 의 3.56% | P13: =3.56*0.01 -> 0.0356
C14: 3 ) 고용보험료 | D14: ='원가계산서(서부지사)'!D14+'원가계산서(동부지사)'!D14 -> 1291446 | E14: 나 ) 의 1.01% | H14: 3 ) 고용보험료 | I14: ='원가계산서(서부지사)'!I14+'원가계산서(동부지사)'!I14 -> 1059204 | J14: =E14 -> 나 ) 의 1.01% | M14: 3 ) 고용보험료 | N14: ='원가계산서(서부지사)'!N14+'원가계산서(동부지사)'!N14 -> 232242 | O14: =E14 -> 나 ) 의 1.01% | P14: =1.01*0.01 -> 0.0101
C15: 4 ) 건강보험료 | D15: ='원가계산서(서부지사)'!D15+'원가계산서(동부지사)'!D15 -> 4522968 | E15: 나 1)의 3.595% | H15: 4 ) 건강보험료 | I15: ='원가계산서(서부지사)'!I15+'원가계산서(동부지사)'!I15 -> 3709598 | J15: =E15 -> 나 1)의 3.595% | M15: 4 ) 건강보험료 | N15: ='원가계산서(서부지사)'!N15+'원가계산서(동부지사)'!N15 -> 813370 | O15: =E15 -> 나 1)의 3.595% | P15: =3.595*0.01 -> 0.03595 | R15: 2026년 신규 비율 반영 3.545% → 3.595%
C16: 5 ) 노인장기요양보험료 | D16: ='원가계산서(서부지사)'!D16+'원가계산서(동부지사)'!D16 -> 594316 | E16: 다 4)의 13.14% | H16: 5 ) 노인장기요양보험료 | I16: ='원가계산서(서부지사)'!I16+'원가계산서(동부지사)'!I16 -> 487440 | J16: =E16 -> 다 4)의 13.14% | M16: 5 ) 노인장기요양보험료 | N16: ='원가계산서(서부지사)'!N16+'원가계산서(동부지사)'!N16 -> 106876 | O16: =E16 -> 다 4)의 13.14% | P16: =13.14*0.01 -> 0.1314 | R16: 2026년 신규 비율 반영 12.95% → 13.14%
C17: 6 ) 연금보험료 | D17: ='원가계산서(서부지사)'!D17+'원가계산서(동부지사)'!D17 -> 5976106 | E17: 나 1)의 4.75% | H17: 6 ) 연금보험료 | I17: ='원가계산서(서부지사)'!I17+'원가계산서(동부지사)'!I17 -> 4901417 | J17: =E17 -> 나 1)의 4.75% | M17: 6 ) 연금보험료 | N17: ='원가계산서(서부지사)'!N17+'원가계산서(동부지사)'!N17 -> 1074689 | O17: =E17 -> 나 1)의 4.75% | P17: =4.75*0.01 -> 0.0475 | R17: 2026년 신규 비율 반영 4.5% → 4.75%
C18: 7 ) 환경보전비 | D18: ='원가계산서(서부지사)'!D18+'원가계산서(동부지사)'!D18 -> 3105993 | E18: (재+직노+기경)*0.3% | H18: 7 ) 환경보전비 | I18: ='원가계산서(서부지사)'!I18+'원가계산서(동부지사)'!I18 -> 2649338 | J18: =E18 -> (재+직노+기경)*0.3% | M18: 7 ) 환경보전비 | N18: ='원가계산서(서부지사)'!N18+'원가계산서(동부지사)'!N18 -> 456655 | O18: =E18 -> (재+직노+기경)*0.3% | P18: =0.3*0.01 -> 0.003
C19: 8 ) 산업안전보건관리비 | D19: ='원가계산서(서부지사)'!D19+'원가계산서(동부지사)'!D19 -> 30446538 | E19: 가+나1)의 2.28%+4,325천원 | H19: 8 ) 산업안전보건관리비 | I19: ='원가계산서(서부지사)'!I19+'원가계산서(동부지사)'!I19 -> 26043798 | J19: =E19 -> 가+나1)의 2.28%+4,325천원 | M19: 8 ) 산업안전보건관리비 | N19: ='원가계산서(서부지사)'!N19+'원가계산서(동부지사)'!N19 -> 4402740 | O19: =E19 -> 가+나1)의 2.28%+4,325천원
C20: 9 ) 퇴직공제부금비 | D20: ='원가계산서(서부지사)'!D20+'원가계산서(동부지사)'!D20 -> 2893693 | E20: 나 1)의 2.3% | H20: 9 ) 퇴직공제부금비 | I20: ='원가계산서(서부지사)'!I20+'원가계산서(동부지사)'!I20 -> 2373317 | J20: =E20 -> 나 1)의 2.3% | M20: 9 ) 퇴직공제부금비 | N20: ='원가계산서(서부지사)'!N20+'원가계산서(동부지사)'!N20 -> 520376 | O20: =E20 -> 나 1)의 2.3% | P20: =2.3*0.01 -> 0.023
C21: 10 ) 기타 경 비 | D21: ='원가계산서(서부지사)'!D21+'원가계산서(동부지사)'!D21 -> 52448338 | E21: (가+나)의 5.1% | H21: 10 ) 기타 경 비 | I21: ='원가계산서(서부지사)'!I21+'원가계산서(동부지사)'!I21 -> 44833878 | J21: =E21 -> (가+나)의 5.1% | M21: 10 ) 기타 경 비 | N21: ='원가계산서(서부지사)'!N21+'원가계산서(동부지사)'!N21 -> 7614460 | O21: =E21 -> (가+나)의 5.1% | P21: =5.1*0.01 -> 0.051
C22: 11 ) 건설기계대여대금 지급보증액 발급 | D22: ='원가계산서(서부지사)'!D22+'원가계산서(동부지사)'!D22 -> 1035330 | E22: 가1)+나1)+다1)의 0.1% | H22: 11 ) 건설기계대여대금 지급보증액 발급 | I22: ='원가계산서(서부지사)'!I22+'원가계산서(동부지사)'!I22 -> 883112 | J22: =E22 -> 가1)+나1)+다1)의 0.1% | M22: 11 ) 건설기계대여대금 지급보증액 발급 | N22: ='원가계산서(서부지사)'!N22+'원가계산서(동부지사)'!N22 -> 152218 | O22: =E22 -> 가1)+나1)+다1)의 0.1% | P22: =0.1*0.01 -> 0.001
C23: 12 ) 품질시험관리비 | D23: ='원가계산서(서부지사)'!D23+'원가계산서(동부지사)'!D23 -> 2825360 | H23: 12 ) 품질시험관리비 | I23: ='원가계산서(서부지사)'!I23+'원가계산서(동부지사)'!I23 -> 2825360 | M23: 12 ) 품질시험관리비 | N23: ='원가계산서(서부지사)'!N23+'원가계산서(동부지사)'!N23 -> 0
C24: 소 계 | D24: ='원가계산서(서부지사)'!D24+'원가계산서(동부지사)'!D24 -> 133399579 | H24: 소 계 | I24: ='원가계산서(서부지사)'!I24+'원가계산서(동부지사)'!I24 -> 111275393 | M24: 소 계 | N24: ='원가계산서(서부지사)'!N24+'원가계산서(동부지사)'!N24 -> 22124186
B25: 계 | D25: ='원가계산서(서부지사)'!D25+'원가계산서(동부지사)'!D25 -> 1161798398 | G25: 계 | I25: ='원가계산서(서부지사)'!I25+'원가계산서(동부지사)'!I25 -> 990371065 | L25: 계 | N25: ='원가계산서(서부지사)'!N25+'원가계산서(동부지사)'!N25 -> 171427333
A26: 2 | B26: 일 반 관 리 비 | D26: ='원가계산서(서부지사)'!D26+'원가계산서(동부지사)'!D26 -> 75516895 | E26: 1 의 6.5% | F26: 2 | G26: 일 반 관 리 비 | I26: ='원가계산서(서부지사)'!I26+'원가계산서(동부지사)'!I26 -> 64374119 | J26: =E26 -> 1 의 6.5% | K26: 2 | L26: 일 반 관 리 비 | N26: ='원가계산서(서부지사)'!N26+'원가계산서(동부지사)'!N26 -> 11142776 | O26: =E26 -> 1 의 6.5% | P26: =6.5*0.01 -> 0.065
A27: 3 | B27: 이 윤 | D27: ='원가계산서(서부지사)'!D27+'원가계산서(동부지사)'!D27 -> 50517329 | E27: 나+다+2의 15% | F27: 3 | G27: 이 윤 | I27: ='원가계산서(서부지사)'!I27+'원가계산서(동부지사)'!I27 -> 42078140 | J27: =E27 -> 나+다+2의 15% | K27: 3 | L27: 이 윤 | N27: ='원가계산서(서부지사)'!N27+'원가계산서(동부지사)'!N27 -> 8439189 | O27: =E27 -> 나+다+2의 15% | P27: =15*0.01 -> 0.15
A28: 4 | B28: 고용개선지원비(PS단가) | D28: ='원가계산서(서부지사)'!D28+'원가계산서(동부지사)'!D28 -> 15706469 | F28: 4 | G28: 고용개선지원비(PS단가) | I28: ='원가계산서(서부지사)'!I28+'원가계산서(동부지사)'!I28 -> 12881958 | K28: 4 | L28: 고용개선지원비(PS단가) | N28: ='원가계산서(서부지사)'!N28+'원가계산서(동부지사)'!N28 -> 2824511 | R28: 11.9% → 14.2%(계약심사) → 14.5%(매뉴얼개정), 고용개선장려금 50% 적용
A29: 5 | B29: 합 계 | D29: ='원가계산서(서부지사)'!D29+'원가계산서(동부지사)'!D29 -> 1303539091 | F29: 5 | G29: 합 계 | I29: ='원가계산서(서부지사)'!I29+'원가계산서(동부지사)'!I29 -> 1109705282 | K29: 5 | L29: 합 계 | N29: ='원가계산서(서부지사)'!N29+'원가계산서(동부지사)'!N29 -> 193833809
A30: 6 | B30: 부 가 가 치 세 | D30: ='원가계산서(서부지사)'!D30+'원가계산서(동부지사)'!D30 -> 130353909 | E30: 5의 10% | F30: 6 | G30: 부 가 가 치 세 | I30: ='원가계산서(서부지사)'!I30+'원가계산서(동부지사)'!I30 -> 110970528 | J30: =E30 -> 5의 10% | K30: 6 | L30: 부 가 가 치 세 | N30: ='원가계산서(서부지사)'!N30+'원가계산서(동부지사)'!N30 -> 19383381 | O30: =E30 -> 5의 10%
A31: 7 | B31: 총 계 | D31: ='원가계산서(서부지사)'!D31+'원가계산서(동부지사)'!D31 -> 1433893000 | F31: 7 | G31: 총 계 | I31: ='원가계산서(서부지사)'!I31+'원가계산서(동부지사)'!I31 -> 1220675810 | K31: 7 | L31: 총 계 | N31: ='원가계산서(서부지사)'!N31+'원가계산서(동부지사)'!N31 -> 213217190
A32: ※ 제비율 적용기준 : 2026년도 건축·산업환경설비공사 원가계산
D34: 1433893000
D35: =D34/D31 -> 1
D38: =D34/1.1 -> 1.3035391e+09
D43: =D11/D31 -> 0.089174069

Sheet 원가계산서(서부지사)
A1: 공 사 원 가 계 산 서 | F1: 공 사 원 가 계 산 서 | K1: 공 사 원 가 계 산 서
A2: □ 2026년~2027년 양지사 열수송관 천공 및 부단수 공사(서부지사) 총차 | F2: □ 2026년~2027년 양지사 열수송관 천공 및 부단수 공사(서부지사) 1차 | K2: □ 2026년~2027년 양지사 열수송관 천공 및 부단수 공사(서부지사) 2차
E3: (단위:원) | J3: (단위:원) | O3: (단위:원)
A4: 구 분 | D4: 금 액 | E4: 비 고 | F4: 구 분 | I4: 금 액 | J4: 비 고 | K4: 구 분 | N4: 금 액 | O4: 비 고
A6: 1. 공 사 원 가 | B6: 가. 재료비 | C6: 1 ) 직접재료비 | D6: =I6+N6 -> 395567740 | F6: 1. 공 사 원 가 | G6: 가. 재료비 | H6: 1 ) 직접재료비 | I6: ='내역서(서부지사)-1차'!F6 -> 395567740 | K6: 1. 공 사 원 가 | L6: 가. 재료비 | M6: 1 ) 직접재료비 | N6: ='내역서(서부지사)-2차'!F6 -> 0
C7: 2 ) 간접재료비 | D7: =I7+N7 -> 0 | H7: 2 ) 간접재료비 | I7: 0 | M7: 2 ) 간접재료비 | N7: 0
C8: 소 계 | D8: =I8+N8 -> 395567740 | H8: 소 계 | I8: =I6+I7 -> 395567740 | M8: 소 계 | N8: =N6+N7 -> 0
B9: 나. 노무비 | C9: 1 ) 직접노무비 | D9: =I9+N9 -> 47809404 | G9: 나. 노무비 | H9: 1 ) 직접노무비 | I9: ='내역서(서부지사)-1차'!H6 -> 47809404 | L9: 나. 노무비 | M9: 1 ) 직접노무비 | N9: ='내역서(서부지사)-2차'!H6 -> 0
C10: 2 ) 간접노무비 | D10: =I10+N10 -> 7219220 | E10: ='원가계산서(양지사)'!E10 -> 나 1)의 15.1% | H10: 2 ) 간접노무비 | I10: =INT(I9*15.1%) -> 7219220 | J10: ='원가계산서(양지사)'!J10 -> 나 1)의 15.1% | M10: 2 ) 간접노무비 | N10: =INT(N9*15.1%) -> 0 | O10: ='원가계산서(양지사)'!O10 -> 나 1)의 15.1% | P10: 0.151
C11: 소 계 | D11: =I11+N11 -> 55028624 | H11: 소 계 | I11: =SUM(I9:I10) -> 55028624 | M11: 소 계 | N11: =SUM(N9:N10) -> 0
B12: 다. 경 비 | C12: 1 ) 기계경비 | D12: =I12+N12 -> 9537940 | G12: 다. 경 비 | H12: 1 ) 기계경비 | I12: ='내역서(서부지사)-1차'!J6 -> 9537940 | L12: 다. 경 비 | M12: 1 ) 기계경비 | N12: ='내역서(서부지사)-2차'!J6 -> 0
C13: 2 ) 산재보험료 | D13: =I13+N13 -> 1959019 | E13: ='원가계산서(양지사)'!E13 -> 나 ) 의 3.56% | H13: 2 ) 산재보험료 | I13: =INT(I11*3.56%) -> 1959019 | J13: ='원가계산서(양지사)'!J13 -> 나 ) 의 3.56% | M13: 2 ) 산재보험료 | N13: =INT(N11*3.56%) -> 0 | O13: ='원가계산서(양지사)'!O13 -> 나 ) 의 3.56% | P13: =3.56*0.01 -> 0.0356
C14: 3 ) 고용보험료 | D14: =I14+N14 -> 555789 | E14: ='원가계산서(양지사)'!E14 -> 나 ) 의 1.01% | H14: 3 ) 고용보험료 | I14: =INT(I11*1.01%) -> 555789 | J14: ='원가계산서(양지사)'!J14 -> 나 ) 의 1.01% | M14: 3 ) 고용보험료 | N14: =INT(N11*1.01%) -> 0 | O14: ='원가계산서(양지사)'!O14 -> 나 ) 의 1.01% | P14: =1.01*0.01 -> 0.0101
C15: 4 ) 건강보험료 | D15: =I15+N15 -> 1946511 | E15: ='원가계산서(양지사)'!E15 -> 나 1)의 3.595% | H15: 4 ) 건강보험료 | I15: 1946511 | J15: ='원가계산서(양지사)'!J15 -> 나 1)의 3.595% | M15: 4 ) 건강보험료 | N15: =INT(N9*3.595%) -> 0 | O15: ='원가계산서(양지사)'!O15 -> 나 1)의 3.595% | P15: =3.595*0.01 -> 0.03595 | R15: 2026년 신규 비율 반영 3.545% → 3.595%
C16: 5 ) 노인장기요양보험료 | D16: =I16+N16 -> 255771 | E16: ='원가계산서(양지사)'!E16 -> 다 4)의 13.14% | H16: 5 ) 노인장기요양보험료 | I16: 255771 | J16: ='원가계산서(양지사)'!J16 -> 다 4)의 13.14% | M16: 5 ) 노인장기요양보험료 | N16: =INT(N15*13.14%) -> 0 | O16: ='원가계산서(양지사)'!O16 -> 다 4)의 13.14% | P16: =13.14*0.01 -> 0.1314 | R16: 2026년 신규 비율 반영 12.95% → 13.14%
C17: 6 ) 연금보험료 | D17: =I17+N17 -> 2571886 | E17: ='원가계산서(양지사)'!E17 -> 나 1)의 4.75% | H17: 6 ) 연금보험료 | I17: 2571886 | J17: ='원가계산서(양지사)'!J17 -> 나 1)의 4.75% | M17: 6 ) 연금보험료 | N17: =INT(N9*4.75%) -> 0 | O17: ='원가계산서(양지사)'!O17 -> 나 1)의 4.75% | P17: =4.75*0.01 -> 0.0475 | R17: 2026년 신규 비율 반영 4.5% → 4.75%
C18: 7 ) 환경보전비 | D18: =I18+N18 -> 1358745 | E18: ='원가계산서(양지사)'!E18 -> (재+직노+기경)*0.3% | H18: 7 ) 환경보전비 | I18: =INT((I6+I9+I12)*0.3%) -> 1358745 | J18: ='원가계산서(양지사)'!J18 -> (재+직노+기경)*0.3% | M18: 7 ) 환경보전비 | N18: =INT((N6+N9+N12)*0.3%) -> 0 | O18: ='원가계산서(양지사)'!O18 -> (재+직노+기경)*0.3% | P18: =0.3*0.01 -> 0.003
C19: 8 ) 산업안전보건관리비 | D19: =I19+N19 -> 13344186 | E19: ='원가계산서(양지사)'!E19 -> 가+나1)의 2.28%+4,325천원 | H19: 8 ) 산업안전보건관리비 | I19: 13344186 | J19: ='원가계산서(양지사)'!J19 -> 가+나1)의 2.28%+4,325천원 | M19: 8 ) 산업안전보건관리비 | N19: =INT((N6+N9)*2.28%)+K37 -> 0 | O19: ='원가계산서(양지사)'!O19 -> 가+나1)의 2.28%+4,325천원
C20: 9 ) 퇴직공제부금비 | D20: =I20+N20 -> 1245334 | E20: ='원가계산서(양지사)'!E20 -> 나 1)의 2.3% | H20: 9 ) 퇴직공제부금비 | I20: 1245334 | J20: ='원가계산서(양지사)'!J20 -> 나 1)의 2.3% | M20: 9 ) 퇴직공제부금비 | N20: =INT(N9*2.3%) -> 0 | O20: ='원가계산서(양지사)'!O20 -> 나 1)의 2.3% | P20: =2.3*0.01 -> 0.023
C21: 10 ) 기타 경 비 | D21: =I21+N21 -> 22980414 | E21: ='원가계산서(양지사)'!E21 -> (가+나)의 5.1% | H21: 10 ) 기타 경 비 | I21: =INT((I6+I11)*5.1%) -> 22980414 | J21: ='원가계산서(양지사)'!J21 -> (가+나)의 5.1% | M21: 10 ) 기타 경 비 | N21: =INT((N6+N11)*5.1%) -> 0 | O21: ='원가계산서(양지사)'!O21 -> (가+나)의 5.1% | P21: =5.1*0.01 -> 0.051
C22: 11 ) 건설기계대여대금 지급보증액 발급 | D22: =I22+N22 -> 452915 | E22: ='원가계산서(양지사)'!E22 -> 가1)+나1)+다1)의 0.1% | H22: 11 ) 건설기계대여대금 지급보증액 발급 | I22: =INT((I6+I9+I12)*0.1%) -> 452915 | J22: ='원가계산서(양지사)'!J22 -> 가1)+나1)+다1)의 0.1% | M22: 11 ) 건설기계대여대금 지급보증액 발급 | N22: =INT((N6+N9+N12)*0.1%) -> 0 | O22: ='원가계산서(양지사)'!O22 -> 가1)+나1)+다1)의 0.1% | P22: =0.1*0.01 -> 0.001
C23: 12 ) 품질시험관리비 | D23: =I23+N23 -> 1412680 | H23: 12 ) 품질시험관리비 | I23: 1412680 | M23: 12 ) 품질시험관리비 | N23: =0 -> 0
C24: 소 계 | D24: =I24+N24 -> 57621190 | H24: 소 계 | I24: =SUM(I12:I23) -> 57621190 | M24: 소 계 | N24: =SUM(N12:N23) -> 0
B25: 계 | D25: =I25+N25 -> 508217554 | G25: 계 | I25: =I8+I11+I24 -> 508217554 | L25: 계 | N25: =N8+N11+N24 -> 0
A26: 2 | B26: 일 반 관 리 비 | D26: =I26+N26 -> 33034141 | E26: ='원가계산서(양지사)'!E26 -> 1 의 6.5% | F26: 2 | G26: 일 반 관 리 비 | I26: =INT(I25*6.5%) -> 33034141 | J26: =E26 -> 1 의 6.5% | K26: 2 | L26: 일 반 관 리 비 | N26: =INT(N25*6.5%) -> 0 | O26: =E26 -> 1 의 6.5% | P26: =6.5*0.01 -> 0.065
A27: 3 | B27: 이 윤 | D27: =I27+N27 -> 21852547 | E27: ='원가계산서(양지사)'!E27 -> 나+다+2의 15% | F27: 3 | G27: 이 윤 | I27: =INT((I11+I24+I26)*15%)-46 -> 21852547 | J27: 나+다+2의 15% | K27: 3 | L27: 이 윤 | N27: =INT((N11+N24+N26)*15%) -> 0 | O27: 나+다+2의 15% | P27: =15*0.01 -> 0.15
A28: 4 | B28: 고용개선지원비(PS단가) | D28: =I28+N28 -> 6759458 | F28: 4 | G28: 고용개선지원비(PS단가) | I28: 6759458 | K28: 4 | L28: 고용개선지원비(PS단가) | N28: 0 | R28: 11.9% → 14.2%(계약심사) → 14.5%(매뉴얼개정), 고용개선장려금 50% 적용
A29: 5 | B29: 합 계 | D29: =I29+N29 -> 569863700 | F29: 5 | G29: 합 계 | I29: =SUM(I25:I28) -> 569863700 | K29: 5 | L29: 합 계 | N29: =SUM(N25:N28) -> 0
A30: 6 | B30: 부 가 가 치 세 | D30: =I30+N30 -> 56986370 | E30: ='원가계산서(양지사)'!E30 -> 5의 10% | F30: 6 | G30: 부 가 가 치 세 | I30: =INT(I29*10%) -> 56986370 | J30: 5의 10% | K30: 6 | L30: 부 가 가 치 세 | N30: =INT(N29*10%) -> 0 | O30: 5의 10%
A31: 7 | B31: 총 계 | D31: =I31+N31 -> 626850070 | F31: 7 | G31: 총 계 | I31: =I29+I30 -> 626850070 | K31: 7 | L31: 총 계 | N31: =N29+N30 -> 0
A32: ※ 제비율 적용기준 : 2026년도 건축·산업환경설비공사 원가계산
I35: 재료비 + 경비 | J35: 비율 | K35: 기초액
H36: 서부1차 | I36: ='내역서(서부지사)-1차'!$F$6+'내역서(서부지사)-1차'!$H$6 -> 443377144 | J36: =I36/SUM($I$36:$I$39) -> 0.43828253 | K36: =ROUND(4325000*$J$36,0) -> 1895572
H37: 서부2차 | I37: ='내역서(서부지사)-2차'!$F$6+'내역서(서부지사)-2차'!$H$6 -> 0 | J37: =I37/SUM($I$36:$I$39) -> 0 | K37: =ROUND(4325000*$J$37,0) -> 0
H38: 동부1차 | I38: ='내역서(동부지사)-1차'!$F$6+'내역서(동부지사)-1차'!$H$6 -> 421960372 | J38: =I38/SUM($I$36:$I$39) -> 0.41711185 | K38: =ROUND(4325000*$J$38,0) -> 1804009
H39: 동부2차 | I39: ='내역서(동부지사)-2차'!$F$6+'내역서(동부지사)-2차'!$H$6 -> 146286520 | J39: =I39/SUM($I$36:$I$39) -> 0.14460562 | K39: =ROUND(4325000*$J$39,0) -> 625419
J41: 산업안전보건관리비 기초액 | K41: =SUM(K36:K39) -> 4325000

Sheet 내역서(서부지사)-0차
A1: 내역서
A2: 공 종 명 | B2: 규 격 | C2: 수량 | D2: 단위 | E2: 재 료 비 | G2: 노 무 비 | I2: 경 비 | K2: 합 계 | M2: 비 고
E3: 단 가 | F3: 금 액 | G3: 단 가 | H3: 금 액 | I3: 단 가 | J3: 금 액 | K3: 단 가 | L3: 금 액 | S3: 할 증 | T3: 화폐변환 | U3: OP값 | V3: EQ | W3: LA | X3: MA | Y3: 금액계상
A4: 공사비내역집계 | C4: 1 | D4: 식 | F4: =TRUNC(F5,0) -> #REF! | H4: =TRUNC(H5,0) -> #REF! | J4: =TRUNC(J5,0) -> #REF! | L4: =F4+H4+J4 -> #REF! | O4: A00
A5: 1.배관공사 | C5: 1 | D5: 식 | E5: =F9 -> #REF! | F5: =TRUNC(E5*C5,0) -> #REF! | G5: =H9 -> #REF! | H5: =TRUNC(G5*C5,0) -> #REF! | I5: =J9 -> #REF! | J5: =TRUNC(I5*C5,0) -> #REF! | K5: =E5+G5+I5 -> #REF! | L5: =F5+H5+J5 -> #REF! | P5: 5 | R5: A01 | BI5: =HYPERLINK("#내역서!A9","A01 →") -> A01 →
A6: >>총계 | F6: =TRUNC(F5,0) -> #REF! | H6: =TRUNC(H5,0) -> #REF! | J6: =TRUNC(J5,0) -> #REF! | K6: =E6+G6+I6 -> 0 | L6: =F6+H6+J6 -> #REF! | P6: 90
F7: 0 | H7: 0 | J7: 0 | K7: =E7+G7+I7 -> 0 | L7: =F7+H7+J7 -> 0 | P7: 100
A9: 1.배관공사 | C9: 1 | D9: 식 | F9: =F26 -> #REF! | H9: =H26 -> #REF! | J9: =J26 -> #REF! | L9: =F9+H9+J9 -> #REF! | O9: A01 | Z9: =#REF!+#REF!+#REF!+#REF!+#REF!+#REF!+#REF!+#REF!+#REF!+#REF!+#REF!+#REF!+#REF!+#REF!+#REF!+#REF!+#REF!+#REF!+#REF!+#REF!+#REF!+#REF!+#REF!+#REF!+#REF!+#REF!+#REF!+#REF!+#REF!+#REF!+#REF!+#REF!+#REF!+#REF!+#REF!+#REF!+#REF! -> #REF! | AA9: =#REF!+#REF!+#REF!+#REF!+#REF!+#REF!+#REF!+#REF!+#REF!+#REF!+#REF!+#REF!+#REF!+#REF!+#REF!+#REF!+#REF!+#REF!+#REF!+#REF!+#REF!+#REF!+#REF!+#REF!+#REF!+#REF!+#REF!+#REF!+#REF!+#REF!+#REF!+#REF!+#REF!+#REF!+#REF!+#REF!+#REF! -> #REF! | AB9: =#REF!+#REF!+#REF!+#REF!+#REF!+#REF!+#REF!+#REF!+#REF!+#REF!+#REF!+#REF!+#REF!+#REF!+#REF!+#REF!+#REF!+#REF!+#REF!+#REF!+#REF!+#REF!+#REF!+#REF!+#REF!+#REF!+#REF!+#REF!+#REF!+#REF!+#REF!+#REF!+#REF!+#REF!+#REF!+#REF!+#REF! -> #REF!
A10: 부단수 천공 | F10: 0 | H10: 0 | J10: 0 | K10: =E10+G10+I10 -> 0 | L10: =F10+H10+J10 -> 0 | P10: 8030
A11: 부단수 천공(차단) | B11: 100A | C11: =수량집계!#REF! -> #REF! | D11: 공 | E11: =일위대가목록!#REF! -> #REF! | F11: =TRUNC(E11*C11,0) -> #REF! | G11: =일위대가목록!#REF! -> #REF! | H11: =TRUNC(G11*C11,0) -> #REF! | I11: =일위대가목록!#REF! -> #REF! | J11: =TRUNC(I11*C11,0) -> #REF! | K11: =E11+G11+I11 -> #REF! | L11: =F11+H11+J11 -> #REF! | M11: No.706 | P11: 8190 | R11: SZD0001-100 | T11: T | BI11: =HYPERLINK("#일위대가목록!A608","SZD0001-100 →") -> SZD0001-100 →
A12: 부단수 천공(차단) | B12: 125A | C12: =수량집계!#REF! -> #REF! | D12: 공 | E12: =일위대가목록!#REF! -> #REF! | F12: =TRUNC(E12*C12,0) -> #REF! | G12: =일위대가목록!#REF! -> #REF! | H12: =TRUNC(G12*C12,0) -> #REF! | I12: =일위대가목록!#REF! -> #REF! | J12: =TRUNC(I12*C12,0) -> #REF! | K12: =E12+G12+I12 -> #REF! | L12: =F12+H12+J12 -> #REF! | M12: No.707 | P12: 8200 | R12: SZD0001-125 | T12: T | BI12: =HYPERLINK("#일위대가목록!A609","SZD0001-125 →") -> SZD0001-125 →
A13: 부단수 천공(차단) | B13: 150A | C13: =수량집계!#REF! -> #REF! | D13: 공 | E13: =일위대가목록!#REF! -> #REF! | F13: =TRUNC(E13*C13,0) -> #REF! | G13: =일위대가목록!#REF! -> #REF! | H13: =TRUNC(G13*C13,0) -> #REF! | I13: =일위대가목록!#REF! -> #REF! | J13: =TRUNC(I13*C13,0) -> #REF! | K13: =E13+G13+I13 -> #REF! | L13: =F13+H13+J13 -> #REF! | M13: No.708 | P13: 8210 | R13: SZD0001-150 | T13: T | BI13: =HYPERLINK("#일위대가목록!A610","SZD0001-150 →") -> SZD0001-150 →
A14: 부단수 천공(차단) | B14: 200A | C14: =수량집계!#REF! -> #REF! | D14: 공 | E14: =일위대가목록!#REF! -> #REF! | F14: =TRUNC(E14*C14,0) -> #REF! | G14: =일위대가목록!#REF! -> #REF! | H14: =TRUNC(G14*C14,0) -> #REF! | I14: =일위대가목록!#REF! -> #REF! | J14: =TRUNC(I14*C14,0) -> #REF! | K14: =E14+G14+I14 -> #REF! | L14: =F14+H14+J14 -> #REF! | M14: No.709 | P14: 8220 | R14: SZD0001-200 | T14: T | BI14: =HYPERLINK("#일위대가목록!A611","SZD0001-200 →") -> SZD0001-200 →
A15: 부단수 천공(차단) | B15: 250A | C15: =수량집계!#REF! -> #REF! | D15: 공 | E15: =일위대가목록!#REF! -> #REF! | F15: =TRUNC(E15*C15,0) -> #REF! | G15: =일위대가목록!#REF! -> #REF! | H15: =TRUNC(G15*C15,0) -> #REF! | I15: =일위대가목록!#REF! -> #REF! | J15: =TRUNC(I15*C15,0) -> #REF! | K15: =E15+G15+I15 -> #REF! | L15: =F15+H15+J15 -> #REF! | M15: No.710 | P15: 8230 | R15: SZD0001-250 | T15: T | BI15: =HYPERLINK("#일위대가목록!A612","SZD0001-250 →") -> SZD0001-250 →
A16: 부단수 천공(차단) | B16: 300A | C16: =수량집계!#REF! -> #REF! | D16: 공 | E16: =일위대가목록!F3 -> 10581357 | F16: =TRUNC(E16*C16,0) -> #REF! | G16: =일위대가목록!G3 -> 2096589 | H16: =TRUNC(G16*C16,0) -> #REF! | I16: =일위대가목록!H3 -> 699695 | J16: =TRUNC(I16*C16,0) -> #REF! | K16: =E16+G16+I16 -> 13377641 | L16: =F16+H16+J16 -> #REF! | M16: No.711 | P16: 8240 | R16: SZD0001-300 | T16: T | BI16: =HYPERLINK("#일위대가목록!A613","SZD0001-300 →") -> SZD0001-300 →
A17: 부단수 천공(차단) | B17: 350A | C17: =수량집계!#REF! -> #REF! | D17: 공 | E17: =일위대가목록!#REF! -> #REF! | F17: =TRUNC(E17*C17,0) -> #REF! | G17: =일위대가목록!#REF! -> #REF! | H17: =TRUNC(G17*C17,0) -> #REF! | I17: =일위대가목록!#REF! -> #REF! | J17: =TRUNC(I17*C17,0) -> #REF! | K17: =E17+G17+I17 -> #REF! | L17: =F17+H17+J17 -> #REF! | M17: No.712 | P17: 8250 | R17: SZD0001-350 | T17: T | BI17: =HYPERLINK("#일위대가목록!A614","SZD0001-350 →") -> SZD0001-350 →
A18: 부단수 천공(차단) | B18: 400A | C18: =수량집계!#REF! -> #REF! | D18: 공 | E18: =일위대가목록!#REF! -> #REF! | F18: =TRUNC(E18*C18,0) -> #REF! | G18: =일위대가목록!#REF! -> #REF! | H18: =TRUNC(G18*C18,0) -> #REF! | I18: =일위대가목록!#REF! -> #REF! | J18: =TRUNC(I18*C18,0) -> #REF! | K18: =E18+G18+I18 -> #REF! | L18: =F18+H18+J18 -> #REF! | M18: No.713 | P18: 8260 | R18: SZD0001-400 | T18: T | BI18: =HYPERLINK("#일위대가목록!A615","SZD0001-400 →") -> SZD0001-400 →
A19: 부단수 천공(차단) | B19: 450A | C19: =수량집계!#REF! -> #REF! | D19: 공 | E19: =일위대가목록!F4 -> 20995856 | F19: =TRUNC(E19*C19,0) -> #REF! | G19: =일위대가목록!G4 -> 2897828 | H19: =TRUNC(G19*C19,0) -> #REF! | I19: =일위대가목록!H4 -> 783296 | J19: =TRUNC(I19*C19,0) -> #REF! | K19: =E19+G19+I19 -> 24676980 | L19: =F19+H19+J19 -> #REF! | M19: No.714 | P19: 8270 | R19: SZD0001-450 | T19: T | BI19: =HYPERLINK("#일위대가목록!A616","SZD0001-450 →") -> SZD0001-450 →
A20: 부단수 천공(차단) | B20: 500A | C20: =수량집계!#REF! -> #REF! | D20: 공 | E20: =일위대가목록!#REF! -> #REF! | F20: =TRUNC(E20*C20,0) -> #REF! | G20: =일위대가목록!#REF! -> #REF! | H20: =TRUNC(G20*C20,0) -> #REF! | I20: =일위대가목록!#REF! -> #REF! | J20: =TRUNC(I20*C20,0) -> #REF! | K20: =E20+G20+I20 -> #REF! | L20: =F20+H20+J20 -> #REF! | M20: No.715 | P20: 8280 | R20: SZD0001-500 | T20: T | BI20: =HYPERLINK("#일위대가목록!A617","SZD0001-500 →") -> SZD0001-500 →
A21: 부단수 천공(차단) | B21: 550A | C21: =수량집계!#REF! -> #REF! | D21: 공 | E21: =일위대가목록!#REF! -> #REF! | F21: =TRUNC(E21*C21,0) -> #REF! | G21: =일위대가목록!#REF! -> #REF! | H21: =TRUNC(G21*C21,0) -> #REF! | I21: =일위대가목록!#REF! -> #REF! | J21: =TRUNC(I21*C21,0) -> #REF! | K21: =E21+G21+I21 -> #REF! | L21: =F21+H21+J21 -> #REF! | M21: No.716 | P21: 8290 | R21: SZD0001-550 | T21: T | BI21: =HYPERLINK("#일위대가목록!A618","SZD0001-550 →") -> SZD0001-550 →
A22: 부단수 천공(차단) | B22: 600A | C22: =수량집계!#REF! -> #REF! | D22: 공 | E22: =일위대가목록!F5 -> 32245254 | F22: =TRUNC(E22*C22,0) -> #REF! | G22: =일위대가목록!G5 -> 3903873 | H22: =TRUNC(G22*C22,0) -> #REF! | I22: =일위대가목록!H5 -> 794083 | J22: =TRUNC(I22*C22,0) -> #REF! | K22: =E22+G22+I22 -> 36943210 | L22: =F22+H22+J22 -> #REF! | M22: No.717 | P22: 8300 | R22: SZD0001-600 | T22: T | BI22: =HYPERLINK("#일위대가목록!A619","SZD0001-600 →") -> SZD0001-600 →
A23: 부단수 천공(차단) | B23: 650A | C23: =수량집계!#REF! -> #REF! | D23: 공 | E23: =일위대가목록!F6 -> 34401427 | F23: =TRUNC(E23*C23,0) -> #REF! | G23: =일위대가목록!G6 -> 4144605 | H23: =TRUNC(G23*C23,0) -> #REF! | I23: =일위대가목록!H6 -> 796319 | J23: =TRUNC(I23*C23,0) -> #REF! | K23: =E23+G23+I23 -> 39342351 | L23: =F23+H23+J23 -> #REF! | M23: No.718 | P23: 8310 | R23: SZD0001-650 | T23: T | BI23: =HYPERLINK("#일위대가목록!A620","SZD0001-650 →") -> SZD0001-650 →
A24: 부단수 천공(차단) | B24: 700A | C24: =수량집계!#REF! -> #REF! | D24: 공 | E24: =일위대가목록!F7 -> 38234376 | F24: =TRUNC(E24*C24,0) -> #REF! | G24: =일위대가목록!G7 -> 4376697 | H24: =TRUNC(G24*C24,0) -> #REF! | I24: =일위대가목록!H7 -> 841347 | J24: =TRUNC(I24*C24,0) -> #REF! | K24: =E24+G24+I24 -> 43452420 | L24: =F24+H24+J24 -> #REF! | M24: No.719 | P24: 8320 | R24: SZD0001-700 | T24: T | BI24: =HYPERLINK("#일위대가목록!A621","SZD0001-700 →") -> SZD0001-700 →
A25: 부단수 천공(차단) | B25: 750A | C25: =수량집계!#REF! -> #REF! | D25: 공 | E25: =일위대가목록!F8 -> 44056471 | F25: =TRUNC(E25*C25,0) -> #REF! | G25: =일위대가목록!G8 -> 4609505 | H25: =TRUNC(G25*C25,0) -> #REF! | I25: =일위대가목록!H8 -> 843446 | J25: =TRUNC(I25*C25,0) -> #REF! | K25: =E25+G25+I25 -> 49509422 | L25: =F25+H25+J25 -> #REF! | M25: No.720 | P25: 8330 | R25: SZD0001-750 | T25: T | BI25: =HYPERLINK("#일위대가목록!A622","SZD0001-750 →") -> SZD0001-750 →
A26: >계 | F26: =TRUNC(F25+F24+F23+F22+F21+F20+F19+F18+F17+F16+F15+F14+F13+F12+F11,0) -> #REF! | H26: =TRUNC(H25+H24+H23+H22+H21+H20+H19+H18+H17+H16+H15+H14+H13+H12+H11,0) -> #REF! | J26: =TRUNC(J25+J24+J23+J22+J21+J20+J19+J18+J17+J16+J15+J14+J13+J12+J11,0) -> #REF! | K26: =E26+G26+I26 -> 0 | L26: =F26+H26+J26 -> #REF! | P26: 8340
F27: 0 | H27: 0 | J27: 0 | K27: =E27+G27+I27 -> 0 | L27: =F27+H27+J27 -> 0 | P27: 8350
F28: 0 | H28: 0 | J28: 0 | K28: =E28+G28+I28 -> 0 | L28: =F28+H28+J28 -> 0 | P28: 14890
A29: <기량시험>
A30: 용접공기량시험 | C30: =5 -> 5 | D30: 인 | F30: =TRUNC(E30*C30,0) -> 0 | G30: =[2]노임!D5 -> 262551 | H30: =TRUNC(G30*C30,0) -> 1312755 | J30: =TRUNC(I30*C30,0) -> 0 | K30: =E30+G30+I30 -> 262551 | L30: =F30+H30+J30 -> 1312755 | P30: 14900

Sheet 내역서(서부지사)-1차
A1: 내역서
A2: 공 종 명 | B2: 규 격 | C2: 수량 | D2: 단위 | E2: 재 료 비 | G2: 노 무 비 | I2: 경 비 | K2: 합 계 | M2: 비 고
E3: 단 가 | F3: 금 액 | G3: 단 가 | H3: 금 액 | I3: 단 가 | J3: 금 액 | K3: 단 가 | L3: 금 액 | S3: 할 증 | T3: 화폐변환 | U3: OP값 | V3: EQ | W3: LA | X3: MA | Y3: 금액계상
A4: 공사비내역집계 | C4: 1 | D4: 식 | F4: =TRUNC(F5,0) -> 395567740 | H4: =TRUNC(H5,0) -> 47809404 | J4: =TRUNC(J5,0) -> 9537940 | L4: =F4+H4+J4 -> 452915084 | O4: A00
A5: 1.배관공사 | C5: 1 | D5: 식 | E5: =F9 -> 395567740 | F5: =TRUNC(E5*C5,0) -> 395567740 | G5: =H9 -> 47809404 | H5: =TRUNC(G5*C5,0) -> 47809404 | I5: =J9 -> 9537940 | J5: =TRUNC(I5*C5,0) -> 9537940 | K5: =E5+G5+I5 -> 452915084 | L5: =F5+H5+J5 -> 452915084 | P5: 5 | R5: A01 | BI5: =HYPERLINK("#내역서!A9","A01 →") -> A01 →
A6: >>총계 | F6: =TRUNC(F5,0) -> 395567740 | H6: =TRUNC(H5,0) -> 47809404 | J6: =TRUNC(J5,0) -> 9537940 | K6: =E6+G6+I6 -> 0 | L6: =F6+H6+J6 -> 452915084 | P6: 90
F7: 0 | H7: 0 | J7: 0 | K7: =E7+G7+I7 -> 0 | L7: =F7+H7+J7 -> 0 | P7: 100
A9: 1.배관공사 | C9: 1 | D9: 식 | F9: =F17 -> 395567740 | H9: =H17 -> 47809404 | J9: =J17 -> 9537940 | L9: =F9+H9+J9 -> 452915084 | O9: A01 | Z9: =#REF!+#REF!+#REF!+#REF!+#REF!+#REF!+#REF!+#REF!+#REF!+#REF!+#REF!+#REF!+#REF!+#REF!+#REF!+#REF!+#REF!+#REF!+#REF!+#REF!+#REF!+#REF!+#REF!+#REF!+#REF!+#REF!+#REF!+#REF!+#REF!+#REF!+#REF!+#REF!+#REF!+#REF!+#REF!+#REF!+#REF! -> #REF! | AA9: =#REF!+#REF!+#REF!+#REF!+#REF!+#REF!+#REF!+#REF!+#REF!+#REF!+#REF!+#REF!+#REF!+#REF!+#REF!+#REF!+#REF!+#REF!+#REF!+#REF!+#REF!+#REF!+#REF!+#REF!+#REF!+#REF!+#REF!+#REF!+#REF!+#REF!+#REF!+#REF!+#REF!+#REF!+#REF!+#REF!+#REF! -> #REF! | AB9: =#REF!+#REF!+#REF!+#REF!+#REF!+#REF!+#REF!+#REF!+#REF!+#REF!+#REF!+#REF!+#REF!+#REF!+#REF!+#REF!+#REF!+#REF!+#REF!+#REF!+#REF!+#REF!+#REF!+#REF!+#REF!+#REF!+#REF!+#REF!+#REF!+#REF!+#REF!+#REF!+#REF!+#REF!+#REF!+#REF!+#REF! -> #REF!
A10: 부단수 천공 | F10: 0 | H10: 0 | J10: 0 | K10: =E10+G10+I10 -> 0 | L10: =F10+H10+J10 -> 0 | P10: 8030
A11: 부단수 천공(차단) | B11: 300A | C11: =수량집계!C6 -> 0 | D11: 공 | E11: =일위대가목록!F3 -> 10581357 | F11: =TRUNC(E11*C11,0) -> 0 | G11: =일위대가목록!G3 -> 2096589 | H11: =TRUNC(G11*C11,0) -> 0 | I11: =일위대가목록!H3 -> 699695 | J11: =TRUNC(I11*C11,0) -> 0 | K11: =E11+G11+I11 -> 13377641 | L11: =F11+H11+J11 -> 0 | M11: No.711 | P11: 8240 | R11: SZD0001-300 | T11: T | BI11: =HYPERLINK("#일위대가목록!A613","SZD0001-300 →") -> SZD0001-300 →
A12: 부단수 천공(차단) | B12: 450A | C12: =수량집계!C7 -> 0 | D12: 공 | E12: =일위대가목록!F4 -> 20995856 | F12: =TRUNC(E12*C12,0) -> 0 | G12: =일위대가목록!G4 -> 2897828 | H12: =TRUNC(G12*C12,0) -> 0 | I12: =일위대가목록!H4 -> 783296 | J12: =TRUNC(I12*C12,0) -> 0 | K12: =E12+G12+I12 -> 24676980 | L12: =F12+H12+J12 -> 0 | M12: No.714 | P12: 8270 | R12: SZD0001-450 | T12: T | BI12: =HYPERLINK("#일위대가목록!A616","SZD0001-450 →") -> SZD0001-450 →
A13: 부단수 천공(차단) | B13: 600A | C13: =수량집계!C8 -> 8 | D13: 공 | E13: =일위대가목록!F5 -> 32245254 | F13: =TRUNC(E13*C13,0) -> 257962032 | G13: =일위대가목록!G5 -> 3903873 | H13: =TRUNC(G13*C13,0) -> 31230984 | I13: =일위대가목록!H5 -> 794083 | J13: =TRUNC(I13*C13,0) -> 6352664 | K13: =E13+G13+I13 -> 36943210 | L13: =F13+H13+J13 -> 295545680 | M13: No.717 | P13: 8300 | R13: SZD0001-600 | T13: T | BI13: =HYPERLINK("#일위대가목록!A619","SZD0001-600 →") -> SZD0001-600 →
A14: 부단수 천공(차단) | B14: 650A | C14: =수량집계!C9 -> 4 | D14: 공 | E14: =일위대가목록!F6 -> 34401427 | F14: =TRUNC(E14*C14,0) -> 137605708 | G14: =일위대가목록!G6 -> 4144605 | H14: =TRUNC(G14*C14,0) -> 16578420 | I14: =일위대가목록!H6 -> 796319 | J14: =TRUNC(I14*C14,0) -> 3185276 | K14: =E14+G14+I14 -> 39342351 | L14: =F14+H14+J14 -> 157369404 | M14: No.718 | P14: 8310 | R14: SZD0001-650 | T14: T | BI14: =HYPERLINK("#일위대가목록!A620","SZD0001-650 →") -> SZD0001-650 →
A15: 부단수 천공(차단) | B15: 700A | C15: =수량집계!C10 -> 0 | D15: 공 | E15: =일위대가목록!F7 -> 38234376 | F15: =TRUNC(E15*C15,0) -> 0 | G15: =일위대가목록!G7 -> 4376697 | H15: =TRUNC(G15*C15,0) -> 0 | I15: =일위대가목록!H7 -> 841347 | J15: =TRUNC(I15*C15,0) -> 0 | K15: =E15+G15+I15 -> 43452420 | L15: =F15+H15+J15 -> 0 | M15: No.719 | P15: 8320 | R15: SZD0001-700 | T15: T | BI15: =HYPERLINK("#일위대가목록!A621","SZD0001-700 →") -> SZD0001-700 →
A16: 부단수 천공(차단) | B16: 750A | C16: =수량집계!C11 -> 0 | D16: 공 | E16: =일위대가목록!F8 -> 44056471 | F16: =TRUNC(E16*C16,0) -> 0 | G16: =일위대가목록!G8 -> 4609505 | H16: =TRUNC(G16*C16,0) -> 0 | I16: =일위대가목록!H8 -> 843446 | J16: =TRUNC(I16*C16,0) -> 0 | K16: =E16+G16+I16 -> 49509422 | L16: =F16+H16+J16 -> 0 | M16: No.720 | P16: 8330 | R16: SZD0001-750 | T16: T | BI16: =HYPERLINK("#일위대가목록!A622","SZD0001-750 →") -> SZD0001-750 →
A17: >계 | F17: =TRUNC(F16+F15+F14+F13+F12+F11,0) -> 395567740 | H17: =TRUNC(H16+H15+H14+H13+H12+H11,0) -> 47809404 | J17: =TRUNC(J16+J15+J14+J13+J12+J11,0) -> 9537940 | L17: =TRUNC(L16+L15+L14+L13+L12+L11,0) -> 452915084 | P17: 8340
F18: 0 | H18: 0 | J18: 0 | K18: =E18+G18+I18 -> 0 | L18: =F18+H18+J18 -> 0 | P18: 8350
A19: <기량시험> | F19: 0 | H19: 0 | J19: 0 | K19: =E19+G19+I19 -> 0 | L19: =F19+H19+J19 -> 0 | P19: 14890
A20: 용접공기량시험 | C20: =5 -> 5 | D20: 인 | E20: =일위대가목록!F9 -> 0 | F20: =C20*E20 -> 0 | G20: =일위대가목록!G9 -> 249476 | H20: =C20*G20 -> 1247380 | I20: =일위대가목록!H9 -> 0 | J20: =C20*I20 -> 0 | K20: =E20+G20+I20 -> 249476 | L20: =F20+H20+J20 -> 1247380 | M20: No.806 | P20: 14900

Sheet 내역서(서부지사)-2차
A1: 내역서
A2: 공 종 명 | B2: 규 격 | C2: 수량 | D2: 단위 | E2: 재 료 비 | G2: 노 무 비 | I2: 경 비 | K2: 합 계 | M2: 비 고
E3: 단 가 | F3: 금 액 | G3: 단 가 | H3: 금 액 | I3: 단 가 | J3: 금 액 | K3: 단 가 | L3: 금 액 | S3: 할 증 | T3: 화폐변환 | U3: OP값 | V3: EQ | W3: LA | X3: MA | Y3: 금액계상
A4: 공사비내역집계 | C4: 1 | D4: 식 | F4: =TRUNC(F5,0) -> 0 | H4: =TRUNC(H5,0) -> 0 | J4: =TRUNC(J5,0) -> 0 | L4: =F4+H4+J4 -> 0 | O4: A00
A5: 1.배관공사 | C5: 1 | D5: 식 | E5: =F9 -> 0 | F5: =TRUNC(E5*C5,0) -> 0 | G5: =H9 -> 0 | H5: =TRUNC(G5*C5,0) -> 0 | I5: =J9 -> 0 | J5: =TRUNC(I5*C5,0) -> 0 | K5: =E5+G5+I5 -> 0 | L5: =F5+H5+J5 -> 0 | P5: 5 | R5: A01 | BI5: =HYPERLINK("#내역서!A9","A01 →") -> A01 →
A6: >>총계 | F6: =TRUNC(F5,0) -> 0 | H6: =TRUNC(H5,0) -> 0 | J6: =TRUNC(J5,0) -> 0 | K6: =E6+G6+I6 -> 0 | L6: =F6+H6+J6 -> 0 | P6: 90
P7: 100
A9: 1.배관공사 | C9: 1 | D9: 식 | F9: =F17 -> 0 | H9: =H17 -> 0 | J9: =J17 -> 0 | L9: =F9+H9+J9 -> 0 | O9: A01 | Z9: =#REF!+#REF!+#REF!+#REF!+#REF!+#REF!+#REF!+#REF!+#REF!+#REF!+#REF!+#REF!+#REF!+#REF!+#REF!+#REF!+#REF!+#REF!+#REF!+#REF!+#REF!+#REF!+#REF!+#REF!+#REF!+#REF!+#REF!+#REF!+#REF!+#REF!+#REF!+#REF!+#REF!+#REF!+#REF!+#REF!+#REF! -> #REF! | AA9: =#REF!+#REF!+#REF!+#REF!+#REF!+#REF!+#REF!+#REF!+#REF!+#REF!+#REF!+#REF!+#REF!+#REF!+#REF!+#REF!+#REF!+#REF!+#REF!+#REF!+#REF!+#REF!+#REF!+#REF!+#REF!+#REF!+#REF!+#REF!+#REF!+#REF!+#REF!+#REF!+#REF!+#REF!+#REF!+#REF!+#REF! -> #REF! | AB9: =#REF!+#REF!+#REF!+#REF!+#REF!+#REF!+#REF!+#REF!+#REF!+#REF!+#REF!+#REF!+#REF!+#REF!+#REF!+#REF!+#REF!+#REF!+#REF!+#REF!+#REF!+#REF!+#REF!+#REF!+#REF!+#REF!+#REF!+#REF!+#REF!+#REF!+#REF!+#REF!+#REF!+#REF!+#REF!+#REF!+#REF! -> #REF!
A10: 부단수 천공 | F10: 0 | H10: 0 | J10: 0 | K10: =E10+G10+I10 -> 0 | L10: =F10+H10+J10 -> 0 | P10: 8030
A11: 부단수 천공(차단) | B11: 300A | C11: =수량집계!D6 -> 0 | D11: 공 | E11: =일위대가목록!F3 -> 10581357 | F11: =TRUNC(E11*C11,0) -> 0 | G11: =일위대가목록!G3 -> 2096589 | H11: =TRUNC(G11*C11,0) -> 0 | I11: =일위대가목록!H3 -> 699695 | J11: =TRUNC(I11*C11,0) -> 0 | K11: =E11+G11+I11 -> 13377641 | L11: =F11+H11+J11 -> 0 | M11: No.711 | P11: 8240 | R11: SZD0001-300 | T11: T | BI11: =HYPERLINK("#일위대가목록!A613","SZD0001-300 →") -> SZD0001-300 →
A12: 부단수 천공(차단) | B12: 450A | C12: =수량집계!D7 -> 0 | D12: 공 | E12: =일위대가목록!F4 -> 20995856 | F12: =TRUNC(E12*C12,0) -> 0 | G12: =일위대가목록!G4 -> 2897828 | H12: =TRUNC(G12*C12,0) -> 0 | I12: =일위대가목록!H4 -> 783296 | J12: =TRUNC(I12*C12,0) -> 0 | K12: =E12+G12+I12 -> 24676980 | L12: =F12+H12+J12 -> 0 | M12: No.714 | P12: 8270 | R12: SZD0001-450 | T12: T | BI12: =HYPERLINK("#일위대가목록!A616","SZD0001-450 →") -> SZD0001-450 →
A13: 부단수 천공(차단) | B13: 600A | C13: =수량집계!D8 -> 0 | D13: 공 | E13: =일위대가목록!F5 -> 32245254 | F13: =TRUNC(E13*C13,0) -> 0 | G13: =일위대가목록!G5 -> 3903873 | H13: =TRUNC(G13*C13,0) -> 0 | I13: =일위대가목록!H5 -> 794083 | J13: =TRUNC(I13*C13,0) -> 0 | K13: =E13+G13+I13 -> 36943210 | L13: =F13+H13+J13 -> 0 | M13: No.717 | P13: 8300 | R13: SZD0001-600 | T13: T | BI13: =HYPERLINK("#일위대가목록!A619","SZD0001-600 →") -> SZD0001-600 →
A14: 부단수 천공(차단) | B14: 650A | C14: =수량집계!D9 -> 0 | D14: 공 | E14: =일위대가목록!F6 -> 34401427 | F14: =TRUNC(E14*C14,0) -> 0 | G14: =일위대가목록!G6 -> 4144605 | H14: =TRUNC(G14*C14,0) -> 0 | I14: =일위대가목록!H6 -> 796319 | J14: =TRUNC(I14*C14,0) -> 0 | K14: =E14+G14+I14 -> 39342351 | L14: =F14+H14+J14 -> 0 | M14: No.718 | P14: 8310 | R14: SZD0001-650 | T14: T | BI14: =HYPERLINK("#일위대가목록!A620","SZD0001-650 →") -> SZD0001-650 →
A15: 부단수 천공(차단) | B15: 700A | C15: =수량집계!D10 -> 0 | D15: 공 | E15: =일위대가목록!F7 -> 38234376 | F15: =TRUNC(E15*C15,0) -> 0 | G15: =일위대가목록!G7 -> 4376697 | H15: =TRUNC(G15*C15,0) -> 0 | I15: =일위대가목록!H7 -> 841347 | J15: =TRUNC(I15*C15,0) -> 0 | K15: =E15+G15+I15 -> 43452420 | L15: =F15+H15+J15 -> 0 | M15: No.719 | P15: 8320 | R15: SZD0001-700 | T15: T | BI15: =HYPERLINK("#일위대가목록!A621","SZD0001-700 →") -> SZD0001-700 →
A16: 부단수 천공(차단) | B16: 750A | C16: =수량집계!D11 -> 0 | D16: 공 | E16: =일위대가목록!F8 -> 44056471 | F16: =TRUNC(E16*C16,0) -> 0 | G16: =일위대가목록!G8 -> 4609505 | H16: =TRUNC(G16*C16,0) -> 0 | I16: =일위대가목록!H8 -> 843446 | J16: =TRUNC(I16*C16,0) -> 0 | K16: =E16+G16+I16 -> 49509422 | L16: =F16+H16+J16 -> 0 | M16: No.720 | P16: 8330 | R16: SZD0001-750 | T16: T | BI16: =HYPERLINK("#일위대가목록!A622","SZD0001-750 →") -> SZD0001-750 →
A17: >계 | F17: =TRUNC(F16+F15+F14+F13+F12+F11,0) -> 0 | H17: =TRUNC(H16+H15+H14+H13+H12+H11,0) -> 0 | J17: =TRUNC(J16+J15+J14+J13+J12+J11,0) -> 0 | L17: =F17+H17+J17 -> 0 | P17: 8340
F18: 0 | H18: 0 | J18: 0 | K18: =E18+G18+I18 -> 0 | L18: =F18+H18+J18 -> 0 | P18: 8350
F19: 0 | H19: 0 | J19: 0 | K19: =E19+G19+I19 -> 0 | L19: =F19+H19+J19 -> 0 | P19: 14890
F20: 0 | H20: 0 | J20: 0 | K20: =E20+G20+I20 -> 0 | L20: =F20+H20+J20 -> 0 | P20: 14900

Sheet 원가계산서(동부지사)
A1: 공 사 원 가 계 산 서 | F1: 공 사 원 가 계 산 서 | K1: 공 사 원 가 계 산 서
A2: □ 2026년~2027년 양지사 열수송관 천공 및 부단수 공사(동부지사) 총차 | F2: □ 2026년~2027년 양지사 열수송관 천공 및 부단수 공사(동부지사) 1차 | K2: □ 2026년~2027년 양지사 열수송관 천공 및 부단수 공사(동부지사) 2차
E3: (단위:원) | J3: (단위:원) | O3: (단위:원)
A4: 구 분 | D4: 금 액 | E4: 비 고 | F4: 구 분 | I4: 금 액 | J4: 비 고 | K4: 구 분 | N4: 금 액 | O4: 비 고
A6: 1. 공 사 원 가 | B6: 가. 재료비 | C6: 1 ) 직접재료비 | D6: =I6+N6 -> 504965006 | F6: 1. 공 사 원 가 | G6: 가. 재료비 | H6: 1 ) 직접재료비 | I6: ='내역서(동부지사)-1차'!F6 -> 378656154 | K6: 1. 공 사 원 가 | L6: 가. 재료비 | M6: 1 ) 직접재료비 | N6: ='내역서(동부지사)-2차'!F6 -> 126308852
C7: 2 ) 간접재료비 | D7: =I7+N7 -> 0 | H7: 2 ) 간접재료비 | I7: 0 | M7: 2 ) 간접재료비 | N7: =0 -> 0
C8: 소 계 | D8: =I8+N8 -> 504965006 | H8: 소 계 | I8: =I6+I7 -> 378656154 | M8: 소 계 | N8: =N6+N7 -> 126308852
B9: 나. 노무비 | C9: 1 ) 직접노무비 | D9: =I9+N9 -> 63281886 | G9: 나. 노무비 | H9: 1 ) 직접노무비 | I9: ='내역서(동부지사)-1차'!H6 -> 43304218 | L9: 나. 노무비 | M9: 1 ) 직접노무비 | N9: ='내역서(동부지사)-2차'!H6 -> 19977668
C10: 2 ) 간접노무비 | D10: =I10+N10 -> 9555563 | E10: ='원가계산서(양지사)'!E10 -> 나 1)의 15.1% | H10: 2 ) 간접노무비 | I10: =INT(I9*15.1%) -> 6538936 | J10: =E10 -> 나 1)의 15.1% | M10: 2 ) 간접노무비 | N10: =INT(N9*15.1%) -> 3016627 | O10: =E10 -> 나 1)의 15.1% | P10: 0.151
C11: 소 계 | D11: =I11+N11 -> 72837449 | H11: 소 계 | I11: =SUM(I9:I10) -> 49843154 | M11: 소 계 | N11: =SUM(N9:N10) -> 22994295 | O11: =E11 -> 0
B12: 다. 경 비 | C12: 1 ) 기계경비 | D12: =I12+N12 -> 14169520 | G12: 다. 경 비 | H12: 1 ) 기계경비 | I12: ='내역서(동부지사)-1차'!J6 -> 8237556 | L12: 다. 경 비 | M12: 1 ) 기계경비 | N12: ='내역서(동부지사)-2차'!J6 -> 5931964 | O12: =E12 -> 0
C13: 2 ) 산재보험료 | D13: =I13+N13 -> 2593012 | E13: ='원가계산서(양지사)'!E13 -> 나 ) 의 3.56% | H13: 2 ) 산재보험료 | I13: =INT(I11*3.56%) -> 1774416 | J13: =E13 -> 나 ) 의 3.56% | M13: 2 ) 산재보험료 | N13: =INT(N11*3.56%) -> 818596 | O13: =E13 -> 나 ) 의 3.56% | P13: =3.56*0.01 -> 0.0356
C14: 3 ) 고용보험료 | D14: =I14+N14 -> 735657 | E14: ='원가계산서(양지사)'!E14 -> 나 ) 의 1.01% | H14: 3 ) 고용보험료 | I14: =INT(I11*1.01%) -> 503415 | J14: =E14 -> 나 ) 의 1.01% | M14: 3 ) 고용보험료 | N14: =INT(N11*1.01%) -> 232242 | O14: =E14 -> 나 ) 의 1.01% | P14: =1.01*0.01 -> 0.0101
C15: 4 ) 건강보험료 | D15: =I15+N15 -> 2576457 | E15: ='원가계산서(양지사)'!E15 -> 나 1)의 3.595% | H15: 4 ) 건강보험료 | I15: 1763087 | J15: =E15 -> 나 1)의 3.595% | M15: 4 ) 건강보험료 | N15: 813370 | O15: =E15 -> 나 1)의 3.595% | P15: =3.545*0.01 -> 0.03545 | R15: 2026년 신규 비율 반영 3.545% → 3.595%
C16: 5 ) 노인장기요양보험료 | D16: =I16+N16 -> 338545 | E16: ='원가계산서(양지사)'!E16 -> 다 4)의 13.14% | H16: 5 ) 노인장기요양보험료 | I16: 231669 | J16: =E16 -> 다 4)의 13.14% | M16: 5 ) 노인장기요양보험료 | N16: 106876 | O16: =E16 -> 다 4)의 13.14% | P16: =12.95*0.01 -> 0.1295 | R16: 2026년 신규 비율 반영 12.95% → 13.14%
C17: 6 ) 연금보험료 | D17: =I17+N17 -> 3404220 | E17: ='원가계산서(양지사)'!E17 -> 나 1)의 4.75% | H17: 6 ) 연금보험료 | I17: 2329531 | J17: =E17 -> 나 1)의 4.75% | M17: 6 ) 연금보험료 | N17: 1074689 | O17: =E17 -> 나 1)의 4.75% | P17: =4.5*0.01 -> 0.045 | R17: 2026년 신규 비율 반영 4.5% → 4.75%
C18: 7 ) 환경보전비 | D18: =I18+N18 -> 1747248 | E18: ='원가계산서(양지사)'!E18 -> (재+직노+기경)*0.3% | H18: 7 ) 환경보전비 | I18: =INT((I6+I9+I12)*0.3%) -> 1290593 | J18: =E18 -> (재+직노+기경)*0.3% | M18: 7 ) 환경보전비 | N18: =INT((N6+N9+N12)*0.3%) -> 456655 | O18: =E18 -> (재+직노+기경)*0.3% | P18: =0.3*0.01 -> 0.003
C19: 8 ) 산업안전보건관리비 | D19: =I19+N19 -> 17102352 | E19: ='원가계산서(양지사)'!E19 -> 가+나1)의 2.28%+4,325천원 | H19: 8 ) 산업안전보건관리비 | I19: 12699612 | J19: =E19 -> 가+나1)의 2.28%+4,325천원 | M19: 8 ) 산업안전보건관리비 | N19: 4402740 | O19: =E19 -> 가+나1)의 2.28%+4,325천원
C20: 9 ) 퇴직공제부금비 | D20: =I20+N20 -> 1648359 | E20: ='원가계산서(양지사)'!E20 -> 나 1)의 2.3% | H20: 9 ) 퇴직공제부금비 | I20: 1127983 | J20: =E20 -> 나 1)의 2.3% | M20: 9 ) 퇴직공제부금비 | N20: 520376 | O20: =E20 -> 나 1)의 2.3% | P20: =2.3*0.01 -> 0.023
C21: 10 ) 기타 경 비 | D21: =I21+N21 -> 29467924 | E21: ='원가계산서(양지사)'!E21 -> (가+나)의 5.1% | H21: 10 ) 기타 경 비 | I21: =INT((I6+I11)*5.1%) -> 21853464 | J21: =E21 -> (가+나)의 5.1% | M21: 10 ) 기타 경 비 | N21: =INT((N6+N11)*5.1%) -> 7614460 | O21: =E21 -> (가+나)의 5.1% | P21: =5.1*0.01 -> 0.051
C22: 11 ) 건설기계대여대금 지급보증액 발급 | D22: =I22+N22 -> 582415 | E22: ='원가계산서(양지사)'!E22 -> 가1)+나1)+다1)의 0.1% | H22: 11 ) 건설기계대여대금 지급보증액 발급 | I22: =INT((I6+I9+I12)*0.1%) -> 430197 | J22: =E22 -> 가1)+나1)+다1)의 0.1% | M22: 11 ) 건설기계대여대금 지급보증액 발급 | N22: =INT((N6+N9+N12)*0.1%) -> 152218 | O22: =E22 -> 가1)+나1)+다1)의 0.1% | P22: =0.1*0.01 -> 0.001
C23: 12 ) 품질시험관리비 | D23: =I23+N23 -> 1412680 | H23: 12 ) 품질시험관리비 | I23: 1412680 | M23: 12 ) 품질시험관리비 | N23: 0
C24: 소 계 | D24: =I24+N24 -> 75778389 | H24: 소 계 | I24: =SUM(I12:I23) -> 53654203 | M24: 소 계 | N24: =SUM(N12:N23) -> 22124186
B25: 계 | D25: =I25+N25 -> 653580844 | G25: 계 | I25: =I8+I11+I24 -> 482153511 | L25: 계 | N25: =N8+N11+N24 -> 171427333
A26: 2 | B26: 일 반 관 리 비 | D26: =I26+N26 -> 42482754 | E26: ='원가계산서(양지사)'!E26 -> 1 의 6.5% | F26: 2 | G26: 일 반 관 리 비 | I26: =INT(I25*6.5%) -> 31339978 | J26: =E26 -> 1 의 6.5% | K26: 2 | L26: 일 반 관 리 비 | N26: =INT(N25*6.5%) -> 11142776 | O26: =E26 -> 1 의 6.5% | P26: 0.065
A27: 3 | B27: 이 윤 | D27: =I27+N27 -> 28664782 | E27: ='원가계산서(양지사)'!E27 -> 나+다+2의 15% | F27: 3 | G27: 이 윤 | I27: =INT((I11+I24+I26)*15%)-7 -> 20225593 | J27: =E27 -> 나+다+2의 15% | K27: 3 | L27: 이 윤 | N27: =INT((N11+N24+N26)*15%)+1 -> 8439189 | O27: =E27 -> 나+다+2의 15% | P27: =15*0.01 -> 0.15
A28: 4 | B28: 고용개선지원비(PS단가) | D28: =I28+N28 -> 8947011 | F28: 4 | G28: 고용개선지원비(PS단가) | I28: 6122500 | K28: 4 | L28: 고용개선지원비(PS단가) | N28: 2824511 | R28: 11.9% → 14.2%(계약심사) → 14.5%(매뉴얼개정), 고용개선장려금 50% 적용
A29: 5 | B29: 합 계 | D29: =I29+N29 -> 733675391 | F29: 5 | G29: 합 계 | I29: =SUM(I25:I28) -> 539841582 | K29: 5 | L29: 합 계 | N29: =SUM(N25:N28) -> 193833809
A30: 6 | B30: 부 가 가 치 세 | D30: =I30+N30 -> 73367539 | E30: ='원가계산서(양지사)'!E30 -> 5의 10% | F30: 6 | G30: 부 가 가 치 세 | I30: =INT(I29*10%) -> 53984158 | J30: =E30 -> 5의 10% | K30: 6 | L30: 부 가 가 치 세 | N30: =INT(N29*10%)+1 -> 19383381 | O30: =E30 -> 5의 10%
A31: 7 | B31: 총 계 | D31: =I31+N31 -> 807042930 | F31: 7 | G31: 총 계 | I31: =I29+I30 -> 593825740 | K31: 7 | L31: 총 계 | N31: =N29+N30 -> 213217190
A32: ※ 제비율 적용기준 : 2026년도 건축·산업환경설비공사 원가계산
I35: 재료비 + 경비 | J35: 비율 | K35: 기초액
H36: 서부1차 | I36: ='내역서(서부지사)-1차'!$F$6+'내역서(서부지사)-1차'!$H$6 -> 443377144 | J36: =I36/SUM($I$36:$I$39) -> 0.43828253 | K36: =ROUND(4325000*$J$36,0) -> 1895572
H37: 서부2차 | I37: ='내역서(서부지사)-2차'!$F$6+'내역서(서부지사)-2차'!$H$6 -> 0 | J37: =I37/SUM($I$36:$I$39) -> 0 | K37: =ROUND(4325000*$J$37,0) -> 0
H38: 동부1차 | I38: ='내역서(동부지사)-1차'!$F$6+'내역서(동부지사)-1차'!$H$6 -> 421960372 | J38: =I38/SUM($I$36:$I$39) -> 0.41711185 | K38: =ROUND(4325000*$J$38,0) -> 1804009
H39: 동부2차 | I39: ='내역서(동부지사)-2차'!$F$6+'내역서(동부지사)-2차'!$H$6 -> 146286520 | J39: =I39/SUM($I$36:$I$39) -> 0.14460562 | K39: =ROUND(4325000*$J$39,0) -> 625419
J41: 산업안전보건관리비 기초액 총계 | K41: =SUM(K36:K39) -> 4325000

Sheet 내역서(동부지사)-0차
A1: 내역서
A2: 공 종 명 | B2: 규 격 | C2: 수량 | D2: 단위 | E2: 재 료 비 | G2: 노 무 비 | I2: 경 비 | K2: 합 계 | M2: 비 고
E3: 단 가 | F3: 금 액 | G3: 단 가 | H3: 금 액 | I3: 단 가 | J3: 금 액 | K3: 단 가 | L3: 금 액 | S3: 할 증 | T3: 화폐변환 | U3: OP값 | V3: EQ | W3: LA | X3: MA | Y3: 금액계상
A4: 공사비내역집계 | C4: 1 | D4: 식 | F4: =TRUNC(F5,0) -> #REF! | H4: =TRUNC(H5,0) -> #REF! | J4: =TRUNC(J5,0) -> #REF! | L4: =F4+H4+J4 -> #REF! | O4: A00
A5: 1.배관공사 | C5: 1 | D5: 식 | E5: =F9 -> #REF! | F5: =TRUNC(E5*C5,0) -> #REF! | G5: =H9 -> #REF! | H5: =TRUNC(G5*C5,0) -> #REF! | I5: =J9 -> #REF! | J5: =TRUNC(I5*C5,0) -> #REF! | K5: =E5+G5+I5 -> #REF! | L5: =F5+H5+J5 -> #REF! | P5: 5 | R5: A01 | BI5: =HYPERLINK("#내역서!A9","A01 →") -> A01 →
A6: >>총계 | F6: =TRUNC(F5,0) -> #REF! | H6: =TRUNC(H5,0) -> #REF! | J6: =TRUNC(J5,0) -> #REF! | K6: =E6+G6+I6 -> 0 | L6: =F6+H6+J6 -> #REF! | P6: 90
F7: 0 | H7: 0 | J7: 0 | K7: =E7+G7+I7 -> 0 | L7: =F7+H7+J7 -> 0 | P7: 100
A9: 1.배관공사 | C9: 1 | D9: 식 | F9: =F26 -> #REF! | H9: =H26 -> #REF! | J9: =J26 -> #REF! | L9: =F9+H9+J9 -> #REF! | O9: A01 | Z9: =#REF!+#REF!+#REF!+#REF!+#REF!+#REF!+#REF!+#REF!+#REF!+#REF!+#REF!+#REF!+#REF!+#REF!+#REF!+#REF!+#REF!+#REF!+#REF!+#REF!+#REF!+#REF!+#REF!+#REF!+#REF!+#REF!+#REF!+#REF!+#REF!+#REF!+#REF!+#REF!+#REF!+#REF!+#REF!+#REF!+#REF! -> #REF! | AA9: =#REF!+#REF!+#REF!+#REF!+#REF!+#REF!+#REF!+#REF!+#REF!+#REF!+#REF!+#REF!+#REF!+#REF!+#REF!+#REF!+#REF!+#REF!+#REF!+#REF!+#REF!+#REF!+#REF!+#REF!+#REF!+#REF!+#REF!+#REF!+#REF!+#REF!+#REF!+#REF!+#REF!+#REF!+#REF!+#REF!+#REF! -> #REF! | AB9: =#REF!+#REF!+#REF!+#REF!+#REF!+#REF!+#REF!+#REF!+#REF!+#REF!+#REF!+#REF!+#REF!+#REF!+#REF!+#REF!+#REF!+#REF!+#REF!+#REF!+#REF!+#REF!+#REF!+#REF!+#REF!+#REF!+#REF!+#REF!+#REF!+#REF!+#REF!+#REF!+#REF!+#REF!+#REF!+#REF!+#REF! -> #REF!
A10: 부단수 천공 | F10: 0 | H10: 0 | J10: 0 | K10: =E10+G10+I10 -> 0 | L10: =F10+H10+J10 -> 0 | P10: 8030
A11: 부단수 천공(차단) | B11: 100A | C11: =수량집계!#REF! -> #REF! | D11: 공 | E11: =일위대가목록!#REF! -> #REF! | F11: =TRUNC(E11*C11,0) -> #REF! | G11: =일위대가목록!#REF! -> #REF! | H11: =TRUNC(G11*C11,0) -> #REF! | I11: =일위대가목록!#REF! -> #REF! | J11: =TRUNC(I11*C11,0) -> #REF! | K11: =E11+G11+I11 -> #REF! | L11: =F11+H11+J11 -> #REF! | M11: No.706 | P11: 8190 | R11: SZD0001-100 | T11: T | BI11: =HYPERLINK("#일위대가목록!A608","SZD0001-100 →") -> SZD0001-100 →
A12: 부단수 천공(차단) | B12: 125A | C12: =수량집계!#REF! -> #REF! | D12: 공 | E12: =일위대가목록!#REF! -> #REF! | F12: =TRUNC(E12*C12,0) -> #REF! | G12: =일위대가목록!#REF! -> #REF! | H12: =TRUNC(G12*C12,0) -> #REF! | I12: =일위대가목록!#REF! -> #REF! | J12: =TRUNC(I12*C12,0) -> #REF! | K12: =E12+G12+I12 -> #REF! | L12: =F12+H12+J12 -> #REF! | M12: No.707 | P12: 8200 | R12: SZD0001-125 | T12: T | BI12: =HYPERLINK("#일위대가목록!A609","SZD0001-125 →") -> SZD0001-125 →
A13: 부단수 천공(차단) | B13: 150A | C13: =수량집계!#REF! -> #REF! | D13: 공 | E13: =일위대가목록!#REF! -> #REF! | F13: =TRUNC(E13*C13,0) -> #REF! | G13: =일위대가목록!#REF! -> #REF! | H13: =TRUNC(G13*C13,0) -> #REF! | I13: =일위대가목록!#REF! -> #REF! | J13: =TRUNC(I13*C13,0) -> #REF! | K13: =E13+G13+I13 -> #REF! | L13: =F13+H13+J13 -> #REF! | M13: No.708 | P13: 8210 | R13: SZD0001-150 | T13: T | BI13: =HYPERLINK("#일위대가목록!A610","SZD0001-150 →") -> SZD0001-150 →
A14: 부단수 천공(차단) | B14: 200A | C14: =수량집계!#REF! -> #REF! | D14: 공 | E14: =일위대가목록!#REF! -> #REF! | F14: =TRUNC(E14*C14,0) -> #REF! | G14: =일위대가목록!#REF! -> #REF! | H14: =TRUNC(G14*C14,0) -> #REF! | I14: =일위대가목록!#REF! -> #REF! | J14: =TRUNC(I14*C14,0) -> #REF! | K14: =E14+G14+I14 -> #REF! | L14: =F14+H14+J14 -> #REF! | M14: No.709 | P14: 8220 | R14: SZD0001-200 | T14: T | BI14: =HYPERLINK("#일위대가목록!A611","SZD0001-200 →") -> SZD0001-200 →
A15: 부단수 천공(차단) | B15: 250A | C15: =수량집계!#REF! -> #REF! | D15: 공 | E15: =일위대가목록!#REF! -> #REF! | F15: =TRUNC(E15*C15,0) -> #REF! | G15: =일위대가목록!#REF! -> #REF! | H15: =TRUNC(G15*C15,0) -> #REF! | I15: =일위대가목록!#REF! -> #REF! | J15: =TRUNC(I15*C15,0) -> #REF! | K15: =E15+G15+I15 -> #REF! | L15: =F15+H15+J15 -> #REF! | M15: No.710 | P15: 8230 | R15: SZD0001-250 | T15: T | BI15: =HYPERLINK("#일위대가목록!A612","SZD0001-250 →") -> SZD0001-250 →
A16: 부단수 천공(차단) | B16: 300A | C16: =수량집계!#REF! -> #REF! | D16: 공 | E16: =일위대가목록!F3 -> 10581357 | F16: =TRUNC(E16*C16,0) -> #REF! | G16: =일위대가목록!G3 -> 2096589 | H16: =TRUNC(G16*C16,0) -> #REF! | I16: =일위대가목록!H3 -> 699695 | J16: =TRUNC(I16*C16,0) -> #REF! | K16: =E16+G16+I16 -> 13377641 | L16: =F16+H16+J16 -> #REF! | M16: No.711 | P16: 8240 | R16: SZD0001-300 | T16: T | BI16: =HYPERLINK("#일위대가목록!A613","SZD0001-300 →") -> SZD0001-300 →
A17: 부단수 천공(차단) | B17: 350A | C17: =수량집계!#REF! -> #REF! | D17: 공 | E17: =일위대가목록!#REF! -> #REF! | F17: =TRUNC(E17*C17,0) -> #REF! | G17: =일위대가목록!#REF! -> #REF! | H17: =TRUNC(G17*C17,0) -> #REF! | I17: =일위대가목록!#REF! -> #REF! | J17: =TRUNC(I17*C17,0) -> #REF! | K17: =E17+G17+I17 -> #REF! | L17: =F17+H17+J17 -> #REF! | M17: No.712 | P17: 8250 | R17: SZD0001-350 | T17: T | BI17: =HYPERLINK("#일위대가목록!A614","SZD0001-350 →") -> SZD0001-350 →
A18: 부단수 천공(차단) | B18: 400A | C18: =수량집계!#REF! -> #REF! | D18: 공 | E18: =일위대가목록!#REF! -> #REF! | F18: =TRUNC(E18*C18,0) -> #REF! | G18: =일위대가목록!#REF! -> #REF! | H18: =TRUNC(G18*C18,0) -> #REF! | I18: =일위대가목록!#REF! -> #REF! | J18: =TRUNC(I18*C18,0) -> #REF! | K18: =E18+G18+I18 -> #REF! | L18: =F18+H18+J18 -> #REF! | M18: No.713 | P18: 8260 | R18: SZD0001-400 | T18: T | BI18: =HYPERLINK("#일위대가목록!A615","SZD0001-400 →") -> SZD0001-400 →
A19: 부단수 천공(차단) | B19: 450A | C19: =수량집계!#REF! -> #REF! | D19: 공 | E19: =일위대가목록!F4 -> 20995856 | F19: =TRUNC(E19*C19,0) -> #REF! | G19: =일위대가목록!G4 -> 2897828 | H19: =TRUNC(G19*C19,0) -> #REF! | I19: =일위대가목록!H4 -> 783296 | J19: =TRUNC(I19*C19,0) -> #REF! | K19: =E19+G19+I19 -> 24676980 | L19: =F19+H19+J19 -> #REF! | M19: No.714 | P19: 8270 | R19: SZD0001-450 | T19: T | BI19: =HYPERLINK("#일위대가목록!A616","SZD0001-450 →") -> SZD0001-450 →
A20: 부단수 천공(차단) | B20: 500A | C20: =수량집계!#REF! -> #REF! | D20: 공 | E20: =일위대가목록!#REF! -> #REF! | F20: =TRUNC(E20*C20,0) -> #REF! | G20: =일위대가목록!#REF! -> #REF! | H20: =TRUNC(G20*C20,0) -> #REF! | I20: =일위대가목록!#REF! -> #REF! | J20: =TRUNC(I20*C20,0) -> #REF! | K20: =E20+G20+I20 -> #REF! | L20: =F20+H20+J20 -> #REF! | M20: No.715 | P20: 8280 | R20: SZD0001-500 | T20: T | BI20: =HYPERLINK("#일위대가목록!A617","SZD0001-500 →") -> SZD0001-500 →
A21: 부단수 천공(차단) | B21: 550A | C21: =수량집계!#REF! -> #REF! | D21: 공 | E21: =일위대가목록!#REF! -> #REF! | F21: =TRUNC(E21*C21,0) -> #REF! | G21: =일위대가목록!#REF! -> #REF! | H21: =TRUNC(G21*C21,0) -> #REF! | I21: =일위대가목록!#REF! -> #REF! | J21: =TRUNC(I21*C21,0) -> #REF! | K21: =E21+G21+I21 -> #REF! | L21: =F21+H21+J21 -> #REF! | M21: No.716 | P21: 8290 | R21: SZD0001-550 | T21: T | BI21: =HYPERLINK("#일위대가목록!A618","SZD0001-550 →") -> SZD0001-550 →
A22: 부단수 천공(차단) | B22: 600A | C22: =수량집계!#REF! -> #REF! | D22: 공 | E22: =일위대가목록!F5 -> 32245254 | F22: =TRUNC(E22*C22,0) -> #REF! | G22: =일위대가목록!G5 -> 3903873 | H22: =TRUNC(G22*C22,0) -> #REF! | I22: =일위대가목록!H5 -> 794083 | J22: =TRUNC(I22*C22,0) -> #REF! | K22: =E22+G22+I22 -> 36943210 | L22: =F22+H22+J22 -> #REF! | M22: No.717 | P22: 8300 | R22: SZD0001-600 | T22: T | BI22: =HYPERLINK("#일위대가목록!A619","SZD0001-600 →") -> SZD0001-600 →
A23: 부단수 천공(차단) | B23: 650A | C23: =수량집계!#REF! -> #REF! | D23: 공 | E23: =일위대가목록!F6 -> 34401427 | F23: =TRUNC(E23*C23,0) -> #REF! | G23: =일위대가목록!G6 -> 4144605 | H23: =TRUNC(G23*C23,0) -> #REF! | I23: =일위대가목록!H6 -> 796319 | J23: =TRUNC(I23*C23,0) -> #REF! | K23: =E23+G23+I23 -> 39342351 | L23: =F23+H23+J23 -> #REF! | M23: No.718 | P23: 8310 | R23: SZD0001-650 | T23: T | BI23: =HYPERLINK("#일위대가목록!A620","SZD0001-650 →") -> SZD0001-650 →
A24: 부단수 천공(차단) | B24: 700A | C24: =수량집계!#REF! -> #REF! | D24: 공 | E24: =일위대가목록!F7 -> 38234376 | F24: =TRUNC(E24*C24,0) -> #REF! | G24: =일위대가목록!G7 -> 4376697 | H24: =TRUNC(G24*C24,0) -> #REF! | I24: =일위대가목록!H7 -> 841347 | J24: =TRUNC(I24*C24,0) -> #REF! | K24: =E24+G24+I24 -> 43452420 | L24: =F24+H24+J24 -> #REF! | M24: No.719 | P24: 8320 | R24: SZD0001-700 | T24: T | BI24: =HYPERLINK("#일위대가목록!A621","SZD0001-700 →") -> SZD0001-700 →
A25: 부단수 천공(차단) | B25: 750A | C25: =수량집계!#REF! -> #REF! | D25: 공 | E25: =일위대가목록!F8 -> 44056471 | F25: =TRUNC(E25*C25,0) -> #REF! | G25: =일위대가목록!G8 -> 4609505 | H25: =TRUNC(G25*C25,0) -> #REF! | I25: =일위대가목록!H8 -> 843446 | J25: =TRUNC(I25*C25,0) -> #REF! | K25: =E25+G25+I25 -> 49509422 | L25: =F25+H25+J25 -> #REF! | M25: No.720 | P25: 8330 | R25: SZD0001-750 | T25: T | BI25: =HYPERLINK("#일위대가목록!A622","SZD0001-750 →") -> SZD0001-750 →
A26: >계 | F26: =TRUNC(F25+F24+F23+F22+F21+F20+F19+F18+F17+F16+F15+F14+F13+F12+F11,0) -> #REF! | H26: =TRUNC(H25+H24+H23+H22+H21+H20+H19+H18+H17+H16+H15+H14+H13+H12+H11,0) -> #REF! | J26: =TRUNC(J25+J24+J23+J22+J21+J20+J19+J18+J17+J16+J15+J14+J13+J12+J11,0) -> #REF! | K26: =E26+G26+I26 -> 0 | L26: =F26+H26+J26 -> #REF! | P26: 8340
F27: 0 | H27: 0 | J27: 0 | K27: =E27+G27+I27 -> 0 | L27: =F27+H27+J27 -> 0 | P27: 8350
F28: 0 | H28: 0 | J28: 0 | K28: =E28+G28+I28 -> 0 | L28: =F28+H28+J28 -> 0 | P28: 14890
A29: <기량시험>
A30: 용접공기량시험 | C30: =0 -> 0 | D30: 인 | F30: =TRUNC(E30*C30,0) -> 0 | G30: =[2]노임!D5 -> 262551 | H30: =TRUNC(G30*C30,0) -> 0 | J30: =TRUNC(I30*C30,0) -> 0 | K30: =E30+G30+I30 -> 262551 | L30: =F30+H30+J30 -> 0 | P30: 14900

Sheet 내역서(동부지사)-1차
A1: 내역서
A2: 공 종 명 | B2: 규 격 | C2: 수량 | D2: 단위 | E2: 재 료 비 | G2: 노 무 비 | I2: 경 비 | K2: 합 계 | M2: 비 고
E3: 단 가 | F3: 금 액 | G3: 단 가 | H3: 금 액 | I3: 단 가 | J3: 금 액 | K3: 단 가 | L3: 금 액 | S3: 할 증 | T3: 화폐변환 | U3: OP값 | V3: EQ | W3: LA | X3: MA | Y3: 금액계상
A4: 공사비내역집계 | C4: 1 | D4: 식 | F4: =TRUNC(F5,0) -> 378656154 | H4: =TRUNC(H5,0) -> 43304218 | J4: =TRUNC(J5,0) -> 8237556 | L4: =F4+H4+J4 -> 430197928 | O4: A00
A5: 1.배관공사 | C5: 1 | D5: 식 | E5: =F9 -> 378656154 | F5: =TRUNC(E5*C5,0) -> 378656154 | G5: =H9 -> 43304218 | H5: =TRUNC(G5*C5,0) -> 43304218 | I5: =J9 -> 8237556 | J5: =TRUNC(I5*C5,0) -> 8237556 | K5: =E5+G5+I5 -> 430197928 | L5: =F5+H5+J5 -> 430197928 | P5: 5 | R5: A01 | BI5: =HYPERLINK("#내역서!A9","A01 →") -> A01 →
A6: >>총계 | F6: =TRUNC(F5,0) -> 378656154 | H6: =TRUNC(H5,0) -> 43304218 | J6: =TRUNC(J5,0) -> 8237556 | K6: =E6+G6+I6 -> 0 | L6: =F6+H6+J6 -> 430197928 | P6: 90
F7: 0 | H7: 0 | J7: 0 | K7: =E7+G7+I7 -> 0 | L7: =F7+H7+J7 -> 0 | P7: 100
A9: 1.배관공사 | C9: 1 | D9: 식 | F9: =F17 -> 378656154 | H9: =H17 -> 43304218 | J9: =J17 -> 8237556 | L9: =F9+H9+J9 -> 430197928 | O9: A01 | Z9: =#REF!+#REF!+#REF!+#REF!+#REF!+#REF!+#REF!+#REF!+#REF!+#REF!+#REF!+#REF!+#REF!+#REF!+#REF!+#REF!+#REF!+#REF!+#REF!+#REF!+#REF!+#REF!+#REF!+#REF!+#REF!+#REF!+#REF!+#REF!+#REF!+#REF!+#REF!+#REF!+#REF!+#REF!+#REF!+#REF!+#REF! -> #REF! | AA9: =#REF!+#REF!+#REF!+#REF!+#REF!+#REF!+#REF!+#REF!+#REF!+#REF!+#REF!+#REF!+#REF!+#REF!+#REF!+#REF!+#REF!+#REF!+#REF!+#REF!+#REF!+#REF!+#REF!+#REF!+#REF!+#REF!+#REF!+#REF!+#REF!+#REF!+#REF!+#REF!+#REF!+#REF!+#REF!+#REF!+#REF! -> #REF! | AB9: =#REF!+#REF!+#REF!+#REF!+#REF!+#REF!+#REF!+#REF!+#REF!+#REF!+#REF!+#REF!+#REF!+#REF!+#REF!+#REF!+#REF!+#REF!+#REF!+#REF!+#REF!+#REF!+#REF!+#REF!+#REF!+#REF!+#REF!+#REF!+#REF!+#REF!+#REF!+#REF!+#REF!+#REF!+#REF!+#REF!+#REF! -> #REF!
A10: 부단수 천공 | F10: 0 | H10: 0 | J10: 0 | K10: =E10+G10+I10 -> 0 | L10: =F10+H10+J10 -> 0 | P10: 8030
A11: 부단수 천공(차단) | B11: 300A | C11: =수량집계!F6 -> 0 | D11: 공 | E11: =일위대가목록!F3 -> 10581357 | F11: =TRUNC(E11*C11,0) -> 0 | G11: =일위대가목록!G3 -> 2096589 | H11: =TRUNC(G11*C11,0) -> 0 | I11: =일위대가목록!H3 -> 699695 | J11: =TRUNC(I11*C11,0) -> 0 | K11: =E11+G11+I11 -> 13377641 | L11: =F11+H11+J11 -> 0 | M11: No.711 | P11: 8240 | R11: SZD0001-300 | T11: T | BI11: =HYPERLINK("#일위대가목록!A613","SZD0001-300 →") -> SZD0001-300 →
A12: 부단수 천공(차단) | B12: 450A | C12: =수량집계!F7 -> 0 | D12: 공 | E12: =일위대가목록!F4 -> 20995856 | F12: =TRUNC(E12*C12,0) -> 0 | G12: =일위대가목록!G4 -> 2897828 | H12: =TRUNC(G12*C12,0) -> 0 | I12: =일위대가목록!H4 -> 783296 | J12: =TRUNC(I12*C12,0) -> 0 | K12: =E12+G12+I12 -> 24676980 | L12: =F12+H12+J12 -> 0 | M12: No.714 | P12: 8270 | R12: SZD0001-450 | T12: T | BI12: =HYPERLINK("#일위대가목록!A616","SZD0001-450 →") -> SZD0001-450 →
A13: 부단수 천공(차단) | B13: 600A | C13: =수량집계!F8 -> 0 | D13: 공 | E13: =일위대가목록!F5 -> 32245254 | F13: =TRUNC(E13*C13,0) -> 0 | G13: =일위대가목록!G5 -> 3903873 | H13: =TRUNC(G13*C13,0) -> 0 | I13: =일위대가목록!H5 -> 794083 | J13: =TRUNC(I13*C13,0) -> 0 | K13: =E13+G13+I13 -> 36943210 | L13: =F13+H13+J13 -> 0 | M13: No.717 | P13: 8300 | R13: SZD0001-600 | T13: T | BI13: =HYPERLINK("#일위대가목록!A619","SZD0001-600 →") -> SZD0001-600 →
A14: 부단수 천공(차단) | B14: 650A | C14: =수량집계!F9 -> 4 | D14: 공 | E14: =일위대가목록!F6 -> 34401427 | F14: =TRUNC(E14*C14,0) -> 137605708 | G14: =일위대가목록!G6 -> 4144605 | H14: =TRUNC(G14*C14,0) -> 16578420 | I14: =일위대가목록!H6 -> 796319 | J14: =TRUNC(I14*C14,0) -> 3185276 | K14: =E14+G14+I14 -> 39342351 | L14: =F14+H14+J14 -> 157369404 | M14: No.718 | P14: 8310 | R14: SZD0001-650 | T14: T | BI14: =HYPERLINK("#일위대가목록!A620","SZD0001-650 →") -> SZD0001-650 →
A15: 부단수 천공(차단) | B15: 700A | C15: =수량집계!F10 -> 4 | D15: 공 | E15: =일위대가목록!F7 -> 38234376 | F15: =TRUNC(E15*C15,0) -> 152937504 | G15: =일위대가목록!G7 -> 4376697 | H15: =TRUNC(G15*C15,0) -> 17506788 | I15: =일위대가목록!H7 -> 841347 | J15: =TRUNC(I15*C15,0) -> 3365388 | K15: =E15+G15+I15 -> 43452420 | L15: =F15+H15+J15 -> 173809680 | M15: No.719 | P15: 8320 | R15: SZD0001-700 | T15: T | BI15: =HYPERLINK("#일위대가목록!A621","SZD0001-700 →") -> SZD0001-700 →
A16: 부단수 천공(차단) | B16: 750A | C16: =수량집계!F11 -> 2 | D16: 공 | E16: =일위대가목록!F8 -> 44056471 | F16: =TRUNC(E16*C16,0) -> 88112942 | G16: =일위대가목록!G8 -> 4609505 | H16: =TRUNC(G16*C16,0) -> 9219010 | I16: =일위대가목록!H8 -> 843446 | J16: =TRUNC(I16*C16,0) -> 1686892 | K16: =E16+G16+I16 -> 49509422 | L16: =F16+H16+J16 -> 99018844 | M16: No.720 | P16: 8330 | R16: SZD0001-750 | T16: T | BI16: =HYPERLINK("#일위대가목록!A622","SZD0001-750 →") -> SZD0001-750 →
A17: >계 | F17: =TRUNC(F16+F15+F14+F13+F12+F11,0) -> 378656154 | H17: =TRUNC(H16+H15+H14+H13+H12+H11,0) -> 43304218 | J17: =TRUNC(J16+J15+J14+J13+J12+J11,0) -> 8237556 | L17: =TRUNC(L16+L15+L14+L13+L12+L11,0) -> 430197928 | P17: 8340
F18: 0 | H18: 0 | J18: 0 | K18: =E18+G18+I18 -> 0 | L18: =F18+H18+J18 -> 0 | P18: 8350
A19: <기량시험> | F19: 0 | H19: 0 | J19: 0 | K19: =E19+G19+I19 -> 0 | L19: =F19+H19+J19 -> 0 | P19: 14890
A20: 용접공기량시험 | C20: =5 -> 5 | D20: 인 | E20: =일위대가목록!F9 -> 0 | F20: =C20*E20 -> 0 | G20: =일위대가목록!G9 -> 249476 | H20: =C20*G20 -> 1247380 | I20: =일위대가목록!H9 -> 0 | J20: =C20*I20 -> 0 | K20: =E20+G20+I20 -> 249476 | L20: =F20+H20+J20 -> 1247380 | M20: No.806 | P20: 14900

Sheet 내역서(동부지사)-2차
A1: 내역서
A2: 공 종 명 | B2: 규 격 | C2: 수량 | D2: 단위 | E2: 재 료 비 | G2: 노 무 비 | I2: 경 비 | K2: 합 계 | M2: 비 고
E3: 단 가 | F3: 금 액 | G3: 단 가 | H3: 금 액 | I3: 단 가 | J3: 금 액 | K3: 단 가 | L3: 금 액 | S3: 할 증 | T3: 화폐변환 | U3: OP값 | V3: EQ | W3: LA | X3: MA | Y3: 금액계상
A4: 공사비내역집계 | C4: 1 | D4: 식 | F4: =TRUNC(F5,0) -> 126308852 | H4: =TRUNC(H5,0) -> 19977668 | J4: =TRUNC(J5,0) -> 5931964 | L4: =F4+H4+J4 -> 152218484 | O4: A00
A5: 1.배관공사 | C5: 1 | D5: 식 | E5: =F9 -> 126308852 | F5: =TRUNC(E5*C5,0) -> 126308852 | G5: =H9 -> 19977668 | H5: =TRUNC(G5*C5,0) -> 19977668 | I5: =J9 -> 5931964 | J5: =TRUNC(I5*C5,0) -> 5931964 | K5: =E5+G5+I5 -> 152218484 | L5: =F5+H5+J5 -> 152218484 | P5: 5 | R5: A01 | BI5: =HYPERLINK("#내역서!A9","A01 →") -> A01 →
A6: >>총계 | F6: =TRUNC(F5,0) -> 126308852 | H6: =TRUNC(H5,0) -> 19977668 | J6: =TRUNC(J5,0) -> 5931964 | K6: =E6+G6+I6 -> 0 | L6: =F6+H6+J6 -> 152218484 | P6: 90
F7: 0 | H7: 0 | J7: 0 | K7: =E7+G7+I7 -> 0 | L7: =F7+H7+J7 -> 0 | P7: 100
A9: 1.배관공사 | C9: 1 | D9: 식 | F9: =F17 -> 126308852 | H9: =H17 -> 19977668 | J9: =J17 -> 5931964 | L9: =F9+H9+J9 -> 152218484 | O9: A01 | Z9: =#REF!+#REF!+#REF!+#REF!+#REF!+#REF!+#REF!+#REF!+#REF!+#REF!+#REF!+#REF!+#REF!+#REF!+#REF!+#REF!+#REF!+#REF!+#REF!+#REF!+#REF!+#REF!+#REF!+#REF!+#REF!+#REF!+#REF!+#REF!+#REF!+#REF!+#REF!+#REF!+#REF!+#REF!+#REF!+#REF!+#REF! -> #REF! | AA9: =#REF!+#REF!+#REF!+#REF!+#REF!+#REF!+#REF!+#REF!+#REF!+#REF!+#REF!+#REF!+#REF!+#REF!+#REF!+#REF!+#REF!+#REF!+#REF!+#REF!+#REF!+#REF!+#REF!+#REF!+#REF!+#REF!+#REF!+#REF!+#REF!+#REF!+#REF!+#REF!+#REF!+#REF!+#REF!+#REF!+#REF! -> #REF! | AB9: =#REF!+#REF!+#REF!+#REF!+#REF!+#REF!+#REF!+#REF!+#REF!+#REF!+#REF!+#REF!+#REF!+#REF!+#REF!+#REF!+#REF!+#REF!+#REF!+#REF!+#REF!+#REF!+#REF!+#REF!+#REF!+#REF!+#REF!+#REF!+#REF!+#REF!+#REF!+#REF!+#REF!+#REF!+#REF!+#REF!+#REF! -> #REF!
A10: 부단수 천공 | F10: 0 | H10: 0 | J10: 0 | K10: =E10+G10+I10 -> 0 | L10: =F10+H10+J10 -> 0 | P10: 8030
