Workbook
Name _15A: [2]가격조사서!$D$4:$D$11
Name _B22: [3]일위대가!$1400:$1413=[3]일위대가!$A$1400
Name _DAN2: [4]단가조사서!$M$1:$N$65536
Name _JIP1: [4]집계표!$A$1:$K$65536
Name _K02: [3]일위대가!$732:$745=[3]일위대가!$A$732
Name _O03: [3]일위대가!$1516:$1529=[3]일위대가!$A$1516
Name _QTY1: [7]SHEET2!$F$3:$F$101
Name _RAN5: [8]토목품셈!$D$1:$AI$146
Name _RAN6: [8]토목품셈!$BO$1:$BZ$25
Name _RAN7: [8]토목품셈!$CB$1:$CJ$24
Name ABCD: [9]CABdata!$E$22:$F$46
Name A노임단가: '[10]노무비(DB)'!$A$1:$D$208
Name bdfgdgr: [11]!Macro8
Name bdfgdgr: [11]!Macro8
Name bdfgdgr: [11]!Macro8
Name bdfgdgr: [11]!Macro8
Name bdfgdgr: [11]!Macro8
Name bdfgdgr: [11]!Macro8
Name bdfgdgr: [11]!Macro8
Name bdfgdgr: [11]!Macro8
Name bdfgdgr: [11]!Macro8
Name bdfgdgr: [11]!Macro8
Name bdfgdgr: [11]!Macro8
Name bdfgdgr: [11]!Macro8
Name bdfgdgr: [11]!Macro8
Name BLDG: [12]LEGEND!$D$8
Name CABDIA: [9]MOTOR!$A$86:$B$408
Name CABLEA: [9]MOTOR!$B$66:$C$82
Name CABLEB: [9]MOTOR!$D$66:$E$82
Name CABLED: [9]MOTOR!$F$66:$G$82
Name CABLEE: [9]MOTOR!$H$66:$I$82
Name CAB허용: [9]MOTOR!$J$66:$N$81
Name cds: [0]!cds
Name cds가로등: [0]!cds가로등
Name CIRCUIT: [13]Sheet1!$C$4:$D$10
Name CLIENT: [12]LEGEND!$D$6
Name CTC: [14]DATA!$H$30:$I$57
Name DANGA_: '[15]Y-WORK'!$D$19:$D$19,'[15]Y-WORK'!$F$19:$BD$19
Name DAT: [16]MCC제원!$A$5:$AG$80
Name ddd가로등: [0]!ddd가로등
Name dfffffs: [0]!dfffffs
Name dffffs가로등: [0]!dffffs가로등
Name dfs가로등: [0]!dfs가로등
Name df가로등: [0]!df가로등
Name DGS: [17]data!$S$4:$T$32
Name EJ: [18]소비자가!$I$46:$J$1593
Name EssAliasTable: "Default"
Name EssOptions: "A1100000000130001000001100000_0000"
Name hidden: [20]TABLE!$H$1,[20]TABLE!$J$1,[20]TABLE!$K$1
Name HIT: '[21]2F 회의실견적(5_14 일대)'!$J$31
Name IEC: '[16]허용전류-IEC DATA'!$A$1:$E$352
Name ilch: [22]ilch!$A$3:$M$25
Name JODO: [17]data!$AA$4:$AE$14
Name KO: '[23]D-RMIL'!$B$7:$C$19
Name KYNGSADO: [24]!KYNGSADO
Name KYNGSADO: [24]!KYNGSADO
Name KYNGSADO: [24]!KYNGSADO
Name KYNGSADO: [24]!KYNGSADO
Name KYNGSADO: [24]!KYNGSADO
Name KYNGSADO: [24]!KYNGSADO

Sheet 견적서
B2: 견 적 서
B5: 문 서 번 호 | G5: DH18-260403-01 | U5: 공 급 자 | W5: 등록번호 | Z5: 140-81-34127
B6: 수 신 | G6: 서울특별시 동부수도사업소 | W6: 상 호 | Z6: (주)대호스토퍼 | AG6: 대표 | AJ6: 이 영 호 | AP6: (인)
W7: 소 재 지 | Z7: 경기도 안산시 단원구 시우로 114(초지동)
B8: 담 당 자 | S8: 귀중 | W8: 업 태 | Z8: 제조업 외 | AG8: 종목 | AJ8: 상하수도설비공사 외
B9: 연 락 처 | W9: 회사전화 | Z9: 031-496-9488 | AG9: 회사팩스 | AJ9: 031-496-9349
B10: 작 성 일 | G10: 46115 | W10: 담 당 자 | Z10: 백승리 차장 | AG10: 휴대전화 | AJ10: 010-5013-7776
B11: 유 효 기 간 | G11: 12개월 | W11: E-Mail | Z11: dhcstopper@hanmail.net
B12: 견 적 명 | G12: 2026년 아차산역 일대 장기사용 배수관 정비공사 부단수 차단공법 선정
B14: 합 계 금 액 | G14: 일금 | I14: =AB14 -> 0 | Y14: 원정 | AA14: ( | AB14: =AJ32 -> 0 | AL14: ) | AM14: (VAT포함)
B16: 아래와 같이 견적을 제출합니다.
B17: 품 명 | G17: 규 격 | L17: 수량 | N17: 단 위 | P17: 재 료 비 | U17: 노 무 비 | Z17: 경 비 | AE17: 소 계 | AJ17: 금 액 | AO17: 비고
B18: 부단수 차단 | G18: 700 | L18: 2 | N18: 개소 | P18: ='내역서(700)'!H5 -> 16824354 | U18: ='내역서(700)'!J5 -> 12637708 | Z18: ='내역서(700)'!L5 -> 8440208 | AE18: =SUM(P18:AD18) -> 37902270 | AJ18: =AE18*L18 -> 75804540 | AO18: 야간
B19: " | G19: 1350 | L19: 1 | N19: 개소 | P19: ='내역서(1350)'!H5 -> 42042653 | U19: ='내역서(1350)'!J5 -> 29448519 | Z19: ='내역서(1350)'!L5 -> 13996950 | AE19: =SUM(P19:AD19) -> 85488122 | AJ19: =AE19*L19 -> 85488122
B31: 단수정리
B32: 합 계(TOTAL) | AJ32: =AJ20+AJ23+AJ26+AJ28+AJ31 -> 0
B33: MEMO | D33: 1. 토공, 가시설공, 피팅부 관보호공(H빔보강)등 부단수 차단 외 공종에 대한 공통 공사비 제외 2. '26년 기준 단가 적용(야간 시공비 적용) 3. 가배관 자재 및 보강 별도(단, 부설비 포함) 4. 납품방법 : 현장설치도 5. 설계가 견적 기준

Sheet 내역서(700)
B1: 부단수 차단공사 설계서
B2: <순공사비내역서>
B3: 공 종 명 | D3: 규 격 | E3: 수량 | F3: 단위 | G3: 재 료 비 | I3: 노 무 비 | K3: 경 비 | M3: 합 계 | O3: 비 고
G4: 단 가 | H4: 금 액 | I4: 단 가 | J4: 금 액 | K4: 단 가 | L4: 금 액 | M4: 단 가 | N4: 금 액
C5: 라인스토핑(강관제) | D5: 700 | H5: =SUM(H6:H17) -> 16824354 | J5: =SUM(J6:J17) -> 12637708 | L5: =SUM(L6:L17) -> 8440208 | N5: =H5+J5+L5 -> 37902270
B6: 1 | C6: 바탕처리(강관제) | D6: 700 | E6: 1 | F6: nr | G6: =H25 -> 265 | H6: =TRUNC(G6*$E6,0) -> 265 | I6: =J25 -> 132091 | J6: =TRUNC(I6*$E6,0) -> 132091 | K6: =L25 -> 394 | L6: =TRUNC(K6*$E6,0) -> 394 | M6: =G6+I6+K6 -> 132750 | N6: =H6+J6+L6 -> 132750 | O6: =B31 -> 3
B7: 2 | C7: 부단수 할정자관 부설 및 접합(강관제) | D7: 700 | E7: 1 | F7: nr | G7: =H42 -> 6861371 | H7: =TRUNC(G7*$E7,0) -> 6861371 | I7: =J42 -> 2326038 | J7: =TRUNC(I7*$E7,0) -> 2326038 | K7: =L42 -> 455081 | L7: =TRUNC(K7*$E7,0) -> 455081 | M7: =G7+I7+K7 -> 9642490 | N7: =H7+J7+L7 -> 9642490 | O7: =B37 -> 4
B8: 3 | C8: 샌드위치 밸브 부설 및 접합 | D8: 600 | E8: 1 | F8: nr | G8: =H70 -> 136480 | H8: =TRUNC(G8*$E8,0) -> 136480 | I8: =J70 -> 648222 | J8: =TRUNC(I8*$E8,0) -> 648222 | K8: =L70 -> 636188 | L8: =TRUNC(K8*$E8,0) -> 636188 | M8: =G8+I8+K8 -> 1420890 | N8: =H8+J8+L8 -> 1420890 | O8: =B66 -> 8
B9: 4 | C9: 부단수천공 분기점 분기/철거 | D9: 600 | E9: 1 | F9: nr | G9: =H91 -> 2363365 | H9: =TRUNC(G9*$E9,0) -> 2363365 | I9: =J91 -> 2570426 | J9: =TRUNC(I9*$E9,0) -> 2570426 | K9: =L91 -> 4274817 | L9: =TRUNC(K9*$E9,0) -> 4274817 | M9: =G9+I9+K9 -> 9208608 | N9: =H9+J9+L9 -> 9208608 | O9: =B78 -> 10
B10: 5 | C10: 등압관 설치/철거 | D10: 50 | E10: 1 | F10: nr | G10: =H145 -> 441147 | H10: =TRUNC(G10*$E10,0) -> 441147 | I10: =J145 -> 348986 | J10: =TRUNC(I10*$E10,0) -> 348986 | K10: =L145 -> 6906 | L10: =TRUNC(K10*$E10,0) -> 6906 | M10: =G10+I10+K10 -> 797039 | N10: =H10+J10+L10 -> 797039 | O10: =B137 -> 18
B11: 6 | C11: 부단수차단/철거 | D11: 700 | E11: 1 | F11: nr | G11: =H177 -> 3391044 | H11: =TRUNC(G11*$E11,0) -> 3391044 | I11: =J177 -> 3678960 | J11: =TRUNC(I11*$E11,0) -> 3678960 | K11: =L177 -> 2303647 | L11: =TRUNC(K11*$E11,0) -> 2303647 | M11: =G11+I11+K11 -> 9373651 | N11: =H11+J11+L11 -> 9373651 | O11: =B169 -> 22
B12: 7 | C12: 플러깅/철거 | D12: 600 | E12: 1 | F12: nr | G12: =H209 -> 2939562 | H12: =TRUNC(G12*$E12,0) -> 2939562 | I12: =J209 -> 931031 | J12: =TRUNC(I12*$E12,0) -> 931031 | K12: =L209 -> 403725 | L12: =TRUNC(K12*$E12,0) -> 403725 | M12: =G12+I12+K12 -> 4274318 | N12: =H12+J12+L12 -> 4274318 | O12: =B202 -> 27
B13: 8 | C13: 샌드위치 밸브 철거 | D13: 600 | E13: 1 | F13: nr | G13: =H234 -> 0 | H13: =TRUNC(G13*$E13,0) -> 0 | I13: =J234 -> 259594 | J13: =TRUNC(I13*$E13,0) -> 259594 | K13: =L234 -> 38090 | L13: =TRUNC(K13*$E13,0) -> 38090 | M13: =G13+I13+K13 -> 297684 | N13: =H13+J13+L13 -> 297684 | O13: =B230 -> 31
B14: 9 | C14: 마개플랜지 부설 및 접합 | D14: 600 | E14: 1 | F14: nr | G14: =H241 -> 691120 | H14: =TRUNC(G14*$E14,0) -> 691120 | I14: =J241 -> 300509 | J14: =TRUNC(I14*$E14,0) -> 300509 | K14: =L241 -> 18006 | L14: =TRUNC(K14*$E14,0) -> 18006 | M14: =G14+I14+K14 -> 1009635 | N14: =H14+J14+L14 -> 1009635 | O14: =B236 -> 32
B15: 10 | C15: 사전조사 | D15: 700 | E15: 1 | F15: nr | G15: =H256 -> 0 | H15: =TRUNC(G15*$E15,0) -> 0 | I15: =J256 -> 628835 | J15: =TRUNC(I15*$E15,0) -> 628835 | K15: =L256 -> 0 | L15: =TRUNC(K15*$E15,0) -> 0 | M15: =G15+I15+K15 -> 628835 | N15: =H15+J15+L15 -> 628835 | O15: =B254 -> 35
B16: 11 | C16: 장비운반비 | D16: 700 | E16: 1 | F16: set | G16: =H260 -> 0 | H16: =TRUNC(G16*$E16,0) -> 0 | I16: =J260 -> 0 | J16: =TRUNC(I16*$E16,0) -> 0 | K16: =L260 -> 303354 | L16: =TRUNC(K16*$E16,0) -> 303354 | M16: =G16+I16+K16 -> 303354 | N16: =H16+J16+L16 -> 303354 | O16: =B258 -> 36
B17: 12 | C17: 밸브개폐비 | D17: 600 | E17: 1 | F17: nr | G17: =H264 -> 0 | H17: =TRUNC(G17*$E17,0) -> 0 | I17: =J264 -> 813016 | J17: =TRUNC(I17*$E17,0) -> 813016 | K17: =L264 -> 0 | L17: =TRUNC(K17*$E17,0) -> 0 | M17: =G17+I17+K17 -> 813016 | N17: =H17+J17+L17 -> 813016 | O17: =B262 -> 37
B19: <일위대가표>
B20: 공 종 명 | D20: 규 격 | E20: 수량 | F20: 단위 | G20: 재 료 비 | I20: 노 무 비 | K20: 경 비 | M20: 합 계 | O20: 비 고
G21: 단 가 | H21: 금 액 | I21: 단 가 | J21: 금 액 | K21: 단 가 | L21: 금 액 | M21: 단 가 | N21: 금 액
B22: 1 | C22: 바탕처리(강관제) | D22: 700 | E22: 1 | F22: nr
C23: 강관 도복장 제거 | E23: 1 | F23: nr | G23: 0 | H23: =TRUNC(G23*$E23,0) -> 0 | I23: =J29 -> 107434 | J23: =TRUNC(I23*$E23,0) -> 107434 | K23: 0 | L23: =TRUNC(K23*$E23,0) -> 0 | M23: =G23+I23+K23 -> 107434 | N23: =H23+J23+L23 -> 107434 | O23: =B27 -> 2
C24: 표면정리 | D24: #180 | E24: 1 | F24: nr | G24: 265 | H24: =TRUNC(G24*$E24,0) -> 265 | I24: =J35 -> 24657 | J24: =TRUNC(I24*$E24,0) -> 24657 | K24: 394 | L24: =TRUNC(K24*$E24,0) -> 394 | M24: =G24+I24+K24 -> 25316 | N24: =H24+J24+L24 -> 25316 | O24: =B31 -> 3
C25: 계 | H25: =SUM(H23:H24) -> 265 | J25: =SUM(J23:J24) -> 132091 | L25: =SUM(L23:L24) -> 394 | N25: =H25+J25+L25 -> 132750
B27: =B22+1 -> 2 | C27: 강관 도복장 제거 | D27: 700 | E27: 1 | F27: nr
C28: 보통인부 | E28: 0.333 | F28: 인 | H28: =TRUNC(G28*$E28,0) -> 0 | I28: =노임!$D$17 -> 322627 | J28: =TRUNC(I28*$E28,0) -> 107434 | L28: =TRUNC(K28*$E28,0) -> 0 | M28: =G28+I28+K28 -> 322627 | N28: =H28+J28+L28 -> 107434
C29: 계 | H29: =SUM(H28:H28) -> 0 | J29: =SUM(J28:J28) -> 107434 | L29: =SUM(L28:L28) -> 0 | N29: =H29+J29+L29 -> 107434
B31: =B27+1 -> 3 | C31: 표면정리 | D31: 700 | E31: 1 | F31: nr
C32: 도장공 | E32: 0.05 | F32: 인 | H32: =TRUNC(G32*$E32,0) -> 0 | I32: =노임!$D$23 -> 493156 | J32: =TRUNC(I32*$E32,0) -> 24657 | L32: =TRUNC(K32*$E32,0) -> 0 | M32: =G32+I32+K32 -> 493156 | N32: =H32+J32+L32 -> 24657
C33: 연마지 | D33: #180 | E33: 0.83 | F33: 매 | G33: 320 | H33: =TRUNC(G33*$E33,0) -> 265 | J33: =TRUNC(I33*$E33,0) -> 0 | L33: =TRUNC(K33*$E33,0) -> 0 | M33: =G33+I33+K33 -> 320 | N33: =H33+J33+L33 -> 265
C34: 공구손료 | D34: 도장공 인력품의 | E34: 0.03 | H34: =TRUNC(G34*$E34,0) -> 0 | J34: =TRUNC(I34*$E34,0) -> 0 | K34: 13150 | L34: =TRUNC(K34*$E34,0) -> 394 | M34: =G34+I34+K34 -> 13150 | N34: =H34+J34+L34 -> 394
C35: 계 | H35: =SUM(H32:H34) -> 265 | J35: =SUM(J32:J34) -> 24657 | L35: =SUM(L32:L34) -> 394 | N35: =H35+J35+L35 -> 25316
B37: =B31+1 -> 4 | C37: 부단수 할정자관 부설 및 접합(강관제) | D37: 700 | E37: 1 | F37: nr
C38: 부단수 할정자관 부설(강관제) | D38: 700 | E38: 1 | F38: nr | G38: 0 | H38: =TRUNC(G38*$E38,0) -> 0 | I38: =J48 -> 572675 | J38: =TRUNC(I38*$E38,0) -> 572675 | K38: 84200 | L38: =TRUNC(K38*$E38,0) -> 84200 | M38: =G38+I38+K38 -> 656875 | N38: =H38+J38+L38 -> 656875 | O38: =B44 -> 5
C39: 부단수 할정자관 접합(강관제) | D39: 700 | E39: 1 | F39: nr | G39: 4900 | H39: =TRUNC(G39*$E39,0) -> 4900 | I39: =J55 -> 1366767 | J39: =TRUNC(I39*$E39,0) -> 1366767 | K39: 370881 | L39: =TRUNC(K39*$E39,0) -> 370881 | M39: =G39+I39+K39 -> 1742548 | N39: =H39+J39+L39 -> 1742548 | O39: =B50 -> 6
C40: 부단수 할정자관 접합부 도장 | D40: 700 | E40: 1 | F40: nr | G40: 28471 | H40: =TRUNC(G40*$E40,0) -> 28471 | I40: =J64 -> 386596 | J40: =TRUNC(I40*$E40,0) -> 386596 | K40: 0 | L40: =TRUNC(K40*$E40,0) -> 0 | M40: =G40+I40+K40 -> 415067 | N40: =H40+J40+L40 -> 415067 | O40: =B57 -> 7
C41: 부단수 할정자관 | D41: 700 | E41: 1 | F41: nr | G41: 6828000 | H41: =TRUNC(G41*$E41,0) -> 6828000 | J41: =TRUNC(I41*$E41,0) -> 0 | L41: =TRUNC(K41*$E41,0) -> 0 | M41: =G41+I41+K41 -> 6828000 | N41: =H41+J41+L41 -> 6828000
C42: 계 | H42: =SUM(H38:H41) -> 6861371 | J42: =SUM(J38:J41) -> 2326038 | L42: =SUM(L38:L41) -> 455081 | N42: =H42+J42+L42 -> 9642490
B44: =B37+1 -> 5 | C44: 부단수 할정자관 부설(강관제) | D44: 700 | E44: 1 | F44: nr
C45: 배관공(수도) | E45: 0.77 | F45: 인 | H45: =TRUNC(G45*$E45,0) -> 0 | I45: =노임!$D$24 -> 492337 | J45: =TRUNC(I45*$E45,0) -> 379099 | L45: =TRUNC(K45*$E45,0) -> 0 | M45: =G45+I45+K45 -> 492337 | N45: =H45+J45+L45 -> 379099
...

Sheet 내역서(1350)
B1: 부단수 차단공사 설계서
B2: <순공사비내역서>
B3: 공 종 명 | D3: 규 격 | E3: 수량 | F3: 단위 | G3: 재 료 비 | I3: 노 무 비 | K3: 경 비 | M3: 합 계 | O3: 비 고
G4: 단 가 | H4: 금 액 | I4: 단 가 | J4: 금 액 | K4: 단 가 | L4: 금 액 | M4: 단 가 | N4: 금 액
C5: 라인스토핑(강관제) | D5: 1350 | H5: =SUM(H6:H17) -> 42042653 | J5: =SUM(J6:J17) -> 29448519 | L5: =SUM(L6:L17) -> 13996950 | N5: =H5+J5+L5 -> 85488122
B6: 1 | C6: 바탕처리(강관제) | D6: 1350 | E6: 1 | F6: nr | G6: =H25 -> 720 | H6: =TRUNC(G6*$E6,0) -> 720 | I6: =J25 -> 362202 | J6: =TRUNC(I6*$E6,0) -> 362202 | K6: =L25 -> 1065 | L6: =TRUNC(K6*$E6,0) -> 1065 | M6: =G6+I6+K6 -> 363987 | N6: =H6+J6+L6 -> 363987 | O6: =B31 -> 3
B7: 2 | C7: 부단수 할정자관 부설 및 접합(강관제) | D7: 1350 | E7: 1 | F7: nr | G7: =H42 -> 14417885 | H7: =TRUNC(G7*$E7,0) -> 14417885 | I7: =J42 -> 8598998 | J7: =TRUNC(I7*$E7,0) -> 8598998 | K7: =L42 -> 930397 | L7: =TRUNC(K7*$E7,0) -> 930397 | M7: =G7+I7+K7 -> 23947280 | N7: =H7+J7+L7 -> 23947280 | O7: =B37 -> 4
B8: 3 | C8: 샌드위치 밸브 부설 및 접합 | D8: 900 | E8: 1 | F8: nr | G8: =H70 -> 303010 | H8: =TRUNC(G8*$E8,0) -> 303010 | I8: =J70 -> 933963 | J8: =TRUNC(I8*$E8,0) -> 933963 | K8: =L70 -> 1081584 | L8: =TRUNC(K8*$E8,0) -> 1081584 | M8: =G8+I8+K8 -> 2318557 | N8: =H8+J8+L8 -> 2318557 | O8: =B66 -> 8
B9: 4 | C9: 부단수천공 분기점 분기/철거 | D9: 900 | E9: 1 | F9: nr | G9: =H91 -> 4907155 | H9: =TRUNC(G9*$E9,0) -> 4907155 | I9: =J91 -> 4395174 | J9: =TRUNC(I9*$E9,0) -> 4395174 | K9: =L91 -> 5766184 | L9: =TRUNC(K9*$E9,0) -> 5766184 | M9: =G9+I9+K9 -> 15068513 | N9: =H9+J9+L9 -> 15068513 | O9: =B78 -> 10
B10: 5 | C10: 등압관 설치/철거 | D10: 100 | E10: 1 | F10: nr | G10: =H145 -> 441686 | H10: =TRUNC(G10*$E10,0) -> 441686 | I10: =J145 -> 441995 | J10: =TRUNC(I10*$E10,0) -> 441995 | K10: =L145 -> 84487 | L10: =TRUNC(K10*$E10,0) -> 84487 | M10: =G10+I10+K10 -> 968168 | N10: =H10+J10+L10 -> 968168 | O10: =B137 -> 18
B11: 6 | C11: 부단수차단/철거 | D11: 1350 | E11: 1 | F11: nr | G11: =H177 -> 15190577 | H11: =TRUNC(G11*$E11,0) -> 15190577 | I11: =J177 -> 10409905 | J11: =TRUNC(I11*$E11,0) -> 10409905 | K11: =L177 -> 4556115 | L11: =TRUNC(K11*$E11,0) -> 4556115 | M11: =G11+I11+K11 -> 30156597 | N11: =H11+J11+L11 -> 30156597 | O11: =B169 -> 22
B12: 7 | C12: 플러깅/철거 | D12: 900 | E12: 1 | F12: nr | G12: =H209 -> 5485950 | H12: =TRUNC(G12*$E12,0) -> 5485950 | I12: =J209 -> 1982079 | J12: =TRUNC(I12*$E12,0) -> 1982079 | K12: =L209 -> 733729 | L12: =TRUNC(K12*$E12,0) -> 733729 | M12: =G12+I12+K12 -> 8201758 | N12: =H12+J12+L12 -> 8201758 | O12: =B202 -> 27
B13: 8 | C13: 샌드위치 밸브 철거 | D13: 900 | E13: 1 | F13: nr | G13: =H234 -> 0 | H13: =TRUNC(G13*$E13,0) -> 0 | I13: =J234 -> 375554 | J13: =TRUNC(I13*$E13,0) -> 375554 | K13: =L234 -> 69460 | L13: =TRUNC(K13*$E13,0) -> 69460 | M13: =G13+I13+K13 -> 445014 | N13: =H13+J13+L13 -> 445014 | O13: =B230 -> 31
B14: 9 | C14: 마개플랜지 부설 및 접합 | D14: 900 | E14: 1 | F14: nr | G14: =H241 -> 1295670 | H14: =TRUNC(G14*$E14,0) -> 1295670 | I14: =J241 -> 475046 | J14: =TRUNC(I14*$E14,0) -> 475046 | K14: =L241 -> 22854 | L14: =TRUNC(K14*$E14,0) -> 22854 | M14: =G14+I14+K14 -> 1793570 | N14: =H14+J14+L14 -> 1793570 | O14: =B236 -> 32
B15: 10 | C15: 사전조사 | D15: 1350 | E15: 1 | F15: nr | G15: =H256 -> 0 | H15: =TRUNC(G15*$E15,0) -> 0 | I15: =J256 -> 335379 | J15: =TRUNC(I15*$E15,0) -> 335379 | K15: =L256 -> 0 | L15: =TRUNC(K15*$E15,0) -> 0 | M15: =G15+I15+K15 -> 335379 | N15: =H15+J15+L15 -> 335379 | O15: =B254 -> 35
B16: 11 | C16: 장비운반비 | D16: 1350 | E16: 1 | F16: set | G16: =H260 -> 0 | H16: =TRUNC(G16*$E16,0) -> 0 | I16: =J260 -> 0 | J16: =TRUNC(I16*$E16,0) -> 0 | K16: =L260 -> 751075 | L16: =TRUNC(K16*$E16,0) -> 751075 | M16: =G16+I16+K16 -> 751075 | N16: =H16+J16+L16 -> 751075 | O16: =B258 -> 36
B17: 12 | C17: 밸브개폐비 | D17: 900 | E17: 1 | F17: nr | G17: =H264 -> 0 | H17: =TRUNC(G17*$E17,0) -> 0 | I17: =J264 -> 1138224 | J17: =TRUNC(I17*$E17,0) -> 1138224 | K17: =L264 -> 0 | L17: =TRUNC(K17*$E17,0) -> 0 | M17: =G17+I17+K17 -> 1138224 | N17: =H17+J17+L17 -> 1138224 | O17: =B262 -> 37
B19: <일위대가표>
B20: 공 종 명 | D20: 규 격 | E20: 수량 | F20: 단위 | G20: 재 료 비 | I20: 노 무 비 | K20: 경 비 | M20: 합 계 | O20: 비 고
G21: 단 가 | H21: 금 액 | I21: 단 가 | J21: 금 액 | K21: 단 가 | L21: 금 액 | M21: 단 가 | N21: 금 액
B22: 1 | C22: 바탕처리(강관제) | D22: 1350 | E22: 1 | F22: nr
C23: 강관 도복장 제거 | E23: 1 | F23: nr | G23: =H29 -> 0 | H23: =TRUNC(G23*$E23,0) -> 0 | I23: =J29 -> 290686 | J23: =TRUNC(I23*$E23,0) -> 290686 | K23: =L29 -> 0 | L23: =TRUNC(K23*$E23,0) -> 0 | M23: =G23+I23+K23 -> 290686 | N23: =H23+J23+L23 -> 290686 | O23: =B27 -> 2
C24: 표면정리 | D24: #180 | E24: 1 | F24: nr | G24: 720 | H24: =TRUNC(G24*$E24,0) -> 720 | I24: =J35 -> 71516 | J24: =TRUNC(I24*$E24,0) -> 71516 | K24: 1065 | L24: =TRUNC(K24*$E24,0) -> 1065 | M24: =G24+I24+K24 -> 73301 | N24: =H24+J24+L24 -> 73301 | O24: =B31 -> 3
C25: 계 | H25: =SUM(H23:H24) -> 720 | J25: =SUM(J23:J24) -> 362202 | L25: =SUM(L23:L24) -> 1065 | N25: =H25+J25+L25 -> 363987
B27: =B22+1 -> 2 | C27: 강관 도복장 제거 | D27: 1350 | E27: 1 | F27: nr
C28: 보통인부 | E28: 0.901 | F28: 인 | H28: =TRUNC(G28*$E28,0) -> 0 | I28: =노임!$D$17 -> 322627 | J28: =TRUNC(I28*$E28,0) -> 290686 | L28: =TRUNC(K28*$E28,0) -> 0 | M28: =G28+I28+K28 -> 322627 | N28: =H28+J28+L28 -> 290686
C29: 계 | H29: =SUM(H28:H28) -> 0 | J29: =SUM(J28:J28) -> 290686 | L29: =SUM(L28:L28) -> 0 | N29: =H29+J29+L29 -> 290686
B31: =B27+1 -> 3 | C31: 표면정리 | D31: 1350 | E31: 1 | F31: nr
C32: 도장공 | E32: 0.135 | F32: 인 | H32: =TRUNC(G32*$E32,0) -> 0 | I32: =노임!$D$21 -> 529755 | J32: =TRUNC(I32*$E32,0) -> 71516 | L32: =TRUNC(K32*$E32,0) -> 0 | M32: =G32+I32+K32 -> 529755 | N32: =H32+J32+L32 -> 71516
C33: 연마지 | D33: #180 | E33: 2.25 | F33: 매 | G33: 320 | H33: =TRUNC(G33*$E33,0) -> 720 | J33: =TRUNC(I33*$E33,0) -> 0 | L33: =TRUNC(K33*$E33,0) -> 0 | M33: =G33+I33+K33 -> 320 | N33: =H33+J33+L33 -> 720
C34: 공구손료 | D34: 도장공 인력품의 | E34: 0.03 | H34: =TRUNC(G34*$E34,0) -> 0 | J34: =TRUNC(I34*$E34,0) -> 0 | K34: 35507 | L34: =TRUNC(K34*$E34,0) -> 1065 | M34: =G34+I34+K34 -> 35507 | N34: =H34+J34+L34 -> 1065
C35: 계 | H35: =SUM(H32:H34) -> 720 | J35: =SUM(J32:J34) -> 71516 | L35: =SUM(L32:L34) -> 1065 | N35: =H35+J35+L35 -> 73301
B37: =B31+1 -> 4 | C37: 부단수 할정자관 부설 및 접합(강관제) | D37: 1350 | E37: 1 | F37: nr
C38: 부단수 할정자관 부설(강관제) | D38: 1350 | E38: 1 | F38: nr | G38: 0 | H38: =TRUNC(G38*$E38,0) -> 0 | I38: =J48 -> 2819403 | J38: =TRUNC(I38*$E38,0) -> 2819403 | K38: 143882 | L38: =TRUNC(K38*$E38,0) -> 143882 | M38: =G38+I38+K38 -> 2963285 | N38: =H38+J38+L38 -> 2963285 | O38: =B44 -> 5
C39: 부단수 할정자관 접합(강관제) | D39: 1350 | E39: 1 | F39: nr | G39: 103929 | H39: =TRUNC(G39*$E39,0) -> 103929 | I39: =J55 -> 5212789 | J39: =TRUNC(I39*$E39,0) -> 5212789 | K39: 786515 | L39: =TRUNC(K39*$E39,0) -> 786515 | M39: =G39+I39+K39 -> 6103233 | N39: =H39+J39+L39 -> 6103233 | O39: =B50 -> 6
C40: 부단수 할정자관 접합부 도장 | D40: 1350 | E40: 1 | F40: nr | G40: 59956 | H40: =TRUNC(G40*$E40,0) -> 59956 | I40: =J64 -> 566806 | J40: =TRUNC(I40*$E40,0) -> 566806 | K40: 0 | L40: =TRUNC(K40*$E40,0) -> 0 | M40: =G40+I40+K40 -> 626762 | N40: =H40+J40+L40 -> 626762 | O40: =B57 -> 7
C41: 부단수 할정자관 | D41: 1350 | E41: 1 | F41: nr | G41: 14254000 | H41: =TRUNC(G41*$E41,0) -> 14254000 | J41: =TRUNC(I41*$E41,0) -> 0 | L41: =TRUNC(K41*$E41,0) -> 0 | M41: =G41+I41+K41 -> 14254000 | N41: =H41+J41+L41 -> 14254000
C42: 계 | H42: =SUM(H38:H41) -> 14417885 | J42: =SUM(J38:J41) -> 8598998 | L42: =SUM(L38:L41) -> 930397 | N42: =H42+J42+L42 -> 23947280
B44: =B37+1 -> 5 | C44: 부단수 할정자관 부설(강관제) | D44: 1350 | E44: 1 | F44: nr
C45: 배관공(수도) | E45: 3.8 | F45: 인 | H45: =TRUNC(G45*$E45,0) -> 0 | I45: =노임!$D$24 -> 492337 | J45: =TRUNC(I45*$E45,0) -> 1870880 | L45: =TRUNC(K45*$E45,0) -> 0 | M45: =G45+I45+K45 -> 492337 | N45: =H45+J45+L45 -> 1870880
...

Sheet 목록(강관)
A1: 일위대가목록
A2: 공 종 명 | C2: 규 격 | D2: 수 량 | E2: 단 위 | G2: 합 계 | I2: 재 료 비 | K2: 노 무 비 | M2: 경 비 | N2: 비 고
A4: 1 | B4: ='강관부설 및 철거'!B5 -> 강관부설(인력) | C4: ='강관부설 및 철거'!C5 -> D80㎜ | D4: 1 | E4: nr | G4: =I4+K4+M4 -> #REF! | I4: ='강관부설 및 철거'!I5 -> #REF! | K4: ='강관부설 및 철거'!K5 -> #REF! | M4: ='강관부설 및 철거'!M5 -> #REF!
A5: 2 | B5: ='강관부설 및 철거'!B11 -> 강관부설(인력) | C5: ='강관부설 및 철거'!C11 -> D100㎜ | D5: 1 | E5: nr | G5: =I5+K5+M5 -> #REF! | I5: ='강관부설 및 철거'!I11 -> #REF! | K5: ='강관부설 및 철거'!K11 -> #REF! | M5: ='강관부설 및 철거'!M11 -> #REF!
A6: 3 | B6: ='강관부설 및 철거'!B17 -> 강관부설(기계) | C6: ='강관부설 및 철거'!C17 -> D100㎜ 이하 | D6: 1 | E6: nr | G6: =I6+K6+M6 -> #REF! | I6: ='강관부설 및 철거'!I17 -> #REF! | K6: ='강관부설 및 철거'!K17 -> #REF! | M6: ='강관부설 및 철거'!M17 -> #REF!
A7: 4 | B7: ='강관부설 및 철거'!B23 -> 강관부설(인력) | C7: ='강관부설 및 철거'!C23 -> D150㎜ | D7: 1 | E7: nr | G7: =I7+K7+M7 -> #REF! | I7: ='강관부설 및 철거'!I23 -> #REF! | K7: ='강관부설 및 철거'!K23 -> #REF! | M7: ='강관부설 및 철거'!M23 -> #REF!
A8: 5 | B8: ='강관부설 및 철거'!B29 -> 강관부설(기계) | C8: ='강관부설 및 철거'!C29 -> D150㎜ | D8: 1 | E8: nr | G8: =I8+K8+M8 -> #REF! | I8: ='강관부설 및 철거'!I29 -> #REF! | K8: ='강관부설 및 철거'!K29 -> #REF! | M8: ='강관부설 및 철거'!M29 -> #REF!
A9: 6 | B9: ='강관부설 및 철거'!B35 -> 강관부설(인력) | C9: ='강관부설 및 철거'!C35 -> D200㎜ | D9: 1 | E9: nr | G9: =I9+K9+M9 -> #REF! | I9: ='강관부설 및 철거'!I35 -> #REF! | K9: ='강관부설 및 철거'!K35 -> #REF! | M9: ='강관부설 및 철거'!M35 -> #REF!
A10: 7 | B10: ='강관부설 및 철거'!B41 -> 강관부설(기계) | C10: ='강관부설 및 철거'!C41 -> D200㎜ | D10: 1 | E10: nr | G10: =I10+K10+M10 -> #REF! | I10: ='강관부설 및 철거'!I41 -> #REF! | K10: ='강관부설 및 철거'!K41 -> #REF! | M10: ='강관부설 및 철거'!M41 -> #REF!
A11: 8 | B11: ='강관부설 및 철거'!B47 -> 강관부설(인력) | C11: ='강관부설 및 철거'!C47 -> D250㎜ | D11: 1 | E11: nr | G11: =I11+K11+M11 -> #REF! | I11: ='강관부설 및 철거'!I47 -> #REF! | K11: ='강관부설 및 철거'!K47 -> #REF! | M11: ='강관부설 및 철거'!M47 -> #REF!
A12: 9 | B12: ='강관부설 및 철거'!B53 -> 강관부설(기계) | C12: ='강관부설 및 철거'!C53 -> D250㎜ | D12: 1 | E12: nr | G12: =I12+K12+M12 -> #REF! | I12: ='강관부설 및 철거'!I53 -> #REF! | K12: ='강관부설 및 철거'!K53 -> #REF! | M12: ='강관부설 및 철거'!M53 -> #REF!
A13: 10 | B13: ='강관부설 및 철거'!B59 -> 강관부설(기계) | C13: ='강관부설 및 철거'!C59 -> D300㎜ | D13: 1 | E13: nr | G13: =I13+K13+M13 -> #REF! | I13: ='강관부설 및 철거'!I59 -> #REF! | K13: ='강관부설 및 철거'!K59 -> #REF! | M13: ='강관부설 및 철거'!M59 -> #REF!
A14: 11 | B14: ='강관부설 및 철거'!B65 -> 강관부설(기계) | C14: ='강관부설 및 철거'!C65 -> D350㎜ | D14: 1 | E14: nr | G14: =I14+K14+M14 -> #REF! | I14: ='강관부설 및 철거'!I65 -> #REF! | K14: ='강관부설 및 철거'!K65 -> #REF! | M14: ='강관부설 및 철거'!M65 -> #REF!
A15: 12 | B15: ='강관부설 및 철거'!B71 -> 강관부설(기계) | C15: ='강관부설 및 철거'!C71 -> D400㎜ | D15: 1 | E15: nr | G15: =I15+K15+M15 -> #REF! | I15: ='강관부설 및 철거'!I71 -> #REF! | K15: ='강관부설 및 철거'!K71 -> #REF! | M15: ='강관부설 및 철거'!M71 -> #REF!
A16: 13 | B16: ='강관부설 및 철거'!B77 -> 강관부설(기계) | C16: ='강관부설 및 철거'!C77 -> D450㎜ | D16: 1 | E16: nr | G16: =I16+K16+M16 -> #REF! | I16: ='강관부설 및 철거'!I77 -> #REF! | K16: ='강관부설 및 철거'!K77 -> #REF! | M16: ='강관부설 및 철거'!M77 -> #REF!
A17: 14 | B17: ='강관부설 및 철거'!B83 -> 강관부설(기계) | C17: ='강관부설 및 철거'!C83 -> D500㎜ | D17: 1 | E17: nr | G17: =I17+K17+M17 -> #REF! | I17: ='강관부설 및 철거'!I83 -> #REF! | K17: ='강관부설 및 철거'!K83 -> #REF! | M17: ='강관부설 및 철거'!M83 -> #REF!
A18: 15 | B18: ='강관부설 및 철거'!B89 -> 강관부설(기계) | C18: ='강관부설 및 철거'!C89 -> D600㎜ | D18: 1 | E18: nr | G18: =I18+K18+M18 -> #REF! | I18: ='강관부설 및 철거'!I89 -> #REF! | K18: ='강관부설 및 철거'!K89 -> #REF! | M18: ='강관부설 및 철거'!M89 -> #REF!
A19: 16 | B19: ='강관부설 및 철거'!B95 -> 강관부설(기계) | C19: ='강관부설 및 철거'!C95 -> D700㎜ | D19: 1 | E19: nr | G19: =I19+K19+M19 -> #REF! | I19: ='강관부설 및 철거'!I95 -> #REF! | K19: ='강관부설 및 철거'!K95 -> #REF! | M19: ='강관부설 및 철거'!M95 -> #REF!
A20: 17 | B20: ='강관부설 및 철거'!B101 -> 강관부설(기계) | C20: ='강관부설 및 철거'!C101 -> D800㎜ | D20: 1 | E20: nr | G20: =I20+K20+M20 -> #REF! | I20: ='강관부설 및 철거'!I101 -> #REF! | K20: ='강관부설 및 철거'!K101 -> #REF! | M20: ='강관부설 및 철거'!M101 -> #REF!
A21: 18 | B21: ='강관부설 및 철거'!B107 -> 강관부설(기계) | C21: ='강관부설 및 철거'!C107 -> D900㎜ | D21: 1 | E21: nr | G21: =I21+K21+M21 -> #REF! | I21: ='강관부설 및 철거'!I107 -> #REF! | K21: ='강관부설 및 철거'!K107 -> #REF! | M21: ='강관부설 및 철거'!M107 -> #REF!
A22: 19 | B22: ='강관부설 및 철거'!B113 -> 강관부설(기계) | C22: ='강관부설 및 철거'!C113 -> D1000㎜ | D22: 1 | E22: nr | G22: =I22+K22+M22 -> #REF! | I22: ='강관부설 및 철거'!I113 -> #REF! | K22: ='강관부설 및 철거'!K113 -> #REF! | M22: ='강관부설 및 철거'!M113 -> #REF!
A23: 20 | B23: ='강관부설 및 철거'!B119 -> 강관부설(기계) | C23: ='강관부설 및 철거'!C119 -> D1100㎜ | D23: 1 | E23: nr | G23: =I23+K23+M23 -> #REF! | I23: ='강관부설 및 철거'!I119 -> #REF! | K23: ='강관부설 및 철거'!K119 -> #REF! | M23: ='강관부설 및 철거'!M119 -> #REF!
A24: 21 | B24: ='강관부설 및 철거'!B125 -> 강관부설(기계) | C24: ='강관부설 및 철거'!C125 -> D1200㎜ | D24: 1 | E24: nr | G24: =I24+K24+M24 -> #REF! | I24: ='강관부설 및 철거'!I125 -> #REF! | K24: ='강관부설 및 철거'!K125 -> #REF! | M24: ='강관부설 및 철거'!M125 -> #REF!
A25: 22 | B25: ='강관부설 및 철거'!B131 -> 강관부설(기계) | C25: ='강관부설 및 철거'!C131 -> D1350㎜ | D25: 1 | E25: nr | G25: =I25+K25+M25 -> #REF! | I25: ='강관부설 및 철거'!I131 -> #REF! | K25: ='강관부설 및 철거'!K131 -> #REF! | M25: ='강관부설 및 철거'!M131 -> #REF!
A26: 23 | B26: ='강관부설 및 철거'!B137 -> 강관부설(기계) | C26: ='강관부설 및 철거'!C137 -> D1500㎜ | D26: 1 | E26: nr | G26: =I26+K26+M26 -> #REF! | I26: ='강관부설 및 철거'!I137 -> #REF! | K26: ='강관부설 및 철거'!K137 -> #REF! | M26: ='강관부설 및 철거'!M137 -> #REF!
A27: 24 | B27: ='강관부설 및 철거'!B143 -> 강관부설(기계) | C27: ='강관부설 및 철거'!C143 -> D1650㎜ | D27: 1 | E27: nr | G27: =I27+K27+M27 -> #REF! | I27: ='강관부설 및 철거'!I143 -> #REF! | K27: ='강관부설 및 철거'!K143 -> #REF! | M27: ='강관부설 및 철거'!M143 -> #REF!
A28: 25 | B28: ='강관부설 및 철거'!B149 -> 강관부설(기계) | C28: ='강관부설 및 철거'!C149 -> D1800㎜ | D28: 1 | E28: nr | G28: =I28+K28+M28 -> #REF! | I28: ='강관부설 및 철거'!I149 -> #REF! | K28: ='강관부설 및 철거'!K149 -> #REF! | M28: ='강관부설 및 철거'!M149 -> #REF!
A29: 26 | B29: ='강관부설 및 철거'!B155 -> 강관부설(기계) | C29: ='강관부설 및 철거'!C155 -> D2000㎜ | D29: 1 | E29: nr | G29: =I29+K29+M29 -> #REF! | I29: ='강관부설 및 철거'!I155 -> #REF! | K29: ='강관부설 및 철거'!K155 -> #REF! | M29: ='강관부설 및 철거'!M155 -> #REF!
A30: 27 | B30: ='강관부설 및 철거'!B161 -> 강관부설(기계) | C30: ='강관부설 및 철거'!C161 -> D2200㎜ | D30: 1 | E30: nr | G30: =I30+K30+M30 -> #REF! | I30: ='강관부설 및 철거'!I161 -> #REF! | K30: ='강관부설 및 철거'!K161 -> #REF! | M30: ='강관부설 및 철거'!M161 -> #REF!
A31: 28 | B31: ='강관부설 및 철거'!B167 -> 강관부설(기계) | C31: ='강관부설 및 철거'!C167 -> D2400㎜ | D31: 1 | E31: nr | G31: =I31+K31+M31 -> #REF! | I31: ='강관부설 및 철거'!I167 -> #REF! | K31: ='강관부설 및 철거'!K167 -> #REF! | M31: ='강관부설 및 철거'!M167 -> #REF!
A32: 29 | B32: =강관용접!B5 -> 강관접합(A종) | C32: =강관용접!C5 -> D80㎜ | D32: 1 | E32: 개소 | G32: =I32+K32+M32 -> #REF! | I32: =강관용접!I5 -> #REF! | K32: =강관용접!K5 -> 25682.5 | M32: =강관용접!M5 -> 1540.9 | N32: 삭제
A33: 30 | B33: =강관용접!B11 -> 강관접합(A종) | C33: =강관용접!C11 -> D100㎜ 이하, 외부용접 | D33: 1 | E33: 개소 | G33: =I33+K33+M33 -> #REF! | I33: =강관용접!I11 -> #REF! | K33: =강관용접!K11 -> 25682.5 | M33: =강관용접!M11 -> 1540.9
A34: 31 | B34: =강관용접!B17 -> 강관접합(A종) | C34: =강관용접!C17 -> D125㎜, 외부용접 | D34: 1 | E34: 개소 | G34: =I34+K34+M34 -> #REF! | I34: =강관용접!I17 -> #REF! | K34: =강관용접!K17 -> 25682.5 | M34: =강관용접!M17 -> 1540.9
A35: 32 | B35: =강관용접!B23 -> 강관접합(A종) | C35: =강관용접!C23 -> D150㎜, 외부용접 | D35: 1 | E35: 개소 | G35: =I35+K35+M35 -> #REF! | I35: =강관용접!I23 -> #REF! | K35: =강관용접!K23 -> 28253.6 | M35: =강관용접!M23 -> 1695.2
A36: 33 | B36: =강관용접!B29 -> 강관접합(A종) | C36: =강관용접!C29 -> D200㎜, 외부용접 | D36: 1 | E36: 개소 | G36: =I36+K36+M36 -> #REF! | I36: =강관용접!I29 -> #REF! | K36: =강관용접!K29 -> 31389.7 | M36: =강관용접!M29 -> 1883.3
A37: 34 | B37: =강관용접!B35 -> 강관접합(A종) | C37: =강관용접!C35 -> D250㎜, 외부용접 | D37: 1 | E37: 개소 | G37: =I37+K37+M37 -> #REF! | I37: =강관용접!I35 -> #REF! | K37: =강관용접!K35 -> 37662 | M37: =강관용접!M35 -> 2259.7
A38: 35 | B38: =강관용접!B41 -> 강관접합(A종) | C38: =강관용접!C41 -> D300㎜, 외부용접 | D38: 1 | E38: 개소 | G38: =I38+K38+M38 -> #REF! | I38: =강관용접!I41 -> #REF! | K38: =강관용접!K41 -> 43454 | M38: =강관용접!M41 -> 2607.2
A39: 36 | B39: =강관용접!B47 -> 강관접합(A종) | C39: =강관용접!C47 -> D350㎜, 외부용접 | D39: 1 | E39: 개소 | G39: =I39+K39+M39 -> #REF! | I39: =강관용접!I47 -> #REF! | K39: =강관용접!K47 -> 51365 | M39: =강관용접!M47 -> 3081.8
A40: 37 | B40: =강관용접!B53 -> 강관접합(A종) | C40: =강관용접!C53 -> D400㎜, 외부용접 | D40: 1 | E40: 개소 | G40: =I40+K40+M40 -> #REF! | I40: =강관용접!I53 -> #REF! | K40: =강관용접!K53 -> 59502 | M40: =강관용접!M53 -> 3570.1
A41: 38 | B41: =강관용접!B59 -> 강관접합(A종) | C41: =강관용접!C59 -> D450㎜, 외부용접 | D41: 1 | E41: 개소 | G41: =I41+K41+M41 -> #REF! | I41: =강관용접!I59 -> #REF! | K41: =강관용접!K59 -> 70634 | M41: =강관용접!M59 -> 4238
...

Sheet 강관부설 및 철거
A1: 일위대가_호표_강관부설(2025년)
A2: 공 종 명 | C2: 규 격 | D2: 수량 | E2: 단위 | F2: 합 계 | H2: 재 료 비 | J2: 노 무 비 | L2: 경 비 | N2: 비 고
F3: 단 가 | G3: 금 액 | H3: 단 가 | I3: 금 액 | J3: 단 가 | K3: 금 액 | L3: 단 가 | M3: 금 액
A5: 1 | B5: 강관부설(인력) | C5: D80㎜ | D5: 1 | E5: nr | G5: =I5+K5+M5 -> #REF! | I5: =I9 -> #REF! | K5: =K9 -> #REF! | M5: =M9 -> #REF! | N5: 토목6-3-1
B6: 배 관 공 | C6: 수도 | D6: 2 | E6: 인 | F6: =H6+J6+L6 -> 262580 | G6: =I6+K6+M6 -> 525160 | H6: 0 | J6: =노임!$D$10 -> 262580 | K6: =TRUNC(J6*D6,1) -> 525160 | L6: 0
B7: 보통인부 | D7: 1 | E7: 인 | F7: =H7+J7+L7 -> 172068 | G7: =I7+K7+M7 -> 172068 | H7: 0 | J7: =노임!$D$3 -> 172068 | K7: =TRUNC(J7*D7,1) -> 172068 | L7: 0
B8: 트럭탑제형 크레인 | C8: 10 TON | E8: hr | F8: =H8+J8+L8 -> #REF! | G8: =I8+K8+M8 -> #REF! | H8: =#REF! -> #REF! | I8: =TRUNC(H8*D8,1) -> #REF! | J8: =#REF! -> #REF! | K8: =TRUNC(J8*D8,1) -> #REF! | L8: =#REF! -> #REF! | M8: =TRUNC(L8*D8,1) -> #REF!
B9: 일 시공량 | C9: 8 | D9: =ROUND(1/C9,4) -> 0.125 | E9: 일/본 | G9: =I9+K9+M9 -> #REF! | I9: =TRUNC(SUM(I6:I8)*$D9,1) -> #REF! | K9: =TRUNC(SUM(K6:K8)*$D9,1) -> #REF! | M9: =TRUNC(SUM(M6:M8)*$D9,1) -> #REF!
A11: =A5+1 -> 2 | B11: 강관부설(인력) | C11: D100㎜ | D11: 1 | E11: nr | G11: =I11+K11+M11 -> #REF! | I11: =I15 -> #REF! | K11: =K15 -> #REF! | M11: =M15 -> #REF! | N11: 토목6-3-1
B12: 배 관 공 | C12: 수도 | D12: 2 | E12: 인 | F12: =H12+J12+L12 -> 262580 | G12: =I12+K12+M12 -> 525160 | H12: 0 | J12: =노임!D10 -> 262580 | K12: =TRUNC(J12*D12,1) -> 525160 | L12: 0
B13: 보통인부 | D13: 1 | E13: 인 | F13: =H13+J13+L13 -> 172068 | G13: =I13+K13+M13 -> 172068 | H13: 0 | J13: =노임!D3 -> 172068 | K13: =TRUNC(J13*D13,1) -> 172068 | L13: 0
B14: 트럭탑제형 크레인 | C14: 10 TON | E14: hr | F14: =H14+J14+L14 -> #REF! | G14: =I14+K14+M14 -> #REF! | H14: =#REF! -> #REF! | I14: =TRUNC(H14*D14,1) -> #REF! | J14: =#REF! -> #REF! | K14: =TRUNC(J14*D14,1) -> #REF! | L14: =#REF! -> #REF! | M14: =TRUNC(L14*D14,1) -> #REF!
B15: 일 시공량 | C15: 6 | D15: =ROUND(1/C15,4) -> 0.1667 | E15: 일/본 | G15: =I15+K15+M15 -> #REF! | I15: =TRUNC(SUM(I12:I14)*$D15,1) -> #REF! | K15: =TRUNC(SUM(K12:K14)*$D15,1) -> #REF! | M15: =TRUNC(SUM(M12:M14)*$D15,1) -> #REF!
A17: =A11+1 -> 3 | B17: 강관부설(기계) | C17: D100㎜ 이하 | D17: 1 | E17: nr | G17: =I17+K17+M17 -> #REF! | I17: =I21 -> #REF! | K17: =K21 -> #REF! | M17: =M21 -> #REF! | N17: 토목6-3-1
B18: 배 관 공 | C18: 수도 | D18: 2 | E18: 인 | F18: =H18+J18+L18 -> 197788 | G18: =I18+K18+M18 -> 395576 | H18: 0 | J18: =노임!D15 -> 197788 | K18: =TRUNC(J18*D18,1) -> 395576 | L18: 0
B19: 보통인부 | D19: 1 | E19: 인 | F19: =H19+J19+L19 -> 282536 | G19: =I19+K19+M19 -> 282536 | H19: 0 | J19: =노임!D7 -> 282536 | K19: =TRUNC(J19*D19,1) -> 282536 | L19: 0
B20: 트럭탑제형 크레인 | C20: 10 TON | D20: 8 | E20: hr | F20: =H20+J20+L20 -> #REF! | G20: =I20+K20+M20 -> #REF! | H20: =#REF! -> #REF! | I20: =TRUNC(H20*D20,1) -> #REF! | J20: =#REF! -> #REF! | K20: =TRUNC(J20*D20,1) -> #REF! | L20: =#REF! -> #REF! | M20: =TRUNC(L20*D20,1) -> #REF!
B21: 일 시공량 | C21: 14 | D21: =ROUND(1/C21,4) -> 0.0714 | E21: 일/본 | G21: =I21+K21+M21 -> #REF! | I21: =TRUNC(SUM(I18:I20)*$D21,1) -> #REF! | K21: =TRUNC(SUM(K18:K20)*$D21,1) -> #REF! | M21: =TRUNC(SUM(M18:M20)*$D21,1) -> #REF!
A23: =A17+1 -> 4 | B23: 강관부설(인력) | C23: D150㎜ | D23: 1 | E23: nr | G23: =I23+K23+M23 -> #REF! | I23: =I27 -> #REF! | K23: =K27 -> #REF! | M23: =M27 -> #REF! | N23: 토목6-3-1
B24: 배 관 공 | C24: 수도 | D24: 3 | E24: 인 | F24: =H24+J24+L24 -> 262580 | G24: =I24+K24+M24 -> 787740 | H24: 0 | J24: =노임!$D$10 -> 262580 | K24: =TRUNC(J24*D24,1) -> 787740 | L24: 0
B25: 보통인부 | D25: 1 | E25: 인 | F25: =H25+J25+L25 -> 172068 | G25: =I25+K25+M25 -> 172068 | H25: 0 | J25: =노임!$D$3 -> 172068 | K25: =TRUNC(J25*D25,1) -> 172068 | L25: 0
B26: 트럭탑제형 크레인 | C26: 10 TON | E26: hr | F26: =H26+J26+L26 -> #REF! | G26: =I26+K26+M26 -> #REF! | H26: =#REF! -> #REF! | I26: =TRUNC(H26*D26,1) -> #REF! | J26: =#REF! -> #REF! | K26: =TRUNC(J26*D26,1) -> #REF! | L26: =#REF! -> #REF! | M26: =TRUNC(L26*D26,1) -> #REF!
B27: 일 시공량 | C27: 6 | D27: =ROUND(1/C27,4) -> 0.1667 | E27: 일/본 | G27: =I27+K27+M27 -> #REF! | I27: =TRUNC(SUM(I24:I26)*$D27,1) -> #REF! | K27: =TRUNC(SUM(K24:K26)*$D27,1) -> #REF! | M27: =TRUNC(SUM(M24:M26)*$D27,1) -> #REF!
A29: =A23+1 -> 5 | B29: 강관부설(기계) | C29: D150㎜ | D29: 1 | E29: nr | G29: =I29+K29+M29 -> #REF! | I29: =I33 -> #REF! | K29: =K33 -> #REF! | M29: =M33 -> #REF! | N29: 토목6-3-1
B30: 배 관 공 | C30: 수도 | D30: 2 | E30: 인 | F30: =H30+J30+L30 -> 262580 | G30: =I30+K30+M30 -> 525160 | H30: 0 | J30: =노임!$D$10 -> 262580 | K30: =TRUNC(J30*D30,1) -> 525160 | L30: 0
B31: 보통인부 | D31: 1 | E31: 인 | F31: =H31+J31+L31 -> 172068 | G31: =I31+K31+M31 -> 172068 | H31: 0 | J31: =노임!$D$3 -> 172068 | K31: =TRUNC(J31*D31,1) -> 172068 | L31: 0
B32: 트럭탑제형 크레인 | C32: 10 TON | D32: 8 | E32: hr | F32: =H32+J32+L32 -> #REF! | G32: =I32+K32+M32 -> #REF! | H32: =#REF! -> #REF! | I32: =TRUNC(H32*D32,1) -> #REF! | J32: =#REF! -> #REF! | K32: =TRUNC(J32*D32,1) -> #REF! | L32: =#REF! -> #REF! | M32: =TRUNC(L32*D32,1) -> #REF!
B33: 일 시공량 | C33: 13 | D33: =ROUND(1/C33,4) -> 0.0769 | E33: 일/본 | G33: =I33+K33+M33 -> #REF! | I33: =TRUNC(SUM(I30:I32)*$D33,1) -> #REF! | K33: =TRUNC(SUM(K30:K32)*$D33,1) -> #REF! | M33: =TRUNC(SUM(M30:M32)*$D33,1) -> #REF!
A35: =A29+1 -> 6 | B35: 강관부설(인력) | C35: D200㎜ | D35: 1 | E35: nr | G35: =I35+K35+M35 -> #REF! | I35: =I39 -> #REF! | K35: =K39 -> #REF! | M35: =M39 -> #REF! | N35: 토목6-3-1
B36: 배 관 공 | C36: 수도 | D36: 4 | E36: 인 | F36: =H36+J36+L36 -> 262580 | G36: =I36+K36+M36 -> 1050320 | H36: 0 | J36: =노임!$D$10 -> 262580 | K36: =TRUNC(J36*D36,1) -> 1050320 | L36: 0
B37: 보통인부 | D37: 1 | E37: 인 | F37: =H37+J37+L37 -> 172068 | G37: =I37+K37+M37 -> 172068 | H37: 0 | J37: =노임!$D$3 -> 172068 | K37: =TRUNC(J37*D37,1) -> 172068 | L37: 0
B38: 트럭탑제형 크레인 | C38: 10 TON | E38: hr | F38: =H38+J38+L38 -> #REF! | G38: =I38+K38+M38 -> #REF! | H38: =#REF! -> #REF! | I38: =TRUNC(H38*D38,1) -> #REF! | J38: =#REF! -> #REF! | K38: =TRUNC(J38*D38,1) -> #REF! | L38: =#REF! -> #REF! | M38: =TRUNC(L38*D38,1) -> #REF!
B39: 일 시공량 | C39: 5 | D39: =ROUND(1/C39,4) -> 0.2 | E39: 일/본 | G39: =I39+K39+M39 -> #REF! | I39: =TRUNC(SUM(I36:I38)*$D39,1) -> #REF! | K39: =TRUNC(SUM(K36:K38)*$D39,1) -> #REF! | M39: =TRUNC(SUM(M36:M38)*$D39,1) -> #REF!
A41: =A35+1 -> 7 | B41: 강관부설(기계) | C41: D200㎜ | D41: 1 | E41: nr | G41: =I41+K41+M41 -> #REF! | I41: =I45 -> #REF! | K41: =K45 -> #REF! | M41: =M45 -> #REF! | N41: 토목6-3-1
B42: 배 관 공 | C42: 수도 | D42: 2 | E42: 인 | F42: =H42+J42+L42 -> 262580 | G42: =I42+K42+M42 -> 525160 | H42: 0 | J42: =노임!$D$10 -> 262580 | K42: =TRUNC(J42*D42,1) -> 525160 | L42: 0
B43: 보통인부 | D43: 1 | E43: 인 | F43: =H43+J43+L43 -> 172068 | G43: =I43+K43+M43 -> 172068 | H43: 0 | J43: =노임!$D$3 -> 172068 | K43: =TRUNC(J43*D43,1) -> 172068 | L43: 0
B44: 트럭탑제형 크레인 | C44: 10 TON | D44: 8 | E44: hr | F44: =H44+J44+L44 -> #REF! | G44: =I44+K44+M44 -> #REF! | H44: =#REF! -> #REF! | I44: =TRUNC(H44*D44,1) -> #REF! | J44: =#REF! -> #REF! | K44: =TRUNC(J44*D44,1) -> #REF! | L44: =#REF! -> #REF! | M44: =TRUNC(L44*D44,1) -> #REF!
B45: 일 시공량 | C45: 12 | D45: =ROUND(1/C45,4) -> 0.0833 | E45: 일/본 | G45: =I45+K45+M45 -> #REF! | I45: =TRUNC(SUM(I42:I44)*$D45,1) -> #REF! | K45: =TRUNC(SUM(K42:K44)*$D45,1) -> #REF! | M45: =TRUNC(SUM(M42:M44)*$D45,1) -> #REF!
A47: =A41+1 -> 8 | B47: 강관부설(인력) | C47: D250㎜ | D47: 1 | E47: nr | G47: =I47+K47+M47 -> #REF! | I47: =I51 -> #REF! | K47: =K51 -> #REF! | M47: =M51 -> #REF! | N47: 토목6-3-1
B48: 배 관 공 | C48: 수도 | D48: 4 | E48: 인 | F48: =H48+J48+L48 -> 262580 | G48: =I48+K48+M48 -> 1050320 | H48: 0 | J48: =노임!$D$10 -> 262580 | K48: =TRUNC(J48*D48,1) -> 1050320 | L48: 0
...

Sheet 강관용접
A1: 일위대가_호표_강관용접(용접봉-2010년 표준품셈 기준)
A2: 공 종 명 | C2: 규 격 | D2: 수량 | E2: 단위 | F2: 합 계 | H2: 재 료 비 | J2: 노 무 비 | L2: 경 비 | N2: 비 고
F3: 단 가 | G3: 금 액 | H3: 단 가 | I3: 금 액 | J3: 단 가 | K3: 금 액 | L3: 단 가 | M3: 금 액
A5: ='강관부설 및 철거'!A167 -> 28 | B5: 강관접합(A종) | C5: D80㎜ | D5: 1 | E5: 개소 | G5: =I5+K5+M5 -> #REF! | I5: =I8+I9 -> #REF! | K5: =K8+K9 -> 25682.5 | M5: =M8+M9 -> 1540.9
B6: 용 접 공(일 반) | D6: 1 | E6: 인 | F6: =H6+J6+L6 -> 282536 | G6: =I6+K6+M6 -> 282536 | H6: 0 | J6: =노임!$D$7 -> 282536 | K6: =TRUNC(J6*D6,1) -> 282536 | L6: 0
B7: 공구손료 및 경장비 | C7: 인력품의 | D7: 6 | E7: % | F7: =H7+J7+L7 -> 282536 | G7: =I7+K7+M7 -> 16952.1 | I7: =TRUNC(H7*D7,1) -> 0 | K7: =TRUNC(J7*D7,1) -> 0 | L7: =K6 -> 282536 | M7: =TRUNC(L7*D7/100,1) -> 16952.1
B8: 일 시공량 | C8: 11 | D8: =ROUND(1/C8,4) -> 0.0909 | E8: 일/개소 | G8: =I8+K8+M8 -> 27223.4 | I8: =TRUNC(SUM(I6:I7)*$D8,1) -> 0 | K8: =TRUNC(SUM(K6:K7)*$D8,1) -> 25682.5 | M8: =TRUNC(SUM(M6:M7)*$D8,1) -> 1540.9
B9: 용접봉(고장력강용) | C9: 4.0㎜ KSD5316 | D9: 0.1 | E9: kg | F9: =H9+J9+L9 -> #REF! | G9: =I9+K9+M9 -> #REF! | H9: =#REF! -> #REF! | I9: =TRUNC(H9*D9,1) -> #REF! | J9: 0 | L9: 0
A11: =A5+1 -> 29 | B11: 강관접합(A종) | C11: D100㎜ 이하, 외부용접 | D11: 1 | E11: 개소 | G11: =I11+K11+M11 -> #REF! | I11: =I14+I15 -> #REF! | K11: =K14+K15 -> 25682.5 | M11: =M14+M15 -> 1540.9 | N11: 토목6-3-2
B12: 용 접 공(일 반) | D12: 1 | E12: 인 | F12: =H12+J12+L12 -> 282536 | G12: =I12+K12+M12 -> 282536 | H12: 0 | J12: =노임!$D$7 -> 282536 | K12: =TRUNC(J12*D12,1) -> 282536 | L12: 0
B13: 공구손료 및 경장비 | C13: 인력품의 | D13: 6 | E13: % | F13: =H13+J13+L13 -> 282536 | G13: =I13+K13+M13 -> 16952.1 | I13: =TRUNC(H13*D13,1) -> 0 | K13: =TRUNC(J13*D13,1) -> 0 | L13: =K12 -> 282536 | M13: =TRUNC(L13*D13/100,1) -> 16952.1
B14: 일 시공량 | C14: 11 | D14: =ROUND(1/C14,4) -> 0.0909 | E14: 일/개소 | G14: =I14+K14+M14 -> 27223.4 | I14: =TRUNC(SUM(I12:I13)*$D14,1) -> 0 | K14: =TRUNC(SUM(K12:K13)*$D14,1) -> 25682.5 | M14: =TRUNC(SUM(M12:M13)*$D14,1) -> 1540.9
B15: 용접봉(고장력강용) | C15: 4.0㎜ KSD5316 | D15: 0.14 | E15: kg | F15: =H15+J15+L15 -> #REF! | G15: =I15+K15+M15 -> #REF! | H15: =#REF! -> #REF! | I15: =TRUNC(H15*D15,1) -> #REF! | J15: 0 | L15: 0
A17: =A11+1 -> 30 | B17: 강관접합(A종) | C17: D125㎜, 외부용접 | D17: 1 | E17: 개소 | G17: =I17+K17+M17 -> #REF! | I17: =I20+I21 -> #REF! | K17: =K20+K21 -> 25682.5 | M17: =M20+M21 -> 1540.9 | N17: =N11 -> 토목6-3-2
B18: 용 접 공(일 반) | D18: 1 | E18: 인 | F18: =H18+J18+L18 -> 282536 | G18: =I18+K18+M18 -> 282536 | H18: 0 | J18: =노임!$D$7 -> 282536 | K18: =TRUNC(J18*D18,1) -> 282536 | L18: 0
B19: 공구손료 및 경장비 | C19: 인력품의 | D19: 6 | E19: % | F19: =H19+J19+L19 -> 282536 | G19: =I19+K19+M19 -> 16952.1 | I19: =TRUNC(H19*D19,1) -> 0 | K19: =TRUNC(J19*D19,1) -> 0 | L19: =K18 -> 282536 | M19: =TRUNC(L19*D19/100,1) -> 16952.1
B20: 일 시공량 | C20: 11 | D20: =ROUND(1/C20,4) -> 0.0909 | E20: 일/개소 | G20: =I20+K20+M20 -> 27223.4 | I20: =TRUNC(SUM(I18:I19)*$D20,1) -> 0 | K20: =TRUNC(SUM(K18:K19)*$D20,1) -> 25682.5 | M20: =TRUNC(SUM(M18:M19)*$D20,1) -> 1540.9
B21: 용접봉(고장력강용) | C21: 4.0㎜ KSD5316 | D21: 0.25 | E21: kg | F21: =H21+J21+L21 -> #REF! | G21: =I21+K21+M21 -> #REF! | H21: =#REF! -> #REF! | I21: =TRUNC(H21*D21,1) -> #REF! | J21: 0 | L21: 0
A23: =A17+1 -> 31 | B23: 강관접합(A종) | C23: D150㎜, 외부용접 | D23: 1 | E23: 개소 | G23: =I23+K23+M23 -> #REF! | I23: =I26+I27 -> #REF! | K23: =K26+K27 -> 28253.6 | M23: =M26+M27 -> 1695.2 | N23: =N17 -> 토목6-3-2
B24: 용 접 공(일 반) | D24: 1 | E24: 인 | F24: =H24+J24+L24 -> 282536 | G24: =I24+K24+M24 -> 282536 | H24: 0 | J24: =노임!$D$7 -> 282536 | K24: =TRUNC(J24*D24,1) -> 282536 | L24: 0
B25: 공구손료 및 경장비 | C25: 인력품의 | D25: 6 | E25: % | F25: =H25+J25+L25 -> 282536 | G25: =I25+K25+M25 -> 16952.1 | I25: =TRUNC(H25*D25,1) -> 0 | K25: =TRUNC(J25*D25,1) -> 0 | L25: =K24 -> 282536 | M25: =TRUNC(L25*D25/100,1) -> 16952.1
B26: 일 시공량 | C26: 10 | D26: =ROUND(1/C26,4) -> 0.1 | E26: 일/개소 | G26: =I26+K26+M26 -> 29948.8 | I26: =TRUNC(SUM(I24:I25)*$D26,1) -> 0 | K26: =TRUNC(SUM(K24:K25)*$D26,1) -> 28253.6 | M26: =TRUNC(SUM(M24:M25)*$D26,1) -> 1695.2
B27: 용접봉(고장력강용) | C27: 4.0㎜ KSD5316 | D27: 0.37 | E27: kg | F27: =H27+J27+L27 -> #REF! | G27: =I27+K27+M27 -> #REF! | H27: =#REF! -> #REF! | I27: =TRUNC(H27*D27,1) -> #REF! | J27: 0 | L27: 0
A29: =A23+1 -> 32 | B29: 강관접합(A종) | C29: D200㎜, 외부용접 | D29: 1 | E29: 개소 | G29: =I29+K29+M29 -> #REF! | I29: =I32+I33 -> #REF! | K29: =K32+K33 -> 31389.7 | M29: =M32+M33 -> 1883.3 | N29: =N23 -> 토목6-3-2
B30: 용 접 공(일 반) | D30: 1 | E30: 인 | F30: =H30+J30+L30 -> 282536 | G30: =I30+K30+M30 -> 282536 | H30: 0 | J30: =노임!$D$7 -> 282536 | K30: =TRUNC(J30*D30,1) -> 282536 | L30: 0
B31: 공구손료 및 경장비 | C31: 인력품의 | D31: 6 | E31: % | F31: =H31+J31+L31 -> 282536 | G31: =I31+K31+M31 -> 16952.1 | I31: =TRUNC(H31*D31,1) -> 0 | K31: =TRUNC(J31*D31,1) -> 0 | L31: =K30 -> 282536 | M31: =TRUNC(L31*D31/100,1) -> 16952.1
B32: 일 시공량 | C32: 9 | D32: =ROUND(1/C32,4) -> 0.1111 | E32: 일/개소 | G32: =I32+K32+M32 -> 33273 | I32: =TRUNC(SUM(I30:I31)*$D32,1) -> 0 | K32: =TRUNC(SUM(K30:K31)*$D32,1) -> 31389.7 | M32: =TRUNC(SUM(M30:M31)*$D32,1) -> 1883.3
B33: 용접봉(고장력강용) | C33: 4.0㎜ KSD5316 | D33: 0.54 | E33: kg | F33: =H33+J33+L33 -> #REF! | G33: =I33+K33+M33 -> #REF! | H33: =#REF! -> #REF! | I33: =TRUNC(H33*D33,1) -> #REF! | J33: 0 | L33: 0
A35: =A29+1 -> 33 | B35: 강관접합(A종) | C35: D250㎜, 외부용접 | D35: 1 | E35: 개소 | G35: =I35+K35+M35 -> #REF! | I35: =I38+I39 -> #REF! | K35: =K38+K39 -> 37662 | M35: =M38+M39 -> 2259.7 | N35: =N29 -> 토목6-3-2
B36: 용 접 공(일 반) | D36: 1 | E36: 인 | F36: =H36+J36+L36 -> 282536 | G36: =I36+K36+M36 -> 282536 | H36: 0 | J36: =노임!$D$7 -> 282536 | K36: =TRUNC(J36*D36,1) -> 282536 | L36: 0
B37: 공구손료 및 경장비 | C37: 인력품의 | D37: 6 | E37: % | F37: =H37+J37+L37 -> 282536 | G37: =I37+K37+M37 -> 16952.1 | I37: =TRUNC(H37*D37,1) -> 0 | K37: =TRUNC(J37*D37,1) -> 0 | L37: =K36 -> 282536 | M37: =TRUNC(L37*D37/100,1) -> 16952.1
B38: 일 시공량 | C38: 7.5 | D38: =ROUND(1/C38,4) -> 0.1333 | E38: 일/개소 | G38: =I38+K38+M38 -> 39921.7 | I38: =TRUNC(SUM(I36:I37)*$D38,1) -> 0 | K38: =TRUNC(SUM(K36:K37)*$D38,1) -> 37662 | M38: =TRUNC(SUM(M36:M37)*$D38,1) -> 2259.7
B39: 용접봉(고장력강용) | C39: 4.0㎜ KSD5316 | D39: 0.54 | E39: kg | F39: =H39+J39+L39 -> #REF! | G39: =I39+K39+M39 -> #REF! | H39: =#REF! -> #REF! | I39: =TRUNC(H39*D39,1) -> #REF! | J39: 0 | L39: 0
A41: =A35+1 -> 34 | B41: 강관접합(A종) | C41: D300㎜, 외부용접 | D41: 1 | E41: 개소 | G41: =I41+K41+M41 -> #REF! | I41: =I44+I45 -> #REF! | K41: =K44+K45 -> 43454 | M41: =M44+M45 -> 2607.2 | N41: =N35 -> 토목6-3-2
B42: 용 접 공(일 반) | D42: 1 | E42: 인 | F42: =H42+J42+L42 -> 282536 | G42: =I42+K42+M42 -> 282536 | H42: 0 | J42: =노임!$D$7 -> 282536 | K42: =TRUNC(J42*D42,1) -> 282536 | L42: 0
B43: 공구손료 및 경장비 | C43: 인력품의 | D43: 6 | E43: % | F43: =H43+J43+L43 -> 282536 | G43: =I43+K43+M43 -> 16952.1 | I43: =TRUNC(H43*D43,1) -> 0 | K43: =TRUNC(J43*D43,1) -> 0 | L43: =K42 -> 282536 | M43: =TRUNC(L43*D43/100,1) -> 16952.1
B44: 일 시공량 | C44: 6.5 | D44: =ROUND(1/C44,4) -> 0.1538 | E44: 일/개소 | G44: =I44+K44+M44 -> 46061.2 | I44: =TRUNC(SUM(I42:I43)*$D44,1) -> 0 | K44: =TRUNC(SUM(K42:K43)*$D44,1) -> 43454 | M44: =TRUNC(SUM(M42:M43)*$D44,1) -> 2607.2
B45: 용접봉(고장력강용) | C45: 4.0㎜ KSD5316 | D45: 0.58 | E45: kg | F45: =H45+J45+L45 -> #REF! | G45: =I45+K45+M45 -> #REF! | H45: =#REF! -> #REF! | I45: =TRUNC(H45*D45,1) -> #REF! | J45: 0 | L45: 0
A47: =A41+1 -> 35 | B47: 강관접합(A종) | C47: D350㎜, 외부용접 | D47: 1 | E47: 개소 | G47: =I47+K47+M47 -> #REF! | I47: =I50+I51 -> #REF! | K47: =K50+K51 -> 51365 | M47: =M50+M51 -> 3081.8 | N47: =N41 -> 토목6-3-2
B48: 용 접 공(일 반) | D48: 1 | E48: 인 | F48: =H48+J48+L48 -> 282536 | G48: =I48+K48+M48 -> 282536 | H48: 0 | J48: =노임!$D$7 -> 282536 | K48: =TRUNC(J48*D48,1) -> 282536 | L48: 0
...

Sheet 강관도장
A1: 일위대가_호표_강관도장(재료비-2010년 표준품셈 기준)
A2: 공 종 명 | C2: 규 격 | D2: 수량 | E2: 단위 | F2: 합 계 | H2: 재 료 비 | J2: 노 무 비 | L2: 경 비 | N2: 비 고
F3: 단 가 | G3: 금 액 | H3: 단 가 | I3: 금 액 | J3: 단 가 | K3: 금 액 | L3: 단 가 | M3: 금 액
A5: =강관용접!A245+1 -> 69 | B5: 강관도장(외부) | C5: D80㎜ | D5: 1 | E5: 개소 | G5: =I5+K5+M5 -> #REF! | I5: =TRUNC(I6,0) -> #REF! | K5: =TRUNC(K6,0) -> 14460 | M5: =TRUNC(M6,0) -> 0
B6: 강관도장(외부) | C6: D300㎜적용(80/300=0.2667) | D6: =80/300 -> 0.26666667 | E6: 개소 | F6: =H6+J6+L6 -> #REF! | G6: =I6+K6+M6 -> #REF! | H6: ='목록(강관)'!$I$78 -> #REF! | I6: =TRUNC(H6*D6,1) -> #REF! | J6: ='목록(강관)'!$K$78 -> 54225 | K6: =TRUNC(J6*D6,1) -> 14460 | L6: ='목록(강관)'!$M$78 -> 0 | M6: =TRUNC(L6*D6,1) -> 0
A8: =A5+1 -> 70 | B8: 강관도장(외부) | C8: D100㎜ | D8: 1 | E8: 개소 | G8: =I8+K8+M8 -> #REF! | I8: =TRUNC(I9,0) -> #REF! | K8: =TRUNC(K9,0) -> 18075 | M8: =TRUNC(M9,0) -> 0
B9: 강관도장(외부) | C9: D300㎜적용(100/300=0.3333) | D9: =100/300 -> 0.33333333 | E9: 개소 | F9: =H9+J9+L9 -> #REF! | G9: =I9+K9+M9 -> #REF! | H9: ='목록(강관)'!$I$78 -> #REF! | I9: =TRUNC(H9*D9,1) -> #REF! | J9: ='목록(강관)'!$K$78 -> 54225 | K9: =TRUNC(J9*D9,1) -> 18075 | L9: ='목록(강관)'!$M$78 -> 0 | M9: =TRUNC(L9*D9,1) -> 0
A11: =A8+1 -> 71 | B11: 강관도장(외부) | C11: D150㎜ | D11: 1 | E11: 개소 | G11: =I11+K11+M11 -> #REF! | I11: =TRUNC(I12,0) -> #REF! | K11: =TRUNC(K12,0) -> 27112 | M11: =TRUNC(M12,0) -> 0
B12: 강관도장(외부) | C12: D300㎜적용(150/300=0.5000) | D12: =150/300 -> 0.5 | E12: 개소 | F12: =H12+J12+L12 -> #REF! | G12: =I12+K12+M12 -> #REF! | H12: ='목록(강관)'!$I$78 -> #REF! | I12: =TRUNC(H12*D12,1) -> #REF! | J12: ='목록(강관)'!$K$78 -> 54225 | K12: =TRUNC(J12*D12,1) -> 27112.5 | L12: ='목록(강관)'!$M$78 -> 0 | M12: =TRUNC(L12*D12,1) -> 0
A14: =A11+1 -> 72 | B14: 강관도장(외부) | C14: D200㎜ | D14: 1 | E14: 개소 | G14: =I14+K14+M14 -> #REF! | I14: =TRUNC(I15,0) -> #REF! | K14: =TRUNC(K15,0) -> 36150 | M14: =TRUNC(M15,0) -> 0
B15: 강관도장(외부) | C15: D300㎜적용(200/300=0.6667) | D15: =200/300 -> 0.66666667 | E15: 개소 | F15: =H15+J15+L15 -> #REF! | G15: =I15+K15+M15 -> #REF! | H15: ='목록(강관)'!$I$78 -> #REF! | I15: =TRUNC(H15*D15,1) -> #REF! | J15: ='목록(강관)'!$K$78 -> 54225 | K15: =TRUNC(J15*D15,1) -> 36150 | L15: ='목록(강관)'!$M$78 -> 0 | M15: =TRUNC(L15*D15,1) -> 0
A17: =A14+1 -> 73 | B17: 강관도장(외부) | C17: D250㎜ | D17: 1 | E17: 개소 | G17: =I17+K17+M17 -> #REF! | I17: =TRUNC(I18,0) -> #REF! | K17: =TRUNC(K18,0) -> 45187 | M17: =TRUNC(M18,0) -> 0 | N17: 토목6-3-3
B18: 강관도장(외부) | C18: D300㎜적용(250/300=0.8333) | D18: =250/300 -> 0.83333333 | E18: 개소 | F18: =H18+J18+L18 -> #REF! | G18: =I18+K18+M18 -> #REF! | H18: ='목록(강관)'!$I$78 -> #REF! | I18: =TRUNC(H18*D18,1) -> #REF! | J18: ='목록(강관)'!$K$78 -> 54225 | K18: =TRUNC(J18*D18,1) -> 45187.5 | L18: ='목록(강관)'!$M$78 -> 0 | M18: =TRUNC(L18*D18,1) -> 0
A20: =A17+1 -> 74 | B20: 강관도장(외부) | C20: D300㎜ | D20: 1 | E20: 개소 | G20: =I20+K20+M20 -> #REF! | I20: =TRUNC(I21+I22+I23+I24+I25+I26,0) -> #REF! | K20: =TRUNC(K21+K22+K23+K24+K25+K26,0) -> 54225 | M20: =TRUNC(M21+M22+M23+M24+M25+M26,0) -> 0 | N20: =N17 -> 토목6-3-3
B21: 액상접착재 | C21: 15kg(18ℓ)/can | D21: 0.1 | E21: kg | F21: =H21+J21+L21 -> #REF! | G21: =I21+K21+M21 -> #REF! | H21: =#REF! -> #REF! | I21: =TRUNC(H21*D21,1) -> #REF! | J21: 0 | L21: 0
B22: 매스틱 | C22: 3T x 40 x 6m | D22: 1.1 | E22: m | F22: =H22+J22+L22 -> #REF! | G22: =I22+K22+M22 -> #REF! | H22: =#REF! -> #REF! | I22: =TRUNC(H22*D22,1) -> #REF! | J22: 0 | L22: 0
B23: 안쪽층테이프 | C23: 0.508mm x 100mm x 30m | D23: 0.79 | E23: ㎡ | F23: =H23+J23+L23 -> #REF! | G23: =I23+K23+M23 -> #REF! | H23: =#REF! -> #REF! | I23: =TRUNC(H23*D23,1) -> #REF! | J23: 0 | L23: 0
B24: 바깥층테이프 | C24: 0.381mm x 100mm x 30m | D24: 0.79 | E24: ㎡ | F24: =H24+J24+L24 -> #REF! | G24: =I24+K24+M24 -> #REF! | H24: =#REF! -> #REF! | I24: =TRUNC(H24*D24,1) -> #REF! | J24: 0 | L24: 0
B25: 도 장 공 | D25: 0.18 | E25: 인 | F25: =H25+J25+L25 -> 263017 | G25: =I25+K25+M25 -> 47343 | H25: 0 | J25: =노임!$D$9 -> 263017 | K25: =TRUNC(J25*D25,1) -> 47343 | L25: 0
B26: 보통인부 | D26: 0.04 | E26: 인 | F26: =H26+J26+L26 -> 172068 | G26: =I26+K26+M26 -> 6882.7 | H26: 0 | J26: =노임!$D$3 -> 172068 | K26: =TRUNC(J26*D26,1) -> 6882.7 | L26: 0
A28: =A20+1 -> 75 | B28: 강관도장(외부) | C28: D350㎜ | D28: 1 | E28: 개소 | G28: =I28+K28+M28 -> #REF! | I28: =TRUNC(I29+I30+I31+I32+I33+I34,0) -> #REF! | K28: =TRUNC(K29+K30+K31+K32+K33+K34,0) -> 63836 | M28: =TRUNC(M29+M30+M31+M32+M33+M34,0) -> 0 | N28: =N20 -> 토목6-3-3
B29: 액상접착재 | C29: 15kg(18ℓ)/can | D29: 0.11 | E29: kg | F29: =H29+J29+L29 -> #REF! | G29: =I29+K29+M29 -> #REF! | H29: =#REF! -> #REF! | I29: =TRUNC(H29*D29,1) -> #REF! | J29: 0 | L29: 0
B30: 매스틱 | C30: 3T x 40 x 6m | D30: 1.23 | E30: m | F30: =H30+J30+L30 -> #REF! | G30: =I30+K30+M30 -> #REF! | H30: =#REF! -> #REF! | I30: =TRUNC(H30*D30,1) -> #REF! | J30: 0 | L30: 0
B31: 안쪽층테이프 | C31: 0.508mm x 100mm x 30m | D31: 0.92 | E31: ㎡ | F31: =H31+J31+L31 -> #REF! | G31: =I31+K31+M31 -> #REF! | H31: =#REF! -> #REF! | I31: =TRUNC(H31*D31,1) -> #REF! | J31: 0 | L31: 0
B32: 바깥층테이프 | C32: 0.381mm x 100mm x 30m | D32: 0.92 | E32: ㎡ | F32: =H32+J32+L32 -> #REF! | G32: =I32+K32+M32 -> #REF! | H32: =#REF! -> #REF! | I32: =TRUNC(H32*D32,1) -> #REF! | J32: 0 | L32: 0
B33: 도 장 공 | D33: 0.21 | E33: 인 | F33: =H33+J33+L33 -> 263017 | G33: =I33+K33+M33 -> 55233.5 | H33: 0 | J33: =노임!$D$9 -> 263017 | K33: =TRUNC(J33*D33,1) -> 55233.5 | L33: 0
B34: 보통인부 | D34: 0.05 | E34: 인 | F34: =H34+J34+L34 -> 172068 | G34: =I34+K34+M34 -> 8603.4 | H34: 0 | J34: =노임!$D$3 -> 172068 | K34: =TRUNC(J34*D34,1) -> 8603.4 | L34: 0
A36: =A28+1 -> 76 | B36: 강관도장(외부) | C36: D400㎜ | D36: 1 | E36: 개소 | G36: =I36+K36+M36 -> #REF! | I36: =TRUNC(I37+I38+I39+I40+I41+I42,0) -> #REF! | K36: =TRUNC(K37+K38+K39+K40+K41+K42,0) -> 70817 | M36: =TRUNC(M37+M38+M39+M40+M41+M42,0) -> 0 | N36: =N28 -> 토목6-3-3
B37: 액상접착재 | C37: 15kg(18ℓ)/can | D37: 0.13 | E37: kg | F37: =H37+J37+L37 -> #REF! | G37: =I37+K37+M37 -> #REF! | H37: =#REF! -> #REF! | I37: =TRUNC(H37*D37,1) -> #REF! | J37: 0 | L37: 0
B38: 매스틱 | C38: 3T x 40 x 6m | D38: 1.4 | E38: m | F38: =H38+J38+L38 -> #REF! | G38: =I38+K38+M38 -> #REF! | H38: =#REF! -> #REF! | I38: =TRUNC(H38*D38,1) -> #REF! | J38: 0 | L38: 0
B39: 안쪽층테이프 | C39: 0.508mm x 100mm x 30m | D39: 1.05 | E39: ㎡ | F39: =H39+J39+L39 -> #REF! | G39: =I39+K39+M39 -> #REF! | H39: =#REF! -> #REF! | I39: =TRUNC(H39*D39,1) -> #REF! | J39: 0 | L39: 0
B40: 바깥층테이프 | C40: 0.381mm x 100mm x 30m | D40: 1.05 | E40: ㎡ | F40: =H40+J40+L40 -> #REF! | G40: =I40+K40+M40 -> #REF! | H40: =#REF! -> #REF! | I40: =TRUNC(H40*D40,1) -> #REF! | J40: 0 | L40: 0
B41: 도 장 공 | D41: 0.23 | E41: 인 | F41: =H41+J41+L41 -> 263017 | G41: =I41+K41+M41 -> 60493.9 | H41: 0 | J41: =노임!$D$9 -> 263017 | K41: =TRUNC(J41*D41,1) -> 60493.9 | L41: 0
B42: 보통인부 | D42: 0.06 | E42: 인 | F42: =H42+J42+L42 -> 172068 | G42: =I42+K42+M42 -> 10324 | H42: 0 | J42: =노임!$D$3 -> 172068 | K42: =TRUNC(J42*D42,1) -> 10324 | L42: 0
A44: =A36+1 -> 77 | B44: 강관도장(외부) | C44: D450㎜ | D44: 1 | E44: 개소 | G44: =I44+K44+M44 -> #REF! | I44: =TRUNC(I45+I46+I47+I48+I49+I50,0) -> #REF! | K44: =TRUNC(K45+K46+K47+K48+K49+K50,0) -> 76078 | M44: =TRUNC(M45+M46+M47+M48+M49+M50,0) -> 0 | N44: =N36 -> 토목6-3-3
B45: 액상접착재 | C45: 15kg(18ℓ)/can | D45: 0.14 | E45: kg | F45: =H45+J45+L45 -> #REF! | G45: =I45+K45+M45 -> #REF! | H45: =#REF! -> #REF! | I45: =TRUNC(H45*D45,1) -> #REF! | J45: 0 | L45: 0
B46: 매스틱 | C46: 3T x 40 x 6m | D46: 1.58 | E46: m | F46: =H46+J46+L46 -> #REF! | G46: =I46+K46+M46 -> #REF! | H46: =#REF! -> #REF! | I46: =TRUNC(H46*D46,1) -> #REF! | J46: 0 | L46: 0
B47: 안쪽층테이프 | C47: 0.508mm x 100mm x 30m | D47: 1.18 | E47: ㎡ | F47: =H47+J47+L47 -> #REF! | G47: =I47+K47+M47 -> #REF! | H47: =#REF! -> #REF! | I47: =TRUNC(H47*D47,1) -> #REF! | J47: 0 | L47: 0
B48: 바깥층테이프 | C48: 0.381mm x 100mm x 30m | D48: 1.18 | E48: ㎡ | F48: =H48+J48+L48 -> #REF! | G48: =I48+K48+M48 -> #REF! | H48: =#REF! -> #REF! | I48: =TRUNC(H48*D48,1) -> #REF! | J48: 0 | L48: 0
B49: 도 장 공 | D49: 0.25 | E49: 인 | F49: =H49+J49+L49 -> 263017 | G49: =I49+K49+M49 -> 65754.2 | H49: 0 | J49: =노임!$D$9 -> 263017 | K49: =TRUNC(J49*D49,1) -> 65754.2 | L49: 0
...

Sheet 강관절단 및 절단(철거)
A1: 일위대가_호표_강관절단(재료비-2010년 표준품셈 기준)
A2: 공 종 명 | C2: 규 격 | D2: 수량 | E2: 단위 | F2: 합 계 | H2: 재 료 비 | J2: 노 무 비 | L2: 경 비 | N2: 비 고
F3: 단 가 | G3: 금 액 | H3: 단 가 | I3: 금 액 | J3: 단 가 | K3: 금 액 | L3: 단 가 | M3: 금 액
A5: =강관도장!A224+1 -> 93 | B5: 강관절단(A종) | C5: D80㎜ | D5: 1 | E5: 개소 | G5: =I5+K5+M5 -> #REF! | I5: =TRUNC(I6+I7+I8+I9+I10,0) -> #REF! | K5: =TRUNC(K6+K7+K8+K9+K10,0) -> 22602 | M5: =TRUNC(M6+M7+M8+M9+M10,0) -> 0 | N5: 토목6-3-4
B6: 용 접 공(일 반) | D6: 0.08 | E6: 인 | F6: =H6+J6+L6 -> 282536 | G6: =I6+K6+M6 -> 22602.8 | H6: 0 | J6: =노임!$D$7 -> 282536 | K6: =TRUNC(J6*D6,1) -> 22602.8 | L6: 0
B7: 산소 | C7: 99% 6000ℓ(기체) 40ℓ | D7: 160 | E7: L | F7: =H7+J7+L7 -> #REF! | G7: =I7+K7+M7 -> #REF! | H7: =#REF! -> #REF! | I7: =TRUNC(H7*D7,1) -> #REF! | J7: 0 | L7: 0
B8: 아세칠렌 | C8: 98% (용접용) 1kg=853ℓ | D8: 0.08 | E8: KG | F8: =H8+J8+L8 -> #REF! | G8: =I8+K8+M8 -> #REF! | H8: =#REF! -> #REF! | I8: =TRUNC(H8*D8,1) -> #REF! | J8: 0 | L8: 0
B9: 연마숫돌 | C9: 355x3.5mm | D9: 0.11 | E9: 개 | F9: =H9+J9+L9 -> #REF! | G9: =I9+K9+M9 -> #REF! | H9: =#REF! -> #REF! | I9: =TRUNC(H9*D9,1) -> #REF! | J9: 0 | L9: 0
B10: 공구손료 및 경장비 | C10: 인력품의 | D10: 2 | E10: % | F10: =H10+J10+L10 -> 0 | G10: =I10+K10+M10 -> 452 | I10: =TRUNC((K6*0.02),1) -> 452 | K10: 0 | M10: 0
A12: =A5+1 -> 94 | B12: 강관절단(A종) | C12: D100㎜ | D12: 1 | E12: 개소 | G12: =I12+K12+M12 -> #REF! | I12: =TRUNC(I13+I14+I15+I16+I17,0) -> #REF! | K12: =TRUNC(K13+K14+K15+K16+K17,0) -> 22602 | M12: =TRUNC(M13+M14+M15+M16+M17,0) -> 0 | N12: =N5 -> 토목6-3-4
B13: 용 접 공(일 반) | D13: 0.08 | E13: 인 | F13: =H13+J13+L13 -> 282536 | G13: =I13+K13+M13 -> 22602.8 | J13: =노임!$D$7 -> 282536 | K13: =TRUNC(J13*D13,1) -> 22602.8 | L13: 0
B14: 산소 | C14: 99% 6000ℓ(기체) 40ℓ | D14: 180 | E14: L | F14: =H14+J14+L14 -> #REF! | G14: =I14+K14+M14 -> #REF! | H14: =#REF! -> #REF! | I14: =TRUNC(H14*D14,1) -> #REF! | J14: 0 | L14: 0
B15: 아세칠렌 | C15: 98% (용접용) 1kg=853ℓ | D15: 0.09 | E15: KG | F15: =H15+J15+L15 -> #REF! | G15: =I15+K15+M15 -> #REF! | H15: =#REF! -> #REF! | I15: =TRUNC(H15*D15,1) -> #REF! | J15: 0 | L15: 0
B16: 연마숫돌 | C16: 355x3.5mm | D16: 0.16 | E16: 개 | F16: =H16+J16+L16 -> #REF! | G16: =I16+K16+M16 -> #REF! | H16: =#REF! -> #REF! | I16: =TRUNC(H16*D16,1) -> #REF! | J16: 0 | L16: 0
B17: 공구손료 및 경장비 | C17: 인력품의 | D17: 2 | E17: % | F17: =H17+J17+L17 -> 0 | G17: =I17+K17+M17 -> 452 | I17: =TRUNC((K13*0.02),1) -> 452 | K17: 0 | M17: 0
A19: =A12+1 -> 95 | B19: 강관절단(A종) | C19: D125㎜ | D19: 1 | E19: 개소 | G19: =I19+K19+M19 -> #REF! | I19: =TRUNC(I20+I21+I22+I23+I24,0) -> #REF! | K19: =TRUNC(K20+K21+K22+K23+K24,0) -> 25428 | M19: =TRUNC(M20+M21+M22+M23+M24,0) -> 0 | N19: =N12 -> 토목6-3-4
B20: 용 접 공(일 반) | D20: 0.09 | E20: 인 | F20: =H20+J20+L20 -> 282536 | G20: =I20+K20+M20 -> 25428.2 | J20: =노임!$D$7 -> 282536 | K20: =TRUNC(J20*D20,1) -> 25428.2 | L20: 0
B21: 산소 | C21: 99% 6000ℓ(기체) 40ℓ | D21: 200 | E21: L | F21: =H21+J21+L21 -> #REF! | G21: =I21+K21+M21 -> #REF! | H21: =#REF! -> #REF! | I21: =TRUNC(H21*D21,1) -> #REF! | J21: 0 | L21: 0
B22: 아세칠렌 | C22: 98% (용접용) 1kg=853ℓ | D22: 0.1 | E22: KG | F22: =H22+J22+L22 -> #REF! | G22: =I22+K22+M22 -> #REF! | H22: =#REF! -> #REF! | I22: =TRUNC(H22*D22,1) -> #REF! | J22: 0 | L22: 0
B23: 연마숫돌 | C23: 355x3.5mm | D23: 0.21 | E23: 개 | F23: =H23+J23+L23 -> #REF! | G23: =I23+K23+M23 -> #REF! | H23: =#REF! -> #REF! | I23: =TRUNC(H23*D23,1) -> #REF! | J23: 0 | L23: 0
B24: 공구손료 및 경장비 | C24: 인력품의 | D24: 2 | E24: % | F24: =H24+J24+L24 -> 0 | G24: =I24+K24+M24 -> 508.5 | I24: =TRUNC((K20*0.02),1) -> 508.5 | K24: 0 | M24: 0
A26: =A19+1 -> 96 | B26: 강관절단(A종) | C26: D150㎜ | D26: 1 | E26: 개소 | G26: =I26+K26+M26 -> #REF! | I26: =TRUNC(I27+I28+I29+I30+I31,0) -> #REF! | K26: =TRUNC(K27+K28+K29+K30+K31,0) -> 28253 | M26: =TRUNC(M27+M28+M29+M30+M31,0) -> 0 | N26: =N19 -> 토목6-3-4
B27: 용 접 공(일 반) | D27: 0.1 | E27: 인 | F27: =H27+J27+L27 -> 282536 | G27: =I27+K27+M27 -> 28253.6 | J27: =노임!$D$7 -> 282536 | K27: =TRUNC(J27*D27,1) -> 28253.6 | L27: 0
B28: 산소 | C28: 99% 6000ℓ(기체) 40ℓ | D28: 230 | E28: L | F28: =H28+J28+L28 -> #REF! | G28: =I28+K28+M28 -> #REF! | H28: =#REF! -> #REF! | I28: =TRUNC(H28*D28,1) -> #REF! | J28: 0 | L28: 0
B29: 아세칠렌 | C29: 98% (용접용) 1kg=853ℓ | D29: 0.12 | E29: KG | F29: =H29+J29+L29 -> #REF! | G29: =I29+K29+M29 -> #REF! | H29: =#REF! -> #REF! | I29: =TRUNC(H29*D29,1) -> #REF! | J29: 0 | L29: 0
B30: 연마숫돌 | C30: 355x3.5mm | D30: 0.27 | E30: 개 | F30: =H30+J30+L30 -> #REF! | G30: =I30+K30+M30 -> #REF! | H30: =#REF! -> #REF! | I30: =TRUNC(H30*D30,1) -> #REF! | J30: 0 | L30: 0
B31: 공구손료 및 경장비 | C31: 인력품의 | D31: 2 | E31: % | F31: =H31+J31+L31 -> 0 | G31: =I31+K31+M31 -> 565 | I31: =TRUNC((K27*0.02),1) -> 565 | K31: 0 | M31: 0
A33: =A26+1 -> 97 | B33: 강관절단(A종) | C33: D200㎜ | D33: 1 | E33: 개소 | G33: =I33+K33+M33 -> #REF! | I33: =TRUNC(I34+I35+I36+I37+I38,0) -> #REF! | K33: =TRUNC(K34+K35+K36+K37+K38,0) -> 36729 | M33: =TRUNC(M34+M35+M36+M37+M38,0) -> 0 | N33: =N26 -> 토목6-3-4
B34: 용 접 공(일 반) | D34: 0.13 | E34: 인 | F34: =H34+J34+L34 -> 282536 | G34: =I34+K34+M34 -> 36729.6 | J34: =노임!$D$7 -> 282536 | K34: =TRUNC(J34*D34,1) -> 36729.6 | L34: 0
B35: 산소 | C35: 99% 6000ℓ(기체) 40ℓ | D35: 270 | E35: L | F35: =H35+J35+L35 -> #REF! | G35: =I35+K35+M35 -> #REF! | H35: =#REF! -> #REF! | I35: =TRUNC(H35*D35,1) -> #REF! | J35: 0 | L35: 0
B36: 아세칠렌 | C36: 98% (용접용) 1kg=853ℓ | D36: 0.14 | E36: KG | F36: =H36+J36+L36 -> #REF! | G36: =I36+K36+M36 -> #REF! | H36: =#REF! -> #REF! | I36: =TRUNC(H36*D36,1) -> #REF! | J36: 0 | L36: 0
B37: 연마숫돌 | C37: 355x3.5mm | D37: 0.4 | E37: 개 | F37: =H37+J37+L37 -> #REF! | G37: =I37+K37+M37 -> #REF! | H37: =#REF! -> #REF! | I37: =TRUNC(H37*D37,1) -> #REF! | J37: 0 | L37: 0
B38: 공구손료 및 경장비 | C38: 인력품의 | D38: 2 | E38: % | F38: =H38+J38+L38 -> 0 | G38: =I38+K38+M38 -> 734.5 | I38: =TRUNC((K34*0.02),1) -> 734.5 | K38: 0 | M38: 0
A40: =A33+1 -> 98 | B40: 강관절단(A종) | C40: D250㎜ | D40: 1 | E40: 개소 | G40: =I40+K40+M40 -> #REF! | I40: =TRUNC(I41+I42+I43+I44+I45,0) -> #REF! | K40: =TRUNC(K41+K42+K43+K44+K45,0) -> 45205 | M40: =TRUNC(M41+M42+M43+M44+M45,0) -> 0 | N40: =N33 -> 토목6-3-4
B41: 용 접 공(일 반) | D41: 0.16 | E41: 인 | F41: =H41+J41+L41 -> 282536 | G41: =I41+K41+M41 -> 45205.7 | J41: =노임!$D$7 -> 282536 | K41: =TRUNC(J41*D41,1) -> 45205.7 | L41: 0
B42: 산소 | C42: 99% 6000ℓ(기체) 40ℓ | D42: 360 | E42: L | F42: =H42+J42+L42 -> #REF! | G42: =I42+K42+M42 -> #REF! | H42: =#REF! -> #REF! | I42: =TRUNC(H42*D42,1) -> #REF! | J42: 0 | L42: 0
B43: 아세칠렌 | C43: 98% (용접용) 1kg=853ℓ | D43: 0.18 | E43: KG | F43: =H43+J43+L43 -> #REF! | G43: =I43+K43+M43 -> #REF! | H43: =#REF! -> #REF! | I43: =TRUNC(H43*D43,1) -> #REF! | J43: 0 | L43: 0
B44: 연마숫돌 | C44: 355x3.5mm | D44: 0.58 | E44: 개 | F44: =H44+J44+L44 -> #REF! | G44: =I44+K44+M44 -> #REF! | H44: =#REF! -> #REF! | I44: =TRUNC(H44*D44,1) -> #REF! | J44: 0 | L44: 0
B45: 공구손료 및 경장비 | C45: 인력품의 | D45: 2 | E45: % | F45: =H45+J45+L45 -> 0 | G45: =I45+K45+M45 -> 904.1 | I45: =TRUNC((K41*0.02),1) -> 904.1 | K45: 0 | M45: 0
A47: =A40+1 -> 99 | B47: 강관절단(A종) | C47: D300㎜ | D47: 1 | E47: 개소 | G47: =I47+K47+M47 -> #REF! | I47: =TRUNC(I48+I49+I50+I51+I52,0) -> #REF! | K47: =TRUNC(K48+K49+K50+K51+K52,0) -> 56507 | M47: =TRUNC(M48+M49+M50+M51+M52,0) -> 0 | N47: =N40 -> 토목6-3-4
...

Sheet 플랜지
A1: 일위대가_호표_플랜지접합(접합부속 별도)
A2: 공 종 명 | C2: 규 격 | D2: 수량 | E2: 단위 | F2: 합 계 | H2: 재 료 비 | J2: 노 무 비 | L2: 경 비 | N2: 비 고
F3: 단 가 | G3: 금 액 | H3: 단 가 | I3: 금 액 | J3: 단 가 | K3: 금 액 | L3: 단 가 | M3: 금 액
A5: =절단!A65+1 -> 57 | B5: 플랜지조인트접합 | C5: D80㎜ | D5: 1 | E5: 개소 | G5: =I5+K5+M5 -> #REF! | I5: =TRUNC(I6+I7+I8+I9,0) -> #REF! | K5: =TRUNC(K6+K7+K8,0) -> 16570 | L5: =TRUNC(L6+L7+L8,0) -> 0 | M5: =TRUNC(M6+M7+M8,0) -> 331 | N5: 토목6-8-7
B6: 배 관 공 | C6: 수도 | D6: 0.05 | E6: 인 | F6: =H6+J6+L6 -> 262580 | G6: =I6+K6+M6 -> 13129 | H6: 0 | J6: =노임!$D$10 -> 262580 | K6: =TRUNC(J6*D6,1) -> 13129 | L6: 0
B7: 보통인부 | D7: 0.02 | E7: 인 | F7: =H7+J7+L7 -> 172068 | G7: =I7+K7+M7 -> 3441.3 | H7: 0 | J7: =노임!$D$3 -> 172068 | K7: =TRUNC(J7*D7,1) -> 3441.3 | L7: 0
B8: 공구손료 및 경장비 | C8: 노무비의 % | D8: 2 | E8: % | F8: =H8+J8+L8 -> 0 | G8: =I8+K8+M8 -> 331.4 | M8: =TRUNC((K6+K7)*D8%,1) -> 331.4
B9: 플랜지접합부속 | C9: D80㎜ | D9: 1 | E9: 조 | H9: =#REF! -> #REF! | I9: =TRUNC(H9*D9,1) -> #REF!
A11: =A5+1 -> 58 | B11: 플랜지조인트접합 | C11: D100㎜ | D11: 1 | E11: 개소 | G11: =I11+K11+M11 -> #REF! | I11: =TRUNC(I12+I13+I14+I15,0) -> #REF! | K11: =TRUNC(K12+K13+K14,0) -> 25263 | L11: =TRUNC(L12+L13+L14,0) -> 0 | M11: =TRUNC(M12+M13+M14,0) -> 505 | N11: 토목6-8-7
B12: 배 관 공 | C12: 수도 | D12: 0.07 | E12: 인 | F12: =H12+J12+L12 -> 262580 | G12: =I12+K12+M12 -> 18380.6 | H12: 0 | J12: =노임!$D$10 -> 262580 | K12: =TRUNC(J12*D12,1) -> 18380.6 | L12: 0
B13: 보통인부 | D13: 0.04 | E13: 인 | F13: =H13+J13+L13 -> 172068 | G13: =I13+K13+M13 -> 6882.7 | H13: 0 | J13: =노임!$D$3 -> 172068 | K13: =TRUNC(J13*D13,1) -> 6882.7 | L13: 0
B14: 공구손료 및 경장비 | C14: 노무비의 % | D14: 2 | E14: % | F14: =H14+J14+L14 -> 0 | G14: =I14+K14+M14 -> 505.2 | M14: =TRUNC((K12+K13)*D14%,1) -> 505.2
B15: 플랜지접합부속 | C15: D100㎜ | D15: 1 | E15: 조 | H15: =#REF! -> #REF! | I15: =TRUNC(H15*D15,1) -> #REF!
A17: =A11+1 -> 59 | B17: 플랜지조인트접합 | C17: D150㎜ | D17: 1 | E17: 개소 | G17: =I17+K17+M17 -> #REF! | I17: =TRUNC(I18+I19+I20+I21,0) -> #REF! | K17: =TRUNC(K18+K19+K20,0) -> 32235 | L17: =TRUNC(L18+L19+L20,0) -> 0 | M17: =TRUNC(M18+M19+M20,0) -> 644 | N17: 토목6-8-7
B18: 배 관 공 | C18: 수도 | D18: 0.09 | E18: 인 | F18: =H18+J18+L18 -> 262580 | G18: =I18+K18+M18 -> 23632.2 | H18: 0 | J18: =노임!$D$10 -> 262580 | K18: =TRUNC(J18*D18,1) -> 23632.2 | L18: 0
B19: 보통인부 | D19: 0.05 | E19: 인 | F19: =H19+J19+L19 -> 172068 | G19: =I19+K19+M19 -> 8603.4 | H19: 0 | J19: =노임!$D$3 -> 172068 | K19: =TRUNC(J19*D19,1) -> 8603.4 | L19: 0
B20: 공구손료 및 경장비 | C20: 노무비의 % | D20: 2 | E20: % | F20: =H20+J20+L20 -> 0 | G20: =I20+K20+M20 -> 644.7 | M20: =TRUNC((K18+K19)*D20%,1) -> 644.7
