Workbook
Name _: #REF!
Name _: #REF!
Name _: #REF!
Name _: #REF!
Name _: #REF!
Name _: #REF!
Name _: #REF!
Name _: #REF!
Name _: #REF!
Name _: #REF!
Name _: #REF!
Name _: #REF!
Name _: #REF!
Name _: #REF!
Name _: #REF!
Name _: #REF!
Name _: #REF!
Name _: #REF!
Name __: #REF!
Name __: #REF!
Name __: #REF!
Name __: #REF!
Name __: #REF!
Name __: #REF!
Name __: #REF!
Name __: #REF!
Name __: #REF!
Name __: #REF!
Name __: #REF!
Name __: #REF!
Name ___: #REF!
Name ___: #REF!
Name ___: #REF!
Name ___: #REF!
Name ___: #REF!
Name ___: #REF!
Name ___: #REF!
Name ___: #REF!
Name ___: #REF!
Name ___: #REF!
Name ___: #REF!
Name ___: #REF!
Name ____: #REF!
Name ____: #REF!
Name ____: #REF!
Name ____: #REF!
Name ____: #REF!
Name ____: #REF!
Name ____: #REF!
Name ____: #REF!
Name ____: #REF!
Name ____: #REF!
Name ____: #REF!
Name ____: #REF!
Name _____: #REF!
Name _____: #REF!
Name _____: #REF!
Name _____: #REF!
Name _____: #REF!
Name _____: #REF!

Sheet 기초자료
B1: 현장명 | C1: 옥회천지방하천정비공사 지장관로이설공사 중 부단수공사
A2: 원도급사 | B2: 주소 | C2: 전북특별자치도전주시덕진구숲정이2길27, 2호
B3: 회사명 | C3: 유한회사 선영건설
B4: 대표이사 | C4: 대표이사 김 신
A5: 하도급사 | B5: 주소 | C5: 경기도 안산시 남산평길 126-4 (팔곡일동)
B6: 회사명 | C6: ㈜ 대호스토퍼
B7: 대표이사 | C7: 대표이사 이영호
A8: 계약년월일 | B8: 2026년01월 일
A9: 계약년월일 | B9: 2026년05월 일
A10: 착공년월일 | B10: 2026년02월 일
A11: 착공년월일 | B11: 2026년07월 일
A12: 준공년월일 | B12: 2026년04월24일
A13: 준공년월일 | B13: 2026년09월30일

Sheet 표지
B2: 관리 | P2: 원본 또는 사본(인쇄물)
B4: 번호
E8: 2026년
D22: 군산시 옥회천 지방하천 정비공사 지장관로 이설공사 중
D25: 부단수 공사
I39: 전주권지사

Sheet 목차
B3: 목 차
B5: 1. | C5: 착공계 | J5: (변 경)
B7: 2. | C7: 하도급 공사원가계산서 | J7: (변 경)
B9: 3. | C9: 하도급 총괄집계표 | J9: (변 경)
B11: 4. | C11: 하도급 내역서 | J11: (변 경)
B13: 5. | C13: 원 , 하 공사원가계산서 | J13: (변 경)
B15: 6. | C15: 원 , 하 총괄집계표 | J15: (변 경)
B17: 7. | C17: 원,하 산출내역서 | J17: (변 경)
B19: 8. | C19: 원 , 하 도급내역서 | J19: (변 경)

Sheet 1.착공계
A7: 1. 착 공 계 ( 변 경 )

Sheet 착공계
A1: .
B2: 착 공 계 (변 경)
B4: 공 사 명 | G4: : | H4: =기초자료!C1 -> 옥회천지방하천정비공사 지장관로이설공사 중 부단수공사
B5: 계 약 금 액 | G5: : | H5: =U5 -> 263010000 | U5: =부단수원가!F72 -> 263010000
B6: 계 약 금 액 | G6: : | H6: =U6 -> 264800000 | U6: =부단수원가!F73 -> 264800000
B7: 계약년월일 | G7: : | H7: =기초자료!B8 -> 2026년01월 일
B8: 계약년월일 | G8: : | H8: 46034
B9: 착공년월일 | G9: : | H9: =기초자료!B10 -> 2026년02월 일
B10: 착공년월일 | G10: : | H10: 46204
B11: 준공년월일 | G11: : | H11: =기초자료!B12 -> 2026년04월24일
B12: 준공년월일 | G12: : | H12: =기초자료!B13 -> 2026년09월30일
B17: 위와 같이 착공하였기에 착공계를 제출합니다.
B19: 2026. 05. .
B21: ※. 첨부서류 : | G21: 1. 현장대리인 선임계 | N21: 1부.
G22: 2. 재직증명서 | N22: 1부.
G23: 3. 경력증명서 | N23: 1부.
G24: 4. 예정공정표 | N24: 1부. | O24: 끝.
M27: =기초자료!C5 -> 경기도 안산시 남산평길 126-4 (팔곡일동)
M28: =기초자료!C6 -> ㈜ 대호스토퍼
M29: =기초자료!C7 -> 대표이사 이영호 | AB29: (인)
B31: 유한회사 선영건설 귀하.
B34: 현 장 대 리 인 선 임 계
B37: 공 사 명 | G37: : | H37: =H4 -> 옥회천지방하천정비공사 지장관로이설공사 중 부단수공사
B39: 상기 공사에 대하여 아래와 같이 현장대리인 선임계를 제출합니다.
B42: 현장대리인 | G42: : | H42: 주소 | M42: : | N42: 서울 은평구 은평로220 117동 1803호 (응암동, 녹번역e편한세상캐슬아파트)
H43: 성명 | M43: : | N43: 강 찬 성
H44: 주민등록번호 | M44: : | N44: 561125-1******
H45: 자격분야및등급 | M45: : | N45: 기계 특급
H46: 관리번호 | M46: : | N46: #0576743
B49: =B19 -> 2026. 05. .
M55: =기초자료!C5 -> 경기도 안산시 남산평길 126-4 (팔곡일동)
M56: =기초자료!C6 -> ㈜ 대호스토퍼
M57: =기초자료!C7 -> 대표이사 이영호 | AB57: (인)
B59: =B31 -> 유한회사 선영건설 귀하.
B62: 재 직 증 명 서
B65: 주소 | G65: : | H65: 서울 은평구 은평로220 117동 1803호 (응암동, 녹번역e편한세상캐슬아파트)
B66: 생년월일 | G66: : | H66: 56.11.25
B67: 성명 | G67: : | H67: 강 찬 성
B68: 근무기간 | G68: : | H68: 26.03.01 ~ 현재
B70: 성 명 | G70: 자격분야 및 등급 | P70: 관 리 번 호 | Y70: 비 고
...

Sheet 하도갑지
A2: 하 도 급 내 역 서 ( 변 경 )
O3: 계약보증금 | P3: 하자담보책임-확인 필 | Q3: 하자담보기간-확인 필
P4: 교량. PC암거5%, 기타3% | Q4: 교량7년, 상하수도3년, 포장2년, 관로3년, 조경2년
B5: 공사명 | D5: : | E5: =기초자료!C1 -> 옥회천지방하천정비공사 지장관로이설공사 중 부단수공사 | O5: 0.1 | P5: 0.05 | Q5: 공종별로 분할
O6: =ROUND($P$12*O5,0) -> 381040000 | P6: =ROUND($P$12*P5,0) -> 190520000
A9: =기초자료!B9 -> 2026년05월 일
H12: =기초자료!C5 -> 경기도 안산시 남산평길 126-4 (팔곡일동) | O12: 하도급금액 | P12: =[326]원하원가!Q61 -> 3810400000
H13: =기초자료!C6 -> ㈜ 대호스토퍼
H14: =기초자료!C7 -> 대표이사 이영호 | L14: (인)
B15: =[326]착공계!B32 -> 유한회사 선영건설 귀하.

Sheet 2.하도원가
A7: 2. 하도급 공사원가계산서(변 경)

Sheet 하도원가
A1: 공 사 원 가 계 산 서 ( 변 경 ) - 하 도 급 사 (특허 - 부단수)
A2: 공사명 : | C2: =기초자료!C1 -> 옥회천지방하천정비공사 지장관로이설공사 중 부단수공사
A3: 비 목 | C3: 구 분 | D3: 설계금액 | E3: 도급금액 | F3: 하도급금액 | G3: 요율(%) | H3: 구 성 비(%) | Q3: 비 고
A4: 순 공 사 원 가 | B4: 재 료 비 | C4: 직접재료비 | D4: =부단수!I6 -> 153278992 | E4: =부단수원가!E4 -> 117158010 | F4: =부단수원가!F4 -> 104491200 | G4: =IFERROR(F4/E4,"") -> 0.89188268
C5: 직접재료비 | D5: =부단수!I7 -> 153278992 | E5: =부단수원가!E5 -> 117158010 | F5: =부단수원가!F5 -> 104491200 | G5: =IFERROR(F5/E5,"") -> 0.89188268
C6: 간접재료비 | D6: 0 | E6: =부단수원가!E6 -> 0 | F6: =부단수원가!F6 -> 0 | G6: =IFERROR(F6/E6,"")
C7: 간접재료비 | D7: 0 | E7: =부단수원가!E7 -> 0 | F7: =부단수원가!F7 -> 0 | G7: =IFERROR(F7/E7,"")
C8: 소 계 | D8: =D4+D6 -> 153278992 | E8: =부단수원가!E8 -> 117158010 | F8: =부단수원가!F8 -> 104491200 | G8: =IFERROR(F8/E8,"") -> 0.89188268
C9: 소 계 | D9: =D5+D7 -> 153278992 | E9: =부단수원가!E9 -> 117158010 | F9: =부단수원가!F9 -> 104491200 | G9: =IFERROR(F9/E9,"") -> 0.89188268
B10: 노 무 비 | C10: 직접노무비 | D10: =부단수!K6 -> 56787340 | E10: =부단수원가!E10 -> 40395673 | F10: =부단수원가!F10 -> 39847240 | G10: =IFERROR(F10/E10,"") -> 0.98642347
C11: 직접노무비 | D11: =부단수!K7 -> 56787340 | E11: =부단수원가!E11 -> 40395673 | F11: =부단수원가!F11 -> 39847240 | G11: =IFERROR(F11/E11,"") -> 0.98642347
C12: 간접노무비 | D12: =INT(D10*I12) -> 8120589 | E12: =부단수원가!E12 -> 5776581 | F12: =부단수원가!F12 -> 5698155 | G12: =IFERROR(F12/E12,"") -> 0.98642346 | H12: (직접노무비) × | I12: 0.143
C13: 간접노무비 | D13: =INT(D11*I13) -> 8120589 | E13: =부단수원가!E13 -> 5776581 | F13: =부단수원가!F13 -> 5698155 | G13: =IFERROR(F13/E13,"") -> 0.98642346 | H13: (직접노무비) × | I13: 0.143
C14: 소 계 | D14: =SUM(D10:D12) -> 121695269 | E14: =부단수원가!E14 -> 46172254 | F14: =부단수원가!F14 -> 45545395 | G14: =IFERROR(F14/E14,"") -> 0.98642347
C15: 소 계 | D15: =SUM(D11:D13) -> 73028518 | E15: =부단수원가!E15 -> 46172254 | F15: =부단수원가!F15 -> 45545395 | G15: =IFERROR(F15/E15,"") -> 0.98642347
B16: 경 비 | C16: 산출경비(기계경비) | D16: =부단수!M6 -> 86100296 | E16: =부단수원가!E16 -> 61247444 | F16: =부단수원가!F16 -> 46881796 | G16: =IFERROR(F16/E16,"") -> 0.76544902
C17: 산출경비(기계경비) | D17: =부단수!M7 -> 86100296 | E17: =부단수원가!E17 -> 61247444 | F17: =부단수원가!F17 -> 46881796 | G17: =IFERROR(F17/E17,"") -> 0.76544902
C18: 산재보험료 | D18: 0 | E18: =부단수원가!E18 -> 0 | F18: =부단수원가!F18 -> 0 | G18: =IFERROR(F18/E18,"") | H18: (직노 ＋ 간노) × | I18: 0.0356
C19: 산재보험료 | D19: 0 | E19: =부단수원가!E19 -> 0 | F19: =부단수원가!F19 -> 0 | G19: =IFERROR(F19/E19,"") | H19: (직노 ＋ 간노) × | I19: 0.0356
C20: 고용보험료 | D20: 0 | E20: =부단수원가!E20 -> 0 | F20: =부단수원가!F20 -> 0 | G20: =IFERROR(F20/E20,"") | H20: (직노 ＋ 간노) × | I20: 0.0101
C21: 고용보험료 | D21: 0 | E21: =부단수원가!E21 -> 0 | F21: =부단수원가!F21 -> 0 | G21: =IFERROR(F21/E21,"") | H21: (직노 ＋ 간노) × | I21: 0.0101
C22: 건강보험료 | D22: =INT(D10*I22) -> 2013111 | E22: =부단수원가!E22 -> 2013111 | F22: =부단수원가!F22 -> 1412584 | G22: =IFERROR(F22/E22,"") -> 0.70169206 | H22: (직노) × | I22: 0.03545
C23: 건강보험료 | D23: =INT(D11*I23) -> 2013111 | E23: =부단수원가!E23 -> 1584251 | F23: =부단수원가!F23 -> 1584251 | G23: =IFERROR(F23/E23,"") -> 1 | H23: (직노) × | I23: 0.03545
C24: 연금보험료 | D24: =INT(D10*I24) -> 2555430 | E24: =부단수원가!E24 -> 2555430 | F24: =부단수원가!F24 -> 1793125 | G24: =IFERROR(F24/E24,"") -> 0.70169208 | H24: (직노) × | I24: 0.045
C25: 연금보험료 | D25: =INT(D11*I25) -> 2555430 | E25: =부단수원가!E25 -> 2011039 | F25: =부단수원가!F25 -> 2011039 | G25: =IFERROR(F25/E25,"") -> 1 | H25: (직노) × | I25: 0.045
C26: 노인장기요양보험료 | D26: =INT(D22*I26) -> 260697 | E26: =부단수원가!E26 -> 260697 | F26: =부단수원가!F26 -> 182929 | G26: =IFERROR(F26/E26,"") -> 0.701692 | H26: (건강보험료) × | I26: 0.1295
C27: 노인장기요양보험료 | D27: =INT(D23*I27) -> 260697 | E27: =부단수원가!E27 -> 205160 | F27: =부단수원가!F27 -> 205160 | G27: =IFERROR(F27/E27,"") -> 1 | H27: (건강보험료) × | I27: 0.1295
C28: 퇴직공제부금비 | D28: 0 | E28: =부단수원가!E28 -> 0 | F28: =부단수원가!F28 -> 0 | G28: =IFERROR(F28/E28,"") | H28: (직노) × | I28: 0.023
C29: 퇴직공제부금비 | D29: 0 | E29: =부단수원가!E29 -> 929100 | F29: =부단수원가!F29 -> 916486 | G29: =IFERROR(F29/E29,"") -> 0.98642342 | H29: (직노) × | I29: 0.023
C30: 건설기계지급보증서 | D30: 0 | E30: =부단수원가!E30 -> 0 | F30: =부단수원가!F30 -> 0 | G30: =IFERROR(F30/E30,"") | H30: (재료＋직노＋산경) × | I30: 0.004
C31: 건설기계지급보증서 | D31: 0 | E31: =부단수원가!E31 -> 0 | F31: =부단수원가!F31 -> 0 | G31: =IFERROR(F31/E31,"") | H31: (재료＋직노＋산경) × | I31: 0.004
C32: 안전관리비 | D32: 0 | E32: =부단수원가!E32 -> 0 | F32: =부단수원가!F32 -> 0 | G32: =IFERROR(F32/E32,"")
C33: 안전관리비 | D33: 0 | E33: =부단수원가!E33 -> 0 | F33: =부단수원가!F33 -> 0 | G33: =IFERROR(F33/E33,"")
C34: 신기술사용료 | D34: 0 | E34: =부단수원가!E34 -> 0 | F34: =부단수원가!F34 -> 0 | G34: =IFERROR(F34/E34,"")
C35: 신기술사용료 | D35: 0 | E35: =부단수원가!E35 -> 0 | F35: =부단수원가!F35 -> 0 | G35: =IFERROR(F35/E35,"")
C36: 품질관리비 | D36: 0 | E36: =부단수원가!E36 -> 0 | F36: =부단수원가!F36 -> 0 | G36: =IFERROR(F36/E36,"")
C37: 품질관리비 | D37: 0 | E37: =부단수원가!E37 -> 0 | F37: =부단수원가!F37 -> 0 | G37: =IFERROR(F37/E37,"")
C38: 산업안전보건관리비 | D38: =INT(((D8+D10)*I38+K38)*O38)*0 -> 0 | E38: =부단수원가!E38 -> 0 | F38: =부단수원가!F38 -> 0 | G38: =IFERROR(F38/E38,"") | H38: ((재료＋직노) × | I38: 0.0199 | J38: ＋ | K38: 0 | M38: ) | N38: × | O38: 1.2 | Q38: ※산업안전보건관리비 산출
C39: 산업안전보건관리비 | D39: =INT(((D9+D11)*I39+K39)*O39)*0 -> 0 | E39: =부단수원가!E39 -> 0 | F39: =부단수원가!F39 -> 0 | G39: =IFERROR(F39/E39,"") | H39: ((재료＋직노) × | I39: 0.0199 | J39: ＋ | K39: 0 | M39: ) | N39: × | O39: 1.2 | Q39: ※산업안전보건관리비 산출
A40: 순 공 사 원 가 | B40: 경 비 | C40: 환경보전비 | D40: 0 | E40: =부단수원가!E40 -> 0 | F40: =부단수원가!F40 -> 0 | G40: =IFERROR(F40/E40,"") | H40: (재료 ＋ 직노 ＋ 산경) × | I40: 0.005 | Q40: ①:((재＋직노)×요율+기초금액)×1.2
...

Sheet 3.하도급 총괄집계표
A7: 3. 하도급 총괄집계표 (변 경)

Sheet 하도총괄집계표
A1: 하 도 급 총 괄 집 계 표(변 경)
A2: 공사명 : | B2: =기초자료!C1 -> 옥회천지방하천정비공사 지장관로이설공사 중 부단수공사
A3: 구 분 | B3: 공 종 명 | C3: 금 액 | E3: 요율(%) | G3: 비 고
C4: 원도급금액 | D4: 하도급 금액 | F4: 표준분류코드 | BB4: 메모
A5: ※ | B5: 도급공사비 | C5: =C77 -> 300980000 | D5: =D77 -> 263010000 | E5: =IFERROR(D5/C5,"") -> 0.87384544
A6: ※ | B6: 도급공사비 | C6: =C78 -> 300800000 | D6: =D78 -> 264800000 | E6: =IFERROR(D6/C6,"") -> 0.88031915
A7: 가 | B7: 직접공사비 | C7: =C9 -> 218801127 | D7: =D9 -> 191220236 | E7: =IFERROR(D7/C7,"") -> 0.87394539 | J7: 10
A8: 가 | B8: 직접공사비 | C8: =C10 -> 218801127 | D8: =D10 -> 191220236 | E8: =IFERROR(D8/C8,"") -> 0.87394539 | J8: 10
A9: Ⅰ | B9: 상수도시설 | C9: =C11 -> 218801127 | D9: =D11 -> 191220236 | E9: =IFERROR(D9/C9,"") -> 0.87394539 | F9: F1400
A10: Ⅰ | B10: 상수도시설 | C10: =C12 -> 218801127 | D10: =D12 -> 191220236 | E10: =IFERROR(D10/C10,"") -> 0.87394539 | F10: F1400
A11: Ⅰ.1 | B11: 송수시설 | C11: =C13 -> 218801127 | D11: =D13 -> 191220236 | E11: =IFERROR(D11/C11,"") -> 0.87394539 | F11: F1441
A12: Ⅰ.1 | B12: 송수시설 | C12: =C14 -> 218801127 | D12: =D14 -> 191220236 | E12: =IFERROR(D12/C12,"") -> 0.87394539 | F12: F1441
A13: 2 | B13: 관로공 | C13: =C17 -> 218801127 | D13: =D17 -> 191220236 | E13: =IFERROR(D13/C13,"") -> 0.87394539 | F13: CG | J13: 30 | L13: A0200 | BC13: =HYPERLINK("#내역서!A35","A0200 →") -> A0200 →
A14: 2 | B14: 관로공 | C14: =C18 -> 218801127 | D14: =D18 -> 191220236 | E14: =IFERROR(D14/C14,"") -> 0.87394539 | F14: CG | J14: 30 | L14: A0200 | BC14: =HYPERLINK("#내역서!A35","A0200 →") -> A0200 →
E15: =IFERROR(D15/C15,"")
E16: =IFERROR(D16/C16,"")
A17: 2 | B17: 관로공 | C17: =C19 -> 218801127 | D17: =D19 -> 191220236 | E17: =IFERROR(D17/C17,"") -> 0.87394539 | F17: CG | I17: A0200 | T17: =#REF!+#REF!+#REF!+#REF!+#REF!+#REF!+#REF!+#REF!+#REF!+#REF!+#REF!+#REF!+#REF!+#REF!+#REF!+#REF!+#REF!+#REF!+#REF!+#REF!+#REF!+#REF!+#REF!+#REF!+#REF!+#REF!+#REF!+#REF!+#REF!+#REF!+#REF!+#REF!+#REF!+#REF!+#REF!+#REF!+#REF! -> #REF! | U17: =#REF!+#REF!+#REF!+#REF!+#REF!+#REF!+#REF!+#REF!+#REF!+#REF!+#REF!+#REF!+#REF!+#REF!+#REF!+#REF!+#REF!+#REF!+#REF!+#REF!+#REF!+#REF!+#REF!+#REF!+#REF!+#REF!+#REF!+#REF!+#REF!+#REF!+#REF!+#REF!+#REF!+#REF!+#REF!+#REF!+#REF! -> #REF! | V17: =#REF!+#REF!+#REF!+#REF!+#REF!+#REF!+#REF!+#REF!+#REF!+#REF!+#REF!+#REF!+#REF!+#REF!+#REF!+#REF!+#REF!+#REF!+#REF!+#REF!+#REF!+#REF!+#REF!+#REF!+#REF!+#REF!+#REF!+#REF!+#REF!+#REF!+#REF!+#REF!+#REF!+#REF!+#REF!+#REF!+#REF! -> #REF!
A18: 2 | B18: 관로공 | C18: =C20 -> 218801127 | D18: =D20 -> 191220236 | E18: =IFERROR(D18/C18,"") -> 0.87394539 | F18: CG | I18: A0200 | T18: =#REF!+#REF!+#REF!+#REF!+#REF!+#REF!+#REF!+#REF!+#REF!+#REF!+#REF!+#REF!+#REF!+#REF!+#REF!+#REF!+#REF!+#REF!+#REF!+#REF!+#REF!+#REF!+#REF!+#REF!+#REF!+#REF!+#REF!+#REF!+#REF!+#REF!+#REF!+#REF!+#REF!+#REF!+#REF!+#REF!+#REF! -> #REF! | U18: =#REF!+#REF!+#REF!+#REF!+#REF!+#REF!+#REF!+#REF!+#REF!+#REF!+#REF!+#REF!+#REF!+#REF!+#REF!+#REF!+#REF!+#REF!+#REF!+#REF!+#REF!+#REF!+#REF!+#REF!+#REF!+#REF!+#REF!+#REF!+#REF!+#REF!+#REF!+#REF!+#REF!+#REF!+#REF!+#REF!+#REF! -> #REF! | V18: =#REF!+#REF!+#REF!+#REF!+#REF!+#REF!+#REF!+#REF!+#REF!+#REF!+#REF!+#REF!+#REF!+#REF!+#REF!+#REF!+#REF!+#REF!+#REF!+#REF!+#REF!+#REF!+#REF!+#REF!+#REF!+#REF!+#REF!+#REF!+#REF!+#REF!+#REF!+#REF!+#REF!+#REF!+#REF!+#REF!+#REF! -> #REF!
A19: 2.10 | B19: 부단수차단 | C19: =부단수!O6 -> 218801127 | D19: =부단수!W6 -> 191220236 | E19: =IFERROR(D19/C19,"") -> 0.87394539 | F19: CGO | J19: 10 | T19: =#REF!+#REF!+#REF!+#REF!+#REF!+#REF!+#REF!+#REF!+#REF!+#REF!+#REF!+#REF!+#REF! -> #REF! | U19: =#REF!+#REF!+#REF!+#REF!+#REF!+#REF!+#REF!+#REF!+#REF!+#REF!+#REF!+#REF!+#REF! -> #REF! | V19: =#REF!+#REF!+#REF!+#REF!+#REF!+#REF!+#REF!+#REF!+#REF!+#REF!+#REF!+#REF!+#REF! -> #REF!
A20: 2.10 | B20: 부단수차단 | C20: =부단수!O7 -> 218801127 | D20: =부단수!W7 -> 191220236 | E20: =IFERROR(D20/C20,"") -> 0.87394539 | F20: CGO | J20: 10 | T20: =#REF!+#REF!+#REF!+#REF!+#REF!+#REF!+#REF!+#REF!+#REF!+#REF!+#REF!+#REF!+#REF! -> #REF! | U20: =#REF!+#REF!+#REF!+#REF!+#REF!+#REF!+#REF!+#REF!+#REF!+#REF!+#REF!+#REF!+#REF! -> #REF! | V20: =#REF!+#REF!+#REF!+#REF!+#REF!+#REF!+#REF!+#REF!+#REF!+#REF!+#REF!+#REF!+#REF! -> #REF!
A23: 나 | B23: 간접공사비 | C23: =SUM(C25:C61) -> 65166543 | D23: =D25+D27+D29+D31+D33+D35+D37+D39+D41+D43+D45+D47+D49+D51+D53+D55+D57+D59+D61 -> 17788915 | E23: =IFERROR(D23/C23,"") -> 0.2729762
A24: 나 | B24: 간접공사비 | C24: =SUM(C26:C62) -> 68863117 | D24: =D26+D28+D30+D32+D34+D36+D38+D40+D42+D44+D46+D48+D50+D52+D54+D56+D58+D60+D62 -> 19117213 | E24: =IFERROR(D24/C24,"") -> 0.27761179
A25: 1 | B25: 간접노무비 | C25: =부단수원가!E12 -> 5776581 | D25: =부단수원가!F12 -> 5698155 | E25: =IFERROR(D25/C25,"") -> 0.98642346
A26: 1 | B26: 간접노무비 | C26: =부단수원가!E13 -> 5776581 | D26: =부단수원가!F13 -> 5698155 | E26: =IFERROR(D26/C26,"") -> 0.98642346
A27: 2 | B27: 산재보험료 | C27: =[327]산출내역서!G101 -> 0 | D27: =부단수원가!F18 -> 0 | E27: =IFERROR(D27/C27,"")
A28: 2 | B28: 산재보험료 | C28: =[327]산출내역서!G102 -> 0 | D28: =부단수원가!F19 -> 0 | E28: =IFERROR(D28/C28,"")
A29: 3 | B29: 고용보험료 | C29: =[327]산출내역서!G102 -> 0 | D29: =부단수원가!F20 -> 0 | E29: =IFERROR(D29/C29,"")
A30: 3 | B30: 고용보험료 | C30: =[327]산출내역서!G103 -> 8265086 | D30: =부단수원가!F21 -> 0 | E30: =IFERROR(D30/C30,"") -> 0
A31: 4 | B31: 건강보험료 | C31: =부단수원가!E22 -> 2013111 | D31: =부단수원가!F22 -> 1412584 | E31: =IFERROR(D31/C31,"") -> 0.70169206
A32: 4 | B32: 건강보험료 | C32: =부단수원가!E23 -> 1584251 | D32: =부단수원가!F23 -> 1584251 | E32: =IFERROR(D32/C32,"") -> 1
A33: 5 | B33: 연금보험료 | C33: =부단수원가!E24 -> 2555430 | D33: =부단수원가!F24 -> 1793125 | E33: =IFERROR(D33/C33,"") -> 0.70169208
A34: 5 | B34: 연금보험료 | C34: =부단수원가!E25 -> 2011039 | D34: =부단수원가!F25 -> 2011039 | E34: =IFERROR(D34/C34,"") -> 1
A35: 6 | B35: 노인장기요양보험료 | C35: =부단수원가!E26 -> 260697 | D35: =부단수원가!F26 -> 182929 | E35: =IFERROR(D35/C35,"") -> 0.701692
A36: 6 | B36: 노인장기요양보험료 | C36: =부단수원가!E27 -> 205160 | D36: =부단수원가!F27 -> 205160 | E36: =IFERROR(D36/C36,"") -> 1
A37: 7 | B37: 퇴직공제부금비 | C37: =부단수원가!E28 -> 0 | D37: =부단수원가!F28 -> 0 | E37: =IFERROR(D37/C37,"")
A38: 7 | B38: 퇴직공제부금비 | C38: =부단수원가!E29 -> 929100 | D38: =부단수원가!F29 -> 916486 | E38: =IFERROR(D38/C38,"") -> 0.98642342
A39: 8 | B39: 건설기계지급보증서 | C39: =부단수원가!E30 -> 0 | D39: =부단수원가!F30 -> 0 | E39: =IFERROR(D39/C39,"")
A40: 8 | B40: 건설기계지급보증서 | C40: =부단수원가!E31 -> 0 | D40: =부단수원가!F31 -> 0 | E40: =IFERROR(D40/C40,"")
A41: 9 | B41: 안전관리비 | C41: =[327]산출내역서!G108 -> 0 | D41: =부단수원가!F32 -> 0 | E41: =IFERROR(D41/C41,"")
A42: 9 | B42: 안전관리비 | C42: =[327]산출내역서!G109 -> 0 | D42: =부단수원가!F33 -> 0 | E42: =IFERROR(D42/C42,"")
...

Sheet 4.하도급 내역서
A7: 4. 하도급 내역서(변 경)

Sheet 하도급내역서
A2: 하도급 내역서(변 경,특허-부단수)
A4: 번호 | B4: 항목 | C4: 규격 | D4: 수량 | E4: 단위 | F4: 설계금액 | H4: 재료비 | J4: 노무비 | L4: 경 비 | N4: 도급금액 | P4: 재료비 | R4: 노무비 | T4: 경 비 | V4: 하도급금액 | X4: 재료비 | Z4: 노무비 | AB4: 경 비 | AD4: 비고
F5: 단 가 | G5: 금 액 | H5: 단 가 | I5: 금 액 | J5: 단 가 | K5: 금 액 | L5: 단 가 | M5: 금 액 | N5: 단 가 | O5: 금 액 | P5: 단 가 | Q5: 금 액 | R5: 단 가 | S5: 금 액 | T5: 단 가 | U5: 금 액 | V5: 단 가 | W5: 금 액 | X5: 단 가 | Y5: 금 액 | Z5: 단 가 | AA5: 금 액 | AB5: 단 가 | AC5: 금 액
B6: 총공사원가 | G6: =G8 -> 296166628 | I6: =I8 -> 153278992 | K6: =K8 -> 56787340 | M6: =M8 -> 86100296 | O6: =O8 -> 218801127 | Q6: =Q8 -> 117158010 | S6: =S8 -> 40395673 | U6: =U8 -> 61247444 | W6: =W8 -> 191220236 | Y6: =Y8 -> 104491200 | AA6: =AA8 -> 39847240 | AC6: =AC8 -> 46881796 | AE6: 합계
B7: 총공사원가 | G7: =G14 -> 296166628 | I7: =I14 -> 153278992 | K7: =K14 -> 56787340 | M7: =M14 -> 86100296 | O7: =O14 -> 218801127 | Q7: =Q14 -> 117158010 | S7: =S14 -> 40395673 | U7: =U14 -> 61247444 | W7: =W14 -> 191220236 | Y7: =Y14 -> 104491200 | AA7: =AA14 -> 39847240 | AC7: =AC14 -> 46881796 | AE7: 합계
A8: 가 | B8: 직접공사비 | G8: =I8+K8+M8 -> 296166628 | I8: =I15 -> 153278992 | K8: =K15 -> 56787340 | M8: =M15 -> 86100296 | O8: =Q8+S8+U8 -> 218801127 | Q8: =Q15 -> 117158010 | S8: =S15 -> 40395673 | U8: =U15 -> 61247444 | W8: =Y8+AA8+AC8 -> 191220236 | Y8: =Y15 -> 104491200 | AA8: =AA15 -> 39847240 | AC8: =AC15 -> 46881796 | AE8: 합계
A9: Ⅰ | B9: 공통시설 | G9: =I9+K9+M9 -> 0 | I9: 0 | K9: 0 | M9: =M10 -> 0 | O9: =Q9+S9+U9 -> 0 | Q9: 0 | S9: 0 | U9: =U10 -> 0 | W9: =Y9+AA9+AC9 -> 0 | Y9: 0 | AA9: 0 | AC9: =AC10 -> 0 | AE9: 합계
A10: 1 | B10: 공통공사 | G10: =I10+K10+M10 -> 0 | I10: =I11 -> 0 | K10: =K11 -> 0 | M10: =M11 -> 0 | O10: =Q10+S10+U10 -> 0 | Q10: =Q11 -> 0 | S10: =S11 -> 0 | U10: =U11 -> 0 | W10: =Y10+AA10+AC10 -> 0 | Y10: =Y11 -> 0 | AA10: =AA11 -> 0 | AC10: =AC11 -> 0 | AE10: 합계
AE11: 직영
AE12: 직영
AE13: 직영
A14: 가 | B14: 직접공사비 | G14: =I14+K14+M14 -> 296166628 | I14: =I29 -> 153278992 | K14: =K29 -> 56787340 | M14: =M29 -> 86100296 | O14: =Q14+S14+U14 -> 218801127 | Q14: =Q29 -> 117158010 | S14: =S29 -> 40395673 | U14: =U29 -> 61247444 | W14: =Y14+AA14+AC14 -> 191220236 | Y14: =Y29 -> 104491200 | AA14: =AA29 -> 39847240 | AC14: =AC29 -> 46881796 | AE14: 합계
A15: Ⅱ | B15: 상수도시설 | G15: =I15+K15+M15 -> 296166628 | I15: =I16+I30+I90+I102+I132+I139 -> 153278992 | K15: =K16+K30+K90+K102+K132+K139 -> 56787340 | M15: =M16+M30+M90+M102+M132+M139 -> 86100296 | O15: =Q15+S15+U15 -> 218801127 | Q15: =Q16+Q30+Q90+Q102+Q132+Q139 -> 117158010 | S15: =S16+S30+S90+S102+S132+S139 -> 40395673 | U15: =U16+U30+U90+U102+U132+U139 -> 61247444 | W15: =Y15+AA15+AC15 -> 191220236 | Y15: =Y16+Y30+Y90+Y102+Y132+Y139 -> 104491200 | AA15: =AA16+AA30+AA90+AA102+AA132+AA139 -> 39847240 | AC15: =AC16+AC30+AC90+AC102+AC132+AC139 -> 46881796 | AE15: 합계
A16: 1 | B16: 토공 | G16: =I16+K16+M16 -> 0 | I16: =I17+I24 -> 0 | K16: =K17+K24 -> 0 | M16: =M17+M24 -> 0 | O16: =Q16+S16+U16 -> 0 | Q16: =Q17+Q24 -> 0 | S16: =S17+S24 -> 0 | U16: =U17+U24 -> 0 | W16: =Y16+AA16+AC16 -> 0 | Y16: =Y17+Y24 -> 0 | AA16: =AA17+AA24 -> 0 | AC16: =AC17+AC24 -> 0 | AE16: 합계
A17: 1.1 | B17: 기존구조물철거 | G17: =I17+K17+M17 -> 0 | I17: =SUM(I18:I23) -> 0 | K17: =SUM(K18:K23) -> 0 | M17: =SUM(M18:M23) -> 0 | O17: =Q17+S17+U17 -> 0 | Q17: =SUM(Q18:Q23) -> 0 | S17: =SUM(S18:S23) -> 0 | U17: =SUM(U18:U23) -> 0 | W17: =Y17+AA17+AC17 -> 0 | Y17: =SUM(Y18:Y23) -> 0 | AA17: =SUM(AA18:AA23) -> 0 | AC17: =SUM(AC18:AC23) -> 0 | AE17: 합계
AE18: 직영
AE19: 직영
AE20: 직영
AE21: 직영
AE22: 직영
AE23: 직영
A24: 1.2 | B24: 토공작업 | G24: =I24+K24+M24 -> 0 | I24: =SUM(I25:I28) -> 0 | K24: =SUM(K25:K28) -> 0 | M24: =SUM(M25:M28) -> 0 | O24: =Q24+S24+U24 -> 0 | Q24: =SUM(Q25:Q28) -> 0 | S24: =SUM(S25:S28) -> 0 | U24: =SUM(U25:U28) -> 0 | W24: =Y24+AA24+AC24 -> 0 | Y24: =SUM(Y25:Y28) -> 0 | AA24: =SUM(AA25:AA28) -> 0 | AC24: =SUM(AC25:AC28) -> 0 | AE24: 합계
AE25: 가시설
AE26: 직영
AE27: 직영
AE28: 직영
A29: Ⅱ | B29: 상수도시설 | G29: =I29+K29+M29 -> 296166628 | I29: =I30+I44+I104+I116+I146+I153 -> 153278992 | K29: =K30+K44+K104+K116+K146+K153 -> 56787340 | M29: =M30+M44+M104+M116+M146+M153 -> 86100296 | O29: =Q29+S29+U29 -> 218801127 | Q29: =Q30+Q44+Q104+Q116+Q146+Q153 -> 117158010 | S29: =S30+S44+S104+S116+S146+S153 -> 40395673 | U29: =U30+U44+U104+U116+U146+U153 -> 61247444 | W29: =Y29+AA29+AC29 -> 191220236 | Y29: =Y30+Y44+Y104+Y116+Y146+Y153 -> 104491200 | AA29: =AA30+AA44+AA104+AA116+AA146+AA153 -> 39847240 | AC29: =AC30+AC44+AC104+AC116+AC146+AC153 -> 46881796 | AE29: 합계
A30: 2 | B30: 관로공 | G30: =I30+K30+M30 -> 296166628 | I30: =I85 -> 153278992 | K30: =K85 -> 56787340 | M30: =M85 -> 86100296 | O30: =Q30+S30+U30 -> 218801127 | Q30: =Q85 -> 117158010 | S30: =S85 -> 40395673 | U30: =U85 -> 61247444 | W30: =Y30+AA30+AC30 -> 191220236 | Y30: =Y85 -> 104491200 | AA30: =AA85 -> 39847240 | AC30: =AC85 -> 46881796 | AE30: 합계
AE31: 관로공
AE32: 관로공
AE33: 관로공
AE34: 관로공
AE35: 관로공
AE36: 관로공
AE37: 관로공
AE38: 관로공
AE39: 관로공
AE40: 관로공
AE41: 관로공
AE42: 관로공
...

Sheet 원하갑지
A2: 원 · 하 도 급 대 비 표 ( 변 경 )
B5: 공사명 | D5: : | E5: =기초자료!C1 -> 옥회천지방하천정비공사 지장관로이설공사 중 부단수공사
A7: =기초자료!B9 -> 2026년05월 일
F9: 원도급사 : | H9: =기초자료!C2 -> 전북특별자치도전주시덕진구숲정이2길27, 2호
H10: =기초자료!C3 -> 유한회사 선영건설
H11: =기초자료!C4 -> 대표이사 김 신 | L11: (인)
F13: 하도급사 : | H13: =기초자료!C5 -> 경기도 안산시 남산평길 126-4 (팔곡일동)
H14: =기초자료!C6 -> ㈜ 대호스토퍼
H15: =기초자료!C7 -> 대표이사 이영호 | L15: (인)

Sheet 5. 원,하 원가계산서
A7: 5. 원 , 하 공사원가계산서(변 경)

Sheet 원히원가
A1: 원 , 하 공 사 원 가 계 산 서(변 경,특허 - 부단수)
A2: 공사명 : | C2: =기초자료!C1 -> 옥회천지방하천정비공사 지장관로이설공사 중 부단수공사
A3: 비 목 | C3: 구 분 | D3: 설계금액 | E3: 도급금액 | F3: 하도급금액 | G3: 요율(%) | H3: 구 성 비(%) | Q3: 비 고
A4: 순 공 사 원 가 | B4: 재 료 비 | C4: 직접재료비 | D4: =부단수!I6 -> 153278992 | E4: =부단수원가!E4 -> 117158010 | F4: =부단수원가!F4 -> 104491200 | G4: =IFERROR(F4/E4,"") -> 0.89188268
C5: 직접재료비 | D5: =부단수!I7 -> 153278992 | E5: =부단수원가!E5 -> 117158010 | F5: =부단수원가!F5 -> 104491200 | G5: =IFERROR(F5/E5,"") -> 0.89188268
C6: 간접재료비 | D6: 0 | E6: =부단수원가!E6 -> 0 | F6: =부단수원가!F6 -> 0 | G6: =IFERROR(F6/E6,"")
C7: 간접재료비 | D7: 0 | E7: =부단수원가!E7 -> 0 | F7: =부단수원가!F7 -> 0 | G7: =IFERROR(F7/E7,"")
C8: 소 계 | D8: =D4+D6 -> 153278992 | E8: =부단수원가!E8 -> 117158010 | F8: =부단수원가!F8 -> 104491200 | G8: =IFERROR(F8/E8,"") -> 0.89188268
C9: 소 계 | D9: =D5+D7 -> 153278992 | E9: =부단수원가!E9 -> 117158010 | F9: =부단수원가!F9 -> 104491200 | G9: =IFERROR(F9/E9,"") -> 0.89188268
B10: 노 무 비 | C10: 직접노무비 | D10: =부단수!K6 -> 56787340 | E10: =부단수원가!E10 -> 40395673 | F10: =부단수원가!F10 -> 39847240 | G10: =IFERROR(F10/E10,"") -> 0.98642347
C11: 직접노무비 | D11: =부단수!K7 -> 56787340 | E11: =부단수원가!E11 -> 40395673 | F11: =부단수원가!F11 -> 39847240 | G11: =IFERROR(F11/E11,"") -> 0.98642347
C12: 간접노무비 | D12: =INT(D10*I12) -> 8120589 | E12: =부단수원가!E12 -> 5776581 | F12: =부단수원가!F12 -> 5698155 | G12: =IFERROR(F12/E12,"") -> 0.98642346 | H12: (직접노무비) × | I12: 0.143
C13: 간접노무비 | D13: =INT(D11*I13) -> 8120589 | E13: =부단수원가!E13 -> 5776581 | F13: =부단수원가!F13 -> 5698155 | G13: =IFERROR(F13/E13,"") -> 0.98642346 | H13: (직접노무비) × | I13: 0.143
C14: 소 계 | D14: =SUM(D10:D12) -> 121695269 | E14: =부단수원가!E14 -> 46172254 | F14: =부단수원가!F14 -> 45545395 | G14: =IFERROR(F14/E14,"") -> 0.98642347
C15: 소 계 | D15: =SUM(D11:D13) -> 73028518 | E15: =부단수원가!E15 -> 46172254 | F15: =부단수원가!F15 -> 45545395 | G15: =IFERROR(F15/E15,"") -> 0.98642347
B16: 경 비 | C16: 산출경비(기계경비) | D16: =부단수!M6 -> 86100296 | E16: =부단수원가!E16 -> 61247444 | F16: =부단수원가!F16 -> 46881796 | G16: =IFERROR(F16/E16,"") -> 0.76544902
C17: 산출경비(기계경비) | D17: =부단수!M7 -> 86100296 | E17: =부단수원가!E17 -> 61247444 | F17: =부단수원가!F17 -> 46881796 | G17: =IFERROR(F17/E17,"") -> 0.76544902
C18: 산재보험료 | D18: 0 | E18: =부단수원가!E18 -> 0 | F18: =부단수원가!F18 -> 0 | G18: =IFERROR(F18/E18,"") | H18: (직노 ＋ 간노) × | I18: 0.0356
C19: 산재보험료 | D19: 0 | E19: =부단수원가!E19 -> 0 | F19: =부단수원가!F19 -> 0 | G19: =IFERROR(F19/E19,"") | H19: (직노 ＋ 간노) × | I19: 0.0356
C20: 고용보험료 | D20: 0 | E20: =부단수원가!E20 -> 0 | F20: =부단수원가!F20 -> 0 | G20: =IFERROR(F20/E20,"") | H20: (직노 ＋ 간노) × | I20: 0.0101
C21: 고용보험료 | D21: 0 | E21: =부단수원가!E21 -> 0 | F21: =부단수원가!F21 -> 0 | G21: =IFERROR(F21/E21,"") | H21: (직노 ＋ 간노) × | I21: 0.0101
C22: 건강보험료 | D22: =INT(D10*I22) -> 2013111 | E22: =부단수원가!E22 -> 2013111 | F22: =부단수원가!F22 -> 1412584 | G22: =IFERROR(F22/E22,"") -> 0.70169206 | H22: (직노) × | I22: 0.03545
C23: 건강보험료 | D23: =INT(D11*I23) -> 2013111 | E23: =부단수원가!E23 -> 1584251 | F23: =부단수원가!F23 -> 1584251 | G23: =IFERROR(F23/E23,"") -> 1 | H23: (직노) × | I23: 0.03545
C24: 연금보험료 | D24: =INT(D10*I24) -> 2555430 | E24: =부단수원가!E24 -> 2555430 | F24: =부단수원가!F24 -> 1793125 | G24: =IFERROR(F24/E24,"") -> 0.70169208 | H24: (직노) × | I24: 0.045
C25: 연금보험료 | D25: =INT(D11*I25) -> 2555430 | E25: =부단수원가!E25 -> 2011039 | F25: =부단수원가!F25 -> 2011039 | G25: =IFERROR(F25/E25,"") -> 1 | H25: (직노) × | I25: 0.045
C26: 노인장기요양보험료 | D26: =INT(D22*I26) -> 260697 | E26: =부단수원가!E26 -> 260697 | F26: =부단수원가!F26 -> 182929 | G26: =IFERROR(F26/E26,"") -> 0.701692 | H26: (건강보험료) × | I26: 0.1295
C27: 노인장기요양보험료 | D27: =INT(D23*I27) -> 260697 | E27: =부단수원가!E27 -> 205160 | F27: =부단수원가!F27 -> 205160 | G27: =IFERROR(F27/E27,"") -> 1 | H27: (건강보험료) × | I27: 0.1295
C28: 퇴직공제부금비 | D28: 0 | E28: =부단수원가!E28 -> 0 | F28: =부단수원가!F28 -> 0 | G28: =IFERROR(F28/E28,"") | H28: (직노) × | I28: 0.023
C29: 퇴직공제부금비 | D29: 0 | E29: =부단수원가!E29 -> 929100 | F29: =부단수원가!F29 -> 916486 | G29: =IFERROR(F29/E29,"") -> 0.98642342 | H29: (직노) × | I29: 0.023
C30: 건설기계지급보증서 | D30: 0 | E30: =부단수원가!E30 -> 0 | F30: =부단수원가!F30 -> 0 | G30: =IFERROR(F30/E30,"") | H30: (재료＋직노＋산경) × | I30: 0.004
C31: 건설기계지급보증서 | D31: 0 | E31: =부단수원가!E31 -> 0 | F31: =부단수원가!F31 -> 0 | G31: =IFERROR(F31/E31,"") | H31: (재료＋직노＋산경) × | I31: 0.004
C32: 안전관리비 | D32: 0 | E32: =부단수원가!E32 -> 0 | F32: =부단수원가!F32 -> 0 | G32: =IFERROR(F32/E32,"")
C33: 안전관리비 | D33: 0 | E33: =부단수원가!E33 -> 0 | F33: =부단수원가!F33 -> 0 | G33: =IFERROR(F33/E33,"")
C34: 신기술사용료 | D34: 0 | E34: =부단수원가!E34 -> 0 | F34: =부단수원가!F34 -> 0 | G34: =IFERROR(F34/E34,"")
C35: 신기술사용료 | D35: 0 | E35: =부단수원가!E35 -> 0 | F35: =부단수원가!F35 -> 0 | G35: =IFERROR(F35/E35,"")
C36: 품질관리비 | D36: 0 | E36: =부단수원가!E36 -> 0 | F36: =부단수원가!F36 -> 0 | G36: =IFERROR(F36/E36,"")
C37: 품질관리비 | D37: 0 | E37: =부단수원가!E37 -> 0 | F37: =부단수원가!F37 -> 0 | G37: =IFERROR(F37/E37,"")
C38: 산업안전보건관리비 | D38: =INT(((D8+D10)*I38+K38)*O38)*0 -> 0 | E38: =부단수원가!E38 -> 0 | F38: =부단수원가!F38 -> 0 | G38: =IFERROR(F38/E38,"") | H38: ((재료＋직노) × | I38: 0.0199 | J38: ＋ | K38: 0 | M38: ) | N38: × | O38: 1.2 | Q38: ※산업안전보건관리비 산출
C39: 산업안전보건관리비 | D39: =INT(((D9+D11)*I39+K39)*O39)*0 -> 0 | E39: =부단수원가!E39 -> 0 | F39: =부단수원가!F39 -> 0 | G39: =IFERROR(F39/E39,"") | H39: ((재료＋직노) × | I39: 0.0199 | J39: ＋ | K39: 0 | M39: ) | N39: × | O39: 1.2 | Q39: ※산업안전보건관리비 산출
C40: 환경보전비 | D40: 0 | E40: =부단수원가!E40 -> 0 | F40: =부단수원가!F40 -> 0 | G40: =IFERROR(F40/E40,"") | H40: (재료 ＋ 직노 ＋ 산경) × | I40: 0.005 | Q40: ①:((재＋직노)×요율+기초금액)×1.2
...

Sheet 6.원 , 하 총괄잡계표
A7: 6. 원 , 하 총괄집계표(변 경)

Sheet 총괄집계표
A1: 원,하 도 급 총 괄 집 계 표(변 경)
A2: 공사명 : | B2: =기초자료!C1 -> 옥회천지방하천정비공사 지장관로이설공사 중 부단수공사
A3: 구 분 | B3: 공 종 명 | C3: 금 액 | E3: 요율(%) | G3: 비 고
C4: 원도급금액 | D4: 하도급 금액 | F4: 표준분류코드 | BB4: 메모
A5: ※ | B5: 도급공사비 | C5: =C77 -> 300980000 | D5: =D77 -> 263010000 | E5: =IFERROR(D5/C5,"") -> 0.87384544
A6: ※ | B6: 도급공사비 | C6: =C78 -> 300800000 | D6: =D78 -> 264800000 | E6: =IFERROR(D6/C6,"") -> 0.88031915
A7: 가 | B7: 직접공사비 | C7: =C9 -> 218801127 | D7: =D9 -> 191220236 | E7: =IFERROR(D7/C7,"") -> 0.87394539 | J7: 10
A8: 가 | B8: 직접공사비 | C8: =C10 -> 218801127 | D8: =D10 -> 191220236 | E8: =IFERROR(D8/C8,"") -> 0.87394539 | J8: 10
A9: Ⅰ | B9: 상수도시설 | C9: =C11 -> 218801127 | D9: =D11 -> 191220236 | E9: =IFERROR(D9/C9,"") -> 0.87394539 | F9: F1400
A10: Ⅰ | B10: 상수도시설 | C10: =C12 -> 218801127 | D10: =D12 -> 191220236 | E10: =IFERROR(D10/C10,"") -> 0.87394539 | F10: F1400
A11: Ⅰ.1 | B11: 송수시설 | C11: =C13 -> 218801127 | D11: =D13 -> 191220236 | E11: =IFERROR(D11/C11,"") -> 0.87394539 | F11: F1441
A12: Ⅰ.1 | B12: 송수시설 | C12: =C14 -> 218801127 | D12: =D14 -> 191220236 | E12: =IFERROR(D12/C12,"") -> 0.87394539 | F12: F1441
A13: 2 | B13: 관로공 | C13: =C17 -> 218801127 | D13: =D17 -> 191220236 | E13: =IFERROR(D13/C13,"") -> 0.87394539 | F13: CG | J13: 30 | L13: A0200 | BC13: =HYPERLINK("#내역서!A35","A0200 →") -> A0200 →
A14: 2 | B14: 관로공 | C14: =C18 -> 218801127 | D14: =D18 -> 191220236 | E14: =IFERROR(D14/C14,"") -> 0.87394539 | F14: CG | J14: 30 | L14: A0200 | BC14: =HYPERLINK("#내역서!A35","A0200 →") -> A0200 →
E15: =IFERROR(D15/C15,"")
E16: =IFERROR(D16/C16,"")
A17: 2 | B17: 관로공 | C17: =C19 -> 218801127 | D17: =D19 -> 191220236 | E17: =IFERROR(D17/C17,"") -> 0.87394539 | F17: CG | I17: A0200 | T17: =#REF!+#REF!+#REF!+#REF!+#REF!+#REF!+#REF!+#REF!+#REF!+#REF!+#REF!+#REF!+#REF!+#REF!+#REF!+#REF!+#REF!+#REF!+#REF!+#REF!+#REF!+#REF!+#REF!+#REF!+#REF!+#REF!+#REF!+#REF!+#REF!+#REF!+#REF!+#REF!+#REF!+#REF!+#REF!+#REF!+#REF! -> #REF! | U17: =#REF!+#REF!+#REF!+#REF!+#REF!+#REF!+#REF!+#REF!+#REF!+#REF!+#REF!+#REF!+#REF!+#REF!+#REF!+#REF!+#REF!+#REF!+#REF!+#REF!+#REF!+#REF!+#REF!+#REF!+#REF!+#REF!+#REF!+#REF!+#REF!+#REF!+#REF!+#REF!+#REF!+#REF!+#REF!+#REF!+#REF! -> #REF! | V17: =#REF!+#REF!+#REF!+#REF!+#REF!+#REF!+#REF!+#REF!+#REF!+#REF!+#REF!+#REF!+#REF!+#REF!+#REF!+#REF!+#REF!+#REF!+#REF!+#REF!+#REF!+#REF!+#REF!+#REF!+#REF!+#REF!+#REF!+#REF!+#REF!+#REF!+#REF!+#REF!+#REF!+#REF!+#REF!+#REF!+#REF! -> #REF!
A18: 2 | B18: 관로공 | C18: =C20 -> 218801127 | D18: =D20 -> 191220236 | E18: =IFERROR(D18/C18,"") -> 0.87394539 | F18: CG | I18: A0200 | T18: =#REF!+#REF!+#REF!+#REF!+#REF!+#REF!+#REF!+#REF!+#REF!+#REF!+#REF!+#REF!+#REF!+#REF!+#REF!+#REF!+#REF!+#REF!+#REF!+#REF!+#REF!+#REF!+#REF!+#REF!+#REF!+#REF!+#REF!+#REF!+#REF!+#REF!+#REF!+#REF!+#REF!+#REF!+#REF!+#REF!+#REF! -> #REF! | U18: =#REF!+#REF!+#REF!+#REF!+#REF!+#REF!+#REF!+#REF!+#REF!+#REF!+#REF!+#REF!+#REF!+#REF!+#REF!+#REF!+#REF!+#REF!+#REF!+#REF!+#REF!+#REF!+#REF!+#REF!+#REF!+#REF!+#REF!+#REF!+#REF!+#REF!+#REF!+#REF!+#REF!+#REF!+#REF!+#REF!+#REF! -> #REF! | V18: =#REF!+#REF!+#REF!+#REF!+#REF!+#REF!+#REF!+#REF!+#REF!+#REF!+#REF!+#REF!+#REF!+#REF!+#REF!+#REF!+#REF!+#REF!+#REF!+#REF!+#REF!+#REF!+#REF!+#REF!+#REF!+#REF!+#REF!+#REF!+#REF!+#REF!+#REF!+#REF!+#REF!+#REF!+#REF!+#REF!+#REF! -> #REF!
A19: 2.10 | B19: 부단수차단 | C19: =부단수!O6 -> 218801127 | D19: =부단수!W6 -> 191220236 | E19: =IFERROR(D19/C19,"") -> 0.87394539 | F19: CGO | J19: 10 | T19: =#REF!+#REF!+#REF!+#REF!+#REF!+#REF!+#REF!+#REF!+#REF!+#REF!+#REF!+#REF!+#REF! -> #REF! | U19: =#REF!+#REF!+#REF!+#REF!+#REF!+#REF!+#REF!+#REF!+#REF!+#REF!+#REF!+#REF!+#REF! -> #REF! | V19: =#REF!+#REF!+#REF!+#REF!+#REF!+#REF!+#REF!+#REF!+#REF!+#REF!+#REF!+#REF!+#REF! -> #REF!
A20: 2.10 | B20: 부단수차단 | C20: =부단수!O8 -> 218801127 | D20: =부단수!W8 -> 191220236 | E20: =IFERROR(D20/C20,"") -> 0.87394539 | F20: CGO | J20: 10 | T20: =#REF!+#REF!+#REF!+#REF!+#REF!+#REF!+#REF!+#REF!+#REF!+#REF!+#REF!+#REF!+#REF! -> #REF! | U20: =#REF!+#REF!+#REF!+#REF!+#REF!+#REF!+#REF!+#REF!+#REF!+#REF!+#REF!+#REF!+#REF! -> #REF! | V20: =#REF!+#REF!+#REF!+#REF!+#REF!+#REF!+#REF!+#REF!+#REF!+#REF!+#REF!+#REF!+#REF! -> #REF!
A23: 나 | B23: 간접공사비 | C23: =C25+C27+C29+C31+C33+C35+C37+C39+C41+C43+C45+C47+C49+C51+C53+C55+C57+C59+C61 -> 20078974 | D23: =SUM(D25:D61) -> 28204006 | E23: =IFERROR(D23/C23,"") -> 1.4046537
A24: 나 | B24: 간접공사비 | C24: =C26+C28+C30+C32+C34+C36+C38+C40+C42+C44+C46+C48+C50+C52+C54+C56+C58+C60+C62 -> 19979286 | D24: =SUM(D26:D62) -> 31207973 | E24: =IFERROR(D24/C24,"") -> 1.5620164
A25: 1 | B25: 간접노무비 | C25: =부단수원가!E12 -> 5776581 | D25: =부단수원가!F12 -> 5698155 | E25: =IFERROR(D25/C25,"") -> 0.98642346
A26: 1 | B26: 간접노무비 | C26: =부단수원가!E13 -> 5776581 | D26: =부단수원가!F13 -> 5698155 | E26: =IFERROR(D26/C26,"") -> 0.98642346
A27: 2 | B27: 산재보험료 | C27: =부단수원가!E18 -> 0 | D27: =부단수원가!F18 -> 0 | E27: =IFERROR(D27/C27,"")
A28: 2 | B28: 산재보험료 | C28: =부단수원가!E19 -> 0 | D28: =부단수원가!F19 -> 0 | E28: =IFERROR(D28/C28,"")
A29: 3 | B29: 고용보험료 | C29: =부단수원가!E20 -> 0 | D29: =부단수원가!F20 -> 0 | E29: =IFERROR(D29/C29,"")
A30: 3 | B30: 고용보험료 | C30: =부단수원가!E21 -> 0 | D30: =부단수원가!F21 -> 0 | E30: =IFERROR(D30/C30,"")
A31: 4 | B31: 건강보험료 | C31: =부단수원가!E22 -> 2013111 | D31: =부단수원가!F22 -> 1412584 | E31: =IFERROR(D31/C31,"") -> 0.70169206
A32: 4 | B32: 건강보험료 | C32: =부단수원가!E23 -> 1584251 | D32: =부단수원가!F23 -> 1584251 | E32: =IFERROR(D32/C32,"") -> 1
A33: 5 | B33: 연금보험료 | C33: =부단수원가!E24 -> 2555430 | D33: =부단수원가!F24 -> 1793125 | E33: =IFERROR(D33/C33,"") -> 0.70169208
A34: 5 | B34: 연금보험료 | C34: =부단수원가!E25 -> 2011039 | D34: =부단수원가!F25 -> 2011039 | E34: =IFERROR(D34/C34,"") -> 1
A35: 6 | B35: 노인장기요양보험료 | C35: =부단수원가!E26 -> 260697 | D35: =부단수원가!F26 -> 182929 | E35: =IFERROR(D35/C35,"") -> 0.701692
A36: 6 | B36: 노인장기요양보험료 | C36: =부단수원가!E27 -> 205160 | D36: =부단수원가!F27 -> 205160 | E36: =IFERROR(D36/C36,"") -> 1
A37: 7 | B37: 퇴직공제부금비 | C37: =부단수원가!E28 -> 0 | D37: =부단수원가!F28 -> 0 | E37: =IFERROR(D37/C37,"")
A38: 7 | B38: 퇴직공제부금비 | C38: =부단수원가!E29 -> 929100 | D38: =부단수원가!F29 -> 916486 | E38: =IFERROR(D38/C38,"") -> 0.98642342
... A62: 19 | B62: 기 타 경 비 | C62: =부단수원가!E53 -> 9473155 | D62: =부단수원가!F53 -> 8702122 | E62: =IFERROR(D62/C62,"") -> 0.91860864
A63: 다 | B63: 일반관리비 | C63: =부단수원가!E56 -> 14332806 | D63: =부단수원가!F56 -> 12540549 | E63: =IFERROR(D63/C63,"") -> 0.87495421
A64: 다 | B64: 일반관리비 | C64: =부단수원가!E57 -> 14326824 | D64: =부단수원가!F57 -> 12620246 | E64: =IFERROR(D64/C64,"") -> 0.88088232
A65: 라 | B65: 이윤 | C65: =부단수원가!E58 -> 20405275 | D65: =부단수원가!F58 -> 17550300 | E65: =IFERROR(D65/C65,"") -> 0.86008642
...

Sheet 7.원 , 하 산출내역서
A7: 7. 원,하 산출내역서(변 경)

Sheet 산출내역서
A2: 원,하산출내역서(변 경,특허-부단수)
A4: 번호 | B4: 항목 | C4: 규격 | D4: 수량 | E4: 단위 | F4: 설계금액 | H4: 재료비 | J4: 노무비 | L4: 경 비 | N4: 도급금액 | P4: 재료비 | R4: 노무비 | T4: 경 비 | V4: 하도급금액 | X4: 재료비 | Z4: 노무비 | AB4: 경 비 | AD4: 요율(%) | AE4: 비 고
F5: 단 가 | G5: 금 액 | H5: 단 가 | I5: 금 액 | J5: 단 가 | K5: 금 액 | L5: 단 가 | M5: 금 액 | N5: 단 가 | O5: 금 액 | P5: 단 가 | Q5: 금 액 | R5: 단 가 | S5: 금 액 | T5: 단 가 | U5: 금 액 | V5: 단 가 | W5: 금 액 | X5: 단 가 | Y5: 금 액 | Z5: 단 가 | AA5: 금 액 | AB5: 단 가 | AC5: 금 액
B6: 총공사원가 | G6: =G8 -> 296166628 | I6: =I8 -> 153278992 | K6: =K8 -> 56787340 | M6: =M8 -> 86100296 | O6: =O8 -> 218801127 | Q6: =Q8 -> 117158010 | S6: =S8 -> 40395673 | U6: =U8 -> 61247444 | W6: =W8 -> 191220236 | Y6: =Y8 -> 104491200 | AA6: =AA8 -> 39847240 | AC6: =AC8 -> 46881796 | AD6: =IFERROR(W6/O6,"") -> 0.87394539 | AF6: 합계
B7: 총공사원가 | G7: =G14 -> 296166628 | I7: =I14 -> 153278992 | K7: =K14 -> 56787340 | M7: =M14 -> 86100296 | O7: =O14 -> 218801127 | Q7: =Q14 -> 117158010 | S7: =S14 -> 40395673 | U7: =U14 -> 61247444 | W7: =W14 -> 191220236 | Y7: =Y14 -> 104491200 | AA7: =AA14 -> 39847240 | AC7: =AC14 -> 46881796 | AD7: =IFERROR(W7/O7,"") -> 0.87394539 | AF7: 합계
A8: 가 | B8: 직접공사비 | G8: =I8+K8+M8 -> 296166628 | I8: =I15 -> 153278992 | K8: =K15 -> 56787340 | M8: =M15 -> 86100296 | O8: =Q8+S8+U8 -> 218801127 | Q8: =Q15 -> 117158010 | S8: =S15 -> 40395673 | U8: =U15 -> 61247444 | W8: =Y8+AA8+AC8 -> 191220236 | Y8: =Y15 -> 104491200 | AA8: =AA15 -> 39847240 | AC8: =AC15 -> 46881796 | AD8: =IFERROR(W8/O8,"") -> 0.87394539 | AF8: 합계
A9: Ⅰ | B9: 공통시설 | G9: =I9+K9+M9 -> 0 | I9: 0 | K9: 0 | M9: =M10 -> 0 | O9: =Q9+S9+U9 -> 0 | Q9: 0 | S9: 0 | U9: =U10 -> 0 | W9: =Y9+AA9+AC9 -> 0 | Y9: 0 | AA9: 0 | AC9: =AC10 -> 0 | AD9: =IFERROR(W9/O9,"") | AF9: 합계
A10: 1 | B10: 공통공사 | G10: =I10+K10+M10 -> 0 | I10: =I11 -> 0 | K10: =K11 -> 0 | M10: =M11 -> 0 | O10: =Q10+S10+U10 -> 0 | Q10: =Q11 -> 0 | S10: =S11 -> 0 | U10: =U11 -> 0 | W10: =Y10+AA10+AC10 -> 0 | Y10: =Y11 -> 0 | AA10: =AA11 -> 0 | AC10: =AC11 -> 0 | AD10: =IFERROR(W10/O10,"") | AF10: 합계
AD11: =IFERROR(W11/O11,"") | AF11: 직영
AD12: =IFERROR(W12/O12,"") | AF12: 직영
AD13: =IFERROR(W13/O13,"") | AF13: 직영
A14: 가 | B14: 직접공사비 | G14: =I14+K14+M14 -> 296166628 | I14: =I29 -> 153278992 | K14: =K29 -> 56787340 | M14: =M29 -> 86100296 | O14: =Q14+S14+U14 -> 218801127 | Q14: =Q29 -> 117158010 | S14: =S29 -> 40395673 | U14: =U29 -> 61247444 | W14: =Y14+AA14+AC14 -> 191220236 | Y14: =Y29 -> 104491200 | AA14: =AA29 -> 39847240 | AC14: =AC29 -> 46881796 | AD14: =IFERROR(W14/O14,"") -> 0.87394539 | AF14: 합계
A15: Ⅱ | B15: 상수도시설 | G15: =I15+K15+M15 -> 296166628 | I15: =I16+I30+I90+I102+I132+I139 -> 153278992 | K15: =K16+K30+K90+K102+K132+K139 -> 56787340 | M15: =M16+M30+M90+M102+M132+M139 -> 86100296 | O15: =Q15+S15+U15 -> 218801127 | Q15: =Q16+Q30+Q90+Q102+Q132+Q139 -> 117158010 | S15: =S16+S30+S90+S102+S132+S139 -> 40395673 | U15: =U16+U30+U90+U102+U132+U139 -> 61247444 | W15: =Y15+AA15+AC15 -> 191220236 | Y15: =Y16+Y30+Y90+Y102+Y132+Y139 -> 104491200 | AA15: =AA16+AA30+AA90+AA102+AA132+AA139 -> 39847240 | AC15: =AC16+AC30+AC90+AC102+AC132+AC139 -> 46881796 | AD15: =IFERROR(W15/O15,"") -> 0.87394539 | AF15: 합계
A16: 1 | B16: 토공 | G16: =I16+K16+M16 -> 0 | I16: =I17+I24 -> 0 | K16: =K17+K24 -> 0 | M16: =M17+M24 -> 0 | O16: =Q16+S16+U16 -> 0 | Q16: =Q17+Q24 -> 0 | S16: =S17+S24 -> 0 | U16: =U17+U24 -> 0 | W16: =Y16+AA16+AC16 -> 0 | Y16: =Y17+Y24 -> 0 | AA16: =AA17+AA24 -> 0 | AC16: =AC17+AC24 -> 0 | AD16: =IFERROR(W16/O16,"") | AF16: 합계
A17: 1.1 | B17: 기존구조물철거 | G17: =I17+K17+M17 -> 0 | I17: =SUM(I18:I23) -> 0 | K17: =SUM(K18:K23) -> 0 | M17: =SUM(M18:M23) -> 0 | O17: =Q17+S17+U17 -> 0 | Q17: =SUM(Q18:Q23) -> 0 | S17: =SUM(S18:S23) -> 0 | U17: =SUM(U18:U23) -> 0 | W17: =Y17+AA17+AC17 -> 0 | Y17: =SUM(Y18:Y23) -> 0 | AA17: =SUM(AA18:AA23) -> 0 | AC17: =SUM(AC18:AC23) -> 0 | AD17: =IFERROR(W17/O17,"") | AF17: 합계
AD18: =IFERROR(W18/O18,"") | AF18: 직영
AD19: =IFERROR(W19/O19,"") | AF19: 직영
AD20: =IFERROR(W20/O20,"") | AF20: 직영
AD21: =IFERROR(W21/O21,"") | AF21: 직영
AD22: =IFERROR(W22/O22,"") | AF22: 직영
AD23: =IFERROR(W23/O23,"") | AF23: 직영
A24: 1.2 | B24: 토공작업 | G24: =I24+K24+M24 -> 0 | I24: =SUM(I25:I28) -> 0 | K24: =SUM(K25:K28) -> 0 | M24: =SUM(M25:M28) -> 0 | O24: =Q24+S24+U24 -> 0 | Q24: =SUM(Q25:Q28) -> 0 | S24: =SUM(S25:S28) -> 0 | U24: =SUM(U25:U28) -> 0 | W24: =Y24+AA24+AC24 -> 0 | Y24: =SUM(Y25:Y28) -> 0 | AA24: =SUM(AA25:AA28) -> 0 | AC24: =SUM(AC25:AC28) -> 0 | AD24: =IFERROR(W24/O24,"") | AF24: 합계
AD25: =IFERROR(W25/O25,"") | AF25: 가시설
AD26: =IFERROR(W26/O26,"") | AF26: 직영
AD27: =IFERROR(W27/O27,"") | AF27: 직영
AD28: =IFERROR(W28/O28,"") | AF28: 직영
A29: Ⅱ | B29: 상수도시설 | G29: =I29+K29+M29 -> 296166628 | I29: =I30+I44+I104+I116+I146+I153 -> 153278992 | K29: =K30+K44+K104+K116+K146+K153 -> 56787340 | M29: =M30+M44+M104+M116+M146+M153 -> 86100296 | O29: =Q29+S29+U29 -> 218801127 | Q29: =Q30+Q44+Q104+Q116+Q146+Q153 -> 117158010 | S29: =S30+S44+S104+S116+S146+S153 -> 40395673 | U29: =U30+U44+U104+U116+U146+U153 -> 61247444 | W29: =Y29+AA29+AC29 -> 191220236 | Y29: =Y84 -> 104491200 | AA29: =AA84 -> 39847240 | AC29: =AC84 -> 46881796 | AD29: =IFERROR(W29/O29,"") -> 0.87394539 | AF29: 합계
A30: 2 | B30: 관로공 | G30: =I30+K30+M30 -> 296166628 | I30: =I85 -> 153278992 | K30: =K85 -> 56787340 | M30: =M85 -> 86100296 | O30: =Q30+S30+U30 -> 218801127 | Q30: =Q85 -> 117158010 | S30: =S85 -> 40395673 | U30: =U85 -> 61247444 | W30: =Y30+AA30+AC30 -> 191220236 | Y30: =Y85 -> 104491200 | AA30: =AA85 -> 39847240 | AC30: =AC85 -> 46881796 | AD30: =IFERROR(W30/O30,"") -> 0.87394539 | AF30: 합계
AD31: =IFERROR(W31/O31,"") | AF31: 관로공
AD32: =IFERROR(W32/O32,"") | AF32: 관로공
AD33: =IFERROR(W33/O33,"") | AF33: 관로공
AD34: =IFERROR(W34/O34,"") | AF34: 관로공
AD35: =IFERROR(W35/O35,"") | AF35: 관로공
AD36: =IFERROR(W36/O36,"") | AF36: 관로공
AD37: =IFERROR(W37/O37,"") | AF37: 관로공
AD38: =IFERROR(W38/O38,"") | AF38: 관로공
AD39: =IFERROR(W39/O39,"") | AF39: 관로공
AD40: =IFERROR(W40/O40,"") | AF40: 관로공
AD41: =IFERROR(W41/O41,"") | AF41: 관로공
AD42: =IFERROR(W42/O42,"") | AF42: 관로공
...

Sheet 8.원,하도급내역서
A7: 8. 원 , 하 도급내역서(변 경)

Sheet 원하내역서
A2: 원,하도급내역서(변 경,특허-부단수)
A4: 번호 | B4: 항목 | C4: 규격 | D4: 수량 | E4: 단위 | F4: 설계금액 | H4: 재료비 | J4: 노무비 | L4: 경 비 | N4: 도급금액 | P4: 재료비 | R4: 노무비 | T4: 경 비 | V4: 하도급금액 | X4: 재료비 | Z4: 노무비 | AB4: 경 비 | AD4: 비고
F5: 단 가 | G5: 금 액 | H5: 단 가 | I5: 금 액 | J5: 단 가 | K5: 금 액 | L5: 단 가 | M5: 금 액 | N5: 단 가 | O5: 금 액 | P5: 단 가 | Q5: 금 액 | R5: 단 가 | S5: 금 액 | T5: 단 가 | U5: 금 액 | V5: 단 가 | W5: 금 액 | X5: 단 가 | Y5: 금 액 | Z5: 단 가 | AA5: 금 액 | AB5: 단 가 | AC5: 금 액
B6: 총공사원가 | G6: =G8 -> 296166628 | I6: =I8 -> 153278992 | K6: =K8 -> 56787340 | M6: =M8 -> 86100296 | O6: =O8 -> 218801127 | Q6: =Q8 -> 117158010 | S6: =S8 -> 40395673 | U6: =U8 -> 61247444 | W6: =W8 -> 191220236 | Y6: =Y8 -> 104491200 | AA6: =AA8 -> 39847240 | AC6: =AC8 -> 46881796 | AE6: 합계
B7: 총공사원가 | G7: =G14 -> 296166628 | I7: =I14 -> 153278992 | K7: =K14 -> 56787340 | M7: =M14 -> 86100296 | O7: =O14 -> 218801127 | Q7: =Q14 -> 117158010 | S7: =S14 -> 40395673 | U7: =U14 -> 61247444 | W7: =W14 -> 191220236 | Y7: =Y14 -> 104491200 | AA7: =AA14 -> 39847240 | AC7: =AC14 -> 46881796 | AE7: 합계
A8: 가 | B8: 직접공사비 | G8: =I8+K8+M8 -> 296166628 | I8: =I15 -> 153278992 | K8: =K15 -> 56787340 | M8: =M15 -> 86100296 | O8: =Q8+S8+U8 -> 218801127 | Q8: =Q15 -> 117158010 | S8: =S15 -> 40395673 | U8: =U15 -> 61247444 | W8: =Y8+AA8+AC8 -> 191220236 | Y8: =Y15 -> 104491200 | AA8: =AA15 -> 39847240 | AC8: =AC15 -> 46881796 | AE8: 합계
A9: Ⅰ | B9: 공통시설 | G9: =I9+K9+M9 -> 0 | I9: 0 | K9: 0 | M9: =M10 -> 0 | O9: =Q9+S9+U9 -> 0 | Q9: 0 | S9: 0 | U9: =U10 -> 0 | W9: =Y9+AA9+AC9 -> 0 | Y9: 0 | AA9: 0 | AC9: =AC10 -> 0 | AE9: 합계
A10: 1 | B10: 공통공사 | G10: =I10+K10+M10 -> 0 | I10: =I11 -> 0 | K10: =K11 -> 0 | M10: =M11 -> 0 | O10: =Q10+S10+U10 -> 0 | Q10: =Q11 -> 0 | S10: =S11 -> 0 | U10: =U11 -> 0 | W10: =Y10+AA10+AC10 -> 0 | Y10: =Y11 -> 0 | AA10: =AA11 -> 0 | AC10: =AC11 -> 0 | AE10: 합계
AE11: 직영
AE12: 직영
AE13: 직영
A14: 가 | B14: 직접공사비 | G14: =I14+K14+M14 -> 296166628 | I14: =I29 -> 153278992 | K14: =K29 -> 56787340 | M14: =M29 -> 86100296 | O14: =Q14+S14+U14 -> 218801127 | Q14: =Q29 -> 117158010 | S14: =S29 -> 40395673 | U14: =U29 -> 61247444 | W14: =Y14+AA14+AC14 -> 191220236 | Y14: =Y29 -> 104491200 | AA14: =AA29 -> 39847240 | AC14: =AC29 -> 46881796 | AE14: 합계
A15: Ⅱ | B15: 상수도시설 | G15: =I15+K15+M15 -> 296166628 | I15: =I16+I30+I90+I102+I132+I139 -> 153278992 | K15: =K16+K30+K90+K102+K132+K139 -> 56787340 | M15: =M16+M30+M90+M102+M132+M139 -> 86100296 | O15: =Q15+S15+U15 -> 218801127 | Q15: =Q16+Q30+Q90+Q102+Q132+Q139 -> 117158010 | S15: =S16+S30+S90+S102+S132+S139 -> 40395673 | U15: =U16+U30+U90+U102+U132+U139 -> 61247444 | W15: =Y15+AA15+AC15 -> 191220236 | Y15: =Y16+Y30+Y90+Y102+Y132+Y139 -> 104491200 | AA15: =AA16+AA30+AA90+AA102+AA132+AA139 -> 39847240 | AC15: =AC16+AC30+AC90+AC102+AC132+AC139 -> 46881796 | AE15: 합계
A16: 1 | B16: 토공 | G16: =I16+K16+M16 -> 0 | I16: =I17+I24 -> 0 | K16: =K17+K24 -> 0 | M16: =M17+M24 -> 0 | O16: =Q16+S16+U16 -> 0 | Q16: =Q17+Q24 -> 0 | S16: =S17+S24 -> 0 | U16: =U17+U24 -> 0 | W16: =Y16+AA16+AC16 -> 0 | Y16: =Y17+Y24 -> 0 | AA16: =AA17+AA24 -> 0 | AC16: =AC17+AC24 -> 0 | AE16: 합계
A17: 1.1 | B17: 기존구조물철거 | G17: =I17+K17+M17 -> 0 | I17: =SUM(I18:I23) -> 0 | K17: =SUM(K18:K23) -> 0 | M17: =SUM(M18:M23) -> 0 | O17: =Q17+S17+U17 -> 0 | Q17: =SUM(Q18:Q23) -> 0 | S17: =SUM(S18:S23) -> 0 | U17: =SUM(U18:U23) -> 0 | W17: =Y17+AA17+AC17 -> 0 | Y17: =SUM(Y18:Y23) -> 0 | AA17: =SUM(AA18:AA23) -> 0 | AC17: =SUM(AC18:AC23) -> 0 | AE17: 합계
AE18: 직영
AE19: 직영
AE20: 직영
AE21: 직영
AE22: 직영
AE23: 직영
A24: 1.2 | B24: 토공작업 | G24: =I24+K24+M24 -> 0 | I24: =SUM(I25:I28) -> 0 | K24: =SUM(K25:K28) -> 0 | M24: =SUM(M25:M28) -> 0 | O24: =Q24+S24+U24 -> 0 | Q24: =SUM(Q25:Q28) -> 0 | S24: =SUM(S25:S28) -> 0 | U24: =SUM(U25:U28) -> 0 | W24: =Y24+AA24+AC24 -> 0 | Y24: =SUM(Y25:Y28) -> 0 | AA24: =SUM(AA25:AA28) -> 0 | AC24: =SUM(AC25:AC28) -> 0 | AE24: 합계
AE25: 가시설
AE26: 직영
AE27: 직영
AE28: 직영
A29: Ⅱ | B29: 상수도시설 | G29: =I29+K29+M29 -> 296166628 | I29: =I30+I44+I104+I116+I146+I153 -> 153278992 | K29: =K30+K44+K104+K116+K146+K153 -> 56787340 | M29: =M30+M44+M104+M116+M146+M153 -> 86100296 | O29: =Q29+S29+U29 -> 218801127 | Q29: =Q30+Q44+Q104+Q116+Q146+Q153 -> 117158010 | S29: =S30+S44+S104+S116+S146+S153 -> 40395673 | U29: =U30+U44+U104+U116+U146+U153 -> 61247444 | W29: =Y29+AA29+AC29 -> 191220236 | Y29: =Y30+Y44+Y104+Y116+Y146+Y153 -> 104491200 | AA29: =AA30+AA44+AA104+AA116+AA146+AA153 -> 39847240 | AC29: =AC30+AC44+AC104+AC116+AC146+AC153 -> 46881796 | AE29: 합계
A30: 2 | B30: 관로공 | G30: =I30+K30+M30 -> 296166628 | I30: =I85 -> 153278992 | K30: =K85 -> 56787340 | M30: =M85 -> 86100296 | O30: =Q30+S30+U30 -> 218801127 | Q30: =Q85 -> 117158010 | S30: =S85 -> 40395673 | U30: =U85 -> 61247444 | W30: =Y30+AA30+AC30 -> 191220236 | Y30: =Y85 -> 104491200 | AA30: =AA85 -> 39847240 | AC30: =AC85 -> 46881796 | AE30: 합계
AE31: 관로공
AE32: 관로공
AE33: 관로공
AE34: 관로공
AE35: 관로공
AE36: 관로공
AE37: 관로공
AE38: 관로공
AE39: 관로공
AE40: 관로공
AE41: 관로공
AE42: 관로공
...

Sheet Sheet8

Sheet 부단수원가
A1: 공 사 원 가 계 산 서 (변 경,특허 - 부단수)
A2: 공사명 : | C2: 군산시 옥회천 지방하천 정비공사 지장관로 이설공사
A3: 비 목 | C3: 구 분 | D3: 설계금액 | E3: 도급금액 | F3: 하도급금액 | G3: 요율(%) | H3: 구 성 비(%) | Q3: 비 고
A4: 순 공 사 원 가 | B4: 재 료 비 | C4: 직접재료비 | D4: =부단수!I6 -> 153278992 | E4: =부단수!Q6 -> 117158010 | F4: =부단수!Y6 -> 104491200 | G4: =IFERROR(F4/E4,"") -> 0.89188268
C5: 직접재료비 | D5: =부단수!I8 -> 153278992 | E5: =부단수!Q7 -> 117158010 | F5: =부단수!Y7 -> 104491200 | G5: =IFERROR(F5/E5,"") -> 0.89188268
C6: 간접재료비 | D6: 0 | E6: 0 | F6: 0 | G6: =IFERROR(F6/E6,"")
C7: 간접재료비 | D7: 0 | E7: 0 | F7: 0 | G7: =IFERROR(F7/E7,"")
C8: 소 계 | D8: =D4+D6 -> 153278992 | E8: =E4+E6 -> 117158010 | F8: =F4+F6 -> 104491200 | G8: =IFERROR(F8/E8,"") -> 0.89188268
C9: 소 계 | D9: =D5+D7 -> 153278992 | E9: =E5+E7 -> 117158010 | F9: =F5+F7 -> 104491200 | G9: =IFERROR(F9/E9,"") -> 0.89188268
B10: 노 무 비 | C10: 직접노무비 | D10: =부단수!K6 -> 56787340 | E10: =부단수!S6 -> 40395673 | F10: =부단수!AA6 -> 39847240 | G10: =IFERROR(F10/E10,"") -> 0.98642347
C11: 직접노무비 | D11: =부단수!K8 -> 56787340 | E11: =부단수!S7 -> 40395673 | F11: =부단수!AA7 -> 39847240 | G11: =IFERROR(F11/E11,"") -> 0.98642347
C12: 간접노무비 | D12: =INT(D10*I12) -> 8120589 | E12: =INT(E10*I12) -> 5776581 | F12: =INT(F10*I12) -> 5698155 | G12: =IFERROR(F12/E12,"") -> 0.98642346 | H12: (직접노무비) × | I12: 0.143
C13: 간접노무비 | D13: =INT(D11*I13) -> 8120589 | E13: =INT(E11*I13) -> 5776581 | F13: =INT(F11*I13) -> 5698155 | G13: =IFERROR(F13/E13,"") -> 0.98642346 | H13: (직접노무비) × | I13: 0.143
C14: 소 계 | D14: =D10+D12 -> 64907929 | E14: =E10+E12 -> 46172254 | F14: =F10+F12 -> 45545395 | G14: =IFERROR(F14/E14,"") -> 0.98642347
C15: 소 계 | D15: =D11+D13 -> 64907929 | E15: =E11+E13 -> 46172254 | F15: =F11+F13 -> 45545395 | G15: =IFERROR(F15/E15,"") -> 0.98642347
B16: 경 비 | C16: 산출경비(기계경비) | D16: =부단수!M6 -> 86100296 | E16: =부단수!U6 -> 61247444 | F16: =부단수!AC6 -> 46881796 | G16: =IFERROR(F16/E16,"") -> 0.76544902
C17: 산출경비(기계경비) | D17: =부단수!M8 -> 86100296 | E17: =부단수!U7 -> 61247444 | F17: =부단수!AC7 -> 46881796 | G17: =IFERROR(F17/E17,"") -> 0.76544902
C18: 산재보험료 | D18: 0 | E18: 0 | F18: 0 | G18: =IFERROR(F18/E18,"") | H18: (직노 ＋ 간노) × | I18: 0.0356
C19: 산재보험료 | D19: 0 | E19: 0 | F19: 0 | G19: =IFERROR(F19/E19,"") | H19: (직노 ＋ 간노) × | I19: 0.0356
C20: 고용보험료 | D20: 0 | E20: 0 | F20: 0 | G20: =IFERROR(F20/E20,"") | H20: (직노 ＋ 간노) × | I20: 0.0101
C21: 고용보험료 | D21: 0 | E21: 0 | F21: 0 | G21: =IFERROR(F21/E21,"") | H21: (직노 ＋ 간노) × | I21: 0.0101
C22: 건강보험료 | D22: =INT(D10*I22) -> 2013111 | E22: =D22 -> 2013111 | F22: =TRUNC(F10*I22,0) -> 1412584 | G22: =IFERROR(F22/E22,"") -> 0.70169206 | H22: (직노) × | I22: 0.03545
C23: 건강보험료 | D23: =INT(D11*I23) -> 2013111 | E23: 1584251 | F23: =E23 -> 1584251 | G23: =IFERROR(F23/E23,"") -> 1 | H23: (직노) × | I23: 0.03545
C24: 연금보험료 | D24: =INT(D10*I24) -> 2555430 | E24: =D24 -> 2555430 | F24: =TRUNC(F10*I24,0) -> 1793125 | G24: =IFERROR(F24/E24,"") -> 0.70169208 | H24: (직노) × | I24: 0.045
C25: 연금보험료 | D25: =INT(D11*I25) -> 2555430 | E25: 2011039 | F25: =E25 -> 2011039 | G25: =IFERROR(F25/E25,"") -> 1 | H25: (직노) × | I25: 0.045
C26: 노인장기요양보험료 | D26: =INT(D22*I26) -> 260697 | E26: =D26 -> 260697 | F26: =TRUNC(F22*I26,0) -> 182929 | G26: =IFERROR(F26/E26,"") -> 0.701692 | H26: (건강보험료) × | I26: 0.1295
C27: 노인장기요양보험료 | D27: =INT(D23*I27) -> 260697 | E27: 205160 | F27: =E27 -> 205160 | G27: =IFERROR(F27/E27,"") -> 1 | H27: (건강보험료) × | I27: 0.1295
C28: 퇴직공제부금비 | D28: 0 | E28: 0 | F28: 0 | G28: =IFERROR(F28/E28,"") | H28: (직노) × | I28: 0.023
C29: 퇴직공제부금비 | D29: 0 | E29: =INT(E10*$I29) -> 929100 | F29: =INT(F10*$I29) -> 916486 | G29: =IFERROR(F29/E29,"") -> 0.98642342 | H29: (직노) × | I29: 0.023
C30: 건설기계지급보증서 | D30: 0 | E30: 0 | F30: 0 | G30: =IFERROR(F30/E30,"") | H30: (재료＋직노＋산경) × | I30: 0.004
C31: 건설기계지급보증서 | D31: 0 | E31: 0 | F31: 0 | G31: =IFERROR(F31/E31,"") | H31: (재료＋직노＋산경) × | I31: 0.004
C32: 안전관리비 | D32: 0 | E32: 0 | F32: 0 | G32: =IFERROR(F32/E32,"")
C33: 안전관리비 | D33: 0 | E33: 0 | F33: 0 | G33: =IFERROR(F33/E33,"")
C34: 신기술사용료 | D34: 0 | E34: 0 | F34: 0 | G34: =IFERROR(F34/E34,"")
C35: 신기술사용료 | D35: 0 | E35: 0 | F35: 0 | G35: =IFERROR(F35/E35,"")
C36: 품질관리비 | D36: 0 | E36: 0 | F36: 0 | G36: =IFERROR(F36/E36,"")
C37: 품질관리비 | D37: 0 | E37: 0 | F37: 0 | G37: =IFERROR(F37/E37,"")
C38: 산업안전보건관리비 | D38: =INT(((D8+D10)*I38+K38)*O38)*0 -> 0 | E38: =INT(((E8+E10)*I38+K38)*O38)*0 -> 0 | F38: =INT(((F8+F10)*I38+K38)*O38)*0 -> 0 | G38: =IFERROR(F38/E38,"") | H38: ((재료＋직노) × | I38: 0.0199 | J38: ＋ | K38: 0 | M38: ) | N38: × | O38: 1.2 | Q38: ※산업안전보건관리비 산출
C39: 산업안전보건관리비 | D39: =INT(((D9+D11)*I39+K39)*O39)*0 -> 0 | E39: =INT(((E9+E11)*I39+K39)*O39)*0 -> 0 | F39: =INT(((F9+F11)*I39+K39)*O39)*0 -> 0 | G39: =IFERROR(F39/E39,"") | H39: ((재료＋직노) × | I39: 0.0199 | J39: ＋ | K39: 0 | M39: ) | N39: × | O39: 1.2 | Q39: ※산업안전보건관리비 산출
C40: 환경보전비 | D40: 0 | E40: 0 | F40: 0 | G40: =IFERROR(F40/E40,"") | H40: (재료 ＋ 직노 ＋ 산경) × | I40: 0.005 | Q40: ①:((재＋직노)×요율+기초금액)×1.2
...

Sheet 부단수
A2: 순공사비산출서(특허-부단수) | AE2: =부단수원가!F76 -> -25919030
A4: 번호 | B4: 항목 | C4: 규격 | D4: 수량 | E4: 단위 | F4: 설계금액 | H4: 재료비 | J4: 노무비 | L4: 경 비 | N4: 도급금액 | P4: 재료비 | R4: 노무비 | T4: 경 비 | V4: 하도급금액 | X4: 재료비 | Z4: 노무비 | AB4: 경 비 | AD4: 비 고 | AE4: 0.70579158
F5: 단 가 | G5: 금 액 | H5: 단 가 | I5: 금 액 | J5: 단 가 | K5: 금 액 | L5: 단 가 | M5: 금 액 | N5: 단 가 | O5: 금 액 | P5: 단 가 | Q5: 금 액 | R5: 단 가 | S5: 금 액 | T5: 단 가 | U5: 금 액 | V5: 단 가 | W5: 금 액 | X5: 단 가 | Y5: 금 액 | Z5: 단 가 | AA5: 금 액 | AB5: 단 가 | AC5: 금 액
B6: 총공사원가 | G6: =G8 -> 296166628 | I6: =I8 -> 153278992 | K6: =K8 -> 56787340 | M6: =M8 -> 86100296 | O6: =O8 -> 218801127 | Q6: =Q8 -> 117158010 | S6: =S8 -> 40395673 | U6: =U8 -> 61247444 | W6: =W8 -> 191220236 | Y6: =Y8 -> 104491200 | AA6: =AA8 -> 39847240 | AC6: =AC8 -> 46881796 | AE6: 합계
B7: 총공사원가 | G7: =G14 -> 296166628 | I7: =I14 -> 153278992 | K7: =K14 -> 56787340 | M7: =M14 -> 86100296 | O7: =O14 -> 218801127 | Q7: =Q14 -> 117158010 | S7: =S14 -> 40395673 | U7: =U14 -> 61247444 | W7: =W14 -> 191220236 | Y7: =Y14 -> 104491200 | AA7: =AA14 -> 39847240 | AC7: =AC14 -> 46881796 | AE7: 합계
A8: 가 | B8: 직접공사비 | G8: =I8+K8+M8 -> 296166628 | I8: =I15 -> 153278992 | K8: =K15 -> 56787340 | M8: =M15 -> 86100296 | O8: =Q8+S8+U8 -> 218801127 | Q8: =Q15 -> 117158010 | S8: =S15 -> 40395673 | U8: =U15 -> 61247444 | W8: =Y8+AA8+AC8 -> 191220236 | Y8: =Y15 -> 104491200 | AA8: =AA15 -> 39847240 | AC8: =AC15 -> 46881796 | AE8: 합계
A9: Ⅰ | B9: 공통시설 | G9: =I9+K9+M9 -> 0 | I9: 0 | K9: 0 | M9: =M10 -> 0 | O9: =Q9+S9+U9 -> 0 | Q9: 0 | S9: 0 | U9: =U10 -> 0 | W9: =Y9+AA9+AC9 -> 0 | Y9: 0 | AA9: 0 | AC9: =AC10 -> 0 | AE9: 합계
A10: 1 | B10: 공통공사 | G10: =I10+K10+M10 -> 0 | I10: =I11 -> 0 | K10: =K11 -> 0 | M10: =M11 -> 0 | O10: =Q10+S10+U10 -> 0 | Q10: =Q11 -> 0 | S10: =S11 -> 0 | U10: =U11 -> 0 | W10: =Y10+AA10+AC10 -> 0 | Y10: =Y11 -> 0 | AA10: =AA11 -> 0 | AC10: =AC11 -> 0 | AE10: 합계
AE11: 직영
AE12: 직영
AE13: 직영
A14: 가 | B14: 직접공사비 | G14: =I14+K14+M14 -> 296166628 | I14: =I29 -> 153278992 | K14: =K29 -> 56787340 | M14: =M29 -> 86100296 | O14: =Q14+S14+U14 -> 218801127 | Q14: =Q29 -> 117158010 | S14: =S29 -> 40395673 | U14: =U29 -> 61247444 | W14: =W29 -> 191220236 | Y14: =Y29 -> 104491200 | AA14: =AA29 -> 39847240 | AC14: =AC29 -> 46881796 | AE14: 합계
A15: Ⅱ | B15: 상수도시설 | G15: =I15+K15+M15 -> 296166628 | I15: =I16+I30+I90+I102+I132+I139 -> 153278992 | K15: =K16+K30+K90+K102+K132+K139 -> 56787340 | M15: =M16+M30+M90+M102+M132+M139 -> 86100296 | O15: =Q15+S15+U15 -> 218801127 | Q15: =Q16+Q30+Q90+Q102+Q132+Q139 -> 117158010 | S15: =S16+S30+S90+S102+S132+S139 -> 40395673 | U15: =U16+U30+U90+U102+U132+U139 -> 61247444 | W15: =Y15+AA15+AC15 -> 191220236 | Y15: =Y30 -> 104491200 | AA15: =AA30 -> 39847240 | AC15: =AC30 -> 46881796 | AE15: 합계
A16: 1 | B16: 토공 | G16: =I16+K16+M16 -> 0 | I16: =I17+I24 -> 0 | K16: =K17+K24 -> 0 | M16: =M17+M24 -> 0 | O16: =Q16+S16+U16 -> 0 | Q16: =Q17+Q24 -> 0 | S16: =S17+S24 -> 0 | U16: =U17+U24 -> 0 | W16: =Y16+AA16+AC16 -> 0 | Y16: =Y17+Y24 -> 0 | AA16: =AA17+AA24 -> 0 | AC16: =AC17+AC24 -> 0 | AE16: 합계
A17: 1.1 | B17: 기존구조물철거 | G17: =I17+K17+M17 -> 0 | I17: =SUM(I18:I23) -> 0 | K17: =SUM(K18:K23) -> 0 | M17: =SUM(M18:M23) -> 0 | O17: =Q17+S17+U17 -> 0 | Q17: =SUM(Q18:Q23) -> 0 | S17: =SUM(S18:S23) -> 0 | U17: =SUM(U18:U23) -> 0 | W17: =Y17+AA17+AC17 -> 0 | Y17: =SUM(Y18:Y23) -> 0 | AA17: =SUM(AA18:AA23) -> 0 | AC17: =SUM(AC18:AC23) -> 0 | AE17: 합계
AE18: 직영
AE19: 직영
AE20: 직영
AE21: 직영
AE22: 직영
AE23: 직영
A24: 1.2 | B24: 토공작업 | G24: =I24+K24+M24 -> 0 | I24: =SUM(I25:I28) -> 0 | K24: =SUM(K25:K28) -> 0 | M24: =SUM(M25:M28) -> 0 | O24: =Q24+S24+U24 -> 0 | Q24: =SUM(Q25:Q28) -> 0 | S24: =SUM(S25:S28) -> 0 | U24: =SUM(U25:U28) -> 0 | W24: =Y24+AA24+AC24 -> 0 | Y24: =SUM(Y25:Y28) -> 0 | AA24: =SUM(AA25:AA28) -> 0 | AC24: =SUM(AC25:AC28) -> 0 | AE24: 합계
AE25: 가시설
AE26: 직영
AE27: 직영
AE28: 직영
A29: Ⅱ | B29: 상수도시설 | G29: =I29+K29+M29 -> 296166628 | I29: =I30+I44+I104+I116+I146+I152 -> 153278992 | K29: =K30+K44+K104+K116+K146+K152 -> 56787340 | M29: =M30+M44+M104+M116+M146+M152 -> 86100296 | O29: =Q29+S29+U29 -> 218801127 | Q29: =Q30+Q44+Q104+Q116+Q146+Q152 -> 117158010 | S29: =S30+S44+S104+S116+S146+S152 -> 40395673 | U29: =U30+U44+U104+U116+U146+U152 -> 61247444 | W29: =Y29+AA29+AC29 -> 191220236 | Y29: =Y84 -> 104491200 | AA29: =AA84 -> 39847240 | AC29: =AC84 -> 46881796 | AE29: 합계
A30: 2 | B30: 관로공 | G30: =I30+K30+M30 -> 296166628 | I30: =I85 -> 153278992 | K30: =K85 -> 56787340 | M30: =M85 -> 86100296 | O30: =Q30+S30+U30 -> 218801127 | Q30: =Q85 -> 117158010 | S30: =S85 -> 40395673 | U30: =U85 -> 61247444 | W30: =Y30+AA30+AC30 -> 191220236 | Y30: =Y85 -> 104491200 | AA30: =AA85 -> 39847240 | AC30: =AC85 -> 46881796 | AE30: 합계
AE31: 관로공
AE32: 관로공
AE33: 관로공
AE34: 관로공
AE35: 관로공
AE36: 관로공
AE37: 관로공
AE38: 관로공
AE39: 관로공
AE40: 관로공
AE41: 관로공
AE42: 관로공
...

Sheet 순공사비 산출서
A1: 순 공 사 비 산 출 서
A2: 공 종 명 | B2: 규 격 | C2: 수량 | D2: 단위 | E2: 합 계 | G2: 재 료 비 | I2: 노 무 비 | K2: 경 비 | M2: 표준분류 코드 | N2: 비 고 | BI2: 메모
E3: 단 가 | F3: 금 액 | G3: 단 가 | H3: 금 액 | I3: 단 가 | J3: 금 액 | K3: 단 가 | L3: 금 액 | T3: 할 증 | U3: 화폐변환 | V3: OP값 | W3: EQ | X3: LA | Y3: MA | Z3: 금액계상
A4: ▣.군산시 옥회천 지방하천 정비공사 지장관로 이설공사 | P4: A0000
A5: ⊙.직접공사비 | C5: 1 | D5: 식 | E5: =G5+I5+K5 -> 0 | F5: =H5+J5+L5 -> #REF! | H5: =TRUNC(H6+H7+H8+H9+H10+H11,0) -> #REF! | J5: =TRUNC(J6+J7+J8+J9+J10+J11,0) -> #REF! | L5: =TRUNC(L6+L7+L8+L9+L10+L11,0) -> #REF! | Q5: 10
A6: 1. 토 공 | C6: 1 | D6: 식 | E6: =G6+I6+K6 -> #REF! | F6: =H6+J6+L6 -> #REF! | G6: =H25 -> #REF! | H6: =TRUNC(G6*C6,0) -> #REF! | I6: =J25 -> #REF! | J6: =TRUNC(I6*C6,0) -> #REF! | K6: =L25 -> #REF! | L6: =TRUNC(K6*C6,0) -> #REF! | M6: CD | Q6: 20 | S6: A0100 | BJ6: =HYPERLINK("#내역서!A17","A0100 →") -> A0100 →
A7: 2. 관로공 | C7: 1 | D7: 식 | E7: =G7+I7+K7 -> #REF! | F7: =H7+J7+L7 -> #REF! | G7: =H43 -> #REF! | H7: =TRUNC(G7*C7,0) -> #REF! | I7: =J43 -> #REF! | J7: =TRUNC(I7*C7,0) -> #REF! | K7: =L43 -> #REF! | L7: =TRUNC(K7*C7,0) -> #REF! | M7: CG | Q7: 30 | S7: A0200 | BJ7: =HYPERLINK("#내역서!A35","A0200 →") -> A0200 →
A8: 3. 구조물공 | C8: 1 | D8: 식 | E8: =G8+I8+K8 -> #REF! | F8: =H8+J8+L8 -> #REF! | G8: =H104 -> #REF! | H8: =TRUNC(G8*C8,0) -> #REF! | I8: =J104 -> #REF! | J8: =TRUNC(I8*C8,0) -> #REF! | K8: =L104 -> #REF! | L8: =TRUNC(K8*C8,0) -> #REF! | M8: CE | Q8: 40 | S8: A0300 | BJ8: =HYPERLINK("#내역서!A96","A0300 →") -> A0300 →
A9: 4. 가시설공 | C9: 1 | D9: 식 | E9: =G9+I9+K9 -> #REF! | F9: =H9+J9+L9 -> #REF! | G9: =H117 -> #REF! | H9: =TRUNC(G9*C9,0) -> #REF! | I9: =J117 -> #REF! | J9: =TRUNC(I9*C9,0) -> #REF! | K9: =L117 -> #REF! | L9: =TRUNC(K9*C9,0) -> #REF! | M9: CA | Q9: 50 | S9: A0400 | BJ9: =HYPERLINK("#내역서!A109","A0400 →") -> A0400 →
A10: 5. 부대공 | C10: 1 | D10: 식 | E10: =G10+I10+K10 -> #REF! | F10: =H10+J10+L10 -> #REF! | G10: =H150 -> #REF! | H10: =TRUNC(G10*C10,0) -> #REF! | I10: =J150 -> #REF! | J10: =TRUNC(I10*C10,0) -> #REF! | K10: =L150 -> #REF! | L10: =TRUNC(K10*C10,0) -> #REF! | M10: CA | Q10: 60 | S10: A0500 | BJ10: =HYPERLINK("#내역서!A142","A0500 →") -> A0500 →
A11: 6. 사급자재 | C11: 1 | D11: 식 | E11: =G11+I11+K11 -> #REF! | F11: =H11+J11+L11 -> #REF! | G11: =H168 -> #REF! | H11: =TRUNC(G11*C11,0) -> #REF! | I11: =J168 -> 0 | J11: =TRUNC(I11*C11,0) -> 0 | K11: =L168 -> 0 | L11: =TRUNC(K11*C11,0) -> 0 | Q11: 80 | S11: A0600 | BJ11: =HYPERLINK("#내역서!A161","A0600 →") -> A0600 →
A13: ⊙.부산물처리 | C13: 1 | D13: 식 | E13: =G13+I13+K13 -> #REF! | F13: =H13+J13+L13 -> #REF! | G13: =H219 -> #REF! | H13: =TRUNC(G13*C13,0) -> #REF! | I13: =J219 -> 0 | J13: =TRUNC(I13*C13,0) -> 0 | K13: =L219 -> 0 | L13: =TRUNC(K13*C13,0) -> 0 | Q13: 100 | S13: A0800 | BJ13: =HYPERLINK("#내역서!A232","A0800 →") -> A0800 →
A14: ⊙.기술사용료 | C14: 1 | D14: 식 | E14: =G14+I14+K14 -> #REF! | F14: =H14+J14+L14 -> #REF! | G14: =H242 -> #REF! | H14: =TRUNC(G14*C14,0) -> #REF! | I14: =J242 -> #REF! | J14: =TRUNC(I14*C14,0) -> #REF! | K14: =L242 -> #REF! | L14: =TRUNC(K14*C14,0) -> #REF! | Q14: 110 | S14: A0900 | BJ14: =HYPERLINK("#내역서!A237","A0900 →") -> A0900 →
E24: =G24+I24+K24 -> 0 | F24: =H24+J24+L24 -> 0 | H24: 0 | J24: 0 | L24: 0 | Q24: 120 | R24: S
A25: 1. 토 공 | C25: 1 | D25: 식 | F25: =H25+J25+L25 -> #REF! | H25: =TRUNC(H28+H29+H31+H32+H33+H34+H36+H37+H38+H39+H41+H42,0) -> #REF! | J25: =TRUNC(J28+J29+J31+J32+J33+J34+J36+J37+J38+J39+J41+J42,0) -> #REF! | L25: =TRUNC(L28+L29+L31+L32+L33+L34+L36+L37+L38+L39+L41+L42,0) -> #REF! | M25: CD | P25: A0100
A26: 1) 기존구조물철거 | E26: =G26+I26+K26 -> 0 | F26: =H26+J26+L26 -> #REF! | H26: =TRUNC(H28+H29+H31+H32+H33+H34,0) -> #REF! | J26: =TRUNC(J28+J29+J31+J32+J33+J34,0) -> #REF! | L26: =TRUNC(L28+L29+L31+L32+L33+L34,0) -> #REF! | M26: CDF | Q26: 10
A27: (1) 기존변실철거 | E27: =G27+I27+K27 -> 0 | F27: =H27+J27+L27 -> #REF! | H27: =TRUNC(H28+H29,0) -> #REF! | J27: =TRUNC(J28+J29,0) -> #REF! | L27: =TRUNC(L28+L29,0) -> #REF! | Q27: 20
A28: - 철근구조물깨기(B/H 0.7M3) | B28: 평균T=30CM이상 | C28: =#REF! -> #REF! | D28: M3 | E28: =G28+I28+K28 -> #REF! | F28: =H28+J28+L28 -> #REF! | G28: =#REF! -> #REF! | H28: =TRUNC(G28*C28,0) -> #REF! | I28: =#REF! -> #REF! | J28: =TRUNC(I28*C28,0) -> #REF! | K28: =#REF! -> #REF! | L28: =TRUNC(K28*C28,0) -> #REF! | N28: #.1 | Q28: 30 | S28: Y00020 | U28: F | BJ28: =HYPERLINK("#일위대가목록!A3","Y00020 →") -> Y00020 →
A29: - 폐기물상차(B/H 0.7M3) | C29: =#REF! -> #REF! | D29: M3 | E29: =G29+I29+K29 -> #REF! | F29: =H29+J29+L29 -> #REF! | G29: =#REF! -> #REF! | H29: =TRUNC(G29*C29,0) -> #REF! | I29: =#REF! -> #REF! | J29: =TRUNC(I29*C29,0) -> #REF! | K29: =#REF! -> #REF! | L29: =TRUNC(K29*C29,0) -> #REF! | N29: #.2 | Q29: 40 | S29: Y00046 | U29: F | BJ29: =HYPERLINK("#일위대가목록!A4","Y00046 →") -> Y00046 →
A30: (2) 기존관철거 | E30: =G30+I30+K30 -> 0 | F30: =H30+J30+L30 -> #REF! | H30: =TRUNC(H31+H32+H33+H34,0) -> #REF! | J30: =TRUNC(J31+J32+J33+J34,0) -> #REF! | L30: =TRUNC(L31+L32+L33+L34,0) -> #REF! | Q30: 50
A31: - 강관절단 | B31: D800MM | C31: =#REF! -> #REF! | D31: 개소 | E31: =G31+I31+K31 -> #REF! | F31: =H31+J31+L31 -> #REF! | G31: =#REF! -> #REF! | H31: =TRUNC(G31*C31,0) -> #REF! | I31: =#REF! -> #REF! | J31: =TRUNC(I31*C31,0) -> #REF! | K31: =#REF! -> #REF! | L31: =TRUNC(K31*C31,0) -> #REF! | N31: No.1 | Q31: 60 | S31: Y0246663 | U31: T | BJ31: =HYPERLINK("#일위대가목록!A58","Y0246663 →") -> Y0246663 →
A32: - 강관절단 | B32: D900MM | C32: =#REF! -> #REF! | D32: 개소 | E32: =G32+I32+K32 -> #REF! | F32: =H32+J32+L32 -> #REF! | G32: =#REF! -> #REF! | H32: =TRUNC(G32*C32,0) -> #REF! | I32: =#REF! -> #REF! | J32: =TRUNC(I32*C32,0) -> #REF! | K32: =#REF! -> #REF! | L32: =TRUNC(K32*C32,0) -> #REF! | N32: No.2 | Q32: 70 | S32: Y0246664 | U32: T | BJ32: =HYPERLINK("#일위대가목록!A59","Y0246664 →") -> Y0246664 →
